5:return {{["x"] = 0, ["y"] = 3, ["param1"] = 14, ["z"] = 3, ["name"] = "default:leaves"}, {["x"] = 0, ["y"] = 4, ["param1"] = 14, ["z"] = 3, ["name"] = "default:leaves"}, {["x"] = 0, ["y"] = 4, ["param1"] = 14, ["z"] = 4, ["name"] = "default:leaves"}, {["x"] = 0, ["y"] = 5, ["param1"] = 14, ["z"] = 2, ["name"] = "default:leaves"}, {["x"] = 0, ["y"] = 5, ["param1"] = 14, ["z"] = 3, ["name"] = "default:leaves"}, {["x"] = 0, ["y"] = 6, ["param1"] = 14, ["z"] = 3, ["name"] = "default:leaves"}, {["x"] = 0, ["y"] = 6, ["param1"] = 14, ["z"] = 4, ["name"] = "default:leaves"}, {["x"] = 0, ["y"] = 7, ["param1"] = 14, ["z"] = 3, ["name"] = "default:leaves"}, {["x"] = 1, ["y"] = 2, ["param1"] = 13, ["z"] = 3, ["name"] = "default:leaves"}, {["x"] = 1, ["y"] = 2, ["param1"] = 13, ["z"] = 4, ["name"] = "default:leaves"}, {["x"] = 1, ["y"] = 3, ["param1"] = 13, ["z"] = 2, ["name"] = "default:leaves"}, {["x"] = 1, ["y"] = 3, ["param1"] = 13, ["z"] = 3, ["name"] = "default:leaves"}, {["x"] = 1, ["y"] = 3, ["param1"] = 13, ["z"] = 4, ["name"] = "default:leaves"}, {["x"] = 1, ["y"] = 3, ["param1"] = 14, ["z"] = 5, ["name"] = "default:leaves"}, {["x"] = 1, ["y"] = 4, ["param1"] = 14, ["z"] = 1, ["name"] = "default:leaves"}, {["x"] = 1, ["y"] = 4, ["param1"] = 13, ["z"] = 2, ["name"] = "default:leaves"}, {["x"] = 1, ["y"] = 4, ["param1"] = 13, ["z"] = 3, ["name"] = "default:leaves"}, {["x"] = 1, ["y"] = 4, ["param1"] = 13, ["z"] = 4, ["name"] = "default:leaves"}, {["x"] = 1, ["y"] = 4, ["param1"] = 14, ["z"] = 5, ["name"] = "default:leaves"}, {["x"] = 1, ["y"] = 5, ["param1"] = 13, ["z"] = 2, ["name"] = "default:leaves"}, {["x"] = 1, ["y"] = 5, ["param1"] = 13, ["z"] = 3, ["name"] = "default:leaves"}, {["x"] = 1, ["y"] = 5, ["param1"] = 13, ["z"] = 4, ["name"] = "default:leaves"}, {["x"] = 1, ["y"] = 6, ["param1"] = 14, ["z"] = 1, ["name"] = "default:leaves"}, {["x"] = 1, ["y"] = 6, ["param1"] = 14, ["z"] = 2, ["name"] = "default:leaves"}, {["x"] = 1, ["y"] = 6, ["param1"] = 13, ["z"] = 3, ["name"] = "default:leaves"}, {["x"] = 1, ["y"] = 6, ["param1"] = 13, ["z"] = 4, ["name"] = "default:leaves"}, {["x"] = 1, ["y"] = 6, ["param1"] = 14, ["z"] = 5, ["name"] = "default:leaves"}, {["x"] = 1, ["y"] = 7, ["param1"] = 14, ["z"] = 2, ["name"] = "default:leaves"}, {["x"] = 1, ["y"] = 7, ["param1"] = 13, ["z"] = 3, ["name"] = "default:leaves"}, {["x"] = 1, ["y"] = 7, ["param1"] = 14, ["z"] = 4, ["name"] = "default:leaves"}, {["x"] = 1, ["y"] = 7, ["param1"] = 14, ["z"] = 5, ["name"] = "default:leaves"}, {["x"] = 1, ["y"] = 8, ["param1"] = 14, ["z"] = 3, ["name"] = "default:leaves"}, {["x"] = 2, ["y"] = 2, ["param1"] = 12, ["z"] = 2, ["name"] = "default:leaves"}, {["x"] = 2, ["y"] = 2, ["param1"] = 12, ["z"] = 4, ["name"] = "default:leaves"}, {["x"] = 2, ["y"] = 2, ["param1"] = 13, ["z"] = 5, ["name"] = "default:leaves"}, {["x"] = 2, ["y"] = 3, ["param1"] = 13, ["z"] = 1, ["name"] = "default:leaves"}, {["x"] = 2, ["y"] = 3, ["param1"] = 12, ["z"] = 2, ["name"] = "default:leaves"}, {["x"] = 2, ["y"] = 3, ["param1"] = 12, ["z"] = 3, ["name"] = "default:leaves"}, {["x"] = 2, ["y"] = 3, ["param1"] = 12, ["z"] = 4, ["name"] = "default:leaves"}, {["x"] = 2, ["y"] = 3, ["param1"] = 13, ["z"] = 5, ["name"] = "default:leaves"}, {["x"] = 2, ["y"] = 4, ["param1"] = 14, ["z"] = 0, ["name"] = "default:leaves"}, {["x"] = 2, ["y"] = 4, ["param1"] = 13, ["z"] = 1, ["name"] = "default:leaves"}, {["x"] = 2, ["y"] = 4, ["param1"] = 12, ["z"] = 2, ["name"] = "default:leaves"}, {["x"] = 2, ["y"] = 4, ["param1"] = 12, ["z"] = 3, ["name"] = "default:leaves"}, {["x"] = 2, ["y"] = 4, ["param1"] = 12, ["z"] = 4, ["name"] = "default:leaves"}, {["x"] = 2, ["y"] = 4, ["param1"] = 13, ["z"] = 5, ["name"] = "default:leaves"}, {["x"] = 2, ["y"] = 4, ["param1"] = 14, ["z"] = 6, ["name"] = "default:leaves"}, {["x"] = 2, ["y"] = 5, ["param1"] = 14, ["z"] = 0, ["name"] = "default:leaves"}, {["x"] = 2, ["y"] = 5, ["param1"] = 13, ["z"] = 1, ["name"] = "default:leaves"}, {["x"] = 2, ["y"] = 5, ["param1"] = 12, ["z"] = 2, ["name"] = "default:leaves"}, {["x"] = 2, ["y"] = 5, ["param1"] = 12, ["z"] = 3, ["name"] = "default:leaves"}, {["x"] = 2, ["y"] = 5, ["param1"] = 12, ["z"] = 4, ["name"] = "default:leaves"}, {["x"] = 2, ["y"] = 5, ["param1"] = 13, ["z"] = 5, ["name"] = "default:leaves"}, {["x"] = 2, ["y"] = 5, ["param1"] = 14, ["z"] = 6, ["name"] = "default:leaves"}, {["x"] = 2, ["y"] = 6, ["param1"] = 14, ["z"] = 0, ["name"] = "default:leaves"}, {["x"] = 2, ["y"] = 6, ["param1"] = 13, ["z"] = 1, ["name"] = "default:leaves"}, {["x"] = 2, ["y"] = 6, ["param1"] = 13, ["z"] = 2, ["name"] = "default:leaves"}, {["x"] = 2, ["y"] = 6, ["param1"] = 13, ["z"] = 3, ["name"] = "default:leaves"}, {["x"] = 2, ["y"] = 6, ["param1"] = 12, ["z"] = 4, ["name"] = "default:leaves"}, {["x"] = 2, ["y"] = 6, ["param1"] = 13, ["z"] = 5, ["name"] = "default:leaves"}, {["x"] = 2, ["y"] = 6, ["param1"] = 14, ["z"] = 6, ["name"] = "default:leaves"}, {["x"] = 2, ["y"] = 7, ["param1"] = 14, ["z"] = 1, ["name"] = "default:leaves"}, {["x"] = 2, ["y"] = 7, ["param1"] = 13, ["z"] = 2, ["name"] = "default:leaves"}, {["x"] = 2, ["y"] = 7, ["param1"] = 14, ["z"] = 3, ["name"] = "default:leaves"}, {["x"] = 2, ["y"] = 7, ["param1"] = 13, ["z"] = 4, ["name"] = "default:leaves"}, {["x"] = 2, ["y"] = 7, ["param1"] = 14, ["z"] = 5, ["name"] = "default:leaves"}, {["x"] = 2, ["y"] = 8, ["param1"] = 14, ["z"] = 2, ["name"] = "default:leaves"}, {["x"] = 2, ["y"] = 8, ["param1"] = 14, ["z"] = 4, ["name"] = "default:leaves"}, {["x"] = 3, ["y"] = 0, ["z"] = 3, ["name"] = "default:tree"}, {["x"] = 3, ["y"] = 1, ["z"] = 3, ["name"] = "default:tree"}, {["x"] = 3, ["y"] = 2, ["param1"] = 13, ["z"] = 1, ["name"] = "default:leaves"}, {["x"] = 3, ["y"] = 2, ["param1"] = 43, ["z"] = 3, ["name"] = "default:tree"}, {["x"] = 3, ["y"] = 2, ["param1"] = 13, ["z"] = 5, ["name"] = "default:leaves"}, {["x"] = 3, ["y"] = 3, ["param1"] = 13, ["z"] = 1, ["name"] = "default:leaves"}, {["x"] = 3, ["y"] = 3, ["param1"] = 12, ["z"] = 2, ["name"] = "default:leaves"}, {["x"] = 3, ["y"] = 3, ["param1"] = 43, ["z"] = 3, ["name"] = "default:tree"}, {["x"] = 3, ["y"] = 3, ["param1"] = 12, ["z"] = 4, ["name"] = "default:leaves"}, {["x"] = 3, ["y"] = 3, ["param1"] = 13, ["z"] = 5, ["name"] = "default:leaves"}, {["x"] = 3, ["y"] = 4, ["param1"] = 14, ["z"] = 0, ["name"] = "default:leaves"}, {["x"] = 3, ["y"] = 4, ["param1"] = 13, ["z"] = 1, ["name"] = "default:leaves"}, {["x"] = 3, ["y"] = 4, ["param1"] = 12, ["z"] = 2, ["name"] = "default:leaves"}, {["x"] = 3, ["y"] = 4, ["param1"] = 43, ["z"] = 3, ["name"] = "default:tree"}, {["x"] = 3, ["y"] = 4, ["param1"] = 13, ["z"] = 5, ["name"] = "default:leaves"}, {["x"] = 3, ["y"] = 5, ["param1"] = 14, ["z"] = 0, ["name"] = "default:leaves"}, {["x"] = 3, ["y"] = 5, ["param1"] = 13, ["z"] = 1, ["name"] = "default:leaves"}, {["x"] = 3, ["y"] = 5, ["param1"] = 12, ["z"] = 2, ["name"] = "default:leaves"}, {["x"] = 3, ["y"] = 5, ["param1"] = 43, ["z"] = 3, ["name"] = "default:tree"}, {["x"] = 3, ["y"] = 5, ["param1"] = 12, ["z"] = 4, ["name"] = "default:leaves"}, {["x"] = 3, ["y"] = 5, ["param1"] = 13, ["z"] = 5, ["name"] = "default:leaves"}, {["x"] = 3, ["y"] = 5, ["param1"] = 14, ["z"] = 6, ["name"] = "default:leaves"}, {["x"] = 3, ["y"] = 6, ["param1"] = 13, ["z"] = 1, ["name"] = "default:leaves"}, {["x"] = 3, ["y"] = 6, ["param1"] = 12, ["z"] = 2, ["name"] = "default:leaves"}, {["x"] = 3, ["y"] = 6, ["param1"] = 12, ["z"] = 3, ["name"] = "default:leaves"}, {["x"] = 3, ["y"] = 6, ["param1"] = 13, ["z"] = 4, ["name"] = "default:leaves"}, {["x"] = 3, ["y"] = 6, ["param1"] = 13, ["z"] = 5, ["name"] = "default:leaves"}, {["x"] = 3, ["y"] = 7, ["param1"] = 14, ["z"] = 0, ["name"] = "default:leaves"}, {["x"] = 3, ["y"] = 7, ["param1"] = 13, ["z"] = 1, ["name"] = "default:leaves"}, {["x"] = 3, ["y"] = 7, ["param1"] = 13, ["z"] = 2, ["name"] = "default:leaves"}, {["x"] = 3, ["y"] = 7, ["param1"] = 13, ["z"] = 3, ["name"] = "default:leaves"}, {["x"] = 3, ["y"] = 7, ["param1"] = 14, ["z"] = 4, ["name"] = "default:leaves"}, {["x"] = 3, ["y"] = 7, ["param1"] = 13, ["z"] = 5, ["name"] = "default:leaves"}, {["x"] = 3, ["y"] = 7, ["param1"] = 14, ["z"] = 6, ["name"] = "default:leaves"}, {["x"] = 3, ["y"] = 8, ["param1"] = 14, ["z"] = 1, ["name"] = "default:leaves"}, {["x"] = 3, ["y"] = 8, ["param1"] = 14, ["z"] = 2, ["name"] = "default:leaves"}, {["x"] = 3, ["y"] = 8, ["param1"] = 14, ["z"] = 3, ["name"] = "default:leaves"}, {["x"] = 3, ["y"] = 8, ["param1"] = 14, ["z"] = 5, ["name"] = "default:leaves"}, {["x"] = 4, ["y"] = 2, ["param1"] = 12, ["z"] = 2, ["name"] = "default:leaves"}, {["x"] = 4, ["y"] = 2, ["param1"] = 12, ["z"] = 4, ["name"] = "default:leaves"}, {["x"] = 4, ["y"] = 3, ["param1"] = 13, ["z"] = 1, ["name"] = "default:leaves"}, {["x"] = 4, ["y"] = 3, ["param1"] = 12, ["z"] = 2, ["name"] = "default:leaves"}, {["x"] = 4, ["y"] = 3, ["param1"] = 12, ["z"] = 3, ["name"] = "default:leaves"}, {["x"] = 4, ["y"] = 3, ["param1"] = 12, ["z"] = 4, ["name"] = "default:leaves"}, {["x"] = 4, ["y"] = 3, ["param1"] = 13, ["z"] = 5, ["name"] = "default:leaves"}, {["x"] = 4, ["y"] = 4, ["param1"] = 14, ["z"] = 0, ["name"] = "default:leaves"}, {["x"] = 4, ["y"] = 4, ["param1"] = 13, ["z"] = 1, ["name"] = "default:leaves"}, {["x"] = 4, ["y"] = 4, ["param1"] = 12, ["z"] = 2, ["name"] = "default:leaves"}, {["x"] = 4, ["y"] = 4, ["param1"] = 12, ["z"] = 3, ["name"] = "default:leaves"}, {["x"] = 4, ["y"] = 4, ["param1"] = 12, ["z"] = 4, ["name"] = "default:leaves"}, {["x"] = 4, ["y"] = 4, ["param1"] = 13, ["z"] = 5, ["name"] = "default:leaves"}, {["x"] = 4, ["y"] = 4, ["param1"] = 14, ["z"] = 6, ["name"] = "default:leaves"}, {["x"] = 4, ["y"] = 5, ["param1"] = 14, ["z"] = 0, ["name"] = "default:leaves"}, {["x"] = 4, ["y"] = 5, ["param1"] = 13, ["z"] = 1, ["name"] = "default:leaves"}, {["x"] = 4, ["y"] = 5, ["param1"] = 12, ["z"] = 2, ["name"] = "default:leaves"}, {["x"] = 4, ["y"] = 5, ["param1"] = 12, ["z"] = 3, ["name"] = "default:leaves"}, {["x"] = 4, ["y"] = 5, ["param1"] = 12, ["z"] = 4, ["name"] = "default:leaves"}, {["x"] = 4, ["y"] = 5, ["param1"] = 13, ["z"] = 5, ["name"] = "default:leaves"}, {["x"] = 4, ["y"] = 5, ["param1"] = 14, ["z"] = 6, ["name"] = "default:leaves"}, {["x"] = 4, ["y"] = 6, ["param1"] = 14, ["z"] = 0, ["name"] = "default:leaves"}, {["x"] = 4, ["y"] = 6, ["param1"] = 13, ["z"] = 1, ["name"] = "default:leaves"}, {["x"] = 4, ["y"] = 6, ["param1"] = 12, ["z"] = 2, ["name"] = "default:leaves"}, {["x"] = 4, ["y"] = 6, ["param1"] = 13, ["z"] = 3, ["name"] = "default:leaves"}, {["x"] = 4, ["y"] = 6, ["param1"] = 12, ["z"] = 4, ["name"] = "default:leaves"}, {["x"] = 4, ["y"] = 6, ["param1"] = 13, ["z"] = 5, ["name"] = "default:leaves"}, {["x"] = 4, ["y"] = 6, ["param1"] = 14, ["z"] = 6, ["name"] = "default:leaves"}, {["x"] = 4, ["y"] = 7, ["param1"] = 14, ["z"] = 1, ["name"] = "default:leaves"}, {["x"] = 4, ["y"] = 7, ["param1"] = 13, ["z"] = 2, ["name"] = "default:leaves"}, {["x"] = 4, ["y"] = 7, ["param1"] = 14, ["z"] = 3, ["name"] = "default:leaves"}, {["x"] = 4, ["y"] = 7, ["param1"] = 13, ["z"] = 4, ["name"] = "default:leaves"}, {["x"] = 4, ["y"] = 7, ["param1"] = 14, ["z"] = 5, ["name"] = "default:leaves"}, {["x"] = 4, ["y"] = 8, ["param1"] = 14, ["z"] = 2, ["name"] = "default:leaves"}, {["x"] = 4, ["y"] = 8, ["param1"] = 14, ["z"] = 4, ["name"] = "default:leaves"}, {["x"] = 5, ["y"] = 2, ["param1"] = 13, ["z"] = 3, ["name"] = "default:leaves"}, {["x"] = 5, ["y"] = 3, ["param1"] = 13, ["z"] = 2, ["name"] = "default:leaves"}, {["x"] = 5, ["y"] = 3, ["param1"] = 13, ["z"] = 3, ["name"] = "default:leaves"}, {["x"] = 5, ["y"] = 3, ["param1"] = 13, ["z"] = 4, ["name"] = "default:leaves"}, {["x"] = 5, ["y"] = 4, ["param1"] = 14, ["z"] = 1, ["name"] = "default:leaves"}, {["x"] = 5, ["y"] = 4, ["param1"] = 13, ["z"] = 2, ["name"] = "default:leaves"}, {["x"] = 5, ["y"] = 4, ["param1"] = 13, ["z"] = 3, ["name"] = "default:leaves"}, {["x"] = 5, ["y"] = 4, ["param1"] = 13, ["z"] = 4, ["name"] = "default:leaves"}, {["x"] = 5, ["y"] = 4, ["param1"] = 14, ["z"] = 5, ["name"] = "default:leaves"}, {["x"] = 5, ["y"] = 5, ["param1"] = 14, ["z"] = 1, ["name"] = "default:leaves"}, {["x"] = 5, ["y"] = 5, ["param1"] = 13, ["z"] = 2, ["name"] = "default:leaves"}, {["x"] = 5, ["y"] = 5, ["param1"] = 13, ["z"] = 3, ["name"] = "default:leaves"}, {["x"] = 5, ["y"] = 5, ["param1"] = 13, ["z"] = 4, ["name"] = "default:leaves"}, {["x"] = 5, ["y"] = 5, ["param1"] = 14, ["z"] = 5, ["name"] = "default:leaves"}, {["x"] = 5, ["y"] = 6, ["param1"] = 14, ["z"] = 1, ["name"] = "default:leaves"}, {["x"] = 5, ["y"] = 6, ["param1"] = 13, ["z"] = 2, ["name"] = "default:leaves"}, {["x"] = 5, ["y"] = 6, ["param1"] = 13, ["z"] = 3, ["name"] = "default:leaves"}, {["x"] = 5, ["y"] = 6, ["param1"] = 13, ["z"] = 4, ["name"] = "default:leaves"}, {["x"] = 5, ["y"] = 6, ["param1"] = 14, ["z"] = 5, ["name"] = "default:leaves"}, {["x"] = 5, ["y"] = 7, ["param1"] = 14, ["z"] = 2, ["name"] = "default:leaves"}, {["x"] = 5, ["y"] = 7, ["param1"] = 13, ["z"] = 3, ["name"] = "default:leaves"}, {["x"] = 5, ["y"] = 7, ["param1"] = 14, ["z"] = 4, ["name"] = "default:leaves"}, {["x"] = 5, ["y"] = 7, ["param1"] = 14, ["z"] = 5, ["name"] = "default:leaves"}, {["x"] = 5, ["y"] = 8, ["param1"] = 14, ["z"] = 3, ["name"] = "default:leaves"}, {["x"] = 6, ["y"] = 3, ["param1"] = 14, ["z"] = 3, ["name"] = "default:leaves"}, {["x"] = 6, ["y"] = 4, ["param1"] = 14, ["z"] = 3, ["name"] = "default:leaves"}, {["x"] = 6, ["y"] = 5, ["param1"] = 14, ["z"] = 2, ["name"] = "default:leaves"}, {["x"] = 6, ["y"] = 5, ["param1"] = 14, ["z"] = 3, ["name"] = "default:leaves"}, {["x"] = 6, ["y"] = 5, ["param1"] = 14, ["z"] = 4, ["name"] = "default:leaves"}, {["x"] = 6, ["y"] = 6, ["param1"] = 14, ["z"] = 2, ["name"] = "default:leaves"}, {["x"] = 6, ["y"] = 6, ["param1"] = 14, ["z"] = 3, ["name"] = "default:leaves"}, {["x"] = 6, ["y"] = 6, ["param1"] = 14, ["z"] = 4, ["name"] = "default:leaves"}, {["x"] = 6, ["y"] = 7, ["param1"] = 14, ["z"] = 3, ["name"] = "default:leaves"}}