5:return {{["x"] = 1, ["y"] = 8, ["param1"] = 14, ["z"] = 4, ["name"] = "default:pine_bush_needles"}, {["x"] = 1, ["y"] = 12, ["param1"] = 14, ["z"] = 5, ["name"] = "default:pine_bush_needles"}, {["x"] = 2, ["y"] = 7, ["param1"] = 13, ["z"] = 4, ["name"] = "default:pine_bush_needles"}, {["x"] = 2, ["y"] = 8, ["param1"] = 14, ["z"] = 3, ["name"] = "default:pine_bush_needles"}, {["x"] = 2, ["y"] = 8, ["param1"] = 13, ["z"] = 4, ["name"] = "default:pine_bush_stem"}, {["x"] = 2, ["y"] = 8, ["param1"] = 13, ["z"] = 5, ["name"] = "default:pine_bush_needles"}, {["x"] = 2, ["y"] = 9, ["param1"] = 14, ["z"] = 4, ["name"] = "default:pine_bush_needles"}, {["x"] = 2, ["y"] = 11, ["param1"] = 13, ["z"] = 5, ["name"] = "default:pine_bush_needles"}, {["x"] = 2, ["y"] = 12, ["param1"] = 14, ["z"] = 4, ["name"] = "default:pine_bush_needles"}, {["x"] = 2, ["y"] = 12, ["param1"] = 13, ["z"] = 5, ["name"] = "default:pine_bush_stem"}, {["x"] = 2, ["y"] = 12, ["param1"] = 14, ["z"] = 6, ["name"] = "default:pine_bush_needles"}, {["x"] = 2, ["y"] = 13, ["param1"] = 14, ["z"] = 5, ["name"] = "default:pine_bush_needles"}, {["x"] = 2, ["y"] = 16, ["param1"] = 14, ["z"] = 4, ["name"] = "default:pine_bush_needles"}, {["x"] = 3, ["y"] = 7, ["param1"] = 13, ["z"] = 3, ["name"] = "default:pine_bush_needles"}, {["x"] = 3, ["y"] = 8, ["param1"] = 14, ["z"] = 2, ["name"] = "default:pine_bush_needles"}, {["x"] = 3, ["y"] = 8, ["param1"] = 13, ["z"] = 3, ["name"] = "default:pine_bush_stem"}, {["x"] = 3, ["param2"] = 18, ["y"] = 8, ["param1"] = 54, ["z"] = 4, ["name"] = "default:pine_tree"}, {["x"] = 3, ["y"] = 8, ["param1"] = 12, ["z"] = 5, ["name"] = "default:pine_bush_stem"}, {["x"] = 3, ["y"] = 8, ["param1"] = 13, ["z"] = 6, ["name"] = "default:pine_bush_needles"}, {["x"] = 3, ["y"] = 9, ["param1"] = 14, ["z"] = 3, ["name"] = "default:pine_bush_needles"}, {["x"] = 3, ["y"] = 9, ["param1"] = 13, ["z"] = 4, ["name"] = "default:pine_bush_stem"}, {["x"] = 3, ["y"] = 9, ["param1"] = 12, ["z"] = 5, ["name"] = "default:pine_bush_needles"}, {["x"] = 3, ["y"] = 10, ["param1"] = 13, ["z"] = 4, ["name"] = "default:pine_bush_needles"}, {["x"] = 3, ["y"] = 11, ["param1"] = 14, ["z"] = 2, ["name"] = "default:pine_bush_needles"}, {["x"] = 3, ["y"] = 11, ["param1"] = 14, ["z"] = 7, ["name"] = "default:pine_bush_needles"}, {["x"] = 3, ["y"] = 12, ["param1"] = 14, ["z"] = 3, ["name"] = "default:pine_bush_needles"}, {["x"] = 3, ["y"] = 12, ["param1"] = 13, ["z"] = 4, ["name"] = "default:pine_bush_stem"}, {["x"] = 3, ["param2"] = 18, ["y"] = 12, ["param1"] = 54, ["z"] = 5, ["name"] = "default:pine_tree"}, {["x"] = 3, ["y"] = 12, ["param1"] = 14, ["z"] = 6, ["name"] = "default:pine_bush_stem"}, {["x"] = 3, ["y"] = 13, ["param1"] = 13, ["z"] = 4, ["name"] = "default:pine_bush_needles"}, {["x"] = 3, ["y"] = 13, ["param1"] = 14, ["z"] = 6, ["name"] = "default:pine_bush_needles"}, {["x"] = 3, ["y"] = 14, ["param1"] = 14, ["z"] = 5, ["name"] = "default:pine_bush_needles"}, {["x"] = 3, ["y"] = 15, ["param1"] = 13, ["z"] = 4, ["name"] = "default:pine_bush_needles"}, {["x"] = 3, ["y"] = 16, ["param1"] = 14, ["z"] = 3, ["name"] = "default:pine_bush_needles"}, {["x"] = 3, ["y"] = 16, ["param1"] = 13, ["z"] = 4, ["name"] = "default:pine_bush_stem"}, {["x"] = 3, ["y"] = 16, ["param1"] = 14, ["z"] = 5, ["name"] = "default:pine_bush_needles"}, {["x"] = 3, ["y"] = 17, ["param1"] = 14, ["z"] = 4, ["name"] = "default:pine_bush_needles"}, {["x"] = 4, ["y"] = 6, ["param1"] = 13, ["z"] = 2, ["name"] = "default:pine_bush_needles"}, {["x"] = 4, ["y"] = 7, ["param1"] = 13, ["z"] = 7, ["name"] = "default:pine_bush_needles"}, {["x"] = 4, ["y"] = 8, ["param1"] = 12, ["z"] = 3, ["name"] = "default:pine_bush_needles"}, {["x"] = 4, ["param2"] = 18, ["y"] = 8, ["param1"] = 54, ["z"] = 4, ["name"] = "default:pine_tree"}, {["x"] = 4, ["y"] = 8, ["param1"] = 11, ["z"] = 5, ["name"] = "default:pine_bush_needles"}, {["x"] = 4, ["y"] = 9, ["param1"] = 12, ["z"] = 4, ["name"] = "default:pine_bush_needles"}, {["x"] = 4, ["y"] = 10, ["param1"] = 13, ["z"] = 7, ["name"] = "default:pine_bush_needles"}, {["x"] = 4, ["y"] = 11, ["param1"] = 14, ["z"] = 1, ["name"] = "default:pine_bush_needles"}, {["x"] = 4, ["y"] = 11, ["param1"] = 13, ["z"] = 2, ["name"] = "default:pine_bush_stem"}, {["x"] = 4, ["y"] = 11, ["param1"] = 12, ["z"] = 6, ["name"] = "default:pine_bush_needles"}, {["x"] = 4, ["y"] = 11, ["param1"] = 13, ["z"] = 7, ["name"] = "default:pine_bush_stem"}, {["x"] = 4, ["y"] = 11, ["param1"] = 14, ["z"] = 8, ["name"] = "default:pine_bush_needles"}, {["x"] = 4, ["y"] = 12, ["param1"] = 14, ["z"] = 2, ["name"] = "default:pine_bush_needles"}, {["x"] = 4, ["param2"] = 18, ["y"] = 12, ["param1"] = 54, ["z"] = 5, ["name"] = "default:pine_tree"}, {["x"] = 4, ["y"] = 12, ["param1"] = 14, ["z"] = 7, ["name"] = "default:pine_bush_needles"}, {["x"] = 4, ["y"] = 14, ["param1"] = 14, ["z"] = 2, ["name"] = "default:pine_bush_needles"}, {["x"] = 4, ["y"] = 14, ["param1"] = 12, ["z"] = 4, ["name"] = "default:pine_bush_needles"}, {["x"] = 4, ["y"] = 14, ["param1"] = 13, ["z"] = 5, ["name"] = "default:pine_bush_stem"}, {["x"] = 4, ["y"] = 14, ["param1"] = 14, ["z"] = 6, ["name"] = "default:pine_bush_needles"}, {["x"] = 4, ["y"] = 15, ["param1"] = 12, ["z"] = 4, ["name"] = "default:pine_bush_needles"}, {["x"] = 4, ["y"] = 15, ["param1"] = 13, ["z"] = 5, ["name"] = "default:pine_bush_needles"}, {["x"] = 4, ["y"] = 16, ["param1"] = 14, ["z"] = 2, ["name"] = "default:pine_bush_needles"}, {["x"] = 4, ["y"] = 16, ["param1"] = 13, ["z"] = 3, ["name"] = "default:pine_bush_stem"}, {["x"] = 4, ["param2"] = 18, ["y"] = 16, ["param1"] = 54, ["z"] = 4, ["name"] = "default:pine_tree"}, {["x"] = 4, ["y"] = 16, ["param1"] = 13, ["z"] = 5, ["name"] = "default:pine_bush_stem"}, {["x"] = 4, ["y"] = 16, ["param1"] = 14, ["z"] = 6, ["name"] = "default:pine_bush_needles"}, {["x"] = 4, ["y"] = 17, ["param1"] = 14, ["z"] = 3, ["name"] = "default:pine_bush_needles"}, {["x"] = 4, ["y"] = 17, ["param1"] = 13, ["z"] = 4, ["name"] = "default:pine_bush_stem"}, {["x"] = 4, ["y"] = 17, ["param1"] = 14, ["z"] = 5, ["name"] = "default:pine_bush_needles"}, {["x"] = 4, ["y"] = 18, ["param1"] = 14, ["z"] = 2, ["name"] = "default:pine_bush_needles"}, {["x"] = 4, ["y"] = 18, ["param1"] = 14, ["z"] = 4, ["name"] = "default:pine_bush_needles"}, {["x"] = 4, ["y"] = 19, ["param1"] = 14, ["z"] = 6, ["name"] = "default:pine_bush_needles"}, {["x"] = 5, ["y"] = 0, ["param1"] = 54, ["z"] = 5, ["name"] = "default:pine_tree"}, {["x"] = 5, ["y"] = 1, ["param1"] = 54, ["z"] = 5, ["name"] = "default:pine_tree"}, {["x"] = 5, ["y"] = 2, ["param1"] = 54, ["z"] = 5, ["name"] = "default:pine_tree"}, {["x"] = 5, ["y"] = 3, ["param1"] = 54, ["z"] = 5, ["name"] = "default:pine_tree"}, {["x"] = 5, ["y"] = 4, ["param1"] = 54, ["z"] = 5, ["name"] = "default:pine_tree"}, {["x"] = 5, ["y"] = 5, ["param1"] = 54, ["z"] = 5, ["name"] = "default:pine_tree"}, {["x"] = 5, ["y"] = 6, ["param1"] = 13, ["z"] = 1, ["name"] = "default:pine_bush_needles"}, {["x"] = 5, ["y"] = 6, ["param1"] = 12, ["z"] = 2, ["name"] = "default:pine_bush_stem"}, {["x"] = 5, ["y"] = 6, ["param1"] = 11, ["z"] = 3, ["name"] = "default:pine_bush_needles"}, {["x"] = 5, ["y"] = 6, ["param1"] = 54, ["z"] = 5, ["name"] = "default:pine_tree"}, {["x"] = 5, ["y"] = 6, ["param1"] = 12, ["z"] = 7, ["name"] = "default:pine_bush_needles"}, {["x"] = 5, ["y"] = 7, ["param1"] = 12, ["z"] = 2, ["name"] = "default:pine_bush_needles"}, {["x"] = 5, ["y"] = 7, ["param1"] = 54, ["z"] = 5, ["name"] = "default:pine_tree"}, {["x"] = 5, ["y"] = 7, ["param1"] = 11, ["z"] = 6, ["name"] = "default:pine_bush_needles"}, {["x"] = 5, ["y"] = 7, ["param1"] = 12, ["z"] = 7, ["name"] = "default:pine_bush_stem"}, {["x"] = 5, ["y"] = 7, ["param1"] = 13, ["z"] = 8, ["name"] = "default:pine_bush_needles"}, {["x"] = 5, ["param2"] = 18, ["y"] = 8, ["param1"] = 54, ["z"] = 4, ["name"] = "default:pine_tree"}, {["x"] = 5, ["y"] = 8, ["param1"] = 54, ["z"] = 5, ["name"] = "default:pine_tree"}, {["x"] = 5, ["y"] = 8, ["param1"] = 12, ["z"] = 7, ["name"] = "default:pine_bush_needles"}, {["x"] = 5, ["y"] = 9, ["param1"] = 54, ["z"] = 5, ["name"] = "default:pine_tree"}, {["x"] = 5, ["y"] = 10, ["param1"] = 13, ["z"] = 1, ["name"] = "default:pine_bush_needles"}, {["x"] = 5, ["y"] = 10, ["param1"] = 54, ["z"] = 5, ["name"] = "default:pine_tree"}, {["x"] = 5, ["y"] = 10, ["param1"] = 13, ["z"] = 8, ["name"] = "default:pine_bush_needles"}, {["x"] = 5, ["y"] = 11, ["param1"] = 14, ["z"] = 0, ["name"] = "default:pine_bush_needles"}, {["x"] = 5, ["y"] = 11, ["param1"] = 13, ["z"] = 1, ["name"] = "default:pine_bush_stem"}, {["x"] = 5, ["param2"] = 9, ["y"] = 11, ["param1"] = 54, ["z"] = 2, ["name"] = "default:pine_tree"}, {["x"] = 5, ["param2"] = 9, ["y"] = 11, ["param1"] = 54, ["z"] = 3, ["name"] = "default:pine_tree"}, {["x"] = 5, ["param2"] = 9, ["y"] = 11, ["param1"] = 54, ["z"] = 4, ["name"] = "default:pine_tree"}, {["x"] = 5, ["y"] = 11, ["param1"] = 54, ["z"] = 5, ["name"] = "default:pine_tree"}, {["x"] = 5, ["param2"] = 7, ["y"] = 11, ["param1"] = 54, ["z"] = 6, ["name"] = "default:pine_tree"}, {["x"] = 5, ["param2"] = 7, ["y"] = 11, ["param1"] = 54, ["z"] = 7, ["name"] = "default:pine_tree"}, {["x"] = 5, ["y"] = 11, ["param1"] = 13, ["z"] = 8, ["name"] = "default:pine_bush_stem"}, {["x"] = 5, ["y"] = 11, ["param1"] = 14, ["z"] = 9, ["name"] = "default:pine_bush_needles"}, {["x"] = 5, ["y"] = 12, ["param1"] = 13, ["z"] = 2, ["name"] = "default:pine_bush_needles"}, {["x"] = 5, ["y"] = 12, ["param1"] = 54, ["z"] = 5, ["name"] = "default:pine_tree"}, {["x"] = 5, ["y"] = 12, ["param1"] = 12, ["z"] = 6, ["name"] = "default:pine_bush_needles"}, {["x"] = 5, ["y"] = 12, ["param1"] = 13, ["z"] = 7, ["name"] = "default:pine_bush_stem"}, {["x"] = 5, ["y"] = 12, ["param1"] = 14, ["z"] = 8, ["name"] = "default:pine_bush_needles"}, {["x"] = 5, ["y"] = 13, ["param1"] = 12, ["z"] = 5, ["name"] = "default:pine_bush_needles"}, {["x"] = 5, ["y"] = 13, ["param1"] = 14, ["z"] = 7, ["name"] = "default:pine_bush_needles"}, {["x"] = 5, ["y"] = 14, ["param1"] = 14, ["z"] = 1, ["name"] = "default:pine_bush_needles"}, {["x"] = 5, ["y"] = 14, ["param1"] = 13, ["z"] = 2, ["name"] = "default:pine_bush_stem"}, {["x"] = 5, ["y"] = 14, ["param1"] = 12, ["z"] = 3, ["name"] = "default:pine_bush_needles"}, {["x"] = 5, ["y"] = 14, ["param1"] = 11, ["z"] = 4, ["name"] = "default:pine_bush_stem"}, {["x"] = 5, ["y"] = 14, ["param1"] = 12, ["z"] = 5, ["name"] = "default:pine_bush_stem"}, {["x"] = 5, ["y"] = 14, ["param1"] = 13, ["z"] = 6, ["name"] = "default:pine_bush_stem"}, {["x"] = 5, ["y"] = 14, ["param1"] = 14, ["z"] = 7, ["name"] = "default:pine_bush_needles"}, {["x"] = 5, ["y"] = 15, ["param1"] = 13, ["z"] = 2, ["name"] = "default:pine_bush_needles"}, {["x"] = 5, ["y"] = 15, ["param1"] = 11, ["z"] = 4, ["name"] = "default:pine_bush_needles"}, {["x"] = 5, ["y"] = 15, ["param1"] = 12, ["z"] = 5, ["name"] = "default:pine_bush_needles"}, {["x"] = 5, ["y"] = 15, ["param1"] = 13, ["z"] = 6, ["name"] = "default:pine_bush_needles"}, {["x"] = 5, ["y"] = 16, ["param1"] = 12, ["z"] = 3, ["name"] = "default:pine_bush_needles"}, {["x"] = 5, ["param2"] = 18, ["y"] = 16, ["param1"] = 54, ["z"] = 4, ["name"] = "default:pine_tree"}, {["x"] = 5, ["y"] = 16, ["param1"] = 12, ["z"] = 5, ["name"] = "default:pine_bush_needles"}, {["x"] = 5, ["y"] = 17, ["param1"] = 13, ["z"] = 2, ["name"] = "default:pine_bush_needles"}, {["x"] = 5, ["y"] = 17, ["param1"] = 12, ["z"] = 4, ["name"] = "default:pine_bush_needles"}, {["x"] = 5, ["y"] = 18, ["param1"] = 14, ["z"] = 1, ["name"] = "default:pine_bush_needles"}, {["x"] = 5, ["y"] = 18, ["param1"] = 13, ["z"] = 2, ["name"] = "default:pine_bush_stem"}, {["x"] = 5, ["y"] = 18, ["param1"] = 14, ["z"] = 3, ["name"] = "default:pine_bush_needles"}, {["x"] = 5, ["y"] = 19, ["param1"] = 14, ["z"] = 2, ["name"] = "default:pine_bush_needles"}, {["x"] = 5, ["y"] = 19, ["param1"] = 14, ["z"] = 5, ["name"] = "default:pine_bush_needles"}, {["x"] = 5, ["y"] = 19, ["param1"] = 13, ["z"] = 6, ["name"] = "default:pine_bush_stem"}, {["x"] = 5, ["y"] = 19, ["param1"] = 14, ["z"] = 7, ["name"] = "default:pine_bush_needles"}, {["x"] = 5, ["y"] = 20, ["param1"] = 14, ["z"] = 6, ["name"] = "default:pine_bush_needles"}, {["x"] = 5, ["y"] = 21, ["param1"] = 14, ["z"] = 3, ["name"] = "default:pine_bush_needles"}, {["x"] = 5, ["y"] = 21, ["param1"] = 14, ["z"] = 4, ["name"] = "default:pine_bush_stem"}, {["x"] = 5, ["y"] = 21, ["param1"] = 14, ["z"] = 5, ["name"] = "default:pine_bush_needles"}, {["x"] = 5, ["y"] = 22, ["param1"] = 14, ["z"] = 3, ["name"] = "default:pine_bush_needles"}, {["x"] = 5, ["y"] = 22, ["param1"] = 14, ["z"] = 4, ["name"] = "default:pine_bush_needles"}, {["x"] = 5, ["y"] = 22, ["param1"] = 14, ["z"] = 5, ["name"] = "default:pine_bush_needles"}, {["x"] = 5, ["y"] = 23, ["param1"] = 14, ["z"] = 4, ["name"] = "default:pine_bush_needles"}, {["x"] = 6, ["y"] = 0, ["param1"] = 54, ["z"] = 4, ["name"] = "default:pine_tree"}, {["x"] = 6, ["y"] = 1, ["param1"] = 54, ["z"] = 4, ["name"] = "default:pine_tree"}, {["x"] = 6, ["y"] = 2, ["param1"] = 54, ["z"] = 4, ["name"] = "default:pine_tree"}, {["x"] = 6, ["y"] = 3, ["param1"] = 54, ["z"] = 4, ["name"] = "default:pine_tree"}, {["x"] = 6, ["y"] = 4, ["param1"] = 54, ["z"] = 4, ["name"] = "default:pine_tree"}, {["x"] = 6, ["y"] = 5, ["param1"] = 13, ["z"] = 1, ["name"] = "default:pine_bush_needles"}, {["x"] = 6, ["y"] = 5, ["param1"] = 54, ["z"] = 4, ["name"] = "default:pine_tree"}, {["x"] = 6, ["param2"] = 18, ["y"] = 5, ["param1"] = 54, ["z"] = 5, ["name"] = "default:pine_tree"}, {["x"] = 6, ["y"] = 6, ["param1"] = 14, ["z"] = 0, ["name"] = "default:pine_bush_needles"}, {["x"] = 6, ["y"] = 6, ["param1"] = 13, ["z"] = 1, ["name"] = "default:pine_bush_stem"}, {["x"] = 6, ["param2"] = 9, ["y"] = 6, ["param1"] = 54, ["z"] = 2, ["name"] = "default:pine_tree"}, {["x"] = 6, ["param2"] = 9, ["y"] = 6, ["param1"] = 54, ["z"] = 3, ["name"] = "default:pine_tree"}, {["x"] = 6, ["y"] = 6, ["param1"] = 54, ["z"] = 4, ["name"] = "default:pine_tree"}, {["x"] = 6, ["y"] = 6, ["param1"] = 13, ["z"] = 8, ["name"] = "default:pine_bush_needles"}, {["x"] = 6, ["y"] = 7, ["param1"] = 13, ["z"] = 1, ["name"] = "default:pine_bush_needles"}, {["x"] = 6, ["y"] = 7, ["param1"] = 12, ["z"] = 2, ["name"] = "default:pine_bush_stem"}, {["x"] = 6, ["y"] = 7, ["param1"] = 11, ["z"] = 3, ["name"] = "default:pine_bush_needles"}, {["x"] = 6, ["y"] = 7, ["param1"] = 54, ["z"] = 4, ["name"] = "default:pine_tree"}, {["x"] = 6, ["param2"] = 7, ["y"] = 7, ["param1"] = 54, ["z"] = 5, ["name"] = "default:pine_tree"}, {["x"] = 6, ["param2"] = 7, ["y"] = 7, ["param1"] = 54, ["z"] = 6, ["name"] = "default:pine_tree"}, {["x"] = 6, ["param2"] = 7, ["y"] = 7, ["param1"] = 54, ["z"] = 7, ["name"] = "default:pine_tree"}, {["x"] = 6, ["y"] = 7, ["param1"] = 13, ["z"] = 8, ["name"] = "default:pine_bush_stem"}, {["x"] = 6, ["y"] = 7, ["param1"] = 14, ["z"] = 9, ["name"] = "default:pine_bush_needles"}, {["x"] = 6, ["y"] = 8, ["param1"] = 12, ["z"] = 2, ["name"] = "default:pine_bush_needles"}, {["x"] = 6, ["y"] = 8, ["param1"] = 54, ["z"] = 4, ["name"] = "default:pine_tree"}, {["x"] = 6, ["y"] = 8, ["param1"] = 13, ["z"] = 7, ["name"] = "default:pine_bush_needles"}, {["x"] = 6, ["y"] = 8, ["param1"] = 14, ["z"] = 8, ["name"] = "default:pine_bush_needles"}, {["x"] = 6, ["y"] = 9, ["param1"] = 54, ["z"] = 4, ["name"] = "default:pine_tree"}, {["x"] = 6, ["y"] = 10, ["param1"] = 54, ["z"] = 4, ["name"] = "default:pine_tree"}, {["x"] = 6, ["y"] = 10, ["param1"] = 13, ["z"] = 7, ["name"] = "default:pine_bush_needles"}, {["x"] = 6, ["y"] = 11, ["param1"] = 13, ["z"] = 1, ["name"] = "default:pine_bush_needles"}, {["x"] = 6, ["y"] = 11, ["param1"] = 12, ["z"] = 2, ["name"] = "default:pine_bush_stem"}, {["x"] = 6, ["y"] = 11, ["param1"] = 54, ["z"] = 4, ["name"] = "default:pine_tree"}, {["x"] = 6, ["y"] = 11, ["param1"] = 12, ["z"] = 6, ["name"] = "default:pine_bush_needles"}, {["x"] = 6, ["y"] = 11, ["param1"] = 13, ["z"] = 7, ["name"] = "default:pine_bush_stem"}, {["x"] = 6, ["y"] = 11, ["param1"] = 14, ["z"] = 8, ["name"] = "default:pine_bush_needles"}, {["x"] = 6, ["y"] = 12, ["param1"] = 12, ["z"] = 2, ["name"] = "default:pine_bush_needles"}, {["x"] = 6, ["y"] = 12, ["param1"] = 54, ["z"] = 4, ["name"] = "default:pine_tree"}, {["x"] = 6, ["y"] = 12, ["param1"] = 13, ["z"] = 7, ["name"] = "default:pine_bush_needles"}, {["x"] = 6, ["y"] = 13, ["param1"] = 12, ["z"] = 2, ["name"] = "default:pine_bush_needles"}, {["x"] = 6, ["y"] = 13, ["param1"] = 54, ["z"] = 4, ["name"] = "default:pine_tree"}, {["x"] = 6, ["y"] = 14, ["param1"] = 14, ["z"] = 0, ["name"] = "default:pine_bush_needles"}, {["x"] = 6, ["y"] = 14, ["param1"] = 13, ["z"] = 1, ["name"] = "default:pine_bush_stem"}, {["x"] = 6, ["y"] = 14, ["param1"] = 12, ["z"] = 2, ["name"] = "default:pine_bush_stem"}, {["x"] = 6, ["param2"] = 9, ["y"] = 14, ["param1"] = 54, ["z"] = 3, ["name"] = "default:pine_tree"}, {["x"] = 6, ["y"] = 14, ["param1"] = 54, ["z"] = 4, ["name"] = "default:pine_tree"}, {["x"] = 6, ["y"] = 14, ["param1"] = 12, ["z"] = 6, ["name"] = "default:pine_bush_needles"}, {["x"] = 6, ["y"] = 15, ["param1"] = 13, ["z"] = 1, ["name"] = "default:pine_bush_needles"}, {["x"] = 6, ["y"] = 15, ["param1"] = 12, ["z"] = 2, ["name"] = "default:pine_bush_needles"}, {["x"] = 6, ["y"] = 15, ["param1"] = 54, ["z"] = 4, ["name"] = "default:pine_tree"}, {["x"] = 6, ["param2"] = 12, ["y"] = 15, ["param1"] = 54, ["z"] = 5, ["name"] = "default:pine_tree"}, {["x"] = 6, ["y"] = 16, ["param1"] = 54, ["z"] = 4, ["name"] = "default:pine_tree"}, {["x"] = 6, ["y"] = 17, ["param1"] = 12, ["z"] = 2, ["name"] = "default:pine_bush_needles"}, {["x"] = 6, ["y"] = 17, ["param1"] = 54, ["z"] = 4, ["name"] = "default:pine_tree"}, {["x"] = 6, ["y"] = 18, ["param1"] = 14, ["z"] = 0, ["name"] = "default:pine_bush_needles"}, {["x"] = 6, ["y"] = 18, ["param1"] = 13, ["z"] = 1, ["name"] = "default:pine_bush_stem"}, {["x"] = 6, ["y"] = 18, ["param1"] = 13, ["z"] = 2, ["name"] = "default:pine_bush_stem"}, {["x"] = 6, ["param2"] = 9, ["y"] = 18, ["param1"] = 54, ["z"] = 3, ["name"] = "default:pine_tree"}, {["x"] = 6, ["y"] = 18, ["param1"] = 54, ["z"] = 4, ["name"] = "default:pine_tree"}, {["x"] = 6, ["y"] = 18, ["param1"] = 12, ["z"] = 6, ["name"] = "default:pine_bush_needles"}, {["x"] = 6, ["y"] = 19, ["param1"] = 14, ["z"] = 1, ["name"] = "default:pine_bush_needles"}, {["x"] = 6, ["y"] = 19, ["param1"] = 14, ["z"] = 2, ["name"] = "default:pine_bush_needles"}, {["x"] = 6, ["y"] = 19, ["param1"] = 54, ["z"] = 4, ["name"] = "default:pine_tree"}, {["x"] = 6, ["param2"] = 7, ["y"] = 19, ["param1"] = 54, ["z"] = 5, ["name"] = "default:pine_tree"}, {["x"] = 6, ["y"] = 19, ["param1"] = 13, ["z"] = 6, ["name"] = "default:pine_bush_stem"}, {["x"] = 6, ["y"] = 19, ["param1"] = 13, ["z"] = 7, ["name"] = "default:pine_bush_stem"}, {["x"] = 6, ["y"] = 19, ["param1"] = 14, ["z"] = 8, ["name"] = "default:pine_bush_needles"}, {["x"] = 6, ["param2"] = 2, ["y"] = 20, ["param1"] = 54, ["z"] = 4, ["name"] = "default:pine_tree"}, {["x"] = 6, ["y"] = 20, ["param1"] = 13, ["z"] = 5, ["name"] = "default:pine_bush_needles"}, {["x"] = 6, ["y"] = 20, ["param1"] = 14, ["z"] = 6, ["name"] = "default:pine_bush_needles"}, {["x"] = 6, ["y"] = 20, ["param1"] = 14, ["z"] = 7, ["name"] = "default:pine_bush_needles"}, {["x"] = 6, ["y"] = 21, ["param1"] = 14, ["z"] = 3, ["name"] = "default:pine_bush_stem"}, {["x"] = 6, ["param2"] = 3, ["y"] = 21, ["param1"] = 54, ["z"] = 4, ["name"] = "default:pine_tree"}, {["x"] = 6, ["y"] = 21, ["param1"] = 14, ["z"] = 5, ["name"] = "default:pine_bush_stem"}, {["x"] = 6, ["y"] = 22, ["param1"] = 14, ["z"] = 3, ["name"] = "default:pine_bush_needles"}, {["x"] = 6, ["y"] = 22, ["param1"] = 13, ["z"] = 4, ["name"] = "default:pine_bush_stem"}, {["x"] = 6, ["y"] = 22, ["param1"] = 14, ["z"] = 5, ["name"] = "default:pine_bush_needles"}, {["x"] = 6, ["y"] = 23, ["param1"] = 14, ["z"] = 3, ["name"] = "default:pine_bush_needles"}, {["x"] = 6, ["y"] = 23, ["param1"] = 13, ["z"] = 4, ["name"] = "default:pine_bush_stem"}, {["x"] = 6, ["y"] = 23, ["param1"] = 14, ["z"] = 5, ["name"] = "default:pine_bush_needles"}, {["x"] = 6, ["y"] = 24, ["param1"] = 14, ["z"] = 4, ["name"] = "default:pine_bush_needles"}, {["x"] = 7, ["y"] = 5, ["param1"] = 13, ["z"] = 2, ["name"] = "default:pine_bush_needles"}, {["x"] = 7, ["param2"] = 12, ["y"] = 5, ["param1"] = 54, ["z"] = 5, ["name"] = "default:pine_tree"}, {["x"] = 7, ["y"] = 5, ["param1"] = 12, ["z"] = 6, ["name"] = "default:pine_bush_needles"}, {["x"] = 7, ["y"] = 6, ["param1"] = 14, ["z"] = 1, ["name"] = "default:pine_bush_needles"}, {["x"] = 7, ["y"] = 6, ["param1"] = 13, ["z"] = 2, ["name"] = "default:pine_bush_stem"}, {["x"] = 7, ["y"] = 6, ["param1"] = 12, ["z"] = 3, ["name"] = "default:pine_bush_needles"}, {["x"] = 7, ["y"] = 6, ["param1"] = 13, ["z"] = 7, ["name"] = "default:pine_bush_needles"}, {["x"] = 7, ["y"] = 7, ["param1"] = 13, ["z"] = 2, ["name"] = "default:pine_bush_needles"}, {["x"] = 7, ["y"] = 7, ["param1"] = 12, ["z"] = 6, ["name"] = "default:pine_bush_needles"}, {["x"] = 7, ["y"] = 7, ["param1"] = 13, ["z"] = 7, ["name"] = "default:pine_bush_stem"}, {["x"] = 7, ["y"] = 7, ["param1"] = 14, ["z"] = 8, ["name"] = "default:pine_bush_needles"}, {["x"] = 7, ["y"] = 8, ["param1"] = 14, ["z"] = 7, ["name"] = "default:pine_bush_needles"}, {["x"] = 7, ["param2"] = 12, ["y"] = 10, ["param1"] = 54, ["z"] = 4, ["name"] = "default:pine_tree"}, {["x"] = 7, ["y"] = 11, ["param1"] = 13, ["z"] = 2, ["name"] = "default:pine_bush_needles"}, {["x"] = 7, ["y"] = 11, ["param1"] = 14, ["z"] = 7, ["name"] = "default:pine_bush_needles"}, {["x"] = 7, ["y"] = 14, ["param1"] = 14, ["z"] = 1, ["name"] = "default:pine_bush_needles"}, {["x"] = 7, ["y"] = 14, ["param1"] = 13, ["z"] = 2, ["name"] = "default:pine_bush_stem"}, {["x"] = 7, ["y"] = 14, ["param1"] = 14, ["z"] = 3, ["name"] = "default:pine_bush_needles"}, {["x"] = 7, ["y"] = 15, ["param1"] = 13, ["z"] = 2, ["name"] = "default:pine_bush_needles"}, {["x"] = 7, ["param2"] = 12, ["y"] = 15, ["param1"] = 54, ["z"] = 5, ["name"] = "default:pine_tree"}, {["x"] = 7, ["y"] = 15, ["param1"] = 13, ["z"] = 6, ["name"] = "default:pine_bush_needles"}, {["x"] = 7, ["y"] = 18, ["param1"] = 14, ["z"] = 1, ["name"] = "default:pine_bush_needles"}, {["x"] = 7, ["y"] = 18, ["param1"] = 13, ["z"] = 2, ["name"] = "default:pine_bush_stem"}, {["x"] = 7, ["y"] = 18, ["param1"] = 14, ["z"] = 3, ["name"] = "default:pine_bush_needles"}, {["x"] = 7, ["y"] = 19, ["param1"] = 14, ["z"] = 2, ["name"] = "default:pine_bush_needles"}, {["x"] = 7, ["y"] = 19, ["param1"] = 14, ["z"] = 5, ["name"] = "default:pine_bush_needles"}, {["x"] = 7, ["y"] = 19, ["param1"] = 13, ["z"] = 6, ["name"] = "default:pine_bush_stem"}, {["x"] = 7, ["y"] = 19, ["param1"] = 14, ["z"] = 7, ["name"] = "default:pine_bush_needles"}, {["x"] = 7, ["y"] = 20, ["param1"] = 14, ["z"] = 6, ["name"] = "default:pine_bush_needles"}, {["x"] = 7, ["y"] = 21, ["param1"] = 14, ["z"] = 3, ["name"] = "default:pine_bush_needles"}, {["x"] = 7, ["y"] = 21, ["param1"] = 14, ["z"] = 4, ["name"] = "default:pine_bush_stem"}, {["x"] = 7, ["y"] = 21, ["param1"] = 14, ["z"] = 5, ["name"] = "default:pine_bush_needles"}, {["x"] = 7, ["y"] = 22, ["param1"] = 14, ["z"] = 3, ["name"] = "default:pine_bush_needles"}, {["x"] = 7, ["y"] = 22, ["param1"] = 14, ["z"] = 4, ["name"] = "default:pine_bush_needles"}, {["x"] = 7, ["y"] = 22, ["param1"] = 14, ["z"] = 5, ["name"] = "default:pine_bush_needles"}, {["x"] = 7, ["y"] = 23, ["param1"] = 14, ["z"] = 4, ["name"] = "default:pine_bush_needles"}, {["x"] = 8, ["y"] = 4, ["param1"] = 13, ["z"] = 6, ["name"] = "default:pine_bush_needles"}, {["x"] = 8, ["y"] = 5, ["param1"] = 13, ["z"] = 3, ["name"] = "default:pine_bush_needles"}, {["x"] = 8, ["y"] = 5, ["param1"] = 12, ["z"] = 4, ["name"] = "default:pine_bush_stem"}, {["x"] = 8, ["param2"] = 12, ["y"] = 5, ["param1"] = 54, ["z"] = 5, ["name"] = "default:pine_tree"}, {["x"] = 8, ["y"] = 5, ["param1"] = 13, ["z"] = 6, ["name"] = "default:pine_bush_stem"}, {["x"] = 8, ["y"] = 5, ["param1"] = 14, ["z"] = 7, ["name"] = "default:pine_bush_needles"}, {["x"] = 8, ["y"] = 6, ["param1"] = 14, ["z"] = 2, ["name"] = "default:pine_bush_needles"}, {["x"] = 8, ["y"] = 6, ["param1"] = 12, ["z"] = 4, ["name"] = "default:pine_bush_needles"}, {["x"] = 8, ["y"] = 6, ["param1"] = 12, ["z"] = 5, ["name"] = "default:pine_bush_needles"}, {["x"] = 8, ["y"] = 6, ["param1"] = 13, ["z"] = 6, ["name"] = "default:pine_bush_needles"}, {["x"] = 8, ["y"] = 7, ["param1"] = 14, ["z"] = 7, ["name"] = "default:pine_bush_needles"}, {["x"] = 8, ["y"] = 10, ["param1"] = 14, ["z"] = 2, ["name"] = "default:pine_bush_needles"}, {["x"] = 8, ["y"] = 10, ["param1"] = 13, ["z"] = 3, ["name"] = "default:pine_bush_stem"}, {["x"] = 8, ["param2"] = 12, ["y"] = 10, ["param1"] = 54, ["z"] = 4, ["name"] = "default:pine_tree"}, {["x"] = 8, ["y"] = 10, ["param1"] = 12, ["z"] = 5, ["name"] = "default:pine_bush_stem"}, {["x"] = 8, ["y"] = 10, ["param1"] = 13, ["z"] = 6, ["name"] = "default:pine_bush_needles"}, {["x"] = 8, ["y"] = 11, ["param1"] = 14, ["z"] = 3, ["name"] = "default:pine_bush_needles"}, {["x"] = 8, ["y"] = 11, ["param1"] = 12, ["z"] = 5, ["name"] = "default:pine_bush_needles"}, {["x"] = 8, ["y"] = 14, ["param1"] = 14, ["z"] = 2, ["name"] = "default:pine_bush_needles"}, {["x"] = 8, ["y"] = 14, ["param1"] = 13, ["z"] = 5, ["name"] = "default:pine_bush_needles"}, {["x"] = 8, ["y"] = 15, ["param1"] = 14, ["z"] = 4, ["name"] = "default:pine_bush_needles"}, {["x"] = 8, ["y"] = 15, ["param1"] = 13, ["z"] = 5, ["name"] = "default:pine_bush_stem"}, {["x"] = 8, ["y"] = 15, ["param1"] = 13, ["z"] = 6, ["name"] = "default:pine_bush_stem"}, {["x"] = 8, ["y"] = 15, ["param1"] = 14, ["z"] = 7, ["name"] = "default:pine_bush_needles"}, {["x"] = 8, ["y"] = 16, ["param1"] = 14, ["z"] = 5, ["name"] = "default:pine_bush_needles"}, {["x"] = 8, ["y"] = 16, ["param1"] = 14, ["z"] = 6, ["name"] = "default:pine_bush_needles"}, {["x"] = 8, ["y"] = 18, ["param1"] = 14, ["z"] = 2, ["name"] = "default:pine_bush_needles"}, {["x"] = 8, ["y"] = 19, ["param1"] = 14, ["z"] = 6, ["name"] = "default:pine_bush_needles"}, {["x"] = 9, ["y"] = 4, ["param1"] = 13, ["z"] = 5, ["name"] = "default:pine_bush_needles"}, {["x"] = 9, ["y"] = 5, ["param1"] = 13, ["z"] = 4, ["name"] = "default:pine_bush_needles"}, {["x"] = 9, ["y"] = 5, ["param1"] = 13, ["z"] = 5, ["name"] = "default:pine_bush_stem"}, {["x"] = 9, ["y"] = 5, ["param1"] = 14, ["z"] = 6, ["name"] = "default:pine_bush_needles"}, {["x"] = 9, ["y"] = 6, ["param1"] = 13, ["z"] = 5, ["name"] = "default:pine_bush_needles"}, {["x"] = 9, ["y"] = 9, ["param1"] = 13, ["z"] = 4, ["name"] = "default:pine_bush_needles"}, {["x"] = 9, ["y"] = 10, ["param1"] = 14, ["z"] = 3, ["name"] = "default:pine_bush_needles"}, {["x"] = 9, ["y"] = 10, ["param1"] = 13, ["z"] = 4, ["name"] = "default:pine_bush_stem"}, {["x"] = 9, ["y"] = 10, ["param1"] = 13, ["z"] = 5, ["name"] = "default:pine_bush_needles"}, {["x"] = 9, ["y"] = 11, ["param1"] = 14, ["z"] = 4, ["name"] = "default:pine_bush_needles"}, {["x"] = 9, ["y"] = 15, ["param1"] = 14, ["z"] = 4, ["name"] = "default:pine_bush_needles"}, {["x"] = 9, ["y"] = 15, ["param1"] = 13, ["z"] = 5, ["name"] = "default:pine_bush_stem"}, {["x"] = 9, ["y"] = 15, ["param1"] = 14, ["z"] = 6, ["name"] = "default:pine_bush_needles"}, {["x"] = 9, ["y"] = 16, ["param1"] = 14, ["z"] = 5, ["name"] = "default:pine_bush_needles"}, {["x"] = 10, ["y"] = 5, ["param1"] = 14, ["z"] = 5, ["name"] = "default:pine_bush_needles"}, {["x"] = 10, ["y"] = 10, ["param1"] = 14, ["z"] = 4, ["name"] = "default:pine_bush_needles"}, {["x"] = 10, ["y"] = 15, ["param1"] = 14, ["z"] = 5, ["name"] = "default:pine_bush_needles"}}