5:return {{["x"] = 0, ["y"] = 8, ["param1"] = 14, ["z"] = 11, ["name"] = "default:pine_needles"}, {["x"] = 1, ["y"] = 7, ["param1"] = 14, ["z"] = 10, ["name"] = "default:pine_needles"}, {["x"] = 1, ["y"] = 7, ["param1"] = 13, ["z"] = 11, ["name"] = "default:pine_needles"}, {["x"] = 1, ["y"] = 8, ["param1"] = 14, ["z"] = 10, ["name"] = "default:pine_needles"}, {["x"] = 1, ["y"] = 8, ["param1"] = 13, ["z"] = 11, ["name"] = "default:pine_needles"}, {["x"] = 1, ["y"] = 8, ["param1"] = 14, ["z"] = 12, ["name"] = "default:pine_needles"}, {["x"] = 1, ["y"] = 9, ["param1"] = 14, ["z"] = 11, ["name"] = "default:pine_needles"}, {["x"] = 1, ["y"] = 13, ["param1"] = 14, ["z"] = 8, ["name"] = "default:pine_needles"}, {["x"] = 2, ["y"] = 6, ["param1"] = 13, ["z"] = 10, ["name"] = "default:pine_needles"}, {["x"] = 2, ["y"] = 6, ["param1"] = 12, ["z"] = 11, ["name"] = "default:pine_needles"}, {["x"] = 2, ["y"] = 7, ["param1"] = 14, ["z"] = 9, ["name"] = "default:pine_needles"}, {["x"] = 2, ["y"] = 7, ["param1"] = 13, ["z"] = 10, ["name"] = "default:pine_needles"}, {["x"] = 2, ["y"] = 7, ["param1"] = 12, ["z"] = 11, ["name"] = "default:pine_needles"}, {["x"] = 2, ["y"] = 7, ["param1"] = 13, ["z"] = 12, ["name"] = "default:pine_needles"}, {["x"] = 2, ["y"] = 8, ["param1"] = 13, ["z"] = 8, ["name"] = "default:pine_needles"}, {["x"] = 2, ["y"] = 8, ["param1"] = 14, ["z"] = 9, ["name"] = "default:pine_needles"}, {["x"] = 2, ["y"] = 8, ["param1"] = 13, ["z"] = 10, ["name"] = "default:pine_needles"}, {["x"] = 2, ["y"] = 8, ["param1"] = 13, ["z"] = 11, ["name"] = "default:pine_needles"}, {["x"] = 2, ["y"] = 8, ["param1"] = 13, ["z"] = 12, ["name"] = "default:pine_needles"}, {["x"] = 2, ["y"] = 8, ["param1"] = 14, ["z"] = 13, ["name"] = "default:pine_needles"}, {["x"] = 2, ["y"] = 9, ["param1"] = 14, ["z"] = 10, ["name"] = "default:pine_needles"}, {["x"] = 2, ["y"] = 9, ["param1"] = 14, ["z"] = 11, ["name"] = "default:pine_needles"}, {["x"] = 2, ["y"] = 9, ["param1"] = 14, ["z"] = 12, ["name"] = "default:pine_needles"}, {["x"] = 2, ["y"] = 12, ["param1"] = 14, ["z"] = 7, ["name"] = "default:pine_needles"}, {["x"] = 2, ["y"] = 12, ["param1"] = 13, ["z"] = 8, ["name"] = "default:pine_needles"}, {["x"] = 2, ["y"] = 13, ["param1"] = 14, ["z"] = 7, ["name"] = "default:pine_needles"}, {["x"] = 2, ["y"] = 13, ["param1"] = 13, ["z"] = 8, ["name"] = "default:pine_needles"}, {["x"] = 2, ["y"] = 13, ["param1"] = 14, ["z"] = 9, ["name"] = "default:pine_needles"}, {["x"] = 2, ["y"] = 14, ["param1"] = 14, ["z"] = 8, ["name"] = "default:pine_needles"}, {["x"] = 3, ["y"] = 6, ["param1"] = 13, ["z"] = 9, ["name"] = "default:pine_needles"}, {["x"] = 3, ["y"] = 6, ["param1"] = 12, ["z"] = 10, ["name"] = "default:pine_needles"}, {["x"] = 3, ["y"] = 6, ["param1"] = 11, ["z"] = 11, ["name"] = "default:pine_needles"}, {["x"] = 3, ["y"] = 6, ["param1"] = 12, ["z"] = 12, ["name"] = "default:pine_needles"}, {["x"] = 3, ["y"] = 7, ["param1"] = 13, ["z"] = 7, ["name"] = "default:pine_needles"}, {["x"] = 3, ["y"] = 7, ["param1"] = 12, ["z"] = 8, ["name"] = "default:pine_needles"}, {["x"] = 3, ["y"] = 7, ["param1"] = 13, ["z"] = 9, ["name"] = "default:pine_needles"}, {["x"] = 3, ["param2"] = 18, ["y"] = 7, ["param1"] = 54, ["z"] = 10, ["name"] = "default:pine_tree"}, {["x"] = 3, ["y"] = 7, ["param1"] = 11, ["z"] = 11, ["name"] = "default:pine_needles"}, {["x"] = 3, ["y"] = 7, ["param1"] = 12, ["z"] = 12, ["name"] = "default:pine_needles"}, {["x"] = 3, ["y"] = 7, ["param1"] = 13, ["z"] = 13, ["name"] = "default:pine_needles"}, {["x"] = 3, ["y"] = 8, ["param1"] = 12, ["z"] = 8, ["name"] = "default:pine_needles"}, {["x"] = 3, ["y"] = 8, ["param1"] = 13, ["z"] = 9, ["name"] = "default:pine_needles"}, {["x"] = 3, ["y"] = 8, ["param1"] = 12, ["z"] = 10, ["name"] = "default:pine_needles"}, {["x"] = 3, ["y"] = 8, ["param1"] = 12, ["z"] = 11, ["name"] = "default:pine_needles"}, {["x"] = 3, ["y"] = 8, ["param1"] = 13, ["z"] = 12, ["name"] = "default:pine_needles"}, {["x"] = 3, ["y"] = 8, ["param1"] = 13, ["z"] = 13, ["name"] = "default:pine_needles"}, {["x"] = 3, ["y"] = 8, ["param1"] = 14, ["z"] = 14, ["name"] = "default:pine_needles"}, {["x"] = 3, ["y"] = 9, ["param1"] = 13, ["z"] = 9, ["name"] = "default:pine_needles"}, {["x"] = 3, ["y"] = 9, ["param1"] = 13, ["z"] = 10, ["name"] = "default:pine_needles"}, {["x"] = 3, ["y"] = 9, ["param1"] = 13, ["z"] = 11, ["name"] = "default:pine_needles"}, {["x"] = 3, ["y"] = 9, ["param1"] = 14, ["z"] = 12, ["name"] = "default:pine_needles"}, {["x"] = 3, ["y"] = 9, ["param1"] = 14, ["z"] = 13, ["name"] = "default:pine_needles"}, {["x"] = 3, ["y"] = 11, ["param1"] = 12, ["z"] = 8, ["name"] = "default:pine_needles"}, {["x"] = 3, ["y"] = 12, ["param1"] = 13, ["z"] = 7, ["name"] = "default:pine_needles"}, {["x"] = 3, ["y"] = 12, ["param1"] = 12, ["z"] = 8, ["name"] = "default:pine_needles"}, {["x"] = 3, ["y"] = 12, ["param1"] = 13, ["z"] = 9, ["name"] = "default:pine_needles"}, {["x"] = 3, ["y"] = 13, ["param1"] = 14, ["z"] = 6, ["name"] = "default:pine_needles"}, {["x"] = 3, ["y"] = 13, ["param1"] = 13, ["z"] = 7, ["name"] = "default:pine_needles"}, {["x"] = 3, ["y"] = 13, ["param1"] = 13, ["z"] = 8, ["name"] = "default:pine_needles"}, {["x"] = 3, ["y"] = 13, ["param1"] = 13, ["z"] = 9, ["name"] = "default:pine_needles"}, {["x"] = 3, ["y"] = 13, ["param1"] = 14, ["z"] = 10, ["name"] = "default:pine_needles"}, {["x"] = 3, ["y"] = 14, ["param1"] = 14, ["z"] = 7, ["name"] = "default:pine_needles"}, {["x"] = 3, ["y"] = 14, ["param1"] = 14, ["z"] = 8, ["name"] = "default:pine_needles"}, {["x"] = 3, ["y"] = 14, ["param1"] = 14, ["z"] = 9, ["name"] = "default:pine_needles"}, {["x"] = 3, ["y"] = 17, ["param1"] = 14, ["z"] = 10, ["name"] = "default:pine_needles"}, {["x"] = 3, ["y"] = 17, ["param1"] = 14, ["z"] = 11, ["name"] = "default:pine_needles"}, {["x"] = 3, ["y"] = 18, ["param1"] = 14, ["z"] = 10, ["name"] = "default:pine_needles"}, {["x"] = 4, ["y"] = 6, ["param1"] = 12, ["z"] = 8, ["name"] = "default:pine_needles"}, {["x"] = 4, ["y"] = 6, ["param1"] = 12, ["z"] = 9, ["name"] = "default:pine_needles"}, {["x"] = 4, ["y"] = 6, ["param1"] = 11, ["z"] = 10, ["name"] = "default:pine_needles"}, {["x"] = 4, ["y"] = 6, ["param1"] = 12, ["z"] = 12, ["name"] = "default:pine_needles"}, {["x"] = 4, ["y"] = 7, ["param1"] = 13, ["z"] = 7, ["name"] = "default:pine_needles"}, {["x"] = 4, ["y"] = 7, ["param1"] = 12, ["z"] = 8, ["name"] = "default:pine_needles"}, {["x"] = 4, ["y"] = 7, ["param1"] = 12, ["z"] = 9, ["name"] = "default:pine_needles"}, {["x"] = 4, ["param2"] = 18, ["y"] = 7, ["param1"] = 54, ["z"] = 10, ["name"] = "default:pine_tree"}, {["x"] = 4, ["y"] = 7, ["param1"] = 11, ["z"] = 11, ["name"] = "default:pine_needles"}, {["x"] = 4, ["y"] = 7, ["param1"] = 12, ["z"] = 12, ["name"] = "default:pine_needles"}, {["x"] = 4, ["y"] = 7, ["param1"] = 13, ["z"] = 13, ["name"] = "default:pine_needles"}, {["x"] = 4, ["y"] = 8, ["param1"] = 12, ["z"] = 8, ["name"] = "default:pine_needles"}, {["x"] = 4, ["y"] = 8, ["param1"] = 12, ["z"] = 9, ["name"] = "default:pine_needles"}, {["x"] = 4, ["y"] = 8, ["param1"] = 11, ["z"] = 10, ["name"] = "default:pine_needles"}, {["x"] = 4, ["y"] = 8, ["param1"] = 11, ["z"] = 11, ["name"] = "default:pine_needles"}, {["x"] = 4, ["y"] = 8, ["param1"] = 12, ["z"] = 12, ["name"] = "default:pine_needles"}, {["x"] = 4, ["y"] = 8, ["param1"] = 13, ["z"] = 13, ["name"] = "default:pine_needles"}, {["x"] = 4, ["y"] = 8, ["param1"] = 14, ["z"] = 14, ["name"] = "default:pine_needles"}, {["x"] = 4, ["y"] = 9, ["param1"] = 12, ["z"] = 9, ["name"] = "default:pine_needles"}, {["x"] = 4, ["y"] = 9, ["param1"] = 12, ["z"] = 10, ["name"] = "default:pine_needles"}, {["x"] = 4, ["y"] = 9, ["param1"] = 12, ["z"] = 11, ["name"] = "default:pine_needles"}, {["x"] = 4, ["y"] = 9, ["param1"] = 13, ["z"] = 12, ["name"] = "default:pine_needles"}, {["x"] = 4, ["y"] = 9, ["param1"] = 14, ["z"] = 13, ["name"] = "default:pine_needles"}, {["x"] = 4, ["y"] = 11, ["param1"] = 13, ["z"] = 7, ["name"] = "default:pine_needles"}, {["x"] = 4, ["y"] = 11, ["param1"] = 12, ["z"] = 8, ["name"] = "default:pine_needles"}, {["x"] = 4, ["y"] = 11, ["param1"] = 12, ["z"] = 9, ["name"] = "default:pine_needles"}, {["x"] = 4, ["y"] = 11, ["param1"] = 13, ["z"] = 10, ["name"] = "default:pine_needles"}, {["x"] = 4, ["y"] = 12, ["param1"] = 14, ["z"] = 6, ["name"] = "default:pine_needles"}, {["x"] = 4, ["y"] = 12, ["param1"] = 13, ["z"] = 7, ["name"] = "default:pine_needles"}, {["x"] = 4, ["y"] = 12, ["param1"] = 12, ["z"] = 8, ["name"] = "default:pine_needles"}, {["x"] = 4, ["y"] = 12, ["param1"] = 12, ["z"] = 9, ["name"] = "default:pine_needles"}, {["x"] = 4, ["y"] = 12, ["param1"] = 13, ["z"] = 10, ["name"] = "default:pine_needles"}, {["x"] = 4, ["y"] = 12, ["param1"] = 13, ["z"] = 11, ["name"] = "default:pine_needles"}, {["x"] = 4, ["y"] = 13, ["param1"] = 14, ["z"] = 7, ["name"] = "default:pine_needles"}, {["x"] = 4, ["y"] = 13, ["param1"] = 13, ["z"] = 8, ["name"] = "default:pine_needles"}, {["x"] = 4, ["y"] = 13, ["param1"] = 12, ["z"] = 9, ["name"] = "default:pine_needles"}, {["x"] = 4, ["y"] = 13, ["param1"] = 13, ["z"] = 10, ["name"] = "default:pine_needles"}, {["x"] = 4, ["y"] = 14, ["param1"] = 14, ["z"] = 7, ["name"] = "default:pine_needles"}, {["x"] = 4, ["y"] = 14, ["param1"] = 14, ["z"] = 8, ["name"] = "default:pine_needles"}, {["x"] = 4, ["y"] = 14, ["param1"] = 13, ["z"] = 9, ["name"] = "default:pine_needles"}, {["x"] = 4, ["y"] = 16, ["param1"] = 13, ["z"] = 10, ["name"] = "default:pine_needles"}, {["x"] = 4, ["y"] = 16, ["param1"] = 13, ["z"] = 11, ["name"] = "default:pine_needles"}, {["x"] = 4, ["y"] = 17, ["param1"] = 14, ["z"] = 9, ["name"] = "default:pine_needles"}, {["x"] = 4, ["y"] = 17, ["param1"] = 13, ["z"] = 10, ["name"] = "default:pine_needles"}, {["x"] = 4, ["y"] = 17, ["param1"] = 13, ["z"] = 11, ["name"] = "default:pine_needles"}, {["x"] = 4, ["y"] = 17, ["param1"] = 14, ["z"] = 12, ["name"] = "default:pine_needles"}, {["x"] = 4, ["y"] = 18, ["param1"] = 14, ["z"] = 9, ["name"] = "default:pine_needles"}, {["x"] = 4, ["y"] = 18, ["param1"] = 13, ["z"] = 10, ["name"] = "default:pine_needles"}, {["x"] = 4, ["y"] = 18, ["param1"] = 14, ["z"] = 11, ["name"] = "default:pine_needles"}, {["x"] = 4, ["y"] = 19, ["param1"] = 14, ["z"] = 10, ["name"] = "default:pine_needles"}, {["x"] = 5, ["y"] = 6, ["param1"] = 12, ["z"] = 8, ["name"] = "default:pine_needles"}, {["x"] = 5, ["y"] = 6, ["param1"] = 11, ["z"] = 9, ["name"] = "default:pine_needles"}, {["x"] = 5, ["y"] = 6, ["param1"] = 10, ["z"] = 10, ["name"] = "default:pine_needles"}, {["x"] = 5, ["y"] = 6, ["param1"] = 10, ["z"] = 11, ["name"] = "default:pine_needles"}, {["x"] = 5, ["y"] = 6, ["param1"] = 11, ["z"] = 12, ["name"] = "default:pine_needles"}, {["x"] = 5, ["y"] = 7, ["param1"] = 13, ["z"] = 7, ["name"] = "default:pine_needles"}, {["x"] = 5, ["y"] = 7, ["param1"] = 12, ["z"] = 8, ["name"] = "default:pine_needles"}, {["x"] = 5, ["param2"] = 9, ["y"] = 7, ["param1"] = 54, ["z"] = 9, ["name"] = "default:pine_tree"}, {["x"] = 5, ["param2"] = 18, ["y"] = 7, ["param1"] = 54, ["z"] = 10, ["name"] = "default:pine_tree"}, {["x"] = 5, ["param2"] = 7, ["y"] = 7, ["param1"] = 54, ["z"] = 11, ["name"] = "default:pine_tree"}, {["x"] = 5, ["y"] = 7, ["param1"] = 12, ["z"] = 12, ["name"] = "default:pine_needles"}, {["x"] = 5, ["y"] = 7, ["param1"] = 13, ["z"] = 13, ["name"] = "default:pine_needles"}, {["x"] = 5, ["y"] = 8, ["param1"] = 12, ["z"] = 8, ["name"] = "default:pine_needles"}, {["x"] = 5, ["y"] = 8, ["param1"] = 11, ["z"] = 9, ["name"] = "default:pine_needles"}, {["x"] = 5, ["y"] = 8, ["param1"] = 11, ["z"] = 10, ["name"] = "default:pine_needles"}, {["x"] = 5, ["y"] = 8, ["param1"] = 12, ["z"] = 11, ["name"] = "default:pine_needles"}, {["x"] = 5, ["y"] = 8, ["param1"] = 13, ["z"] = 12, ["name"] = "default:pine_needles"}, {["x"] = 5, ["y"] = 8, ["param1"] = 14, ["z"] = 13, ["name"] = "default:pine_needles"}, {["x"] = 5, ["y"] = 9, ["param1"] = 12, ["z"] = 10, ["name"] = "default:pine_needles"}, {["x"] = 5, ["y"] = 9, ["param1"] = 13, ["z"] = 11, ["name"] = "default:pine_needles"}, {["x"] = 5, ["y"] = 9, ["param1"] = 14, ["z"] = 12, ["name"] = "default:pine_needles"}, {["x"] = 5, ["y"] = 11, ["param1"] = 13, ["z"] = 7, ["name"] = "default:pine_needles"}, {["x"] = 5, ["y"] = 11, ["param1"] = 11, ["z"] = 9, ["name"] = "default:pine_needles"}, {["x"] = 5, ["y"] = 11, ["param1"] = 12, ["z"] = 10, ["name"] = "default:pine_needles"}, {["x"] = 5, ["y"] = 11, ["param1"] = 14, ["z"] = 14, ["name"] = "default:pine_needles"}, {["x"] = 5, ["y"] = 11, ["param1"] = 14, ["z"] = 15, ["name"] = "default:pine_needles"}, {["x"] = 5, ["y"] = 11, ["param1"] = 14, ["z"] = 16, ["name"] = "default:pine_needles"}, {["x"] = 5, ["y"] = 12, ["param1"] = 14, ["z"] = 6, ["name"] = "default:pine_needles"}, {["x"] = 5, ["y"] = 12, ["param1"] = 13, ["z"] = 7, ["name"] = "default:pine_needles"}, {["x"] = 5, ["y"] = 12, ["param1"] = 12, ["z"] = 8, ["name"] = "default:pine_needles"}, {["x"] = 5, ["param2"] = 18, ["y"] = 12, ["param1"] = 54, ["z"] = 9, ["name"] = "default:pine_tree"}, {["x"] = 5, ["y"] = 12, ["param1"] = 12, ["z"] = 10, ["name"] = "default:pine_needles"}, {["x"] = 5, ["y"] = 12, ["param1"] = 13, ["z"] = 11, ["name"] = "default:pine_needles"}, {["x"] = 5, ["y"] = 13, ["param1"] = 14, ["z"] = 7, ["name"] = "default:pine_needles"}, {["x"] = 5, ["y"] = 13, ["param1"] = 13, ["z"] = 8, ["name"] = "default:pine_needles"}, {["x"] = 5, ["y"] = 13, ["param1"] = 12, ["z"] = 9, ["name"] = "default:pine_needles"}, {["x"] = 5, ["y"] = 13, ["param1"] = 12, ["z"] = 10, ["name"] = "default:pine_needles"}, {["x"] = 5, ["y"] = 16, ["param1"] = 13, ["z"] = 9, ["name"] = "default:pine_needles"}, {["x"] = 5, ["y"] = 16, ["param1"] = 12, ["z"] = 10, ["name"] = "default:pine_needles"}, {["x"] = 5, ["y"] = 16, ["param1"] = 13, ["z"] = 11, ["name"] = "default:pine_needles"}, {["x"] = 5, ["y"] = 17, ["param1"] = 14, ["z"] = 8, ["name"] = "default:pine_needles"}, {["x"] = 5, ["y"] = 17, ["param1"] = 13, ["z"] = 9, ["name"] = "default:pine_needles"}, {["x"] = 5, ["y"] = 17, ["param1"] = 12, ["z"] = 10, ["name"] = "default:pine_needles"}, {["x"] = 5, ["y"] = 17, ["param1"] = 13, ["z"] = 11, ["name"] = "default:pine_needles"}, {["x"] = 5, ["y"] = 17, ["param1"] = 14, ["z"] = 12, ["name"] = "default:pine_needles"}, {["x"] = 5, ["y"] = 18, ["param1"] = 14, ["z"] = 9, ["name"] = "default:pine_needles"}, {["x"] = 5, ["y"] = 18, ["param1"] = 13, ["z"] = 10, ["name"] = "default:pine_needles"}, {["x"] = 5, ["y"] = 18, ["param1"] = 14, ["z"] = 11, ["name"] = "default:pine_needles"}, {["x"] = 5, ["y"] = 19, ["param1"] = 14, ["z"] = 10, ["name"] = "default:pine_needles"}, {["x"] = 6, ["y"] = 5, ["param1"] = 14, ["z"] = 3, ["name"] = "default:pine_needles"}, {["x"] = 6, ["y"] = 5, ["param1"] = 14, ["z"] = 4, ["name"] = "default:pine_needles"}, {["x"] = 6, ["y"] = 5, ["param1"] = 14, ["z"] = 5, ["name"] = "default:pine_needles"}, {["x"] = 6, ["y"] = 6, ["param1"] = 10, ["z"] = 9, ["name"] = "default:pine_needles"}, {["x"] = 6, ["y"] = 6, ["param1"] = 10, ["z"] = 10, ["name"] = "default:pine_needles"}, {["x"] = 6, ["y"] = 6, ["param1"] = 11, ["z"] = 11, ["name"] = "default:pine_needles"}, {["x"] = 6, ["y"] = 7, ["param1"] = 12, ["z"] = 7, ["name"] = "default:pine_needles"}, {["x"] = 6, ["y"] = 7, ["param1"] = 11, ["z"] = 8, ["name"] = "default:pine_needles"}, {["x"] = 6, ["y"] = 7, ["param1"] = 10, ["z"] = 9, ["name"] = "default:pine_needles"}, {["x"] = 6, ["param2"] = 18, ["y"] = 7, ["param1"] = 54, ["z"] = 10, ["name"] = "default:pine_tree"}, {["x"] = 6, ["y"] = 7, ["param1"] = 12, ["z"] = 11, ["name"] = "default:pine_needles"}, {["x"] = 6, ["y"] = 7, ["param1"] = 13, ["z"] = 12, ["name"] = "default:pine_needles"}, {["x"] = 6, ["y"] = 8, ["param1"] = 11, ["z"] = 9, ["name"] = "default:pine_needles"}, {["x"] = 6, ["y"] = 8, ["param1"] = 12, ["z"] = 10, ["name"] = "default:pine_needles"}, {["x"] = 6, ["y"] = 8, ["param1"] = 13, ["z"] = 11, ["name"] = "default:pine_needles"}, {["x"] = 6, ["y"] = 8, ["param1"] = 14, ["z"] = 12, ["name"] = "default:pine_needles"}, {["x"] = 6, ["y"] = 10, ["param1"] = 13, ["z"] = 14, ["name"] = "default:pine_needles"}, {["x"] = 6, ["y"] = 10, ["param1"] = 13, ["z"] = 15, ["name"] = "default:pine_needles"}, {["x"] = 6, ["y"] = 10, ["param1"] = 13, ["z"] = 16, ["name"] = "default:pine_needles"}, {["x"] = 6, ["y"] = 11, ["param1"] = 13, ["z"] = 7, ["name"] = "default:pine_needles"}, {["x"] = 6, ["y"] = 11, ["param1"] = 12, ["z"] = 8, ["name"] = "default:pine_needles"}, {["x"] = 6, ["y"] = 11, ["param1"] = 11, ["z"] = 9, ["name"] = "default:pine_needles"}, {["x"] = 6, ["y"] = 11, ["param1"] = 12, ["z"] = 10, ["name"] = "default:pine_needles"}, {["x"] = 6, ["y"] = 11, ["param1"] = 14, ["z"] = 13, ["name"] = "default:pine_needles"}, {["x"] = 6, ["y"] = 11, ["param1"] = 14, ["z"] = 14, ["name"] = "default:pine_needles"}, {["x"] = 6, ["y"] = 11, ["param1"] = 13, ["z"] = 15, ["name"] = "default:pine_needles"}, {["x"] = 6, ["y"] = 11, ["param1"] = 13, ["z"] = 16, ["name"] = "default:pine_needles"}, {["x"] = 6, ["y"] = 11, ["param1"] = 14, ["z"] = 17, ["name"] = "default:pine_needles"}, {["x"] = 6, ["y"] = 12, ["param1"] = 14, ["z"] = 7, ["name"] = "default:pine_needles"}, {["x"] = 6, ["y"] = 12, ["param1"] = 13, ["z"] = 8, ["name"] = "default:pine_needles"}, {["x"] = 6, ["param2"] = 18, ["y"] = 12, ["param1"] = 54, ["z"] = 9, ["name"] = "default:pine_tree"}, {["x"] = 6, ["y"] = 12, ["param1"] = 12, ["z"] = 10, ["name"] = "default:pine_needles"}, {["x"] = 6, ["y"] = 12, ["param1"] = 13, ["z"] = 11, ["name"] = "default:pine_needles"}, {["x"] = 6, ["y"] = 12, ["param1"] = 14, ["z"] = 15, ["name"] = "default:pine_needles"}, {["x"] = 6, ["y"] = 12, ["param1"] = 14, ["z"] = 16, ["name"] = "default:pine_needles"}, {["x"] = 6, ["y"] = 13, ["param1"] = 14, ["z"] = 8, ["name"] = "default:pine_needles"}, {["x"] = 6, ["y"] = 13, ["param1"] = 13, ["z"] = 9, ["name"] = "default:pine_needles"}, {["x"] = 6, ["y"] = 13, ["param1"] = 12, ["z"] = 10, ["name"] = "default:pine_needles"}, {["x"] = 6, ["y"] = 15, ["param1"] = 14, ["z"] = 5, ["name"] = "default:pine_needles"}, {["x"] = 6, ["y"] = 15, ["param1"] = 14, ["z"] = 6, ["name"] = "default:pine_needles"}, {["x"] = 6, ["y"] = 16, ["param1"] = 13, ["z"] = 9, ["name"] = "default:pine_needles"}, {["x"] = 6, ["y"] = 16, ["param1"] = 12, ["z"] = 10, ["name"] = "default:pine_needles"}, {["x"] = 6, ["y"] = 16, ["param1"] = 13, ["z"] = 11, ["name"] = "default:pine_needles"}, {["x"] = 6, ["y"] = 17, ["param1"] = 14, ["z"] = 8, ["name"] = "default:pine_needles"}, {["x"] = 6, ["y"] = 17, ["param1"] = 13, ["z"] = 9, ["name"] = "default:pine_needles"}, {["x"] = 6, ["param2"] = 18, ["y"] = 17, ["param1"] = 54, ["z"] = 10, ["name"] = "default:pine_tree"}, {["x"] = 6, ["y"] = 17, ["param1"] = 13, ["z"] = 11, ["name"] = "default:pine_needles"}, {["x"] = 6, ["y"] = 17, ["param1"] = 14, ["z"] = 12, ["name"] = "default:pine_needles"}, {["x"] = 6, ["y"] = 18, ["param1"] = 14, ["z"] = 9, ["name"] = "default:pine_needles"}, {["x"] = 6, ["y"] = 18, ["param1"] = 13, ["z"] = 10, ["name"] = "default:pine_needles"}, {["x"] = 6, ["y"] = 18, ["param1"] = 14, ["z"] = 11, ["name"] = "default:pine_needles"}, {["x"] = 6, ["y"] = 20, ["param1"] = 14, ["z"] = 10, ["name"] = "default:pine_needles"}, {["x"] = 6, ["y"] = 21, ["param1"] = 14, ["z"] = 9, ["name"] = "default:pine_needles"}, {["x"] = 7, ["y"] = 4, ["param1"] = 13, ["z"] = 3, ["name"] = "default:pine_needles"}, {["x"] = 7, ["y"] = 4, ["param1"] = 13, ["z"] = 4, ["name"] = "default:pine_needles"}, {["x"] = 7, ["y"] = 4, ["param1"] = 13, ["z"] = 5, ["name"] = "default:pine_needles"}, {["x"] = 7, ["y"] = 5, ["param1"] = 14, ["z"] = 2, ["name"] = "default:pine_needles"}, {["x"] = 7, ["y"] = 5, ["param1"] = 13, ["z"] = 3, ["name"] = "default:pine_needles"}, {["x"] = 7, ["y"] = 5, ["param1"] = 13, ["z"] = 4, ["name"] = "default:pine_needles"}, {["x"] = 7, ["y"] = 5, ["param1"] = 13, ["z"] = 5, ["name"] = "default:pine_needles"}, {["x"] = 7, ["y"] = 5, ["param1"] = 12, ["z"] = 6, ["name"] = "default:pine_needles"}, {["x"] = 7, ["y"] = 5, ["param1"] = 11, ["z"] = 13, ["name"] = "default:pine_needles"}, {["x"] = 7, ["y"] = 5, ["param1"] = 11, ["z"] = 14, ["name"] = "default:pine_needles"}, {["x"] = 7, ["y"] = 5, ["param1"] = 12, ["z"] = 15, ["name"] = "default:pine_needles"}, {["x"] = 7, ["y"] = 6, ["param1"] = 14, ["z"] = 1, ["name"] = "default:pine_needles"}, {["x"] = 7, ["y"] = 6, ["param1"] = 14, ["z"] = 2, ["name"] = "default:pine_needles"}, {["x"] = 7, ["y"] = 6, ["param1"] = 14, ["z"] = 3, ["name"] = "default:pine_needles"}, {["x"] = 7, ["y"] = 6, ["param1"] = 14, ["z"] = 4, ["name"] = "default:pine_needles"}, {["x"] = 7, ["y"] = 6, ["param1"] = 13, ["z"] = 5, ["name"] = "default:pine_needles"}, {["x"] = 7, ["y"] = 7, ["param1"] = 10, ["z"] = 8, ["name"] = "default:pine_needles"}, {["x"] = 7, ["y"] = 7, ["param1"] = 11, ["z"] = 9, ["name"] = "default:pine_needles"}, {["x"] = 7, ["param2"] = 18, ["y"] = 7, ["param1"] = 54, ["z"] = 10, ["name"] = "default:pine_tree"}, {["x"] = 7, ["y"] = 7, ["param1"] = 13, ["z"] = 11, ["name"] = "default:pine_needles"}, {["x"] = 7, ["y"] = 7, ["param1"] = 14, ["z"] = 12, ["name"] = "default:pine_needles"}, {["x"] = 7, ["y"] = 8, ["param1"] = 13, ["z"] = 10, ["name"] = "default:pine_needles"}, {["x"] = 7, ["y"] = 9, ["param1"] = 13, ["z"] = 14, ["name"] = "default:pine_needles"}, {["x"] = 7, ["y"] = 9, ["param1"] = 12, ["z"] = 15, ["name"] = "default:pine_needles"}, {["x"] = 7, ["y"] = 10, ["param1"] = 14, ["z"] = 13, ["name"] = "default:pine_needles"}, {["x"] = 7, ["y"] = 10, ["param1"] = 13, ["z"] = 14, ["name"] = "default:pine_needles"}, {["x"] = 7, ["y"] = 10, ["param1"] = 12, ["z"] = 15, ["name"] = "default:pine_needles"}, {["x"] = 7, ["y"] = 10, ["param1"] = 12, ["z"] = 16, ["name"] = "default:pine_needles"}, {["x"] = 7, ["y"] = 11, ["param1"] = 14, ["z"] = 13, ["name"] = "default:pine_needles"}, {["x"] = 7, ["y"] = 11, ["param1"] = 13, ["z"] = 14, ["name"] = "default:pine_needles"}, {["x"] = 7, ["y"] = 11, ["param1"] = 13, ["z"] = 15, ["name"] = "default:pine_needles"}, {["x"] = 7, ["y"] = 11, ["param1"] = 13, ["z"] = 16, ["name"] = "default:pine_needles"}, {["x"] = 7, ["y"] = 11, ["param1"] = 13, ["z"] = 17, ["name"] = "default:pine_needles"}, {["x"] = 7, ["y"] = 11, ["param1"] = 14, ["z"] = 18, ["name"] = "default:pine_needles"}, {["x"] = 7, ["y"] = 12, ["param1"] = 12, ["z"] = 8, ["name"] = "default:pine_needles"}, {["x"] = 7, ["param2"] = 18, ["y"] = 12, ["param1"] = 54, ["z"] = 9, ["name"] = "default:pine_tree"}, {["x"] = 7, ["y"] = 12, ["param1"] = 13, ["z"] = 10, ["name"] = "default:pine_needles"}, {["x"] = 7, ["y"] = 12, ["param1"] = 14, ["z"] = 14, ["name"] = "default:pine_needles"}, {["x"] = 7, ["y"] = 12, ["param1"] = 14, ["z"] = 15, ["name"] = "default:pine_needles"}, {["x"] = 7, ["y"] = 12, ["param1"] = 14, ["z"] = 16, ["name"] = "default:pine_needles"}, {["x"] = 7, ["y"] = 12, ["param1"] = 14, ["z"] = 17, ["name"] = "default:pine_needles"}, {["x"] = 7, ["y"] = 13, ["param1"] = 12, ["z"] = 9, ["name"] = "default:pine_needles"}, {["x"] = 7, ["y"] = 14, ["param1"] = 13, ["z"] = 5, ["name"] = "default:pine_needles"}, {["x"] = 7, ["y"] = 14, ["param1"] = 13, ["z"] = 6, ["name"] = "default:pine_needles"}, {["x"] = 7, ["y"] = 15, ["param1"] = 14, ["z"] = 4, ["name"] = "default:pine_needles"}, {["x"] = 7, ["y"] = 15, ["param1"] = 13, ["z"] = 5, ["name"] = "default:pine_needles"}, {["x"] = 7, ["y"] = 15, ["param1"] = 13, ["z"] = 6, ["name"] = "default:pine_needles"}, {["x"] = 7, ["y"] = 15, ["param1"] = 14, ["z"] = 7, ["name"] = "default:pine_needles"}, {["x"] = 7, ["y"] = 16, ["param1"] = 14, ["z"] = 3, ["name"] = "default:pine_needles"}, {["x"] = 7, ["y"] = 16, ["param1"] = 14, ["z"] = 4, ["name"] = "default:pine_needles"}, {["x"] = 7, ["y"] = 16, ["param1"] = 14, ["z"] = 5, ["name"] = "default:pine_needles"}, {["x"] = 7, ["y"] = 16, ["param1"] = 14, ["z"] = 6, ["name"] = "default:pine_needles"}, {["x"] = 7, ["y"] = 16, ["param1"] = 13, ["z"] = 10, ["name"] = "default:pine_needles"}, {["x"] = 7, ["y"] = 17, ["param1"] = 13, ["z"] = 9, ["name"] = "default:pine_needles"}, {["x"] = 7, ["param2"] = 18, ["y"] = 17, ["param1"] = 54, ["z"] = 10, ["name"] = "default:pine_tree"}, {["x"] = 7, ["y"] = 17, ["param1"] = 14, ["z"] = 11, ["name"] = "default:pine_needles"}, {["x"] = 7, ["y"] = 18, ["param1"] = 13, ["z"] = 10, ["name"] = "default:pine_needles"}, {["x"] = 7, ["y"] = 20, ["param1"] = 14, ["z"] = 8, ["name"] = "default:pine_needles"}, {["x"] = 7, ["y"] = 20, ["param1"] = 13, ["z"] = 9, ["name"] = "default:pine_needles"}, {["x"] = 7, ["y"] = 20, ["param1"] = 13, ["z"] = 10, ["name"] = "default:pine_needles"}, {["x"] = 7, ["y"] = 20, ["param1"] = 14, ["z"] = 11, ["name"] = "default:pine_needles"}, {["x"] = 7, ["y"] = 21, ["param1"] = 14, ["z"] = 9, ["name"] = "default:pine_needles"}, {["x"] = 7, ["y"] = 21, ["param1"] = 14, ["z"] = 10, ["name"] = "default:pine_needles"}, {["x"] = 8, ["y"] = 4, ["param1"] = 13, ["z"] = 2, ["name"] = "default:pine_needles"}, {["x"] = 8, ["y"] = 4, ["param1"] = 12, ["z"] = 3, ["name"] = "default:pine_needles"}, {["x"] = 8, ["y"] = 4, ["param1"] = 12, ["z"] = 4, ["name"] = "default:pine_needles"}, {["x"] = 8, ["y"] = 4, ["param1"] = 12, ["z"] = 5, ["name"] = "default:pine_needles"}, {["x"] = 8, ["y"] = 4, ["param1"] = 11, ["z"] = 6, ["name"] = "default:pine_needles"}, {["x"] = 8, ["y"] = 4, ["param1"] = 10, ["z"] = 14, ["name"] = "default:pine_needles"}, {["x"] = 8, ["y"] = 5, ["param1"] = 13, ["z"] = 1, ["name"] = "default:pine_needles"}, {["x"] = 8, ["y"] = 5, ["param1"] = 13, ["z"] = 2, ["name"] = "default:pine_needles"}, {["x"] = 8, ["y"] = 5, ["param1"] = 12, ["z"] = 3, ["name"] = "default:pine_needles"}, {["x"] = 8, ["y"] = 5, ["param1"] = 12, ["z"] = 4, ["name"] = "default:pine_needles"}, {["x"] = 8, ["param2"] = 18, ["y"] = 5, ["z"] = 5, ["name"] = "default:pine_tree"}, {["x"] = 8, ["y"] = 5, ["param1"] = 11, ["z"] = 6, ["name"] = "default:pine_needles"}, {["x"] = 8, ["y"] = 5, ["param1"] = 10, ["z"] = 7, ["name"] = "default:pine_needles"}, {["x"] = 8, ["y"] = 5, ["param1"] = 11, ["z"] = 12, ["name"] = "default:pine_needles"}, {["x"] = 8, ["y"] = 5, ["param1"] = 10, ["z"] = 13, ["name"] = "default:pine_needles"}, {["x"] = 8, ["y"] = 5, ["param1"] = 10, ["z"] = 14, ["name"] = "default:pine_needles"}, {["x"] = 8, ["y"] = 5, ["param1"] = 11, ["z"] = 15, ["name"] = "default:pine_needles"}, {["x"] = 8, ["y"] = 5, ["param1"] = 12, ["z"] = 16, ["name"] = "default:pine_needles"}, {["x"] = 8, ["y"] = 6, ["param1"] = 14, ["z"] = 0, ["name"] = "default:pine_needles"}, {["x"] = 8, ["y"] = 6, ["param1"] = 13, ["z"] = 1, ["name"] = "default:pine_needles"}, {["x"] = 8, ["y"] = 6, ["param1"] = 13, ["z"] = 2, ["name"] = "default:pine_needles"}, {["x"] = 8, ["y"] = 6, ["param1"] = 13, ["z"] = 3, ["name"] = "default:pine_needles"}, {["x"] = 8, ["y"] = 6, ["param1"] = 13, ["z"] = 4, ["name"] = "default:pine_needles"}, {["x"] = 8, ["y"] = 6, ["param1"] = 12, ["z"] = 5, ["name"] = "default:pine_needles"}, {["x"] = 8, ["y"] = 6, ["param1"] = 11, ["z"] = 6, ["name"] = "default:pine_needles"}, {["x"] = 8, ["y"] = 6, ["param1"] = 11, ["z"] = 13, ["name"] = "default:pine_needles"}, {["x"] = 8, ["y"] = 6, ["param1"] = 10, ["z"] = 14, ["name"] = "default:pine_needles"}, {["x"] = 8, ["y"] = 6, ["param1"] = 11, ["z"] = 15, ["name"] = "default:pine_needles"}, {["x"] = 8, ["y"] = 6, ["param1"] = 12, ["z"] = 16, ["name"] = "default:pine_needles"}, {["x"] = 8, ["y"] = 6, ["param1"] = 13, ["z"] = 17, ["name"] = "default:pine_needles"}, {["x"] = 8, ["y"] = 7, ["param1"] = 14, ["z"] = 1, ["name"] = "default:pine_needles"}, {["x"] = 8, ["y"] = 7, ["param1"] = 14, ["z"] = 2, ["name"] = "default:pine_needles"}, {["x"] = 8, ["y"] = 7, ["param1"] = 13, ["z"] = 3, ["name"] = "default:pine_needles"}, {["x"] = 8, ["y"] = 7, ["param1"] = 13, ["z"] = 4, ["name"] = "default:pine_needles"}, {["x"] = 8, ["param2"] = 18, ["y"] = 7, ["param1"] = 54, ["z"] = 10, ["name"] = "default:pine_tree"}, {["x"] = 8, ["y"] = 9, ["param1"] = 13, ["z"] = 13, ["name"] = "default:pine_needles"}, {["x"] = 8, ["y"] = 9, ["param1"] = 12, ["z"] = 14, ["name"] = "default:pine_needles"}, {["x"] = 8, ["y"] = 9, ["param1"] = 11, ["z"] = 15, ["name"] = "default:pine_needles"}, {["x"] = 8, ["y"] = 9, ["param1"] = 12, ["z"] = 16, ["name"] = "default:pine_needles"}, {["x"] = 8, ["y"] = 10, ["param1"] = 13, ["z"] = 4, ["name"] = "default:pine_needles"}, {["x"] = 8, ["y"] = 10, ["param1"] = 12, ["z"] = 5, ["name"] = "default:pine_needles"}, {["x"] = 8, ["y"] = 10, ["param1"] = 11, ["z"] = 6, ["name"] = "default:pine_needles"}, {["x"] = 8, ["y"] = 10, ["param1"] = 14, ["z"] = 12, ["name"] = "default:pine_needles"}, {["x"] = 8, ["y"] = 10, ["param1"] = 13, ["z"] = 13, ["name"] = "default:pine_needles"}, {["x"] = 8, ["y"] = 10, ["param1"] = 12, ["z"] = 14, ["name"] = "default:pine_needles"}, {["x"] = 8, ["y"] = 10, ["param1"] = 12, ["z"] = 15, ["name"] = "default:pine_needles"}, {["x"] = 8, ["y"] = 10, ["param1"] = 12, ["z"] = 16, ["name"] = "default:pine_needles"}, {["x"] = 8, ["y"] = 10, ["param1"] = 13, ["z"] = 17, ["name"] = "default:pine_needles"}, {["x"] = 8, ["y"] = 11, ["param1"] = 13, ["z"] = 13, ["name"] = "default:pine_needles"}, {["x"] = 8, ["y"] = 11, ["param1"] = 12, ["z"] = 14, ["name"] = "default:pine_needles"}, {["x"] = 8, ["y"] = 11, ["param1"] = 13, ["z"] = 15, ["name"] = "default:pine_needles"}, {["x"] = 8, ["y"] = 11, ["param1"] = 13, ["z"] = 16, ["name"] = "default:pine_needles"}, {["x"] = 8, ["y"] = 11, ["param1"] = 13, ["z"] = 17, ["name"] = "default:pine_needles"}, {["x"] = 8, ["y"] = 11, ["param1"] = 14, ["z"] = 18, ["name"] = "default:pine_needles"}, {["x"] = 8, ["param2"] = 18, ["y"] = 12, ["param1"] = 54, ["z"] = 9, ["name"] = "default:pine_tree"}, {["x"] = 8, ["y"] = 12, ["param1"] = 14, ["z"] = 13, ["name"] = "default:pine_needles"}, {["x"] = 8, ["y"] = 12, ["param1"] = 14, ["z"] = 15, ["name"] = "default:pine_needles"}, {["x"] = 8, ["y"] = 12, ["param1"] = 14, ["z"] = 16, ["name"] = "default:pine_needles"}, {["x"] = 8, ["y"] = 12, ["param1"] = 14, ["z"] = 17, ["name"] = "default:pine_needles"}, {["x"] = 8, ["y"] = 14, ["param1"] = 13, ["z"] = 4, ["name"] = "default:pine_needles"}, {["x"] = 8, ["y"] = 14, ["param1"] = 12, ["z"] = 5, ["name"] = "default:pine_needles"}, {["x"] = 8, ["y"] = 14, ["param1"] = 12, ["z"] = 6, ["name"] = "default:pine_needles"}, {["x"] = 8, ["y"] = 15, ["param1"] = 13, ["z"] = 3, ["name"] = "default:pine_needles"}, {["x"] = 8, ["y"] = 15, ["param1"] = 13, ["z"] = 4, ["name"] = "default:pine_needles"}, {["x"] = 8, ["y"] = 15, ["param1"] = 12, ["z"] = 5, ["name"] = "default:pine_needles"}, {["x"] = 8, ["y"] = 15, ["param1"] = 13, ["z"] = 6, ["name"] = "default:pine_needles"}, {["x"] = 8, ["y"] = 15, ["param1"] = 13, ["z"] = 7, ["name"] = "default:pine_needles"}, {["x"] = 8, ["y"] = 15, ["param1"] = 14, ["z"] = 13, ["name"] = "default:pine_needles"}, {["x"] = 8, ["y"] = 15, ["param1"] = 14, ["z"] = 14, ["name"] = "default:pine_needles"}, {["x"] = 8, ["y"] = 16, ["param1"] = 14, ["z"] = 2, ["name"] = "default:pine_needles"}, {["x"] = 8, ["y"] = 16, ["param1"] = 13, ["z"] = 3, ["name"] = "default:pine_needles"}, {["x"] = 8, ["y"] = 16, ["param1"] = 13, ["z"] = 4, ["name"] = "default:pine_needles"}, {["x"] = 8, ["y"] = 16, ["param1"] = 13, ["z"] = 5, ["name"] = "default:pine_needles"}, {["x"] = 8, ["y"] = 16, ["param1"] = 14, ["z"] = 6, ["name"] = "default:pine_needles"}, {["x"] = 8, ["y"] = 16, ["param1"] = 14, ["z"] = 7, ["name"] = "default:pine_needles"}, {["x"] = 8, ["y"] = 17, ["param1"] = 14, ["z"] = 3, ["name"] = "default:pine_needles"}, {["x"] = 8, ["y"] = 17, ["param1"] = 14, ["z"] = 4, ["name"] = "default:pine_needles"}, {["x"] = 8, ["y"] = 17, ["param1"] = 14, ["z"] = 5, ["name"] = "default:pine_needles"}, {["x"] = 8, ["param2"] = 18, ["y"] = 17, ["param1"] = 54, ["z"] = 10, ["name"] = "default:pine_tree"}, {["x"] = 8, ["y"] = 20, ["param1"] = 14, ["z"] = 7, ["name"] = "default:pine_needles"}, {["x"] = 8, ["y"] = 20, ["param1"] = 13, ["z"] = 8, ["name"] = "default:pine_needles"}, {["x"] = 8, ["param2"] = 18, ["y"] = 20, ["z"] = 10, ["name"] = "default:pine_tree"}, {["x"] = 8, ["y"] = 20, ["param1"] = 13, ["z"] = 11, ["name"] = "default:pine_needles"}, {["x"] = 8, ["y"] = 20, ["param1"] = 14, ["z"] = 12, ["name"] = "default:pine_needles"}, {["x"] = 8, ["y"] = 21, ["param1"] = 14, ["z"] = 8, ["name"] = "default:pine_needles"}, {["x"] = 8, ["y"] = 21, ["param1"] = 13, ["z"] = 9, ["name"] = "default:pine_needles"}, {["x"] = 8, ["y"] = 21, ["param1"] = 13, ["z"] = 10, ["name"] = "default:pine_needles"}, {["x"] = 8, ["y"] = 21, ["param1"] = 14, ["z"] = 11, ["name"] = "default:pine_needles"}, {["x"] = 8, ["y"] = 22, ["param1"] = 14, ["z"] = 8, ["name"] = "default:pine_needles"}, {["x"] = 8, ["y"] = 22, ["param1"] = 14, ["z"] = 9, ["name"] = "default:pine_needles"}, {["x"] = 8, ["y"] = 22, ["param1"] = 14, ["z"] = 10, ["name"] = "default:pine_needles"}, {["x"] = 8, ["y"] = 23, ["param1"] = 14, ["z"] = 9, ["name"] = "default:pine_needles"}, {["x"] = 8, ["y"] = 23, ["param1"] = 14, ["z"] = 10, ["name"] = "default:pine_needles"}, {["x"] = 9, ["y"] = 0, ["param1"] = 54, ["z"] = 9, ["name"] = "default:pine_tree"}, {["x"] = 9, ["y"] = 0, ["z"] = 10, ["name"] = "default:pine_tree"}, {["x"] = 9, ["y"] = 1, ["param1"] = 54, ["z"] = 9, ["name"] = "default:pine_tree"}, {["x"] = 9, ["y"] = 1, ["z"] = 10, ["name"] = "default:pine_tree"}, {["x"] = 9, ["y"] = 2, ["param1"] = 54, ["z"] = 9, ["name"] = "default:pine_tree"}, {["x"] = 9, ["y"] = 2, ["z"] = 10, ["name"] = "default:pine_tree"}, {["x"] = 9, ["y"] = 3, ["param1"] = 54, ["z"] = 9, ["name"] = "default:pine_tree"}, {["x"] = 9, ["y"] = 3, ["z"] = 10, ["name"] = "default:pine_tree"}, {["x"] = 9, ["y"] = 4, ["param1"] = 13, ["z"] = 2, ["name"] = "default:pine_needles"}, {["x"] = 9, ["y"] = 4, ["param1"] = 12, ["z"] = 3, ["name"] = "default:pine_needles"}, {["x"] = 9, ["y"] = 4, ["param1"] = 11, ["z"] = 4, ["name"] = "default:pine_needles"}, {["x"] = 9, ["y"] = 4, ["param1"] = 11, ["z"] = 5, ["name"] = "default:pine_needles"}, {["x"] = 9, ["y"] = 4, ["param1"] = 10, ["z"] = 6, ["name"] = "default:pine_needles"}, {["x"] = 9, ["y"] = 4, ["param1"] = 54, ["z"] = 9, ["name"] = "default:pine_tree"}, {["x"] = 9, ["y"] = 4, ["z"] = 10, ["name"] = "default:pine_tree"}, {["x"] = 9, ["y"] = 4, ["param1"] = 10, ["z"] = 13, ["name"] = "default:pine_needles"}, {["x"] = 9, ["y"] = 4, ["param1"] = 11, ["z"] = 14, ["name"] = "default:pine_needles"}, {["x"] = 9, ["y"] = 4, ["param1"] = 13, ["z"] = 16, ["name"] = "default:pine_needles"}, {["x"] = 9, ["y"] = 5, ["param1"] = 14, ["z"] = 1, ["name"] = "default:pine_needles"}, {["x"] = 9, ["y"] = 5, ["param1"] = 13, ["z"] = 2, ["name"] = "default:pine_needles"}, {["x"] = 9, ["param2"] = 9, ["y"] = 5, ["param1"] = 54, ["z"] = 3, ["name"] = "default:pine_tree"}, {["x"] = 9, ["param2"] = 9, ["y"] = 5, ["param1"] = 54, ["z"] = 4, ["name"] = "default:pine_tree"}, {["x"] = 9, ["param2"] = 9, ["y"] = 5, ["param1"] = 54, ["z"] = 5, ["name"] = "default:pine_tree"}, {["x"] = 9, ["param2"] = 9, ["y"] = 5, ["param1"] = 54, ["z"] = 6, ["name"] = "default:pine_tree"}, {["x"] = 9, ["param2"] = 7, ["y"] = 5, ["param1"] = 54, ["z"] = 7, ["name"] = "default:pine_tree"}, {["x"] = 9, ["param2"] = 7, ["y"] = 5, ["param1"] = 54, ["z"] = 8, ["name"] = "default:pine_tree"}, {["x"] = 9, ["y"] = 5, ["param1"] = 54, ["z"] = 9, ["name"] = "default:pine_tree"}, {["x"] = 9, ["y"] = 5, ["z"] = 10, ["name"] = "default:pine_tree"}, {["x"] = 9, ["y"] = 5, ["param1"] = 11, ["z"] = 12, ["name"] = "default:pine_needles"}, {["x"] = 9, ["y"] = 5, ["param1"] = 10, ["z"] = 13, ["name"] = "default:pine_needles"}, {["x"] = 9, ["param2"] = 18, ["y"] = 5, ["z"] = 14, ["name"] = "default:pine_tree"}, {["x"] = 9, ["y"] = 5, ["param1"] = 12, ["z"] = 15, ["name"] = "default:pine_needles"}, {["x"] = 9, ["y"] = 5, ["param1"] = 13, ["z"] = 16, ["name"] = "default:pine_needles"}, {["x"] = 9, ["y"] = 5, ["param1"] = 14, ["z"] = 17, ["name"] = "default:pine_needles"}, {["x"] = 9, ["y"] = 6, ["param1"] = 14, ["z"] = 1, ["name"] = "default:pine_needles"}, {["x"] = 9, ["y"] = 6, ["param1"] = 13, ["z"] = 2, ["name"] = "default:pine_needles"}, {["x"] = 9, ["y"] = 6, ["param1"] = 12, ["z"] = 3, ["name"] = "default:pine_needles"}, {["x"] = 9, ["y"] = 6, ["param1"] = 12, ["z"] = 4, ["name"] = "default:pine_needles"}, {["x"] = 9, ["y"] = 6, ["param1"] = 11, ["z"] = 5, ["name"] = "default:pine_needles"}, {["x"] = 9, ["y"] = 6, ["param1"] = 10, ["z"] = 6, ["name"] = "default:pine_needles"}, {["x"] = 9, ["y"] = 6, ["param1"] = 9, ["z"] = 7, ["name"] = "default:pine_needles"}, {["x"] = 9, ["y"] = 6, ["param1"] = 54, ["z"] = 9, ["name"] = "default:pine_tree"}, {["x"] = 9, ["y"] = 6, ["param1"] = 54, ["z"] = 10, ["name"] = "default:pine_tree"}, {["x"] = 9, ["y"] = 6, ["param1"] = 11, ["z"] = 13, ["name"] = "default:pine_needles"}, {["x"] = 9, ["y"] = 6, ["param1"] = 11, ["z"] = 14, ["name"] = "default:pine_needles"}, {["x"] = 9, ["y"] = 6, ["param1"] = 12, ["z"] = 15, ["name"] = "default:pine_needles"}, {["x"] = 9, ["y"] = 6, ["param1"] = 13, ["z"] = 16, ["name"] = "default:pine_needles"}, {["x"] = 9, ["y"] = 6, ["param1"] = 14, ["z"] = 17, ["name"] = "default:pine_needles"}, {["x"] = 9, ["y"] = 7, ["param1"] = 14, ["z"] = 2, ["name"] = "default:pine_needles"}, {["x"] = 9, ["y"] = 7, ["param1"] = 13, ["z"] = 3, ["name"] = "default:pine_needles"}, {["x"] = 9, ["y"] = 7, ["param1"] = 12, ["z"] = 4, ["name"] = "default:pine_needles"}, {["x"] = 9, ["y"] = 7, ["param1"] = 54, ["z"] = 9, ["name"] = "default:pine_tree"}, {["x"] = 9, ["y"] = 7, ["param1"] = 54, ["z"] = 10, ["name"] = "default:pine_tree"}, {["x"] = 9, ["y"] = 7, ["param1"] = 12, ["z"] = 15, ["name"] = "default:pine_needles"}, {["x"] = 9, ["y"] = 7, ["param1"] = 13, ["z"] = 16, ["name"] = "default:pine_needles"}, {["x"] = 9, ["y"] = 8, ["param1"] = 54, ["z"] = 9, ["name"] = "default:pine_tree"}, {["x"] = 9, ["y"] = 8, ["param1"] = 54, ["z"] = 10, ["name"] = "default:pine_tree"}, {["x"] = 9, ["y"] = 9, ["param1"] = 12, ["z"] = 4, ["name"] = "default:pine_needles"}, {["x"] = 9, ["y"] = 9, ["param1"] = 11, ["z"] = 5, ["name"] = "default:pine_needles"}, {["x"] = 9, ["y"] = 9, ["param1"] = 10, ["z"] = 6, ["name"] = "default:pine_needles"}, {["x"] = 9, ["y"] = 9, ["param1"] = 54, ["z"] = 9, ["name"] = "default:pine_tree"}, {["x"] = 9, ["y"] = 9, ["param1"] = 54, ["z"] = 10, ["name"] = "default:pine_tree"}, {["x"] = 9, ["y"] = 9, ["param1"] = 12, ["z"] = 13, ["name"] = "default:pine_needles"}, {["x"] = 9, ["y"] = 9, ["param1"] = 11, ["z"] = 14, ["name"] = "default:pine_needles"}, {["x"] = 9, ["y"] = 9, ["param1"] = 12, ["z"] = 15, ["name"] = "default:pine_needles"}, {["x"] = 9, ["y"] = 9, ["param1"] = 13, ["z"] = 16, ["name"] = "default:pine_needles"}, {["x"] = 9, ["y"] = 10, ["param1"] = 13, ["z"] = 3, ["name"] = "default:pine_needles"}, {["x"] = 9, ["y"] = 10, ["param1"] = 12, ["z"] = 4, ["name"] = "default:pine_needles"}, {["x"] = 9, ["y"] = 10, ["param1"] = 11, ["z"] = 5, ["name"] = "default:pine_needles"}, {["x"] = 9, ["y"] = 10, ["param1"] = 11, ["z"] = 6, ["name"] = "default:pine_needles"}, {["x"] = 9, ["y"] = 10, ["param1"] = 10, ["z"] = 7, ["name"] = "default:pine_needles"}, {["x"] = 9, ["y"] = 10, ["param1"] = 54, ["z"] = 9, ["name"] = "default:pine_tree"}, {["x"] = 9, ["param2"] = 7, ["y"] = 10, ["z"] = 10, ["name"] = "default:pine_tree"}, {["x"] = 9, ["param2"] = 7, ["y"] = 10, ["param1"] = 54, ["z"] = 11, ["name"] = "default:pine_tree"}, {["x"] = 9, ["param2"] = 7, ["y"] = 10, ["param1"] = 54, ["z"] = 12, ["name"] = "default:pine_tree"}, {["x"] = 9, ["param2"] = 7, ["y"] = 10, ["param1"] = 54, ["z"] = 13, ["name"] = "default:pine_tree"}, {["x"] = 9, ["param2"] = 7, ["y"] = 10, ["param1"] = 54, ["z"] = 14, ["name"] = "default:pine_tree"}, {["x"] = 9, ["y"] = 10, ["param1"] = 12, ["z"] = 15, ["name"] = "default:pine_needles"}, {["x"] = 9, ["y"] = 10, ["param1"] = 13, ["z"] = 16, ["name"] = "default:pine_needles"}, {["x"] = 9, ["y"] = 10, ["param1"] = 14, ["z"] = 17, ["name"] = "default:pine_needles"}, {["x"] = 9, ["y"] = 11, ["param1"] = 12, ["z"] = 4, ["name"] = "default:pine_needles"}, {["x"] = 9, ["y"] = 11, ["param1"] = 11, ["z"] = 5, ["name"] = "default:pine_needles"}, {["x"] = 9, ["y"] = 11, ["param1"] = 12, ["z"] = 6, ["name"] = "default:pine_needles"}, {["x"] = 9, ["y"] = 11, ["param1"] = 54, ["z"] = 9, ["name"] = "default:pine_tree"}, {["x"] = 9, ["y"] = 11, ["param1"] = 13, ["z"] = 12, ["name"] = "default:pine_needles"}, {["x"] = 9, ["y"] = 11, ["param1"] = 12, ["z"] = 13, ["name"] = "default:pine_needles"}, {["x"] = 9, ["y"] = 11, ["param1"] = 11, ["z"] = 14, ["name"] = "default:pine_needles"}, {["x"] = 9, ["y"] = 11, ["param1"] = 12, ["z"] = 15, ["name"] = "default:pine_needles"}, {["x"] = 9, ["y"] = 11, ["param1"] = 13, ["z"] = 16, ["name"] = "default:pine_needles"}, {["x"] = 9, ["y"] = 11, ["param1"] = 14, ["z"] = 17, ["name"] = "default:pine_needles"}, {["x"] = 9, ["param2"] = 20, ["y"] = 12, ["z"] = 9, ["name"] = "default:pine_tree"}, {["x"] = 9, ["y"] = 12, ["param1"] = 12, ["z"] = 14, ["name"] = "default:pine_needles"}, {["x"] = 9, ["y"] = 12, ["param1"] = 13, ["z"] = 15, ["name"] = "default:pine_needles"}, {["x"] = 9, ["y"] = 12, ["param1"] = 14, ["z"] = 16, ["name"] = "default:pine_needles"}, {["x"] = 9, ["param2"] = 20, ["y"] = 13, ["z"] = 9, ["name"] = "default:pine_tree"}, {["x"] = 9, ["y"] = 14, ["param1"] = 13, ["z"] = 4, ["name"] = "default:pine_needles"}, {["x"] = 9, ["y"] = 14, ["param1"] = 12, ["z"] = 5, ["name"] = "default:pine_needles"}, {["x"] = 9, ["y"] = 14, ["param1"] = 12, ["z"] = 6, ["name"] = "default:pine_needles"}, {["x"] = 9, ["y"] = 14, ["param1"] = 12, ["z"] = 7, ["name"] = "default:pine_needles"}, {["x"] = 9, ["param2"] = 20, ["y"] = 14, ["z"] = 9, ["name"] = "default:pine_tree"}, {["x"] = 9, ["y"] = 14, ["param1"] = 13, ["z"] = 13, ["name"] = "default:pine_needles"}, {["x"] = 9, ["y"] = 14, ["param1"] = 13, ["z"] = 14, ["name"] = "default:pine_needles"}, {["x"] = 9, ["y"] = 15, ["param1"] = 13, ["z"] = 3, ["name"] = "default:pine_needles"}, {["x"] = 9, ["y"] = 15, ["param1"] = 13, ["z"] = 4, ["name"] = "default:pine_needles"}, {["x"] = 9, ["y"] = 15, ["param1"] = 12, ["z"] = 5, ["name"] = "default:pine_needles"}, {["x"] = 9, ["param2"] = 9, ["y"] = 15, ["param1"] = 54, ["z"] = 6, ["name"] = "default:pine_tree"}, {["x"] = 9, ["param2"] = 9, ["y"] = 15, ["param1"] = 54, ["z"] = 7, ["name"] = "default:pine_tree"}, {["x"] = 9, ["param2"] = 9, ["y"] = 15, ["param1"] = 54, ["z"] = 8, ["name"] = "default:pine_tree"}, {["x"] = 9, ["y"] = 15, ["z"] = 9, ["name"] = "default:pine_tree"}, {["x"] = 9, ["y"] = 15, ["param1"] = 13, ["z"] = 12, ["name"] = "default:pine_needles"}, {["x"] = 9, ["y"] = 15, ["param1"] = 13, ["z"] = 13, ["name"] = "default:pine_needles"}, {["x"] = 9, ["y"] = 15, ["param1"] = 13, ["z"] = 14, ["name"] = "default:pine_needles"}, {["x"] = 9, ["y"] = 15, ["param1"] = 14, ["z"] = 15, ["name"] = "default:pine_needles"}, {["x"] = 9, ["y"] = 16, ["param1"] = 14, ["z"] = 2, ["name"] = "default:pine_needles"}, {["x"] = 9, ["y"] = 16, ["param1"] = 13, ["z"] = 3, ["name"] = "default:pine_needles"}, {["x"] = 9, ["y"] = 16, ["param1"] = 13, ["z"] = 4, ["name"] = "default:pine_needles"}, {["x"] = 9, ["y"] = 16, ["param1"] = 13, ["z"] = 5, ["name"] = "default:pine_needles"}, {["x"] = 9, ["y"] = 16, ["param1"] = 13, ["z"] = 6, ["name"] = "default:pine_needles"}, {["x"] = 9, ["y"] = 16, ["param1"] = 13, ["z"] = 7, ["name"] = "default:pine_needles"}, {["x"] = 9, ["y"] = 16, ["z"] = 9, ["name"] = "default:pine_tree"}, {["x"] = 9, ["y"] = 16, ["param1"] = 14, ["z"] = 13, ["name"] = "default:pine_needles"}, {["x"] = 9, ["y"] = 16, ["param1"] = 14, ["z"] = 14, ["name"] = "default:pine_needles"}, {["x"] = 9, ["y"] = 17, ["param1"] = 14, ["z"] = 3, ["name"] = "default:pine_needles"}, {["x"] = 9, ["y"] = 17, ["param1"] = 14, ["z"] = 4, ["name"] = "default:pine_needles"}, {["x"] = 9, ["y"] = 17, ["param1"] = 14, ["z"] = 5, ["name"] = "default:pine_needles"}, {["x"] = 9, ["y"] = 17, ["param1"] = 14, ["z"] = 6, ["name"] = "default:pine_needles"}, {["x"] = 9, ["y"] = 17, ["z"] = 9, ["name"] = "default:pine_tree"}, {["x"] = 9, ["param2"] = 18, ["y"] = 17, ["z"] = 10, ["name"] = "default:pine_tree"}, {["x"] = 9, ["y"] = 18, ["z"] = 9, ["name"] = "default:pine_tree"}, {["x"] = 9, ["y"] = 19, ["z"] = 9, ["name"] = "default:pine_tree"}, {["x"] = 9, ["y"] = 20, ["param1"] = 14, ["z"] = 6, ["name"] = "default:pine_needles"}, {["x"] = 9, ["y"] = 20, ["param1"] = 13, ["z"] = 7, ["name"] = "default:pine_needles"}, {["x"] = 9, ["y"] = 20, ["z"] = 9, ["name"] = "default:pine_tree"}, {["x"] = 9, ["param2"] = 18, ["y"] = 20, ["z"] = 10, ["name"] = "default:pine_tree"}, {["x"] = 9, ["y"] = 20, ["param1"] = 13, ["z"] = 12, ["name"] = "default:pine_needles"}, {["x"] = 9, ["y"] = 20, ["param1"] = 14, ["z"] = 13, ["name"] = "default:pine_needles"}, {["x"] = 9, ["y"] = 21, ["param1"] = 14, ["z"] = 7, ["name"] = "default:pine_needles"}, {["x"] = 9, ["y"] = 21, ["param1"] = 13, ["z"] = 8, ["name"] = "default:pine_needles"}, {["x"] = 9, ["y"] = 21, ["z"] = 9, ["name"] = "default:pine_tree"}, {["x"] = 9, ["y"] = 21, ["param1"] = 12, ["z"] = 10, ["name"] = "default:pine_needles"}, {["x"] = 9, ["y"] = 21, ["param1"] = 13, ["z"] = 11, ["name"] = "default:pine_needles"}, {["x"] = 9, ["y"] = 21, ["param1"] = 14, ["z"] = 12, ["name"] = "default:pine_needles"}, {["x"] = 9, ["y"] = 22, ["param1"] = 14, ["z"] = 8, ["name"] = "default:pine_needles"}, {["x"] = 9, ["y"] = 22, ["z"] = 9, ["name"] = "default:pine_tree"}, {["x"] = 9, ["y"] = 22, ["param1"] = 13, ["z"] = 10, ["name"] = "default:pine_needles"}, {["x"] = 9, ["y"] = 22, ["param1"] = 14, ["z"] = 11, ["name"] = "default:pine_needles"}, {["x"] = 9, ["y"] = 23, ["param1"] = 14, ["z"] = 8, ["name"] = "default:pine_needles"}, {["x"] = 9, ["y"] = 23, ["param1"] = 13, ["z"] = 9, ["name"] = "default:pine_needles"}, {["x"] = 9, ["y"] = 23, ["param1"] = 14, ["z"] = 10, ["name"] = "default:pine_needles"}, {["x"] = 9, ["y"] = 24, ["param1"] = 14, ["z"] = 9, ["name"] = "default:pine_needles"}, {["x"] = 10, ["y"] = 0, ["z"] = 9, ["name"] = "default:pine_tree"}, {["x"] = 10, ["y"] = 0, ["z"] = 10, ["name"] = "default:pine_tree"}, {["x"] = 10, ["y"] = 1, ["z"] = 9, ["name"] = "default:pine_tree"}, {["x"] = 10, ["y"] = 1, ["z"] = 10, ["name"] = "default:pine_tree"}, {["x"] = 10, ["y"] = 2, ["z"] = 9, ["name"] = "default:pine_tree"}, {["x"] = 10, ["y"] = 2, ["z"] = 10, ["name"] = "default:pine_tree"}, {["x"] = 10, ["y"] = 3, ["z"] = 9, ["name"] = "default:pine_tree"}, {["x"] = 10, ["y"] = 3, ["z"] = 10, ["name"] = "default:pine_tree"}, {["x"] = 10, ["y"] = 4, ["param1"] = 12, ["z"] = 3, ["name"] = "default:pine_needles"}, {["x"] = 10, ["y"] = 4, ["param1"] = 11, ["z"] = 5, ["name"] = "default:pine_needles"}, {["x"] = 10, ["y"] = 4, ["param1"] = 10, ["z"] = 6, ["name"] = "default:pine_needles"}, {["x"] = 10, ["y"] = 4, ["z"] = 9, ["name"] = "default:pine_tree"}, {["x"] = 10, ["y"] = 4, ["z"] = 10, ["name"] = "default:pine_tree"}, {["x"] = 10, ["y"] = 4, ["param1"] = 11, ["z"] = 14, ["name"] = "default:pine_needles"}, {["x"] = 10, ["y"] = 4, ["param1"] = 11, ["z"] = 15, ["name"] = "default:pine_needles"}, {["x"] = 10, ["y"] = 4, ["param1"] = 12, ["z"] = 16, ["name"] = "default:pine_needles"}, {["x"] = 10, ["y"] = 4, ["param1"] = 13, ["z"] = 17, ["name"] = "default:pine_needles"}, {["x"] = 10, ["y"] = 5, ["param1"] = 13, ["z"] = 2, ["name"] = "default:pine_needles"}, {["x"] = 10, ["y"] = 5, ["param1"] = 12, ["z"] = 3, ["name"] = "default:pine_needles"}, {["x"] = 10, ["y"] = 5, ["param1"] = 11, ["z"] = 4, ["name"] = "default:pine_needles"}, {["x"] = 10, ["param2"] = 12, ["y"] = 5, ["z"] = 5, ["name"] = "default:pine_tree"}, {["x"] = 10, ["y"] = 5, ["param1"] = 10, ["z"] = 6, ["name"] = "default:pine_needles"}, {["x"] = 10, ["y"] = 5, ["param1"] = 9, ["z"] = 7, ["name"] = "default:pine_needles"}, {["x"] = 10, ["y"] = 5, ["z"] = 9, ["name"] = "default:pine_tree"}, {["x"] = 10, ["y"] = 5, ["z"] = 10, ["name"] = "default:pine_tree"}, {["x"] = 10, ["param2"] = 9, ["y"] = 5, ["param1"] = 54, ["z"] = 11, ["name"] = "default:pine_tree"}, {["x"] = 10, ["param2"] = 9, ["y"] = 5, ["param1"] = 54, ["z"] = 12, ["name"] = "default:pine_tree"}, {["x"] = 10, ["param2"] = 7, ["y"] = 5, ["param1"] = 54, ["z"] = 13, ["name"] = "default:pine_tree"}, {["x"] = 10, ["param2"] = 7, ["y"] = 5, ["param1"] = 54, ["z"] = 14, ["name"] = "default:pine_tree"}, {["x"] = 10, ["param2"] = 7, ["y"] = 5, ["param1"] = 54, ["z"] = 15, ["name"] = "default:pine_tree"}, {["x"] = 10, ["param2"] = 7, ["y"] = 5, ["param1"] = 54, ["z"] = 16, ["name"] = "default:pine_tree"}, {["x"] = 10, ["y"] = 5, ["param1"] = 13, ["z"] = 17, ["name"] = "default:pine_needles"}, {["x"] = 10, ["y"] = 5, ["param1"] = 14, ["z"] = 18, ["name"] = "default:pine_needles"}, {["x"] = 10, ["y"] = 6, ["param1"] = 14, ["z"] = 1, ["name"] = "default:pine_needles"}, {["x"] = 10, ["y"] = 6, ["param1"] = 13, ["z"] = 2, ["name"] = "default:pine_needles"}, {["x"] = 10, ["y"] = 6, ["param1"] = 12, ["z"] = 3, ["name"] = "default:pine_needles"}, {["x"] = 10, ["y"] = 6, ["param1"] = 11, ["z"] = 4, ["name"] = "default:pine_needles"}, {["x"] = 10, ["y"] = 6, ["param1"] = 11, ["z"] = 5, ["name"] = "default:pine_needles"}, {["x"] = 10, ["y"] = 6, ["param1"] = 10, ["z"] = 6, ["name"] = "default:pine_needles"}, {["x"] = 10, ["y"] = 6, ["param1"] = 54, ["z"] = 9, ["name"] = "default:pine_tree"}, {["x"] = 10, ["y"] = 6, ["param1"] = 54, ["z"] = 10, ["name"] = "default:pine_tree"}, {["x"] = 10, ["y"] = 6, ["param1"] = 13, ["z"] = 12, ["name"] = "default:pine_needles"}, {["x"] = 10, ["y"] = 6, ["param1"] = 12, ["z"] = 13, ["name"] = "default:pine_needles"}, {["x"] = 10, ["y"] = 6, ["param1"] = 11, ["z"] = 14, ["name"] = "default:pine_needles"}, {["x"] = 10, ["y"] = 6, ["param1"] = 11, ["z"] = 15, ["name"] = "default:pine_needles"}, {["x"] = 10, ["y"] = 6, ["param1"] = 12, ["z"] = 16, ["name"] = "default:pine_needles"}, {["x"] = 10, ["y"] = 6, ["param1"] = 13, ["z"] = 17, ["name"] = "default:pine_needles"}, {["x"] = 10, ["y"] = 6, ["param1"] = 14, ["z"] = 18, ["name"] = "default:pine_needles"}, {["x"] = 10, ["y"] = 7, ["param1"] = 13, ["z"] = 3, ["name"] = "default:pine_needles"}, {["x"] = 10, ["y"] = 7, ["param1"] = 54, ["z"] = 9, ["name"] = "default:pine_tree"}, {["x"] = 10, ["y"] = 7, ["param1"] = 54, ["z"] = 10, ["name"] = "default:pine_tree"}, {["x"] = 10, ["y"] = 7, ["param1"] = 11, ["z"] = 14, ["name"] = "default:pine_needles"}, {["x"] = 10, ["y"] = 7, ["param1"] = 12, ["z"] = 15, ["name"] = "default:pine_needles"}, {["x"] = 10, ["y"] = 7, ["param1"] = 13, ["z"] = 16, ["name"] = "default:pine_needles"}, {["x"] = 10, ["y"] = 7, ["param1"] = 14, ["z"] = 17, ["name"] = "default:pine_needles"}, {["x"] = 10, ["y"] = 8, ["param1"] = 54, ["z"] = 9, ["name"] = "default:pine_tree"}, {["x"] = 10, ["y"] = 8, ["param1"] = 54, ["z"] = 10, ["name"] = "default:pine_tree"}, {["x"] = 10, ["y"] = 9, ["param1"] = 13, ["z"] = 3, ["name"] = "default:pine_needles"}, {["x"] = 10, ["y"] = 9, ["param1"] = 12, ["z"] = 4, ["name"] = "default:pine_needles"}, {["x"] = 10, ["y"] = 9, ["param1"] = 11, ["z"] = 6, ["name"] = "default:pine_needles"}, {["x"] = 10, ["y"] = 9, ["param1"] = 54, ["z"] = 9, ["name"] = "default:pine_tree"}, {["x"] = 10, ["y"] = 9, ["param1"] = 54, ["z"] = 10, ["name"] = "default:pine_tree"}, {["x"] = 10, ["y"] = 9, ["param1"] = 12, ["z"] = 13, ["name"] = "default:pine_needles"}, {["x"] = 10, ["y"] = 9, ["param1"] = 12, ["z"] = 14, ["name"] = "default:pine_needles"}, {["x"] = 10, ["y"] = 9, ["param1"] = 13, ["z"] = 15, ["name"] = "default:pine_needles"}, {["x"] = 10, ["y"] = 10, ["param1"] = 14, ["z"] = 2, ["name"] = "default:pine_needles"}, {["x"] = 10, ["y"] = 10, ["param1"] = 13, ["z"] = 3, ["name"] = "default:pine_needles"}, {["x"] = 10, ["y"] = 10, ["param1"] = 12, ["z"] = 4, ["name"] = "default:pine_needles"}, {["x"] = 10, ["param2"] = 9, ["y"] = 10, ["param1"] = 54, ["z"] = 5, ["name"] = "default:pine_tree"}, {["x"] = 10, ["param2"] = 9, ["y"] = 10, ["param1"] = 54, ["z"] = 6, ["name"] = "default:pine_tree"}, {["x"] = 10, ["param2"] = 9, ["y"] = 10, ["param1"] = 54, ["z"] = 7, ["name"] = "default:pine_tree"}, {["x"] = 10, ["param2"] = 9, ["y"] = 10, ["param1"] = 54, ["z"] = 8, ["name"] = "default:pine_tree"}, {["x"] = 10, ["param2"] = 9, ["y"] = 10, ["z"] = 9, ["name"] = "default:pine_tree"}, {["x"] = 10, ["y"] = 10, ["param1"] = 54, ["z"] = 10, ["name"] = "default:pine_tree"}, {["x"] = 10, ["y"] = 10, ["param1"] = 13, ["z"] = 12, ["name"] = "default:pine_needles"}, {["x"] = 10, ["y"] = 10, ["param1"] = 12, ["z"] = 13, ["name"] = "default:pine_needles"}, {["x"] = 10, ["y"] = 10, ["param1"] = 12, ["z"] = 14, ["name"] = "default:pine_needles"}, {["x"] = 10, ["y"] = 10, ["param1"] = 13, ["z"] = 15, ["name"] = "default:pine_needles"}, {["x"] = 10, ["y"] = 10, ["param1"] = 14, ["z"] = 16, ["name"] = "default:pine_needles"}, {["x"] = 10, ["y"] = 11, ["param1"] = 14, ["z"] = 3, ["name"] = "default:pine_needles"}, {["x"] = 10, ["y"] = 11, ["param1"] = 13, ["z"] = 4, ["name"] = "default:pine_needles"}, {["x"] = 10, ["y"] = 11, ["param1"] = 12, ["z"] = 5, ["name"] = "default:pine_needles"}, {["x"] = 10, ["y"] = 11, ["param1"] = 13, ["z"] = 6, ["name"] = "default:pine_needles"}, {["x"] = 10, ["y"] = 11, ["param1"] = 12, ["z"] = 7, ["name"] = "default:pine_needles"}, {["x"] = 10, ["y"] = 11, ["param1"] = 54, ["z"] = 10, ["name"] = "default:pine_tree"}, {["x"] = 10, ["y"] = 11, ["param1"] = 12, ["z"] = 13, ["name"] = "default:pine_needles"}, {["x"] = 10, ["y"] = 11, ["param1"] = 12, ["z"] = 14, ["name"] = "default:pine_needles"}, {["x"] = 10, ["y"] = 11, ["param1"] = 13, ["z"] = 15, ["name"] = "default:pine_needles"}, {["x"] = 10, ["y"] = 11, ["param1"] = 14, ["z"] = 16, ["name"] = "default:pine_needles"}, {["x"] = 10, ["y"] = 12, ["param1"] = 14, ["z"] = 3, ["name"] = "default:pine_needles"}, {["x"] = 10, ["y"] = 12, ["param1"] = 13, ["z"] = 4, ["name"] = "default:pine_needles"}, {["x"] = 10, ["param2"] = 3, ["y"] = 12, ["z"] = 10, ["name"] = "default:pine_tree"}, {["x"] = 10, ["param2"] = 3, ["y"] = 13, ["z"] = 10, ["name"] = "default:pine_tree"}, {["x"] = 10, ["y"] = 14, ["param1"] = 13, ["z"] = 5, ["name"] = "default:pine_needles"}, {["x"] = 10, ["y"] = 14, ["param1"] = 13, ["z"] = 6, ["name"] = "default:pine_needles"}, {["x"] = 10, ["param2"] = 3, ["y"] = 14, ["z"] = 10, ["name"] = "default:pine_tree"}, {["x"] = 10, ["y"] = 14, ["param1"] = 13, ["z"] = 12, ["name"] = "default:pine_needles"}, {["x"] = 10, ["y"] = 14, ["param1"] = 12, ["z"] = 13, ["name"] = "default:pine_needles"}, {["x"] = 10, ["y"] = 14, ["param1"] = 13, ["z"] = 14, ["name"] = "default:pine_needles"}, {["x"] = 10, ["y"] = 14, ["param1"] = 14, ["z"] = 15, ["name"] = "default:pine_needles"}, {["x"] = 10, ["y"] = 15, ["param1"] = 14, ["z"] = 4, ["name"] = "default:pine_needles"}, {["x"] = 10, ["y"] = 15, ["param1"] = 13, ["z"] = 5, ["name"] = "default:pine_needles"}, {["x"] = 10, ["y"] = 15, ["param1"] = 13, ["z"] = 6, ["name"] = "default:pine_needles"}, {["x"] = 10, ["y"] = 15, ["param1"] = 12, ["z"] = 7, ["name"] = "default:pine_needles"}, {["x"] = 10, ["param2"] = 3, ["y"] = 15, ["z"] = 10, ["name"] = "default:pine_tree"}, {["x"] = 10, ["param2"] = 7, ["y"] = 15, ["param1"] = 54, ["z"] = 11, ["name"] = "default:pine_tree"}, {["x"] = 10, ["param2"] = 7, ["y"] = 15, ["param1"] = 54, ["z"] = 12, ["name"] = "default:pine_tree"}, {["x"] = 10, ["param2"] = 7, ["y"] = 15, ["param1"] = 54, ["z"] = 13, ["name"] = "default:pine_tree"}, {["x"] = 10, ["y"] = 15, ["param1"] = 13, ["z"] = 14, ["name"] = "default:pine_needles"}, {["x"] = 10, ["y"] = 15, ["param1"] = 14, ["z"] = 15, ["name"] = "default:pine_needles"}, {["x"] = 10, ["y"] = 16, ["param1"] = 14, ["z"] = 3, ["name"] = "default:pine_needles"}, {["x"] = 10, ["y"] = 16, ["param1"] = 14, ["z"] = 4, ["name"] = "default:pine_needles"}, {["x"] = 10, ["y"] = 16, ["param1"] = 14, ["z"] = 5, ["name"] = "default:pine_needles"}, {["x"] = 10, ["y"] = 16, ["param1"] = 14, ["z"] = 6, ["name"] = "default:pine_needles"}, {["x"] = 10, ["y"] = 16, ["z"] = 10, ["name"] = "default:pine_tree"}, {["x"] = 10, ["y"] = 16, ["param1"] = 13, ["z"] = 12, ["name"] = "default:pine_needles"}, {["x"] = 10, ["y"] = 16, ["param1"] = 13, ["z"] = 13, ["name"] = "default:pine_needles"}, {["x"] = 10, ["y"] = 16, ["param1"] = 13, ["z"] = 14, ["name"] = "default:pine_needles"}, {["x"] = 10, ["y"] = 16, ["param1"] = 14, ["z"] = 15, ["name"] = "default:pine_needles"}, {["x"] = 10, ["param2"] = 18, ["y"] = 17, ["z"] = 9, ["name"] = "default:pine_tree"}, {["x"] = 10, ["y"] = 17, ["z"] = 10, ["name"] = "default:pine_tree"}, {["x"] = 10, ["y"] = 17, ["param1"] = 14, ["z"] = 14, ["name"] = "default:pine_needles"}, {["x"] = 10, ["y"] = 18, ["z"] = 10, ["name"] = "default:pine_tree"}, {["x"] = 10, ["y"] = 19, ["param1"] = 13, ["z"] = 7, ["name"] = "default:pine_needles"}, {["x"] = 10, ["y"] = 19, ["param1"] = 12, ["z"] = 8, ["name"] = "default:pine_needles"}, {["x"] = 10, ["y"] = 19, ["z"] = 10, ["name"] = "default:pine_tree"}, {["x"] = 10, ["y"] = 19, ["param1"] = 12, ["z"] = 11, ["name"] = "default:pine_needles"}, {["x"] = 10, ["y"] = 19, ["param1"] = 13, ["z"] = 12, ["name"] = "default:pine_needles"}, {["x"] = 10, ["y"] = 20, ["param1"] = 14, ["z"] = 6, ["name"] = "default:pine_needles"}, {["x"] = 10, ["y"] = 20, ["param1"] = 13, ["z"] = 7, ["name"] = "default:pine_needles"}, {["x"] = 10, ["param2"] = 9, ["y"] = 20, ["z"] = 8, ["name"] = "default:pine_tree"}, {["x"] = 10, ["param2"] = 9, ["y"] = 20, ["z"] = 9, ["name"] = "default:pine_tree"}, {["x"] = 10, ["y"] = 20, ["z"] = 10, ["name"] = "default:pine_tree"}, {["x"] = 10, ["param2"] = 7, ["y"] = 20, ["z"] = 11, ["name"] = "default:pine_tree"}, {["x"] = 10, ["y"] = 20, ["param1"] = 13, ["z"] = 12, ["name"] = "default:pine_needles"}, {["x"] = 10, ["y"] = 20, ["param1"] = 14, ["z"] = 13, ["name"] = "default:pine_needles"}, {["x"] = 10, ["y"] = 21, ["param1"] = 14, ["z"] = 6, ["name"] = "default:pine_needles"}, {["x"] = 10, ["y"] = 21, ["param1"] = 14, ["z"] = 7, ["name"] = "default:pine_needles"}, {["x"] = 10, ["y"] = 21, ["param1"] = 13, ["z"] = 8, ["name"] = "default:pine_needles"}, {["x"] = 10, ["y"] = 21, ["param1"] = 12, ["z"] = 9, ["name"] = "default:pine_needles"}, {["x"] = 10, ["y"] = 21, ["param1"] = 13, ["z"] = 10, ["name"] = "default:pine_needles"}, {["x"] = 10, ["y"] = 21, ["param1"] = 13, ["z"] = 11, ["name"] = "default:pine_needles"}, {["x"] = 10, ["y"] = 21, ["param1"] = 13, ["z"] = 12, ["name"] = "default:pine_needles"}, {["x"] = 10, ["y"] = 21, ["param1"] = 14, ["z"] = 13, ["name"] = "default:pine_needles"}, {["x"] = 10, ["y"] = 22, ["param1"] = 14, ["z"] = 8, ["name"] = "default:pine_needles"}, {["x"] = 10, ["y"] = 22, ["param1"] = 13, ["z"] = 9, ["name"] = "default:pine_needles"}, {["x"] = 10, ["y"] = 22, ["param1"] = 14, ["z"] = 10, ["name"] = "default:pine_needles"}, {["x"] = 10, ["y"] = 22, ["param1"] = 13, ["z"] = 11, ["name"] = "default:pine_needles"}, {["x"] = 10, ["y"] = 22, ["param1"] = 14, ["z"] = 12, ["name"] = "default:pine_needles"}, {["x"] = 10, ["y"] = 23, ["param1"] = 14, ["z"] = 9, ["name"] = "default:pine_needles"}, {["x"] = 10, ["y"] = 23, ["param1"] = 14, ["z"] = 11, ["name"] = "default:pine_needles"}, {["x"] = 10, ["y"] = 24, ["param1"] = 14, ["z"] = 11, ["name"] = "default:pine_needles"}, {["x"] = 11, ["y"] = 4, ["param1"] = 12, ["z"] = 4, ["name"] = "default:pine_needles"}, {["x"] = 11, ["y"] = 4, ["param1"] = 12, ["z"] = 5, ["name"] = "default:pine_needles"}, {["x"] = 11, ["y"] = 4, ["param1"] = 11, ["z"] = 13, ["name"] = "default:pine_needles"}, {["x"] = 11, ["y"] = 4, ["param1"] = 12, ["z"] = 14, ["name"] = "default:pine_needles"}, {["x"] = 11, ["y"] = 4, ["param1"] = 12, ["z"] = 15, ["name"] = "default:pine_needles"}, {["x"] = 11, ["y"] = 4, ["param1"] = 12, ["z"] = 16, ["name"] = "default:pine_needles"}, {["x"] = 11, ["y"] = 4, ["param1"] = 13, ["z"] = 17, ["name"] = "default:pine_needles"}, {["x"] = 11, ["y"] = 5, ["param1"] = 13, ["z"] = 3, ["name"] = "default:pine_needles"}, {["x"] = 11, ["y"] = 5, ["param1"] = 12, ["z"] = 4, ["name"] = "default:pine_needles"}, {["x"] = 11, ["y"] = 5, ["param1"] = 12, ["z"] = 5, ["name"] = "default:pine_needles"}, {["x"] = 11, ["y"] = 5, ["param1"] = 11, ["z"] = 6, ["name"] = "default:pine_needles"}, {["x"] = 11, ["y"] = 5, ["param1"] = 10, ["z"] = 7, ["name"] = "default:pine_needles"}, {["x"] = 11, ["y"] = 5, ["param1"] = 13, ["z"] = 12, ["name"] = "default:pine_needles"}, {["x"] = 11, ["y"] = 5, ["param1"] = 12, ["z"] = 13, ["name"] = "default:pine_needles"}, {["x"] = 11, ["param2"] = 12, ["y"] = 5, ["z"] = 14, ["name"] = "default:pine_tree"}, {["x"] = 11, ["y"] = 5, ["param1"] = 12, ["z"] = 15, ["name"] = "default:pine_needles"}, {["x"] = 11, ["y"] = 5, ["param1"] = 12, ["z"] = 16, ["name"] = "default:pine_needles"}, {["x"] = 11, ["y"] = 5, ["param1"] = 13, ["z"] = 17, ["name"] = "default:pine_needles"}, {["x"] = 11, ["y"] = 5, ["param1"] = 14, ["z"] = 18, ["name"] = "default:pine_needles"}, {["x"] = 11, ["y"] = 6, ["param1"] = 14, ["z"] = 2, ["name"] = "default:pine_needles"}, {["x"] = 11, ["y"] = 6, ["param1"] = 12, ["z"] = 4, ["name"] = "default:pine_needles"}, {["x"] = 11, ["y"] = 6, ["param1"] = 12, ["z"] = 5, ["name"] = "default:pine_needles"}, {["x"] = 11, ["y"] = 6, ["param1"] = 13, ["z"] = 13, ["name"] = "default:pine_needles"}, {["x"] = 11, ["y"] = 6, ["param1"] = 12, ["z"] = 14, ["name"] = "default:pine_needles"}, {["x"] = 11, ["y"] = 6, ["param1"] = 12, ["z"] = 15, ["name"] = "default:pine_needles"}, {["x"] = 11, ["y"] = 6, ["param1"] = 12, ["z"] = 16, ["name"] = "default:pine_needles"}, {["x"] = 11, ["y"] = 6, ["param1"] = 13, ["z"] = 17, ["name"] = "default:pine_needles"}, {["x"] = 11, ["y"] = 6, ["param1"] = 14, ["z"] = 18, ["name"] = "default:pine_needles"}, {["x"] = 11, ["param2"] = 12, ["y"] = 7, ["param1"] = 54, ["z"] = 9, ["name"] = "default:pine_tree"}, {["x"] = 11, ["y"] = 7, ["param1"] = 13, ["z"] = 15, ["name"] = "default:pine_needles"}, {["x"] = 11, ["y"] = 7, ["param1"] = 13, ["z"] = 16, ["name"] = "default:pine_needles"}, {["x"] = 11, ["y"] = 7, ["param1"] = 14, ["z"] = 17, ["name"] = "default:pine_needles"}, {["x"] = 11, ["y"] = 7, ["param1"] = 14, ["z"] = 18, ["name"] = "default:pine_needles"}, {["x"] = 11, ["y"] = 9, ["param1"] = 12, ["z"] = 4, ["name"] = "default:pine_needles"}, {["x"] = 11, ["y"] = 9, ["param1"] = 12, ["z"] = 5, ["name"] = "default:pine_needles"}, {["x"] = 11, ["y"] = 9, ["param1"] = 12, ["z"] = 6, ["name"] = "default:pine_needles"}, {["x"] = 11, ["y"] = 10, ["param1"] = 14, ["z"] = 2, ["name"] = "default:pine_needles"}, {["x"] = 11, ["y"] = 10, ["param1"] = 13, ["z"] = 3, ["name"] = "default:pine_needles"}, {["x"] = 11, ["y"] = 10, ["param1"] = 12, ["z"] = 4, ["name"] = "default:pine_needles"}, {["x"] = 11, ["y"] = 10, ["param1"] = 12, ["z"] = 5, ["name"] = "default:pine_needles"}, {["x"] = 11, ["y"] = 10, ["param1"] = 13, ["z"] = 6, ["name"] = "default:pine_needles"}, {["x"] = 11, ["y"] = 10, ["param1"] = 12, ["z"] = 7, ["name"] = "default:pine_needles"}, {["x"] = 11, ["y"] = 10, ["param1"] = 13, ["z"] = 13, ["name"] = "default:pine_needles"}, {["x"] = 11, ["y"] = 10, ["param1"] = 12, ["z"] = 14, ["name"] = "default:pine_needles"}, {["x"] = 11, ["y"] = 11, ["param1"] = 14, ["z"] = 2, ["name"] = "default:pine_needles"}, {["x"] = 11, ["y"] = 11, ["param1"] = 13, ["z"] = 3, ["name"] = "default:pine_needles"}, {["x"] = 11, ["y"] = 11, ["param1"] = 13, ["z"] = 4, ["name"] = "default:pine_needles"}, {["x"] = 11, ["y"] = 11, ["param1"] = 13, ["z"] = 5, ["name"] = "default:pine_needles"}, {["x"] = 11, ["y"] = 11, ["param1"] = 14, ["z"] = 6, ["name"] = "default:pine_needles"}, {["x"] = 11, ["y"] = 12, ["param1"] = 14, ["z"] = 3, ["name"] = "default:pine_needles"}, {["x"] = 11, ["y"] = 12, ["param1"] = 14, ["z"] = 4, ["name"] = "default:pine_needles"}, {["x"] = 11, ["y"] = 12, ["param1"] = 14, ["z"] = 5, ["name"] = "default:pine_needles"}, {["x"] = 11, ["param2"] = 12, ["y"] = 12, ["param1"] = 54, ["z"] = 10, ["name"] = "default:pine_tree"}, {["x"] = 11, ["y"] = 14, ["param1"] = 13, ["z"] = 13, ["name"] = "default:pine_needles"}, {["x"] = 11, ["y"] = 14, ["param1"] = 12, ["z"] = 14, ["name"] = "default:pine_needles"}, {["x"] = 11, ["y"] = 14, ["param1"] = 13, ["z"] = 15, ["name"] = "default:pine_needles"}, {["x"] = 11, ["y"] = 15, ["param1"] = 14, ["z"] = 5, ["name"] = "default:pine_needles"}, {["x"] = 11, ["y"] = 15, ["param1"] = 14, ["z"] = 6, ["name"] = "default:pine_needles"}, {["x"] = 11, ["y"] = 15, ["param1"] = 14, ["z"] = 12, ["name"] = "default:pine_needles"}, {["x"] = 11, ["y"] = 15, ["param1"] = 13, ["z"] = 13, ["name"] = "default:pine_needles"}, {["x"] = 11, ["y"] = 15, ["param1"] = 12, ["z"] = 14, ["name"] = "default:pine_needles"}, {["x"] = 11, ["y"] = 15, ["param1"] = 13, ["z"] = 15, ["name"] = "default:pine_needles"}, {["x"] = 11, ["y"] = 15, ["param1"] = 14, ["z"] = 16, ["name"] = "default:pine_needles"}, {["x"] = 11, ["y"] = 16, ["param1"] = 13, ["z"] = 13, ["name"] = "default:pine_needles"}, {["x"] = 11, ["y"] = 16, ["param1"] = 13, ["z"] = 14, ["name"] = "default:pine_needles"}, {["x"] = 11, ["y"] = 16, ["param1"] = 14, ["z"] = 15, ["name"] = "default:pine_needles"}, {["x"] = 11, ["y"] = 16, ["param1"] = 14, ["z"] = 16, ["name"] = "default:pine_needles"}, {["x"] = 11, ["param2"] = 12, ["y"] = 17, ["param1"] = 54, ["z"] = 9, ["name"] = "default:pine_tree"}, {["x"] = 11, ["y"] = 17, ["param1"] = 14, ["z"] = 13, ["name"] = "default:pine_needles"}, {["x"] = 11, ["y"] = 17, ["param1"] = 14, ["z"] = 14, ["name"] = "default:pine_needles"}, {["x"] = 11, ["y"] = 17, ["param1"] = 14, ["z"] = 15, ["name"] = "default:pine_needles"}, {["x"] = 11, ["y"] = 20, ["param1"] = 14, ["z"] = 7, ["name"] = "default:pine_needles"}, {["x"] = 11, ["y"] = 20, ["param1"] = 13, ["z"] = 8, ["name"] = "default:pine_needles"}, {["x"] = 11, ["param2"] = 12, ["y"] = 20, ["z"] = 10, ["name"] = "default:pine_tree"}, {["x"] = 11, ["y"] = 20, ["param1"] = 14, ["z"] = 12, ["name"] = "default:pine_needles"}, {["x"] = 11, ["y"] = 20, ["param1"] = 14, ["z"] = 13, ["name"] = "default:pine_needles"}, {["x"] = 11, ["y"] = 21, ["param1"] = 14, ["z"] = 8, ["name"] = "default:pine_needles"}, {["x"] = 11, ["y"] = 21, ["param1"] = 13, ["z"] = 9, ["name"] = "default:pine_needles"}, {["x"] = 11, ["y"] = 21, ["param1"] = 14, ["z"] = 10, ["name"] = "default:pine_needles"}, {["x"] = 11, ["y"] = 21, ["param1"] = 14, ["z"] = 11, ["name"] = "default:pine_needles"}, {["x"] = 11, ["y"] = 21, ["param1"] = 14, ["z"] = 12, ["name"] = "default:pine_needles"}, {["x"] = 11, ["y"] = 22, ["param1"] = 14, ["z"] = 9, ["name"] = "default:pine_needles"}, {["x"] = 11, ["y"] = 22, ["param1"] = 14, ["z"] = 11, ["name"] = "default:pine_needles"}, {["x"] = 12, ["y"] = 4, ["param1"] = 12, ["z"] = 13, ["name"] = "default:pine_needles"}, {["x"] = 12, ["y"] = 4, ["param1"] = 13, ["z"] = 14, ["name"] = "default:pine_needles"}, {["x"] = 12, ["y"] = 4, ["param1"] = 13, ["z"] = 15, ["name"] = "default:pine_needles"}, {["x"] = 12, ["y"] = 4, ["param1"] = 13, ["z"] = 16, ["name"] = "default:pine_needles"}, {["x"] = 12, ["y"] = 5, ["param1"] = 13, ["z"] = 4, ["name"] = "default:pine_needles"}, {["x"] = 12, ["y"] = 5, ["param1"] = 13, ["z"] = 5, ["name"] = "default:pine_needles"}, {["x"] = 12, ["y"] = 5, ["param1"] = 12, ["z"] = 6, ["name"] = "default:pine_needles"}, {["x"] = 12, ["y"] = 5, ["param1"] = 14, ["z"] = 12, ["name"] = "default:pine_needles"}, {["x"] = 12, ["y"] = 5, ["param1"] = 13, ["z"] = 13, ["name"] = "default:pine_needles"}, {["x"] = 12, ["y"] = 5, ["param1"] = 13, ["z"] = 14, ["name"] = "default:pine_needles"}, {["x"] = 12, ["y"] = 5, ["param1"] = 13, ["z"] = 15, ["name"] = "default:pine_needles"}, {["x"] = 12, ["y"] = 5, ["param1"] = 13, ["z"] = 16, ["name"] = "default:pine_needles"}, {["x"] = 12, ["y"] = 5, ["param1"] = 13, ["z"] = 17, ["name"] = "default:pine_needles"}, {["x"] = 12, ["y"] = 6, ["param1"] = 13, ["z"] = 14, ["name"] = "default:pine_needles"}, {["x"] = 12, ["y"] = 6, ["param1"] = 13, ["z"] = 15, ["name"] = "default:pine_needles"}, {["x"] = 12, ["y"] = 6, ["param1"] = 13, ["z"] = 16, ["name"] = "default:pine_needles"}, {["x"] = 12, ["y"] = 6, ["param1"] = 13, ["z"] = 17, ["name"] = "default:pine_needles"}, {["x"] = 12, ["y"] = 6, ["param1"] = 14, ["z"] = 18, ["name"] = "default:pine_needles"}, {["x"] = 12, ["y"] = 7, ["param1"] = 11, ["z"] = 7, ["name"] = "default:pine_needles"}, {["x"] = 12, ["y"] = 7, ["param1"] = 10, ["z"] = 8, ["name"] = "default:pine_needles"}, {["x"] = 12, ["param2"] = 12, ["y"] = 7, ["param1"] = 54, ["z"] = 9, ["name"] = "default:pine_tree"}, {["x"] = 12, ["y"] = 7, ["param1"] = 13, ["z"] = 10, ["name"] = "default:pine_needles"}, {["x"] = 12, ["y"] = 7, ["param1"] = 14, ["z"] = 11, ["name"] = "default:pine_needles"}, {["x"] = 12, ["y"] = 7, ["param1"] = 14, ["z"] = 15, ["name"] = "default:pine_needles"}, {["x"] = 12, ["y"] = 7, ["param1"] = 14, ["z"] = 16, ["name"] = "default:pine_needles"}, {["x"] = 12, ["y"] = 7, ["param1"] = 14, ["z"] = 17, ["name"] = "default:pine_needles"}, {["x"] = 12, ["y"] = 8, ["param1"] = 12, ["z"] = 9, ["name"] = "default:pine_needles"}, {["x"] = 12, ["y"] = 10, ["param1"] = 14, ["z"] = 3, ["name"] = "default:pine_needles"}, {["x"] = 12, ["y"] = 10, ["param1"] = 13, ["z"] = 4, ["name"] = "default:pine_needles"}, {["x"] = 12, ["y"] = 10, ["param1"] = 13, ["z"] = 5, ["name"] = "default:pine_needles"}, {["x"] = 12, ["y"] = 10, ["param1"] = 14, ["z"] = 6, ["name"] = "default:pine_needles"}, {["x"] = 12, ["y"] = 11, ["param1"] = 14, ["z"] = 3, ["name"] = "default:pine_needles"}, {["x"] = 12, ["y"] = 11, ["param1"] = 14, ["z"] = 4, ["name"] = "default:pine_needles"}, {["x"] = 12, ["y"] = 11, ["param1"] = 14, ["z"] = 5, ["name"] = "default:pine_needles"}, {["x"] = 12, ["y"] = 12, ["param1"] = 12, ["z"] = 9, ["name"] = "default:pine_needles"}, {["x"] = 12, ["param2"] = 12, ["y"] = 12, ["param1"] = 54, ["z"] = 10, ["name"] = "default:pine_tree"}, {["x"] = 12, ["y"] = 12, ["param1"] = 14, ["z"] = 11, ["name"] = "default:pine_needles"}, {["x"] = 12, ["y"] = 13, ["param1"] = 13, ["z"] = 10, ["name"] = "default:pine_needles"}, {["x"] = 12, ["y"] = 14, ["param1"] = 14, ["z"] = 13, ["name"] = "default:pine_needles"}, {["x"] = 12, ["y"] = 14, ["param1"] = 13, ["z"] = 14, ["name"] = "default:pine_needles"}, {["x"] = 12, ["y"] = 15, ["param1"] = 14, ["z"] = 13, ["name"] = "default:pine_needles"}, {["x"] = 12, ["y"] = 15, ["param1"] = 13, ["z"] = 14, ["name"] = "default:pine_needles"}, {["x"] = 12, ["y"] = 15, ["param1"] = 14, ["z"] = 15, ["name"] = "default:pine_needles"}, {["x"] = 12, ["y"] = 16, ["param1"] = 12, ["z"] = 9, ["name"] = "default:pine_needles"}, {["x"] = 12, ["y"] = 16, ["param1"] = 14, ["z"] = 13, ["name"] = "default:pine_needles"}, {["x"] = 12, ["y"] = 16, ["param1"] = 14, ["z"] = 14, ["name"] = "default:pine_needles"}, {["x"] = 12, ["y"] = 17, ["param1"] = 14, ["z"] = 7, ["name"] = "default:pine_needles"}, {["x"] = 12, ["y"] = 17, ["param1"] = 13, ["z"] = 8, ["name"] = "default:pine_needles"}, {["x"] = 12, ["param2"] = 12, ["y"] = 17, ["param1"] = 54, ["z"] = 9, ["name"] = "default:pine_tree"}, {["x"] = 12, ["y"] = 17, ["param1"] = 13, ["z"] = 10, ["name"] = "default:pine_needles"}, {["x"] = 12, ["y"] = 18, ["param1"] = 13, ["z"] = 9, ["name"] = "default:pine_needles"}, {["x"] = 12, ["y"] = 20, ["param1"] = 14, ["z"] = 8, ["name"] = "default:pine_needles"}, {["x"] = 12, ["y"] = 20, ["param1"] = 13, ["z"] = 9, ["name"] = "default:pine_needles"}, {["x"] = 12, ["y"] = 20, ["param1"] = 13, ["z"] = 10, ["name"] = "default:pine_needles"}, {["x"] = 12, ["y"] = 20, ["param1"] = 14, ["z"] = 11, ["name"] = "default:pine_needles"}, {["x"] = 12, ["y"] = 21, ["param1"] = 14, ["z"] = 9, ["name"] = "default:pine_needles"}, {["x"] = 12, ["y"] = 21, ["param1"] = 14, ["z"] = 10, ["name"] = "default:pine_needles"}, {["x"] = 13, ["y"] = 4, ["param1"] = 14, ["z"] = 14, ["name"] = "default:pine_needles"}, {["x"] = 13, ["y"] = 4, ["param1"] = 14, ["z"] = 15, ["name"] = "default:pine_needles"}, {["x"] = 13, ["y"] = 5, ["param1"] = 13, ["z"] = 13, ["name"] = "default:pine_needles"}, {["x"] = 13, ["y"] = 5, ["param1"] = 14, ["z"] = 14, ["name"] = "default:pine_needles"}, {["x"] = 13, ["y"] = 5, ["param1"] = 14, ["z"] = 15, ["name"] = "default:pine_needles"}, {["x"] = 13, ["y"] = 5, ["param1"] = 14, ["z"] = 16, ["name"] = "default:pine_needles"}, {["x"] = 13, ["y"] = 6, ["param1"] = 11, ["z"] = 8, ["name"] = "default:pine_needles"}, {["x"] = 13, ["y"] = 6, ["param1"] = 11, ["z"] = 9, ["name"] = "default:pine_needles"}, {["x"] = 13, ["y"] = 6, ["param1"] = 14, ["z"] = 15, ["name"] = "default:pine_needles"}, {["x"] = 13, ["y"] = 6, ["param1"] = 14, ["z"] = 16, ["name"] = "default:pine_needles"}, {["x"] = 13, ["y"] = 6, ["param1"] = 14, ["z"] = 17, ["name"] = "default:pine_needles"}, {["x"] = 13, ["y"] = 7, ["param1"] = 13, ["z"] = 6, ["name"] = "default:pine_needles"}, {["x"] = 13, ["y"] = 7, ["param1"] = 12, ["z"] = 7, ["name"] = "default:pine_needles"}, {["x"] = 13, ["y"] = 7, ["param1"] = 11, ["z"] = 8, ["name"] = "default:pine_needles"}, {["x"] = 13, ["param2"] = 12, ["y"] = 7, ["param1"] = 54, ["z"] = 9, ["name"] = "default:pine_tree"}, {["x"] = 13, ["y"] = 7, ["param1"] = 12, ["z"] = 10, ["name"] = "default:pine_needles"}, {["x"] = 13, ["y"] = 7, ["param1"] = 13, ["z"] = 11, ["name"] = "default:pine_needles"}, {["x"] = 13, ["y"] = 7, ["param1"] = 14, ["z"] = 12, ["name"] = "default:pine_needles"}, {["x"] = 13, ["y"] = 8, ["param1"] = 11, ["z"] = 9, ["name"] = "default:pine_needles"}, {["x"] = 13, ["y"] = 8, ["param1"] = 12, ["z"] = 10, ["name"] = "default:pine_needles"}, {["x"] = 13, ["y"] = 8, ["param1"] = 13, ["z"] = 11, ["name"] = "default:pine_needles"}, {["x"] = 13, ["y"] = 10, ["param1"] = 14, ["z"] = 4, ["name"] = "default:pine_needles"}, {["x"] = 13, ["y"] = 10, ["param1"] = 14, ["z"] = 5, ["name"] = "default:pine_needles"}, {["x"] = 13, ["y"] = 11, ["param1"] = 12, ["z"] = 10, ["name"] = "default:pine_needles"}, {["x"] = 13, ["y"] = 11, ["param1"] = 13, ["z"] = 11, ["name"] = "default:pine_needles"}, {["x"] = 13, ["y"] = 12, ["param1"] = 12, ["z"] = 8, ["name"] = "default:pine_needles"}, {["x"] = 13, ["y"] = 12, ["param1"] = 11, ["z"] = 9, ["name"] = "default:pine_needles"}, {["x"] = 13, ["param2"] = 12, ["y"] = 12, ["param1"] = 54, ["z"] = 10, ["name"] = "default:pine_tree"}, {["x"] = 13, ["y"] = 12, ["param1"] = 13, ["z"] = 11, ["name"] = "default:pine_needles"}, {["x"] = 13, ["y"] = 12, ["param1"] = 14, ["z"] = 12, ["name"] = "default:pine_needles"}, {["x"] = 13, ["y"] = 12, ["param1"] = 13, ["z"] = 13, ["name"] = "default:pine_needles"}, {["x"] = 13, ["y"] = 13, ["param1"] = 12, ["z"] = 9, ["name"] = "default:pine_needles"}, {["x"] = 13, ["y"] = 13, ["param1"] = 13, ["z"] = 10, ["name"] = "default:pine_needles"}, {["x"] = 13, ["y"] = 13, ["param1"] = 14, ["z"] = 11, ["name"] = "default:pine_needles"}, {["x"] = 13, ["y"] = 15, ["param1"] = 14, ["z"] = 13, ["name"] = "default:pine_needles"}, {["x"] = 13, ["y"] = 15, ["param1"] = 14, ["z"] = 14, ["name"] = "default:pine_needles"}, {["x"] = 13, ["y"] = 16, ["param1"] = 13, ["z"] = 7, ["name"] = "default:pine_needles"}, {["x"] = 13, ["y"] = 16, ["param1"] = 12, ["z"] = 8, ["name"] = "default:pine_needles"}, {["x"] = 13, ["y"] = 16, ["param1"] = 12, ["z"] = 9, ["name"] = "default:pine_needles"}, {["x"] = 13, ["y"] = 17, ["param1"] = 14, ["z"] = 6, ["name"] = "default:pine_needles"}, {["x"] = 13, ["y"] = 17, ["param1"] = 13, ["z"] = 7, ["name"] = "default:pine_needles"}, {["x"] = 13, ["y"] = 17, ["param1"] = 13, ["z"] = 8, ["name"] = "default:pine_needles"}, {["x"] = 13, ["param2"] = 12, ["y"] = 17, ["param1"] = 54, ["z"] = 9, ["name"] = "default:pine_tree"}, {["x"] = 13, ["y"] = 17, ["param1"] = 13, ["z"] = 10, ["name"] = "default:pine_needles"}, {["x"] = 13, ["y"] = 17, ["param1"] = 14, ["z"] = 11, ["name"] = "default:pine_needles"}, {["x"] = 13, ["y"] = 18, ["param1"] = 14, ["z"] = 7, ["name"] = "default:pine_needles"}, {["x"] = 13, ["y"] = 18, ["param1"] = 14, ["z"] = 8, ["name"] = "default:pine_needles"}, {["x"] = 13, ["y"] = 18, ["param1"] = 13, ["z"] = 9, ["name"] = "default:pine_needles"}, {["x"] = 13, ["y"] = 18, ["param1"] = 14, ["z"] = 10, ["name"] = "default:pine_needles"}, {["x"] = 13, ["y"] = 20, ["param1"] = 14, ["z"] = 9, ["name"] = "default:pine_needles"}, {["x"] = 13, ["y"] = 20, ["param1"] = 14, ["z"] = 10, ["name"] = "default:pine_needles"}, {["x"] = 13, ["y"] = 21, ["param1"] = 14, ["z"] = 10, ["name"] = "default:pine_needles"}, {["x"] = 14, ["y"] = 6, ["param1"] = 13, ["z"] = 7, ["name"] = "default:pine_needles"}, {["x"] = 14, ["y"] = 6, ["param1"] = 12, ["z"] = 8, ["name"] = "default:pine_needles"}, {["x"] = 14, ["y"] = 6, ["param1"] = 11, ["z"] = 9, ["name"] = "default:pine_needles"}, {["x"] = 14, ["y"] = 6, ["param1"] = 11, ["z"] = 10, ["name"] = "default:pine_needles"}, {["x"] = 14, ["y"] = 6, ["param1"] = 12, ["z"] = 11, ["name"] = "default:pine_needles"}, {["x"] = 14, ["y"] = 7, ["param1"] = 14, ["z"] = 6, ["name"] = "default:pine_needles"}, {["x"] = 14, ["y"] = 7, ["param1"] = 13, ["z"] = 7, ["name"] = "default:pine_needles"}, {["x"] = 14, ["param2"] = 9, ["y"] = 7, ["param1"] = 54, ["z"] = 8, ["name"] = "default:pine_tree"}, {["x"] = 14, ["param2"] = 12, ["y"] = 7, ["param1"] = 54, ["z"] = 9, ["name"] = "default:pine_tree"}, {["x"] = 14, ["param2"] = 7, ["y"] = 7, ["param1"] = 54, ["z"] = 10, ["name"] = "default:pine_tree"}, {["x"] = 14, ["y"] = 7, ["param1"] = 12, ["z"] = 11, ["name"] = "default:pine_needles"}, {["x"] = 14, ["y"] = 7, ["param1"] = 13, ["z"] = 12, ["name"] = "default:pine_needles"}, {["x"] = 14, ["y"] = 8, ["param1"] = 13, ["z"] = 7, ["name"] = "default:pine_needles"}, {["x"] = 14, ["y"] = 8, ["param1"] = 12, ["z"] = 8, ["name"] = "default:pine_needles"}, {["x"] = 14, ["y"] = 8, ["param1"] = 11, ["z"] = 9, ["name"] = "default:pine_needles"}, {["x"] = 14, ["y"] = 8, ["param1"] = 11, ["z"] = 10, ["name"] = "default:pine_needles"}, {["x"] = 14, ["y"] = 8, ["param1"] = 12, ["z"] = 11, ["name"] = "default:pine_needles"}, {["x"] = 14, ["y"] = 11, ["param1"] = 12, ["z"] = 9, ["name"] = "default:pine_needles"}, {["x"] = 14, ["y"] = 11, ["param1"] = 11, ["z"] = 10, ["name"] = "default:pine_needles"}, {["x"] = 14, ["y"] = 11, ["param1"] = 12, ["z"] = 11, ["name"] = "default:pine_needles"}, {["x"] = 14, ["y"] = 12, ["param1"] = 12, ["z"] = 8, ["name"] = "default:pine_needles"}, {["x"] = 14, ["y"] = 12, ["param1"] = 12, ["z"] = 9, ["name"] = "default:pine_needles"}, {["x"] = 14, ["param2"] = 12, ["y"] = 12, ["param1"] = 54, ["z"] = 10, ["name"] = "default:pine_tree"}, {["x"] = 14, ["y"] = 12, ["param1"] = 12, ["z"] = 11, ["name"] = "default:pine_needles"}, {["x"] = 14, ["y"] = 12, ["param1"] = 13, ["z"] = 12, ["name"] = "default:pine_needles"}, {["x"] = 14, ["y"] = 12, ["param1"] = 14, ["z"] = 13, ["name"] = "default:pine_needles"}, {["x"] = 14, ["y"] = 13, ["param1"] = 12, ["z"] = 9, ["name"] = "default:pine_needles"}, {["x"] = 14, ["y"] = 13, ["param1"] = 12, ["z"] = 10, ["name"] = "default:pine_needles"}, {["x"] = 14, ["y"] = 13, ["param1"] = 13, ["z"] = 11, ["name"] = "default:pine_needles"}, {["x"] = 14, ["y"] = 13, ["param1"] = 14, ["z"] = 12, ["name"] = "default:pine_needles"}, {["x"] = 14, ["y"] = 14, ["param1"] = 13, ["z"] = 10, ["name"] = "default:pine_needles"}, {["x"] = 14, ["y"] = 14, ["param1"] = 14, ["z"] = 11, ["name"] = "default:pine_needles"}, {["x"] = 14, ["y"] = 16, ["param1"] = 13, ["z"] = 7, ["name"] = "default:pine_needles"}, {["x"] = 14, ["y"] = 16, ["param1"] = 12, ["z"] = 8, ["name"] = "default:pine_needles"}, {["x"] = 14, ["y"] = 16, ["param1"] = 12, ["z"] = 9, ["name"] = "default:pine_needles"}, {["x"] = 14, ["y"] = 16, ["param1"] = 13, ["z"] = 10, ["name"] = "default:pine_needles"}, {["x"] = 14, ["y"] = 17, ["param1"] = 14, ["z"] = 6, ["name"] = "default:pine_needles"}, {["x"] = 14, ["y"] = 17, ["param1"] = 13, ["z"] = 7, ["name"] = "default:pine_needles"}, {["x"] = 14, ["y"] = 17, ["param1"] = 12, ["z"] = 8, ["name"] = "default:pine_needles"}, {["x"] = 14, ["y"] = 17, ["param1"] = 12, ["z"] = 9, ["name"] = "default:pine_needles"}, {["x"] = 14, ["y"] = 17, ["param1"] = 13, ["z"] = 10, ["name"] = "default:pine_needles"}, {["x"] = 14, ["y"] = 17, ["param1"] = 14, ["z"] = 11, ["name"] = "default:pine_needles"}, {["x"] = 14, ["y"] = 18, ["param1"] = 14, ["z"] = 6, ["name"] = "default:pine_needles"}, {["x"] = 14, ["y"] = 18, ["param1"] = 13, ["z"] = 7, ["name"] = "default:pine_needles"}, {["x"] = 14, ["y"] = 18, ["param1"] = 13, ["z"] = 8, ["name"] = "default:pine_needles"}, {["x"] = 14, ["y"] = 18, ["param1"] = 13, ["z"] = 9, ["name"] = "default:pine_needles"}, {["x"] = 14, ["y"] = 18, ["param1"] = 14, ["z"] = 10, ["name"] = "default:pine_needles"}, {["x"] = 14, ["y"] = 19, ["param1"] = 14, ["z"] = 7, ["name"] = "default:pine_needles"}, {["x"] = 14, ["y"] = 19, ["param1"] = 14, ["z"] = 8, ["name"] = "default:pine_needles"}, {["x"] = 14, ["y"] = 19, ["param1"] = 14, ["z"] = 9, ["name"] = "default:pine_needles"}, {["x"] = 15, ["y"] = 6, ["param1"] = 13, ["z"] = 7, ["name"] = "default:pine_needles"}, {["x"] = 15, ["y"] = 6, ["param1"] = 11, ["z"] = 9, ["name"] = "default:pine_needles"}, {["x"] = 15, ["y"] = 6, ["param1"] = 11, ["z"] = 10, ["name"] = "default:pine_needles"}, {["x"] = 15, ["y"] = 6, ["param1"] = 12, ["z"] = 11, ["name"] = "default:pine_needles"}, {["x"] = 15, ["y"] = 7, ["param1"] = 14, ["z"] = 6, ["name"] = "default:pine_needles"}, {["x"] = 15, ["y"] = 7, ["param1"] = 13, ["z"] = 7, ["name"] = "default:pine_needles"}, {["x"] = 15, ["y"] = 7, ["param1"] = 12, ["z"] = 8, ["name"] = "default:pine_needles"}, {["x"] = 15, ["param2"] = 12, ["y"] = 7, ["param1"] = 54, ["z"] = 9, ["name"] = "default:pine_tree"}, {["x"] = 15, ["y"] = 7, ["param1"] = 11, ["z"] = 10, ["name"] = "default:pine_needles"}, {["x"] = 15, ["y"] = 7, ["param1"] = 12, ["z"] = 11, ["name"] = "default:pine_needles"}, {["x"] = 15, ["y"] = 7, ["param1"] = 13, ["z"] = 12, ["name"] = "default:pine_needles"}, {["x"] = 15, ["y"] = 8, ["param1"] = 13, ["z"] = 7, ["name"] = "default:pine_needles"}, {["x"] = 15, ["y"] = 8, ["param1"] = 12, ["z"] = 8, ["name"] = "default:pine_needles"}, {["x"] = 15, ["y"] = 8, ["param1"] = 11, ["z"] = 9, ["name"] = "default:pine_needles"}, {["x"] = 15, ["y"] = 8, ["param1"] = 11, ["z"] = 10, ["name"] = "default:pine_needles"}, {["x"] = 15, ["y"] = 8, ["param1"] = 12, ["z"] = 11, ["name"] = "default:pine_needles"}, {["x"] = 15, ["y"] = 9, ["param1"] = 12, ["z"] = 8, ["name"] = "default:pine_needles"}, {["x"] = 15, ["y"] = 9, ["param1"] = 12, ["z"] = 9, ["name"] = "default:pine_needles"}, {["x"] = 15, ["y"] = 11, ["param1"] = 13, ["z"] = 9, ["name"] = "default:pine_needles"}, {["x"] = 15, ["y"] = 11, ["param1"] = 12, ["z"] = 10, ["name"] = "default:pine_needles"}, {["x"] = 15, ["y"] = 11, ["param1"] = 12, ["z"] = 11, ["name"] = "default:pine_needles"}, {["x"] = 15, ["y"] = 12, ["param1"] = 12, ["z"] = 8, ["name"] = "default:pine_needles"}, {["x"] = 15, ["y"] = 12, ["param1"] = 13, ["z"] = 9, ["name"] = "default:pine_needles"}, {["x"] = 15, ["y"] = 12, ["param1"] = 12, ["z"] = 10, ["name"] = "default:pine_needles"}, {["x"] = 15, ["y"] = 12, ["param1"] = 12, ["z"] = 11, ["name"] = "default:pine_needles"}, {["x"] = 15, ["y"] = 12, ["param1"] = 13, ["z"] = 12, ["name"] = "default:pine_needles"}, {["x"] = 15, ["y"] = 12, ["param1"] = 14, ["z"] = 13, ["name"] = "default:pine_needles"}, {["x"] = 15, ["y"] = 13, ["param1"] = 13, ["z"] = 9, ["name"] = "default:pine_needles"}, {["x"] = 15, ["y"] = 13, ["param1"] = 12, ["z"] = 10, ["name"] = "default:pine_needles"}, {["x"] = 15, ["y"] = 13, ["param1"] = 13, ["z"] = 11, ["name"] = "default:pine_needles"}, {["x"] = 15, ["y"] = 13, ["param1"] = 14, ["z"] = 12, ["name"] = "default:pine_needles"}, {["x"] = 15, ["y"] = 14, ["param1"] = 13, ["z"] = 10, ["name"] = "default:pine_needles"}, {["x"] = 15, ["y"] = 14, ["param1"] = 14, ["z"] = 11, ["name"] = "default:pine_needles"}, {["x"] = 15, ["y"] = 16, ["param1"] = 12, ["z"] = 8, ["name"] = "default:pine_needles"}, {["x"] = 15, ["y"] = 16, ["param1"] = 13, ["z"] = 9, ["name"] = "default:pine_needles"}, {["x"] = 15, ["y"] = 17, ["param1"] = 13, ["z"] = 7, ["name"] = "default:pine_needles"}, {["x"] = 15, ["y"] = 17, ["param1"] = 12, ["z"] = 8, ["name"] = "default:pine_needles"}, {["x"] = 15, ["y"] = 17, ["param1"] = 13, ["z"] = 9, ["name"] = "default:pine_needles"}, {["x"] = 15, ["y"] = 17, ["param1"] = 14, ["z"] = 10, ["name"] = "default:pine_needles"}, {["x"] = 15, ["y"] = 18, ["param1"] = 14, ["z"] = 6, ["name"] = "default:pine_needles"}, {["x"] = 15, ["y"] = 18, ["param1"] = 13, ["z"] = 7, ["name"] = "default:pine_needles"}, {["x"] = 15, ["y"] = 18, ["param1"] = 13, ["z"] = 8, ["name"] = "default:pine_needles"}, {["x"] = 15, ["y"] = 18, ["param1"] = 13, ["z"] = 9, ["name"] = "default:pine_needles"}, {["x"] = 15, ["y"] = 18, ["param1"] = 14, ["z"] = 10, ["name"] = "default:pine_needles"}, {["x"] = 15, ["y"] = 19, ["param1"] = 14, ["z"] = 7, ["name"] = "default:pine_needles"}, {["x"] = 15, ["y"] = 19, ["param1"] = 14, ["z"] = 8, ["name"] = "default:pine_needles"}, {["x"] = 15, ["y"] = 19, ["param1"] = 14, ["z"] = 9, ["name"] = "default:pine_needles"}, {["x"] = 16, ["y"] = 6, ["param1"] = 13, ["z"] = 7, ["name"] = "default:pine_needles"}, {["x"] = 16, ["y"] = 6, ["param1"] = 12, ["z"] = 8, ["name"] = "default:pine_needles"}, {["x"] = 16, ["y"] = 6, ["param1"] = 12, ["z"] = 9, ["name"] = "default:pine_needles"}, {["x"] = 16, ["y"] = 6, ["param1"] = 12, ["z"] = 10, ["name"] = "default:pine_needles"}, {["x"] = 16, ["y"] = 7, ["param1"] = 14, ["z"] = 6, ["name"] = "default:pine_needles"}, {["x"] = 16, ["y"] = 7, ["param1"] = 13, ["z"] = 7, ["name"] = "default:pine_needles"}, {["x"] = 16, ["y"] = 7, ["param1"] = 12, ["z"] = 8, ["name"] = "default:pine_needles"}, {["x"] = 16, ["param2"] = 12, ["y"] = 7, ["param1"] = 54, ["z"] = 9, ["name"] = "default:pine_tree"}, {["x"] = 16, ["y"] = 7, ["param1"] = 12, ["z"] = 10, ["name"] = "default:pine_needles"}, {["x"] = 16, ["y"] = 7, ["param1"] = 13, ["z"] = 11, ["name"] = "default:pine_needles"}, {["x"] = 16, ["y"] = 8, ["param1"] = 14, ["z"] = 6, ["name"] = "default:pine_needles"}, {["x"] = 16, ["y"] = 8, ["param1"] = 13, ["z"] = 7, ["name"] = "default:pine_needles"}, {["x"] = 16, ["y"] = 8, ["param1"] = 12, ["z"] = 8, ["name"] = "default:pine_needles"}, {["x"] = 16, ["y"] = 8, ["param1"] = 12, ["z"] = 9, ["name"] = "default:pine_needles"}, {["x"] = 16, ["y"] = 8, ["param1"] = 12, ["z"] = 10, ["name"] = "default:pine_needles"}, {["x"] = 16, ["y"] = 9, ["param1"] = 14, ["z"] = 7, ["name"] = "default:pine_needles"}, {["x"] = 16, ["y"] = 9, ["param1"] = 13, ["z"] = 8, ["name"] = "default:pine_needles"}, {["x"] = 16, ["y"] = 9, ["param1"] = 13, ["z"] = 9, ["name"] = "default:pine_needles"}, {["x"] = 16, ["y"] = 9, ["param1"] = 13, ["z"] = 10, ["name"] = "default:pine_needles"}, {["x"] = 16, ["y"] = 11, ["param1"] = 13, ["z"] = 10, ["name"] = "default:pine_needles"}, {["x"] = 16, ["y"] = 12, ["param1"] = 14, ["z"] = 9, ["name"] = "default:pine_needles"}, {["x"] = 16, ["y"] = 12, ["param1"] = 13, ["z"] = 10, ["name"] = "default:pine_needles"}, {["x"] = 16, ["y"] = 12, ["param1"] = 13, ["z"] = 11, ["name"] = "default:pine_needles"}, {["x"] = 16, ["y"] = 12, ["param1"] = 14, ["z"] = 12, ["name"] = "default:pine_needles"}, {["x"] = 16, ["y"] = 13, ["param1"] = 14, ["z"] = 9, ["name"] = "default:pine_needles"}, {["x"] = 16, ["y"] = 13, ["param1"] = 13, ["z"] = 10, ["name"] = "default:pine_needles"}, {["x"] = 16, ["y"] = 13, ["param1"] = 13, ["z"] = 11, ["name"] = "default:pine_needles"}, {["x"] = 16, ["y"] = 13, ["param1"] = 14, ["z"] = 12, ["name"] = "default:pine_needles"}, {["x"] = 16, ["y"] = 14, ["param1"] = 14, ["z"] = 10, ["name"] = "default:pine_needles"}, {["x"] = 16, ["y"] = 14, ["param1"] = 14, ["z"] = 11, ["name"] = "default:pine_needles"}, {["x"] = 16, ["y"] = 17, ["param1"] = 13, ["z"] = 8, ["name"] = "default:pine_needles"}, {["x"] = 16, ["y"] = 18, ["param1"] = 14, ["z"] = 7, ["name"] = "default:pine_needles"}, {["x"] = 16, ["y"] = 18, ["param1"] = 13, ["z"] = 8, ["name"] = "default:pine_needles"}, {["x"] = 16, ["y"] = 18, ["param1"] = 14, ["z"] = 9, ["name"] = "default:pine_needles"}, {["x"] = 16, ["y"] = 19, ["param1"] = 14, ["z"] = 8, ["name"] = "default:pine_needles"}, {["x"] = 17, ["y"] = 6, ["param1"] = 13, ["z"] = 8, ["name"] = "default:pine_needles"}, {["x"] = 17, ["y"] = 6, ["param1"] = 13, ["z"] = 9, ["name"] = "default:pine_needles"}, {["x"] = 17, ["y"] = 7, ["param1"] = 13, ["z"] = 7, ["name"] = "default:pine_needles"}, {["x"] = 17, ["y"] = 7, ["param1"] = 13, ["z"] = 8, ["name"] = "default:pine_needles"}, {["x"] = 17, ["y"] = 7, ["param1"] = 13, ["z"] = 9, ["name"] = "default:pine_needles"}, {["x"] = 17, ["y"] = 7, ["param1"] = 13, ["z"] = 10, ["name"] = "default:pine_needles"}, {["x"] = 17, ["y"] = 8, ["param1"] = 14, ["z"] = 6, ["name"] = "default:pine_needles"}, {["x"] = 17, ["y"] = 8, ["param1"] = 13, ["z"] = 7, ["name"] = "default:pine_needles"}, {["x"] = 17, ["y"] = 8, ["param1"] = 13, ["z"] = 8, ["name"] = "default:pine_needles"}, {["x"] = 17, ["y"] = 8, ["param1"] = 13, ["z"] = 9, ["name"] = "default:pine_needles"}, {["x"] = 17, ["y"] = 8, ["param1"] = 13, ["z"] = 10, ["name"] = "default:pine_needles"}, {["x"] = 17, ["y"] = 8, ["param1"] = 13, ["z"] = 11, ["name"] = "default:pine_needles"}, {["x"] = 17, ["y"] = 9, ["param1"] = 14, ["z"] = 7, ["name"] = "default:pine_needles"}, {["x"] = 17, ["y"] = 9, ["param1"] = 13, ["z"] = 8, ["name"] = "default:pine_needles"}, {["x"] = 17, ["y"] = 9, ["param1"] = 14, ["z"] = 9, ["name"] = "default:pine_needles"}, {["x"] = 17, ["y"] = 12, ["param1"] = 13, ["z"] = 11, ["name"] = "default:pine_needles"}, {["x"] = 17, ["y"] = 13, ["param1"] = 14, ["z"] = 10, ["name"] = "default:pine_needles"}, {["x"] = 17, ["y"] = 13, ["param1"] = 14, ["z"] = 11, ["name"] = "default:pine_needles"}, {["x"] = 17, ["y"] = 13, ["param1"] = 14, ["z"] = 12, ["name"] = "default:pine_needles"}, {["x"] = 17, ["y"] = 18, ["param1"] = 14, ["z"] = 8, ["name"] = "default:pine_needles"}, {["x"] = 18, ["y"] = 7, ["param1"] = 14, ["z"] = 8, ["name"] = "default:pine_needles"}, {["x"] = 18, ["y"] = 7, ["param1"] = 14, ["z"] = 9, ["name"] = "default:pine_needles"}, {["x"] = 18, ["y"] = 8, ["param1"] = 14, ["z"] = 7, ["name"] = "default:pine_needles"}, {["x"] = 18, ["y"] = 8, ["param1"] = 14, ["z"] = 8, ["name"] = "default:pine_needles"}, {["x"] = 18, ["y"] = 8, ["param1"] = 14, ["z"] = 9, ["name"] = "default:pine_needles"}, {["x"] = 18, ["y"] = 8, ["param1"] = 14, ["z"] = 10, ["name"] = "default:pine_needles"}, {["x"] = 18, ["y"] = 9, ["param1"] = 14, ["z"] = 8, ["name"] = "default:pine_needles"}, {["x"] = 18, ["y"] = 13, ["param1"] = 14, ["z"] = 11, ["name"] = "default:pine_needles"}}