5:return {{["x"] = 1, ["y"] = 8, ["param1"] = 14, ["z"] = 10, ["name"] = "default:aspen_leaves"}, {["x"] = 1, ["y"] = 8, ["param1"] = 14, ["z"] = 11, ["name"] = "default:aspen_leaves"}, {["x"] = 1, ["y"] = 8, ["param1"] = 14, ["z"] = 12, ["name"] = "default:aspen_leaves"}, {["x"] = 1, ["y"] = 8, ["param1"] = 14, ["z"] = 13, ["name"] = "default:aspen_leaves"}, {["x"] = 1, ["y"] = 9, ["param1"] = 14, ["z"] = 5, ["name"] = "default:aspen_leaves"}, {["x"] = 1, ["y"] = 9, ["param1"] = 14, ["z"] = 6, ["name"] = "default:aspen_leaves"}, {["x"] = 1, ["y"] = 9, ["param1"] = 14, ["z"] = 9, ["name"] = "default:aspen_leaves"}, {["x"] = 1, ["y"] = 9, ["param1"] = 14, ["z"] = 10, ["name"] = "default:aspen_leaves"}, {["x"] = 1, ["y"] = 9, ["param1"] = 14, ["z"] = 11, ["name"] = "default:aspen_leaves"}, {["x"] = 1, ["y"] = 9, ["param1"] = 14, ["z"] = 12, ["name"] = "default:aspen_leaves"}, {["x"] = 1, ["y"] = 9, ["param1"] = 14, ["z"] = 13, ["name"] = "default:aspen_leaves"}, {["x"] = 1, ["y"] = 9, ["param1"] = 14, ["z"] = 14, ["name"] = "default:aspen_leaves"}, {["x"] = 1, ["y"] = 10, ["param1"] = 14, ["z"] = 11, ["name"] = "default:aspen_leaves"}, {["x"] = 1, ["y"] = 10, ["param1"] = 14, ["z"] = 12, ["name"] = "default:aspen_leaves"}, {["x"] = 1, ["y"] = 10, ["param1"] = 14, ["z"] = 13, ["name"] = "default:aspen_leaves"}, {["x"] = 2, ["y"] = 7, ["param1"] = 13, ["z"] = 12, ["name"] = "default:aspen_leaves"}, {["x"] = 2, ["y"] = 7, ["param1"] = 13, ["z"] = 13, ["name"] = "default:aspen_leaves"}, {["x"] = 2, ["y"] = 8, ["param1"] = 13, ["z"] = 6, ["name"] = "default:aspen_leaves"}, {["x"] = 2, ["y"] = 8, ["param1"] = 14, ["z"] = 9, ["name"] = "default:aspen_leaves"}, {["x"] = 2, ["y"] = 8, ["param1"] = 13, ["z"] = 11, ["name"] = "default:aspen_leaves"}, {["x"] = 2, ["y"] = 8, ["param1"] = 13, ["z"] = 12, ["name"] = "default:aspen_leaves"}, {["x"] = 2, ["y"] = 8, ["param1"] = 13, ["z"] = 13, ["name"] = "default:aspen_leaves"}, {["x"] = 2, ["y"] = 8, ["param1"] = 13, ["z"] = 14, ["name"] = "default:aspen_leaves"}, {["x"] = 2, ["y"] = 9, ["param1"] = 14, ["z"] = 3, ["name"] = "default:aspen_leaves"}, {["x"] = 2, ["y"] = 9, ["param1"] = 13, ["z"] = 5, ["name"] = "default:aspen_leaves"}, {["x"] = 2, ["y"] = 9, ["param1"] = 13, ["z"] = 6, ["name"] = "default:aspen_leaves"}, {["x"] = 2, ["y"] = 9, ["param1"] = 14, ["z"] = 7, ["name"] = "default:aspen_leaves"}, {["x"] = 2, ["y"] = 9, ["param1"] = 14, ["z"] = 9, ["name"] = "default:aspen_leaves"}, {["x"] = 2, ["y"] = 9, ["param1"] = 13, ["z"] = 10, ["name"] = "default:aspen_leaves"}, {["x"] = 2, ["y"] = 9, ["param1"] = 13, ["z"] = 11, ["name"] = "default:aspen_leaves"}, {["x"] = 2, ["param2"] = 18, ["y"] = 9, ["z"] = 12, ["name"] = "default:tree"}, {["x"] = 2, ["y"] = 9, ["param1"] = 13, ["z"] = 13, ["name"] = "default:aspen_leaves"}, {["x"] = 2, ["y"] = 9, ["param1"] = 13, ["z"] = 14, ["name"] = "default:aspen_leaves"}, {["x"] = 2, ["y"] = 9, ["param1"] = 14, ["z"] = 15, ["name"] = "default:aspen_leaves"}, {["x"] = 2, ["y"] = 10, ["param1"] = 14, ["z"] = 2, ["name"] = "default:aspen_leaves"}, {["x"] = 2, ["y"] = 10, ["param1"] = 14, ["z"] = 4, ["name"] = "default:aspen_leaves"}, {["x"] = 2, ["y"] = 10, ["param1"] = 14, ["z"] = 5, ["name"] = "default:aspen_leaves"}, {["x"] = 2, ["y"] = 10, ["param1"] = 14, ["z"] = 6, ["name"] = "default:aspen_leaves"}, {["x"] = 2, ["y"] = 10, ["param1"] = 14, ["z"] = 7, ["name"] = "default:aspen_leaves"}, {["x"] = 2, ["y"] = 10, ["param1"] = 14, ["z"] = 9, ["name"] = "default:aspen_leaves"}, {["x"] = 2, ["y"] = 10, ["param1"] = 14, ["z"] = 10, ["name"] = "default:aspen_leaves"}, {["x"] = 2, ["y"] = 10, ["param1"] = 14, ["z"] = 11, ["name"] = "default:aspen_leaves"}, {["x"] = 2, ["y"] = 10, ["param1"] = 14, ["z"] = 12, ["name"] = "default:aspen_leaves"}, {["x"] = 2, ["y"] = 10, ["param1"] = 14, ["z"] = 13, ["name"] = "default:aspen_leaves"}, {["x"] = 2, ["y"] = 10, ["param1"] = 14, ["z"] = 14, ["name"] = "default:aspen_leaves"}, {["x"] = 2, ["y"] = 11, ["param1"] = 14, ["z"] = 3, ["name"] = "default:aspen_leaves"}, {["x"] = 2, ["y"] = 11, ["param1"] = 14, ["z"] = 5, ["name"] = "default:aspen_leaves"}, {["x"] = 2, ["y"] = 11, ["param1"] = 14, ["z"] = 6, ["name"] = "default:aspen_leaves"}, {["x"] = 3, ["y"] = 7, ["param1"] = 12, ["z"] = 11, ["name"] = "default:aspen_leaves"}, {["x"] = 3, ["y"] = 7, ["param1"] = 12, ["z"] = 12, ["name"] = "default:aspen_leaves"}, {["x"] = 3, ["y"] = 7, ["param1"] = 12, ["z"] = 13, ["name"] = "default:aspen_leaves"}, {["x"] = 3, ["y"] = 8, ["param1"] = 12, ["z"] = 5, ["name"] = "default:aspen_leaves"}, {["x"] = 3, ["y"] = 8, ["param1"] = 12, ["z"] = 6, ["name"] = "default:aspen_leaves"}, {["x"] = 3, ["y"] = 8, ["param1"] = 13, ["z"] = 7, ["name"] = "default:aspen_leaves"}, {["x"] = 3, ["y"] = 8, ["param1"] = 13, ["z"] = 9, ["name"] = "default:aspen_leaves"}, {["x"] = 3, ["y"] = 8, ["param1"] = 12, ["z"] = 10, ["name"] = "default:aspen_leaves"}, {["x"] = 3, ["y"] = 8, ["param1"] = 12, ["z"] = 11, ["name"] = "default:aspen_leaves"}, {["x"] = 3, ["param2"] = 18, ["y"] = 8, ["z"] = 12, ["name"] = "default:tree"}, {["x"] = 3, ["y"] = 8, ["param1"] = 12, ["z"] = 13, ["name"] = "default:aspen_leaves"}, {["x"] = 3, ["y"] = 8, ["param1"] = 13, ["z"] = 15, ["name"] = "default:aspen_leaves"}, {["x"] = 3, ["y"] = 9, ["param1"] = 14, ["z"] = 1, ["name"] = "default:aspen_leaves"}, {["x"] = 3, ["y"] = 9, ["param1"] = 13, ["z"] = 2, ["name"] = "default:aspen_leaves"}, {["x"] = 3, ["y"] = 9, ["param1"] = 13, ["z"] = 4, ["name"] = "default:aspen_leaves"}, {["x"] = 3, ["y"] = 9, ["param1"] = 12, ["z"] = 5, ["name"] = "default:aspen_leaves"}, {["x"] = 3, ["param2"] = 18, ["y"] = 9, ["z"] = 6, ["name"] = "default:tree"}, {["x"] = 3, ["y"] = 9, ["param1"] = 13, ["z"] = 7, ["name"] = "default:aspen_leaves"}, {["x"] = 3, ["y"] = 9, ["param1"] = 14, ["z"] = 8, ["name"] = "default:aspen_leaves"}, {["x"] = 3, ["y"] = 9, ["param1"] = 13, ["z"] = 9, ["name"] = "default:aspen_leaves"}, {["x"] = 3, ["param2"] = 9, ["y"] = 9, ["z"] = 10, ["name"] = "default:tree"}, {["x"] = 3, ["param2"] = 9, ["y"] = 9, ["z"] = 11, ["name"] = "default:tree"}, {["x"] = 3, ["y"] = 9, ["z"] = 12, ["name"] = "default:tree"}, {["x"] = 3, ["y"] = 9, ["param1"] = 12, ["z"] = 13, ["name"] = "default:aspen_leaves"}, {["x"] = 3, ["y"] = 9, ["param1"] = 14, ["z"] = 15, ["name"] = "default:aspen_leaves"}, {["x"] = 3, ["y"] = 9, ["param1"] = 14, ["z"] = 16, ["name"] = "default:aspen_leaves"}, {["x"] = 3, ["y"] = 10, ["param1"] = 14, ["z"] = 1, ["name"] = "default:aspen_leaves"}, {["x"] = 3, ["y"] = 10, ["param1"] = 13, ["z"] = 2, ["name"] = "default:aspen_leaves"}, {["x"] = 3, ["y"] = 10, ["param1"] = 13, ["z"] = 3, ["name"] = "default:aspen_leaves"}, {["x"] = 3, ["y"] = 10, ["param1"] = 13, ["z"] = 4, ["name"] = "default:aspen_leaves"}, {["x"] = 3, ["y"] = 10, ["param1"] = 13, ["z"] = 5, ["name"] = "default:aspen_leaves"}, {["x"] = 3, ["y"] = 10, ["param1"] = 13, ["z"] = 6, ["name"] = "default:aspen_leaves"}, {["x"] = 3, ["y"] = 10, ["param1"] = 14, ["z"] = 7, ["name"] = "default:aspen_leaves"}, {["x"] = 3, ["y"] = 10, ["param1"] = 14, ["z"] = 9, ["name"] = "default:aspen_leaves"}, {["x"] = 3, ["y"] = 10, ["param1"] = 14, ["z"] = 10, ["name"] = "default:aspen_leaves"}, {["x"] = 3, ["y"] = 10, ["param1"] = 13, ["z"] = 11, ["name"] = "default:aspen_leaves"}, {["x"] = 3, ["y"] = 10, ["param1"] = 13, ["z"] = 12, ["name"] = "default:aspen_leaves"}, {["x"] = 3, ["y"] = 10, ["param1"] = 13, ["z"] = 13, ["name"] = "default:aspen_leaves"}, {["x"] = 3, ["y"] = 11, ["param1"] = 14, ["z"] = 2, ["name"] = "default:aspen_leaves"}, {["x"] = 3, ["y"] = 11, ["param1"] = 14, ["z"] = 3, ["name"] = "default:aspen_leaves"}, {["x"] = 3, ["y"] = 11, ["param1"] = 14, ["z"] = 4, ["name"] = "default:aspen_leaves"}, {["x"] = 3, ["y"] = 11, ["param1"] = 14, ["z"] = 5, ["name"] = "default:aspen_leaves"}, {["x"] = 3, ["y"] = 11, ["param1"] = 14, ["z"] = 6, ["name"] = "default:aspen_leaves"}, {["x"] = 3, ["y"] = 11, ["param1"] = 14, ["z"] = 7, ["name"] = "default:aspen_leaves"}, {["x"] = 3, ["y"] = 12, ["param1"] = 14, ["z"] = 12, ["name"] = "default:aspen_leaves"}, {["x"] = 3, ["y"] = 13, ["param1"] = 14, ["z"] = 11, ["name"] = "default:aspen_leaves"}, {["x"] = 3, ["y"] = 13, ["param1"] = 14, ["z"] = 12, ["name"] = "default:aspen_leaves"}, {["x"] = 3, ["y"] = 13, ["param1"] = 14, ["z"] = 13, ["name"] = "default:aspen_leaves"}, {["x"] = 3, ["y"] = 13, ["param1"] = 14, ["z"] = 14, ["name"] = "default:aspen_leaves"}, {["x"] = 3, ["y"] = 14, ["param1"] = 14, ["z"] = 12, ["name"] = "default:aspen_leaves"}, {["x"] = 3, ["y"] = 16, ["param1"] = 14, ["z"] = 11, ["name"] = "default:aspen_leaves"}, {["x"] = 3, ["y"] = 16, ["param1"] = 14, ["z"] = 12, ["name"] = "default:aspen_leaves"}, {["x"] = 4, ["y"] = 7, ["param1"] = 13, ["z"] = 8, ["name"] = "default:aspen_leaves"}, {["x"] = 4, ["y"] = 7, ["param1"] = 12, ["z"] = 9, ["name"] = "default:aspen_leaves"}, {["x"] = 4, ["y"] = 7, ["param1"] = 12, ["z"] = 14, ["name"] = "default:aspen_leaves"}, {["x"] = 4, ["y"] = 7, ["param1"] = 13, ["z"] = 15, ["name"] = "default:aspen_leaves"}, {["x"] = 4, ["y"] = 7, ["param1"] = 14, ["z"] = 16, ["name"] = "default:aspen_leaves"}, {["x"] = 4, ["y"] = 8, ["param1"] = 11, ["z"] = 5, ["name"] = "default:aspen_leaves"}, {["x"] = 4, ["y"] = 8, ["param1"] = 11, ["z"] = 6, ["name"] = "default:aspen_leaves"}, {["x"] = 4, ["y"] = 8, ["param1"] = 12, ["z"] = 9, ["name"] = "default:aspen_leaves"}, {["x"] = 4, ["y"] = 8, ["param1"] = 11, ["z"] = 11, ["name"] = "default:aspen_leaves"}, {["x"] = 4, ["param2"] = 18, ["y"] = 8, ["z"] = 12, ["name"] = "default:tree"}, {["x"] = 4, ["y"] = 8, ["param1"] = 11, ["z"] = 13, ["name"] = "default:aspen_leaves"}, {["x"] = 4, ["y"] = 8, ["param1"] = 12, ["z"] = 14, ["name"] = "default:aspen_leaves"}, {["x"] = 4, ["y"] = 8, ["param1"] = 13, ["z"] = 15, ["name"] = "default:aspen_leaves"}, {["x"] = 4, ["y"] = 8, ["param1"] = 14, ["z"] = 16, ["name"] = "default:aspen_leaves"}, {["x"] = 4, ["y"] = 9, ["param1"] = 14, ["z"] = 2, ["name"] = "default:aspen_leaves"}, {["x"] = 4, ["y"] = 9, ["param1"] = 13, ["z"] = 3, ["name"] = "default:aspen_leaves"}, {["x"] = 4, ["y"] = 9, ["param1"] = 12, ["z"] = 4, ["name"] = "default:aspen_leaves"}, {["x"] = 4, ["y"] = 9, ["param1"] = 11, ["z"] = 5, ["name"] = "default:aspen_leaves"}, {["x"] = 4, ["param2"] = 18, ["y"] = 9, ["z"] = 6, ["name"] = "default:tree"}, {["x"] = 4, ["y"] = 9, ["param1"] = 12, ["z"] = 7, ["name"] = "default:aspen_leaves"}, {["x"] = 4, ["y"] = 9, ["param1"] = 13, ["z"] = 8, ["name"] = "default:aspen_leaves"}, {["x"] = 4, ["y"] = 9, ["param1"] = 12, ["z"] = 9, ["name"] = "default:aspen_leaves"}, {["x"] = 4, ["y"] = 9, ["param1"] = 12, ["z"] = 10, ["name"] = "default:aspen_leaves"}, {["x"] = 4, ["y"] = 9, ["param1"] = 11, ["z"] = 11, ["name"] = "default:aspen_leaves"}, {["x"] = 4, ["y"] = 9, ["param1"] = 11, ["z"] = 12, ["name"] = "default:aspen_leaves"}, {["x"] = 4, ["y"] = 9, ["param1"] = 11, ["z"] = 13, ["name"] = "default:aspen_leaves"}, {["x"] = 4, ["y"] = 9, ["param1"] = 12, ["z"] = 14, ["name"] = "default:aspen_leaves"}, {["x"] = 4, ["y"] = 9, ["param1"] = 13, ["z"] = 15, ["name"] = "default:aspen_leaves"}, {["x"] = 4, ["y"] = 9, ["param1"] = 14, ["z"] = 16, ["name"] = "default:aspen_leaves"}, {["x"] = 4, ["y"] = 10, ["param1"] = 14, ["z"] = 1, ["name"] = "default:aspen_leaves"}, {["x"] = 4, ["y"] = 10, ["param1"] = 14, ["z"] = 2, ["name"] = "default:aspen_leaves"}, {["x"] = 4, ["y"] = 10, ["param1"] = 13, ["z"] = 3, ["name"] = "default:aspen_leaves"}, {["x"] = 4, ["param2"] = 9, ["y"] = 10, ["z"] = 4, ["name"] = "default:tree"}, {["x"] = 4, ["param2"] = 9, ["y"] = 10, ["z"] = 5, ["name"] = "default:tree"}, {["x"] = 4, ["y"] = 10, ["z"] = 6, ["name"] = "default:tree"}, {["x"] = 4, ["y"] = 10, ["param1"] = 13, ["z"] = 7, ["name"] = "default:aspen_leaves"}, {["x"] = 4, ["y"] = 10, ["param1"] = 13, ["z"] = 9, ["name"] = "default:aspen_leaves"}, {["x"] = 4, ["y"] = 10, ["param1"] = 12, ["z"] = 11, ["name"] = "default:aspen_leaves"}, {["x"] = 4, ["y"] = 10, ["param1"] = 12, ["z"] = 12, ["name"] = "default:aspen_leaves"}, {["x"] = 4, ["y"] = 10, ["param1"] = 12, ["z"] = 13, ["name"] = "default:aspen_leaves"}, {["x"] = 4, ["y"] = 10, ["param1"] = 13, ["z"] = 14, ["name"] = "default:aspen_leaves"}, {["x"] = 4, ["y"] = 10, ["param1"] = 14, ["z"] = 16, ["name"] = "default:aspen_leaves"}, {["x"] = 4, ["y"] = 11, ["param1"] = 14, ["z"] = 1, ["name"] = "default:aspen_leaves"}, {["x"] = 4, ["y"] = 11, ["param1"] = 14, ["z"] = 3, ["name"] = "default:aspen_leaves"}, {["x"] = 4, ["y"] = 11, ["param1"] = 14, ["z"] = 4, ["name"] = "default:aspen_leaves"}, {["x"] = 4, ["y"] = 11, ["param1"] = 14, ["z"] = 5, ["name"] = "default:aspen_leaves"}, {["x"] = 4, ["y"] = 11, ["param1"] = 13, ["z"] = 6, ["name"] = "default:aspen_leaves"}, {["x"] = 4, ["y"] = 11, ["param1"] = 13, ["z"] = 7, ["name"] = "default:aspen_leaves"}, {["x"] = 4, ["y"] = 11, ["param1"] = 14, ["z"] = 8, ["name"] = "default:aspen_leaves"}, {["x"] = 4, ["y"] = 11, ["param1"] = 14, ["z"] = 9, ["name"] = "default:aspen_leaves"}, {["x"] = 4, ["y"] = 12, ["param1"] = 14, ["z"] = 9, ["name"] = "default:aspen_leaves"}, {["x"] = 4, ["y"] = 12, ["param1"] = 14, ["z"] = 10, ["name"] = "default:aspen_leaves"}, {["x"] = 4, ["y"] = 12, ["param1"] = 13, ["z"] = 11, ["name"] = "default:aspen_leaves"}, {["x"] = 4, ["y"] = 12, ["param1"] = 13, ["z"] = 12, ["name"] = "default:aspen_leaves"}, {["x"] = 4, ["y"] = 12, ["param1"] = 13, ["z"] = 14, ["name"] = "default:aspen_leaves"}, {["x"] = 4, ["y"] = 13, ["param1"] = 14, ["z"] = 9, ["name"] = "default:aspen_leaves"}, {["x"] = 4, ["y"] = 13, ["param1"] = 13, ["z"] = 11, ["name"] = "default:aspen_leaves"}, {["x"] = 4, ["param2"] = 18, ["y"] = 13, ["z"] = 12, ["name"] = "default:tree"}, {["x"] = 4, ["y"] = 13, ["param1"] = 13, ["z"] = 13, ["name"] = "default:aspen_leaves"}, {["x"] = 4, ["y"] = 13, ["param1"] = 13, ["z"] = 14, ["name"] = "default:aspen_leaves"}, {["x"] = 4, ["y"] = 13, ["param1"] = 14, ["z"] = 15, ["name"] = "default:aspen_leaves"}, {["x"] = 4, ["y"] = 14, ["param1"] = 13, ["z"] = 11, ["name"] = "default:aspen_leaves"}, {["x"] = 4, ["y"] = 14, ["param1"] = 13, ["z"] = 12, ["name"] = "default:aspen_leaves"}, {["x"] = 4, ["y"] = 14, ["param1"] = 14, ["z"] = 13, ["name"] = "default:aspen_leaves"}, {["x"] = 4, ["y"] = 14, ["param1"] = 14, ["z"] = 14, ["name"] = "default:aspen_leaves"}, {["x"] = 4, ["y"] = 15, ["param1"] = 14, ["z"] = 6, ["name"] = "default:aspen_leaves"}, {["x"] = 4, ["y"] = 15, ["param1"] = 14, ["z"] = 7, ["name"] = "default:aspen_leaves"}, {["x"] = 4, ["y"] = 15, ["param1"] = 14, ["z"] = 8, ["name"] = "default:aspen_leaves"}, {["x"] = 4, ["y"] = 15, ["param1"] = 13, ["z"] = 11, ["name"] = "default:aspen_leaves"}, {["x"] = 4, ["y"] = 16, ["param1"] = 14, ["z"] = 7, ["name"] = "default:aspen_leaves"}, {["x"] = 4, ["y"] = 16, ["param1"] = 14, ["z"] = 10, ["name"] = "default:aspen_leaves"}, {["x"] = 4, ["y"] = 16, ["param1"] = 13, ["z"] = 11, ["name"] = "default:aspen_leaves"}, {["x"] = 4, ["y"] = 16, ["param1"] = 13, ["z"] = 12, ["name"] = "default:aspen_leaves"}, {["x"] = 4, ["y"] = 16, ["param1"] = 14, ["z"] = 13, ["name"] = "default:aspen_leaves"}, {["x"] = 4, ["y"] = 17, ["param1"] = 14, ["z"] = 11, ["name"] = "default:aspen_leaves"}, {["x"] = 4, ["y"] = 17, ["param1"] = 14, ["z"] = 12, ["name"] = "default:aspen_leaves"}, {["x"] = 4, ["y"] = 17, ["param1"] = 14, ["z"] = 13, ["name"] = "default:aspen_leaves"}, {["x"] = 5, ["y"] = 3, ["param1"] = 12, ["z"] = 5, ["name"] = "default:aspen_leaves"}, {["x"] = 5, ["y"] = 3, ["param1"] = 11, ["z"] = 6, ["name"] = "default:aspen_leaves"}, {["x"] = 5, ["y"] = 4, ["param1"] = 13, ["z"] = 4, ["name"] = "default:aspen_leaves"}, {["x"] = 5, ["y"] = 4, ["param1"] = 12, ["z"] = 5, ["name"] = "default:aspen_leaves"}, {["x"] = 5, ["y"] = 4, ["param1"] = 11, ["z"] = 6, ["name"] = "default:aspen_leaves"}, {["x"] = 5, ["y"] = 4, ["param1"] = 12, ["z"] = 7, ["name"] = "default:aspen_leaves"}, {["x"] = 5, ["y"] = 5, ["param1"] = 12, ["z"] = 5, ["name"] = "default:aspen_leaves"}, {["x"] = 5, ["y"] = 6, ["param1"] = 13, ["z"] = 8, ["name"] = "default:aspen_leaves"}, {["x"] = 5, ["y"] = 6, ["param1"] = 12, ["z"] = 9, ["name"] = "default:aspen_leaves"}, {["x"] = 5, ["y"] = 6, ["param1"] = 11, ["z"] = 10, ["name"] = "default:aspen_leaves"}, {["x"] = 5, ["y"] = 7, ["param1"] = 13, ["z"] = 8, ["name"] = "default:aspen_leaves"}, {["x"] = 5, ["y"] = 7, ["param1"] = 12, ["z"] = 9, ["name"] = "default:aspen_leaves"}, {["x"] = 5, ["y"] = 7, ["param1"] = 11, ["z"] = 10, ["name"] = "default:aspen_leaves"}, {["x"] = 5, ["y"] = 7, ["param1"] = 12, ["z"] = 15, ["name"] = "default:aspen_leaves"}, {["x"] = 5, ["y"] = 7, ["param1"] = 13, ["z"] = 16, ["name"] = "default:aspen_leaves"}, {["x"] = 5, ["y"] = 8, ["param1"] = 12, ["z"] = 9, ["name"] = "default:aspen_leaves"}, {["x"] = 5, ["y"] = 8, ["param1"] = 10, ["z"] = 11, ["name"] = "default:aspen_leaves"}, {["x"] = 5, ["param2"] = 18, ["y"] = 8, ["z"] = 12, ["name"] = "default:tree"}, {["x"] = 5, ["param2"] = 7, ["y"] = 8, ["z"] = 13, ["name"] = "default:tree"}, {["x"] = 5, ["param2"] = 7, ["y"] = 8, ["z"] = 14, ["name"] = "default:tree"}, {["x"] = 5, ["param2"] = 7, ["y"] = 8, ["z"] = 15, ["name"] = "default:tree"}, {["x"] = 5, ["y"] = 8, ["param1"] = 13, ["z"] = 16, ["name"] = "default:aspen_leaves"}, {["x"] = 5, ["y"] = 8, ["param1"] = 14, ["z"] = 17, ["name"] = "default:aspen_leaves"}, {["x"] = 5, ["y"] = 9, ["param1"] = 14, ["z"] = 1, ["name"] = "default:aspen_leaves"}, {["x"] = 5, ["y"] = 9, ["param1"] = 13, ["z"] = 4, ["name"] = "default:aspen_leaves"}, {["x"] = 5, ["param2"] = 18, ["y"] = 9, ["z"] = 6, ["name"] = "default:tree"}, {["x"] = 5, ["y"] = 9, ["param1"] = 12, ["z"] = 7, ["name"] = "default:aspen_leaves"}, {["x"] = 5, ["y"] = 9, ["param1"] = 11, ["z"] = 10, ["name"] = "default:aspen_leaves"}, {["x"] = 5, ["y"] = 9, ["param1"] = 10, ["z"] = 11, ["name"] = "default:aspen_leaves"}, {["x"] = 5, ["y"] = 9, ["param1"] = 10, ["z"] = 12, ["name"] = "default:aspen_leaves"}, {["x"] = 5, ["y"] = 9, ["param1"] = 11, ["z"] = 13, ["name"] = "default:aspen_leaves"}, {["x"] = 5, ["y"] = 9, ["param1"] = 12, ["z"] = 14, ["name"] = "default:aspen_leaves"}, {["x"] = 5, ["y"] = 9, ["param1"] = 13, ["z"] = 15, ["name"] = "default:aspen_leaves"}, {["x"] = 5, ["y"] = 9, ["param1"] = 14, ["z"] = 16, ["name"] = "default:aspen_leaves"}, {["x"] = 5, ["y"] = 10, ["param1"] = 14, ["z"] = 1, ["name"] = "default:aspen_leaves"}, {["x"] = 5, ["y"] = 10, ["param1"] = 14, ["z"] = 3, ["name"] = "default:aspen_leaves"}, {["x"] = 5, ["y"] = 10, ["param1"] = 14, ["z"] = 4, ["name"] = "default:aspen_leaves"}, {["x"] = 5, ["y"] = 10, ["param1"] = 13, ["z"] = 5, ["name"] = "default:aspen_leaves"}, {["x"] = 5, ["y"] = 10, ["param1"] = 12, ["z"] = 6, ["name"] = "default:aspen_leaves"}, {["x"] = 5, ["y"] = 10, ["param1"] = 12, ["z"] = 7, ["name"] = "default:aspen_leaves"}, {["x"] = 5, ["y"] = 10, ["param1"] = 12, ["z"] = 10, ["name"] = "default:aspen_leaves"}, {["x"] = 5, ["y"] = 10, ["param1"] = 11, ["z"] = 12, ["name"] = "default:aspen_leaves"}, {["x"] = 5, ["y"] = 10, ["param1"] = 11, ["z"] = 13, ["name"] = "default:aspen_leaves"}, {["x"] = 5, ["y"] = 10, ["param1"] = 13, ["z"] = 15, ["name"] = "default:aspen_leaves"}, {["x"] = 5, ["y"] = 10, ["param1"] = 14, ["z"] = 16, ["name"] = "default:aspen_leaves"}, {["x"] = 5, ["y"] = 11, ["param1"] = 14, ["z"] = 3, ["name"] = "default:aspen_leaves"}, {["x"] = 5, ["y"] = 11, ["param1"] = 14, ["z"] = 5, ["name"] = "default:aspen_leaves"}, {["x"] = 5, ["y"] = 11, ["param1"] = 13, ["z"] = 6, ["name"] = "default:aspen_leaves"}, {["x"] = 5, ["y"] = 11, ["param1"] = 13, ["z"] = 8, ["name"] = "default:aspen_leaves"}, {["x"] = 5, ["y"] = 11, ["param1"] = 13, ["z"] = 9, ["name"] = "default:aspen_leaves"}, {["x"] = 5, ["y"] = 11, ["param1"] = 13, ["z"] = 10, ["name"] = "default:aspen_leaves"}, {["x"] = 5, ["y"] = 12, ["param1"] = 13, ["z"] = 8, ["name"] = "default:aspen_leaves"}, {["x"] = 5, ["y"] = 12, ["param1"] = 13, ["z"] = 9, ["name"] = "default:aspen_leaves"}, {["x"] = 5, ["y"] = 12, ["param1"] = 13, ["z"] = 10, ["name"] = "default:aspen_leaves"}, {["x"] = 5, ["y"] = 12, ["param1"] = 12, ["z"] = 12, ["name"] = "default:aspen_leaves"}, {["x"] = 5, ["y"] = 12, ["param1"] = 12, ["z"] = 13, ["name"] = "default:aspen_leaves"}, {["x"] = 5, ["y"] = 12, ["param1"] = 13, ["z"] = 14, ["name"] = "default:aspen_leaves"}, {["x"] = 5, ["y"] = 12, ["param1"] = 14, ["z"] = 15, ["name"] = "default:aspen_leaves"}, {["x"] = 5, ["y"] = 13, ["param1"] = 13, ["z"] = 8, ["name"] = "default:aspen_leaves"}, {["x"] = 5, ["y"] = 13, ["param1"] = 14, ["z"] = 9, ["name"] = "default:aspen_leaves"}, {["x"] = 5, ["y"] = 13, ["param1"] = 13, ["z"] = 10, ["name"] = "default:aspen_leaves"}, {["x"] = 5, ["param2"] = 18, ["y"] = 13, ["z"] = 12, ["name"] = "default:tree"}, {["x"] = 5, ["y"] = 13, ["param1"] = 12, ["z"] = 13, ["name"] = "default:aspen_leaves"}, {["x"] = 5, ["y"] = 13, ["param1"] = 13, ["z"] = 14, ["name"] = "default:aspen_leaves"}, {["x"] = 5, ["y"] = 13, ["param1"] = 14, ["z"] = 15, ["name"] = "default:aspen_leaves"}, {["x"] = 5, ["y"] = 14, ["param1"] = 13, ["z"] = 6, ["name"] = "default:aspen_leaves"}, {["x"] = 5, ["y"] = 14, ["param1"] = 13, ["z"] = 7, ["name"] = "default:aspen_leaves"}, {["x"] = 5, ["y"] = 14, ["param1"] = 12, ["z"] = 12, ["name"] = "default:aspen_leaves"}, {["x"] = 5, ["y"] = 14, ["param1"] = 13, ["z"] = 13, ["name"] = "default:aspen_leaves"}, {["x"] = 5, ["y"] = 15, ["param1"] = 14, ["z"] = 5, ["name"] = "default:aspen_leaves"}, {["x"] = 5, ["y"] = 15, ["param1"] = 13, ["z"] = 6, ["name"] = "default:aspen_leaves"}, {["x"] = 5, ["y"] = 15, ["param1"] = 13, ["z"] = 7, ["name"] = "default:aspen_leaves"}, {["x"] = 5, ["y"] = 15, ["param1"] = 14, ["z"] = 8, ["name"] = "default:aspen_leaves"}, {["x"] = 5, ["y"] = 15, ["param1"] = 14, ["z"] = 10, ["name"] = "default:aspen_leaves"}, {["x"] = 5, ["y"] = 15, ["param1"] = 13, ["z"] = 11, ["name"] = "default:aspen_leaves"}, {["x"] = 5, ["y"] = 15, ["param1"] = 12, ["z"] = 12, ["name"] = "default:aspen_leaves"}, {["x"] = 5, ["y"] = 16, ["param1"] = 14, ["z"] = 6, ["name"] = "default:aspen_leaves"}, {["x"] = 5, ["y"] = 16, ["param1"] = 14, ["z"] = 7, ["name"] = "default:aspen_leaves"}, {["x"] = 5, ["y"] = 16, ["param1"] = 14, ["z"] = 8, ["name"] = "default:aspen_leaves"}, {["x"] = 5, ["y"] = 16, ["param1"] = 14, ["z"] = 10, ["name"] = "default:aspen_leaves"}, {["x"] = 5, ["y"] = 16, ["param1"] = 13, ["z"] = 11, ["name"] = "default:aspen_leaves"}, {["x"] = 5, ["y"] = 16, ["param1"] = 13, ["z"] = 12, ["name"] = "default:aspen_leaves"}, {["x"] = 5, ["y"] = 16, ["param1"] = 13, ["z"] = 13, ["name"] = "default:aspen_leaves"}, {["x"] = 5, ["y"] = 17, ["param1"] = 14, ["z"] = 10, ["name"] = "default:aspen_leaves"}, {["x"] = 5, ["y"] = 17, ["param1"] = 14, ["z"] = 11, ["name"] = "default:aspen_leaves"}, {["x"] = 5, ["y"] = 17, ["param1"] = 14, ["z"] = 12, ["name"] = "default:aspen_leaves"}, {["x"] = 5, ["y"] = 17, ["param1"] = 14, ["z"] = 13, ["name"] = "default:aspen_leaves"}, {["x"] = 5, ["y"] = 17, ["param1"] = 14, ["z"] = 14, ["name"] = "default:aspen_leaves"}, {["x"] = 6, ["y"] = 3, ["param1"] = 12, ["z"] = 4, ["name"] = "default:aspen_leaves"}, {["x"] = 6, ["y"] = 3, ["param1"] = 11, ["z"] = 5, ["name"] = "default:aspen_leaves"}, {["x"] = 6, ["y"] = 3, ["param1"] = 12, ["z"] = 6, ["name"] = "default:aspen_leaves"}, {["x"] = 6, ["y"] = 3, ["param1"] = 13, ["z"] = 7, ["name"] = "default:aspen_leaves"}, {["x"] = 6, ["y"] = 4, ["param1"] = 13, ["z"] = 3, ["name"] = "default:aspen_leaves"}, {["x"] = 6, ["y"] = 4, ["param1"] = 12, ["z"] = 4, ["name"] = "default:aspen_leaves"}, {["x"] = 6, ["param2"] = 9, ["y"] = 4, ["param1"] = 43, ["z"] = 5, ["name"] = "default:tree"}, {["x"] = 6, ["param2"] = 9, ["y"] = 4, ["param1"] = 43, ["z"] = 6, ["name"] = "default:tree"}, {["x"] = 6, ["y"] = 4, ["param1"] = 13, ["z"] = 7, ["name"] = "default:aspen_leaves"}, {["x"] = 6, ["y"] = 5, ["param1"] = 12, ["z"] = 4, ["name"] = "default:aspen_leaves"}, {["x"] = 6, ["y"] = 5, ["param1"] = 11, ["z"] = 5, ["name"] = "default:aspen_leaves"}, {["x"] = 6, ["y"] = 5, ["param1"] = 12, ["z"] = 6, ["name"] = "default:aspen_leaves"}, {["x"] = 6, ["y"] = 5, ["param1"] = 13, ["z"] = 7, ["name"] = "default:aspen_leaves"}, {["x"] = 6, ["y"] = 7, ["param1"] = 14, ["z"] = 8, ["name"] = "default:aspen_leaves"}, {["x"] = 6, ["param2"] = 18, ["y"] = 7, ["z"] = 9, ["name"] = "default:tree"}, {["x"] = 6, ["param2"] = 7, ["y"] = 7, ["z"] = 10, ["name"] = "default:tree"}, {["x"] = 6, ["param2"] = 7, ["y"] = 7, ["z"] = 11, ["name"] = "default:tree"}, {["x"] = 6, ["param2"] = 22, ["y"] = 7, ["z"] = 12, ["name"] = "default:tree"}, {["x"] = 6, ["y"] = 8, ["param1"] = 13, ["z"] = 3, ["name"] = "default:aspen_leaves"}, {["x"] = 6, ["param2"] = 2, ["y"] = 8, ["z"] = 12, ["name"] = "default:tree"}, {["x"] = 6, ["y"] = 8, ["param1"] = 12, ["z"] = 14, ["name"] = "default:aspen_leaves"}, {["x"] = 6, ["y"] = 8, ["param1"] = 13, ["z"] = 15, ["name"] = "default:aspen_leaves"}, {["x"] = 6, ["y"] = 8, ["param1"] = 14, ["z"] = 16, ["name"] = "default:aspen_leaves"}, {["x"] = 6, ["y"] = 9, ["param1"] = 13, ["z"] = 1, ["name"] = "default:aspen_leaves"}, {["x"] = 6, ["y"] = 9, ["param1"] = 14, ["z"] = 2, ["name"] = "default:aspen_leaves"}, {["x"] = 6, ["y"] = 9, ["param1"] = 13, ["z"] = 3, ["name"] = "default:aspen_leaves"}, {["x"] = 6, ["y"] = 9, ["param1"] = 12, ["z"] = 4, ["name"] = "default:aspen_leaves"}, {["x"] = 6, ["param2"] = 18, ["y"] = 9, ["z"] = 6, ["name"] = "default:tree"}, {["x"] = 6, ["y"] = 9, ["param1"] = 11, ["z"] = 11, ["name"] = "default:aspen_leaves"}, {["x"] = 6, ["y"] = 9, ["param1"] = 10, ["z"] = 12, ["name"] = "default:aspen_leaves"}, {["x"] = 6, ["y"] = 9, ["param1"] = 11, ["z"] = 13, ["name"] = "default:aspen_leaves"}, {["x"] = 6, ["y"] = 9, ["param1"] = 12, ["z"] = 14, ["name"] = "default:aspen_leaves"}, {["x"] = 6, ["y"] = 9, ["param1"] = 13, ["z"] = 15, ["name"] = "default:aspen_leaves"}, {["x"] = 6, ["y"] = 9, ["param1"] = 14, ["z"] = 16, ["name"] = "default:aspen_leaves"}, {["x"] = 6, ["y"] = 10, ["param1"] = 14, ["z"] = 0, ["name"] = "default:aspen_leaves"}, {["x"] = 6, ["y"] = 10, ["param1"] = 13, ["z"] = 1, ["name"] = "default:aspen_leaves"}, {["x"] = 6, ["y"] = 10, ["param1"] = 14, ["z"] = 2, ["name"] = "default:aspen_leaves"}, {["x"] = 6, ["y"] = 10, ["param1"] = 13, ["z"] = 3, ["name"] = "default:aspen_leaves"}, {["x"] = 6, ["y"] = 10, ["param1"] = 13, ["z"] = 4, ["name"] = "default:aspen_leaves"}, {["x"] = 6, ["y"] = 10, ["param1"] = 12, ["z"] = 6, ["name"] = "default:aspen_leaves"}, {["x"] = 6, ["y"] = 10, ["param1"] = 13, ["z"] = 7, ["name"] = "default:aspen_leaves"}, {["x"] = 6, ["y"] = 10, ["param1"] = 10, ["z"] = 12, ["name"] = "default:aspen_leaves"}, {["x"] = 6, ["y"] = 10, ["param1"] = 12, ["z"] = 14, ["name"] = "default:aspen_leaves"}, {["x"] = 6, ["y"] = 11, ["param1"] = 14, ["z"] = 1, ["name"] = "default:aspen_leaves"}, {["x"] = 6, ["y"] = 11, ["param1"] = 14, ["z"] = 2, ["name"] = "default:aspen_leaves"}, {["x"] = 6, ["y"] = 11, ["param1"] = 14, ["z"] = 3, ["name"] = "default:aspen_leaves"}, {["x"] = 6, ["y"] = 11, ["param1"] = 14, ["z"] = 4, ["name"] = "default:aspen_leaves"}, {["x"] = 6, ["y"] = 11, ["param1"] = 12, ["z"] = 6, ["name"] = "default:aspen_leaves"}, {["x"] = 6, ["y"] = 11, ["param1"] = 13, ["z"] = 7, ["name"] = "default:aspen_leaves"}, {["x"] = 6, ["y"] = 11, ["param1"] = 11, ["z"] = 12, ["name"] = "default:aspen_leaves"}, {["x"] = 6, ["y"] = 11, ["param1"] = 11, ["z"] = 13, ["name"] = "default:aspen_leaves"}, {["x"] = 6, ["y"] = 11, ["param1"] = 12, ["z"] = 14, ["name"] = "default:aspen_leaves"}, {["x"] = 6, ["y"] = 12, ["param1"] = 14, ["z"] = 8, ["name"] = "default:aspen_leaves"}, {["x"] = 6, ["param2"] = 18, ["y"] = 12, ["z"] = 9, ["name"] = "default:tree"}, {["x"] = 6, ["param2"] = 7, ["y"] = 12, ["z"] = 10, ["name"] = "default:tree"}, {["x"] = 6, ["param2"] = 7, ["y"] = 12, ["z"] = 11, ["name"] = "default:tree"}, {["x"] = 6, ["param2"] = 7, ["y"] = 12, ["z"] = 12, ["name"] = "default:tree"}, {["x"] = 6, ["y"] = 12, ["param1"] = 11, ["z"] = 13, ["name"] = "default:aspen_leaves"}, {["x"] = 6, ["y"] = 12, ["param1"] = 12, ["z"] = 14, ["name"] = "default:aspen_leaves"}, {["x"] = 6, ["y"] = 12, ["param1"] = 13, ["z"] = 15, ["name"] = "default:aspen_leaves"}, {["x"] = 6, ["y"] = 13, ["param1"] = 13, ["z"] = 9, ["name"] = "default:aspen_leaves"}, {["x"] = 6, ["param2"] = 3, ["y"] = 13, ["z"] = 12, ["name"] = "default:tree"}, {["x"] = 6, ["param2"] = 7, ["y"] = 13, ["z"] = 13, ["name"] = "default:tree"}, {["x"] = 6, ["param2"] = 7, ["y"] = 13, ["z"] = 14, ["name"] = "default:tree"}, {["x"] = 6, ["y"] = 13, ["param1"] = 13, ["z"] = 15, ["name"] = "default:aspen_leaves"}, {["x"] = 6, ["y"] = 13, ["param1"] = 14, ["z"] = 16, ["name"] = "default:aspen_leaves"}, {["x"] = 6, ["y"] = 14, ["param1"] = 14, ["z"] = 5, ["name"] = "default:aspen_leaves"}, {["x"] = 6, ["y"] = 14, ["param1"] = 13, ["z"] = 6, ["name"] = "default:aspen_leaves"}, {["x"] = 6, ["y"] = 14, ["param1"] = 13, ["z"] = 7, ["name"] = "default:aspen_leaves"}, {["x"] = 6, ["y"] = 14, ["param1"] = 12, ["z"] = 11, ["name"] = "default:aspen_leaves"}, {["x"] = 6, ["y"] = 14, ["param1"] = 11, ["z"] = 12, ["name"] = "default:aspen_leaves"}, {["x"] = 6, ["y"] = 14, ["param1"] = 12, ["z"] = 13, ["name"] = "default:aspen_leaves"}, {["x"] = 6, ["y"] = 14, ["param1"] = 13, ["z"] = 14, ["name"] = "default:aspen_leaves"}, {["x"] = 6, ["y"] = 14, ["param1"] = 14, ["z"] = 15, ["name"] = "default:aspen_leaves"}, {["x"] = 6, ["y"] = 15, ["param1"] = 14, ["z"] = 5, ["name"] = "default:aspen_leaves"}, {["x"] = 6, ["y"] = 15, ["param1"] = 13, ["z"] = 6, ["name"] = "default:aspen_leaves"}, {["x"] = 6, ["param2"] = 18, ["y"] = 15, ["z"] = 7, ["name"] = "default:tree"}, {["x"] = 6, ["y"] = 15, ["param1"] = 14, ["z"] = 8, ["name"] = "default:aspen_leaves"}, {["x"] = 6, ["y"] = 15, ["param1"] = 12, ["z"] = 11, ["name"] = "default:aspen_leaves"}, {["x"] = 6, ["y"] = 16, ["param1"] = 14, ["z"] = 5, ["name"] = "default:aspen_leaves"}, {["x"] = 6, ["y"] = 16, ["param1"] = 14, ["z"] = 6, ["name"] = "default:aspen_leaves"}, {["x"] = 6, ["y"] = 16, ["param1"] = 14, ["z"] = 7, ["name"] = "default:aspen_leaves"}, {["x"] = 6, ["y"] = 16, ["param1"] = 14, ["z"] = 8, ["name"] = "default:aspen_leaves"}, {["x"] = 6, ["y"] = 16, ["param1"] = 14, ["z"] = 9, ["name"] = "default:aspen_leaves"}, {["x"] = 6, ["y"] = 16, ["param1"] = 13, ["z"] = 10, ["name"] = "default:aspen_leaves"}, {["x"] = 6, ["param2"] = 18, ["y"] = 16, ["z"] = 11, ["name"] = "default:tree"}, {["x"] = 6, ["y"] = 16, ["param1"] = 12, ["z"] = 12, ["name"] = "default:aspen_leaves"}, {["x"] = 6, ["y"] = 16, ["param1"] = 13, ["z"] = 13, ["name"] = "default:aspen_leaves"}, {["x"] = 6, ["y"] = 16, ["param1"] = 14, ["z"] = 14, ["name"] = "default:aspen_leaves"}, {["x"] = 6, ["y"] = 17, ["param1"] = 14, ["z"] = 9, ["name"] = "default:aspen_leaves"}, {["x"] = 6, ["y"] = 17, ["param1"] = 14, ["z"] = 10, ["name"] = "default:aspen_leaves"}, {["x"] = 6, ["y"] = 17, ["param1"] = 14, ["z"] = 11, ["name"] = "default:aspen_leaves"}, {["x"] = 6, ["y"] = 17, ["param1"] = 13, ["z"] = 12, ["name"] = "default:aspen_leaves"}, {["x"] = 6, ["y"] = 17, ["param1"] = 13, ["z"] = 13, ["name"] = "default:aspen_leaves"}, {["x"] = 6, ["y"] = 17, ["param1"] = 14, ["z"] = 14, ["name"] = "default:aspen_leaves"}, {["x"] = 6, ["y"] = 18, ["param1"] = 14, ["z"] = 12, ["name"] = "default:aspen_leaves"}, {["x"] = 6, ["y"] = 18, ["param1"] = 14, ["z"] = 13, ["name"] = "default:aspen_leaves"}, {["x"] = 7, ["y"] = 3, ["param1"] = 13, ["z"] = 4, ["name"] = "default:aspen_leaves"}, {["x"] = 7, ["y"] = 3, ["param1"] = 13, ["z"] = 6, ["name"] = "default:aspen_leaves"}, {["x"] = 7, ["y"] = 3, ["param1"] = 14, ["z"] = 7, ["name"] = "default:aspen_leaves"}, {["x"] = 7, ["y"] = 4, ["param1"] = 13, ["z"] = 4, ["name"] = "default:aspen_leaves"}, {["x"] = 7, ["y"] = 4, ["param1"] = 12, ["z"] = 5, ["name"] = "default:aspen_leaves"}, {["x"] = 7, ["param2"] = 18, ["y"] = 4, ["param1"] = 43, ["z"] = 6, ["name"] = "default:tree"}, {["x"] = 7, ["y"] = 5, ["param1"] = 12, ["z"] = 5, ["name"] = "default:aspen_leaves"}, {["x"] = 7, ["param2"] = 18, ["y"] = 7, ["z"] = 9, ["name"] = "default:tree"}, {["x"] = 7, ["y"] = 8, ["param1"] = 13, ["z"] = 2, ["name"] = "default:aspen_leaves"}, {["x"] = 7, ["y"] = 8, ["param1"] = 13, ["z"] = 3, ["name"] = "default:aspen_leaves"}, {["x"] = 7, ["y"] = 8, ["param1"] = 13, ["z"] = 4, ["name"] = "default:aspen_leaves"}, {["x"] = 7, ["param2"] = 23, ["y"] = 8, ["z"] = 7, ["name"] = "default:tree"}, {["x"] = 7, ["y"] = 8, ["param1"] = 11, ["z"] = 12, ["name"] = "default:aspen_leaves"}, {["x"] = 7, ["y"] = 9, ["param1"] = 13, ["z"] = 1, ["name"] = "default:aspen_leaves"}, {["x"] = 7, ["y"] = 9, ["param1"] = 13, ["z"] = 2, ["name"] = "default:aspen_leaves"}, {["x"] = 7, ["y"] = 9, ["param1"] = 13, ["z"] = 3, ["name"] = "default:aspen_leaves"}, {["x"] = 7, ["param2"] = 9, ["y"] = 9, ["z"] = 4, ["name"] = "default:tree"}, {["x"] = 7, ["param2"] = 9, ["y"] = 9, ["z"] = 5, ["name"] = "default:tree"}, {["x"] = 7, ["param2"] = 9, ["y"] = 9, ["z"] = 6, ["name"] = "default:tree"}, {["x"] = 7, ["y"] = 9, ["z"] = 7, ["name"] = "default:tree"}, {["x"] = 7, ["y"] = 9, ["param1"] = 11, ["z"] = 12, ["name"] = "default:aspen_leaves"}, {["x"] = 7, ["y"] = 9, ["param1"] = 12, ["z"] = 13, ["name"] = "default:aspen_leaves"}, {["x"] = 7, ["y"] = 9, ["param1"] = 13, ["z"] = 14, ["name"] = "default:aspen_leaves"}, {["x"] = 7, ["y"] = 10, ["param1"] = 14, ["z"] = 0, ["name"] = "default:aspen_leaves"}, {["x"] = 7, ["y"] = 10, ["param1"] = 13, ["z"] = 1, ["name"] = "default:aspen_leaves"}, {["x"] = 7, ["param2"] = 9, ["y"] = 10, ["z"] = 2, ["name"] = "default:tree"}, {["x"] = 7, ["param2"] = 9, ["y"] = 10, ["z"] = 3, ["name"] = "default:tree"}, {["x"] = 7, ["y"] = 10, ["z"] = 4, ["name"] = "default:tree"}, {["x"] = 7, ["y"] = 10, ["param1"] = 12, ["z"] = 5, ["name"] = "default:aspen_leaves"}, {["x"] = 7, ["y"] = 10, ["param1"] = 13, ["z"] = 6, ["name"] = "default:aspen_leaves"}, {["x"] = 7, ["y"] = 10, ["param1"] = 14, ["z"] = 7, ["name"] = "default:aspen_leaves"}, {["x"] = 7, ["y"] = 11, ["param1"] = 14, ["z"] = 1, ["name"] = "default:aspen_leaves"}, {["x"] = 7, ["y"] = 11, ["param1"] = 14, ["z"] = 2, ["name"] = "default:aspen_leaves"}, {["x"] = 7, ["y"] = 11, ["param1"] = 14, ["z"] = 3, ["name"] = "default:aspen_leaves"}, {["x"] = 7, ["y"] = 11, ["param1"] = 13, ["z"] = 4, ["name"] = "default:aspen_leaves"}, {["x"] = 7, ["y"] = 11, ["param1"] = 12, ["z"] = 5, ["name"] = "default:aspen_leaves"}, {["x"] = 7, ["y"] = 11, ["param1"] = 13, ["z"] = 6, ["name"] = "default:aspen_leaves"}, {["x"] = 7, ["y"] = 11, ["param1"] = 14, ["z"] = 7, ["name"] = "default:aspen_leaves"}, {["x"] = 7, ["param2"] = 18, ["y"] = 12, ["z"] = 9, ["name"] = "default:tree"}, {["x"] = 7, ["y"] = 12, ["param1"] = 12, ["z"] = 13, ["name"] = "default:aspen_leaves"}, {["x"] = 7, ["y"] = 12, ["param1"] = 13, ["z"] = 14, ["name"] = "default:aspen_leaves"}, {["x"] = 7, ["y"] = 13, ["param1"] = 13, ["z"] = 14, ["name"] = "default:aspen_leaves"}, {["x"] = 7, ["y"] = 13, ["param1"] = 14, ["z"] = 15, ["name"] = "default:aspen_leaves"}, {["x"] = 7, ["y"] = 14, ["param1"] = 13, ["z"] = 5, ["name"] = "default:aspen_leaves"}, {["x"] = 7, ["y"] = 14, ["param1"] = 13, ["z"] = 6, ["name"] = "default:aspen_leaves"}, {["x"] = 7, ["y"] = 14, ["param1"] = 14, ["z"] = 7, ["name"] = "default:aspen_leaves"}, {["x"] = 7, ["y"] = 14, ["param1"] = 11, ["z"] = 12, ["name"] = "default:aspen_leaves"}, {["x"] = 7, ["y"] = 14, ["param1"] = 12, ["z"] = 13, ["name"] = "default:aspen_leaves"}, {["x"] = 7, ["y"] = 14, ["param1"] = 14, ["z"] = 15, ["name"] = "default:aspen_leaves"}, {["x"] = 7, ["y"] = 15, ["param1"] = 14, ["z"] = 4, ["name"] = "default:aspen_leaves"}, {["x"] = 7, ["y"] = 15, ["param1"] = 13, ["z"] = 5, ["name"] = "default:aspen_leaves"}, {["x"] = 7, ["y"] = 15, ["param1"] = 13, ["z"] = 6, ["name"] = "default:aspen_leaves"}, {["x"] = 7, ["param2"] = 18, ["y"] = 15, ["z"] = 7, ["name"] = "default:tree"}, {["x"] = 7, ["y"] = 15, ["param1"] = 13, ["z"] = 14, ["name"] = "default:aspen_leaves"}, {["x"] = 7, ["y"] = 16, ["param1"] = 14, ["z"] = 5, ["name"] = "default:aspen_leaves"}, {["x"] = 7, ["y"] = 16, ["param1"] = 14, ["z"] = 6, ["name"] = "default:aspen_leaves"}, {["x"] = 7, ["y"] = 16, ["param1"] = 14, ["z"] = 7, ["name"] = "default:aspen_leaves"}, {["x"] = 7, ["y"] = 16, ["param1"] = 14, ["z"] = 9, ["name"] = "default:aspen_leaves"}, {["x"] = 7, ["y"] = 16, ["param1"] = 13, ["z"] = 10, ["name"] = "default:aspen_leaves"}, {["x"] = 7, ["param2"] = 18, ["y"] = 16, ["z"] = 11, ["name"] = "default:tree"}, {["x"] = 7, ["y"] = 16, ["param1"] = 12, ["z"] = 12, ["name"] = "default:aspen_leaves"}, {["x"] = 7, ["y"] = 16, ["param1"] = 13, ["z"] = 13, ["name"] = "default:aspen_leaves"}, {["x"] = 7, ["y"] = 16, ["param1"] = 13, ["z"] = 14, ["name"] = "default:aspen_leaves"}, {["x"] = 7, ["y"] = 16, ["param1"] = 14, ["z"] = 15, ["name"] = "default:aspen_leaves"}, {["x"] = 7, ["y"] = 17, ["param1"] = 14, ["z"] = 9, ["name"] = "default:aspen_leaves"}, {["x"] = 7, ["y"] = 17, ["param1"] = 13, ["z"] = 10, ["name"] = "default:aspen_leaves"}, {["x"] = 7, ["y"] = 17, ["param1"] = 13, ["z"] = 11, ["name"] = "default:aspen_leaves"}, {["x"] = 7, ["y"] = 17, ["param1"] = 13, ["z"] = 12, ["name"] = "default:aspen_leaves"}, {["x"] = 7, ["y"] = 17, ["param1"] = 14, ["z"] = 13, ["name"] = "default:aspen_leaves"}, {["x"] = 7, ["y"] = 17, ["param1"] = 14, ["z"] = 14, ["name"] = "default:aspen_leaves"}, {["x"] = 7, ["y"] = 18, ["param1"] = 14, ["z"] = 10, ["name"] = "default:aspen_leaves"}, {["x"] = 7, ["y"] = 18, ["param1"] = 14, ["z"] = 11, ["name"] = "default:aspen_leaves"}, {["x"] = 7, ["y"] = 18, ["param1"] = 14, ["z"] = 12, ["name"] = "default:aspen_leaves"}, {["x"] = 7, ["y"] = 19, ["param1"] = 14, ["z"] = 11, ["name"] = "default:aspen_leaves"}, {["x"] = 8, ["y"] = 3, ["param1"] = 13, ["z"] = 5, ["name"] = "default:aspen_leaves"}, {["x"] = 8, ["y"] = 3, ["param1"] = 12, ["z"] = 6, ["name"] = "default:aspen_leaves"}, {["x"] = 8, ["y"] = 3, ["param1"] = 13, ["z"] = 7, ["name"] = "default:aspen_leaves"}, {["x"] = 8, ["param2"] = 7, ["y"] = 3, ["z"] = 8, ["name"] = "default:tree"}, {["x"] = 8, ["param2"] = 7, ["y"] = 3, ["param1"] = 43, ["z"] = 9, ["name"] = "default:tree"}, {["x"] = 8, ["param2"] = 2, ["y"] = 3, ["param1"] = 43, ["z"] = 10, ["name"] = "default:tree"}, {["x"] = 8, ["y"] = 4, ["param1"] = 14, ["z"] = 4, ["name"] = "default:aspen_leaves"}, {["x"] = 8, ["y"] = 4, ["param1"] = 13, ["z"] = 5, ["name"] = "default:aspen_leaves"}, {["x"] = 8, ["param2"] = 18, ["y"] = 4, ["param1"] = 43, ["z"] = 6, ["name"] = "default:tree"}, {["x"] = 8, ["param2"] = 9, ["y"] = 4, ["param1"] = 43, ["z"] = 7, ["name"] = "default:tree"}, {["x"] = 8, ["param2"] = 9, ["y"] = 4, ["param1"] = 43, ["z"] = 8, ["name"] = "default:tree"}, {["x"] = 8, ["param2"] = 9, ["y"] = 4, ["param1"] = 43, ["z"] = 9, ["name"] = "default:tree"}, {["x"] = 8, ["param2"] = 2, ["y"] = 4, ["param1"] = 43, ["z"] = 10, ["name"] = "default:tree"}, {["x"] = 8, ["y"] = 5, ["param1"] = 13, ["z"] = 5, ["name"] = "default:aspen_leaves"}, {["x"] = 8, ["y"] = 5, ["param1"] = 12, ["z"] = 6, ["name"] = "default:aspen_leaves"}, {["x"] = 8, ["y"] = 5, ["param1"] = 43, ["z"] = 9, ["name"] = "default:tree"}, {["x"] = 8, ["y"] = 5, ["param1"] = 43, ["z"] = 10, ["name"] = "default:tree"}, {["x"] = 8, ["y"] = 6, ["z"] = 9, ["name"] = "default:tree"}, {["x"] = 8, ["y"] = 6, ["z"] = 10, ["name"] = "default:tree"}, {["x"] = 8, ["param2"] = 18, ["y"] = 7, ["z"] = 9, ["name"] = "default:tree"}, {["x"] = 8, ["param2"] = 2, ["y"] = 7, ["z"] = 10, ["name"] = "default:tree"}, {["x"] = 8, ["param2"] = 18, ["y"] = 8, ["z"] = 7, ["name"] = "default:tree"}, {["x"] = 8, ["param2"] = 2, ["y"] = 8, ["z"] = 10, ["name"] = "default:tree"}, {["x"] = 8, ["param2"] = 7, ["y"] = 8, ["z"] = 11, ["name"] = "default:tree"}, {["x"] = 8, ["param2"] = 18, ["y"] = 8, ["z"] = 12, ["name"] = "default:tree"}, {["x"] = 8, ["y"] = 9, ["param1"] = 14, ["z"] = 2, ["name"] = "default:aspen_leaves"}, {["x"] = 8, ["y"] = 9, ["param1"] = 14, ["z"] = 3, ["name"] = "default:aspen_leaves"}, {["x"] = 8, ["y"] = 9, ["param1"] = 14, ["z"] = 4, ["name"] = "default:aspen_leaves"}, {["x"] = 8, ["param2"] = 2, ["y"] = 9, ["z"] = 10, ["name"] = "default:tree"}, {["x"] = 8, ["y"] = 10, ["param1"] = 14, ["z"] = 1, ["name"] = "default:aspen_leaves"}, {["x"] = 8, ["y"] = 10, ["param1"] = 14, ["z"] = 2, ["name"] = "default:aspen_leaves"}, {["x"] = 8, ["y"] = 10, ["param1"] = 13, ["z"] = 5, ["name"] = "default:aspen_leaves"}, {["x"] = 8, ["param2"] = 2, ["y"] = 10, ["z"] = 10, ["name"] = "default:tree"}, {["x"] = 8, ["y"] = 11, ["param1"] = 14, ["z"] = 2, ["name"] = "default:aspen_leaves"}, {["x"] = 8, ["y"] = 11, ["param1"] = 14, ["z"] = 3, ["name"] = "default:aspen_leaves"}, {["x"] = 8, ["y"] = 11, ["param1"] = 14, ["z"] = 4, ["name"] = "default:aspen_leaves"}, {["x"] = 8, ["y"] = 11, ["param1"] = 13, ["z"] = 5, ["name"] = "default:aspen_leaves"}, {["x"] = 8, ["param2"] = 2, ["y"] = 11, ["z"] = 10, ["name"] = "default:tree"}, {["x"] = 8, ["param2"] = 18, ["y"] = 12, ["z"] = 9, ["name"] = "default:tree"}, {["x"] = 8, ["param2"] = 2, ["y"] = 12, ["z"] = 10, ["name"] = "default:tree"}, {["x"] = 8, ["y"] = 13, ["z"] = 10, ["name"] = "default:tree"}, {["x"] = 8, ["y"] = 14, ["param1"] = 13, ["z"] = 5, ["name"] = "default:aspen_leaves"}, {["x"] = 8, ["y"] = 14, ["param1"] = 13, ["z"] = 6, ["name"] = "default:aspen_leaves"}, {["x"] = 8, ["y"] = 14, ["z"] = 10, ["name"] = "default:tree"}, {["x"] = 8, ["y"] = 15, ["param1"] = 14, ["z"] = 4, ["name"] = "default:aspen_leaves"}, {["x"] = 8, ["y"] = 15, ["param1"] = 13, ["z"] = 5, ["name"] = "default:aspen_leaves"}, {["x"] = 8, ["param2"] = 9, ["y"] = 15, ["z"] = 6, ["name"] = "default:tree"}, {["x"] = 8, ["param2"] = 9, ["y"] = 15, ["z"] = 7, ["name"] = "default:tree"}, {["x"] = 8, ["param2"] = 9, ["y"] = 15, ["z"] = 8, ["name"] = "default:tree"}, {["x"] = 8, ["param2"] = 9, ["y"] = 15, ["z"] = 9, ["name"] = "default:tree"}, {["x"] = 8, ["y"] = 15, ["z"] = 10, ["name"] = "default:tree"}, {["x"] = 8, ["y"] = 15, ["param1"] = 12, ["z"] = 13, ["name"] = "default:aspen_leaves"}, {["x"] = 8, ["y"] = 15, ["param1"] = 13, ["z"] = 14, ["name"] = "default:aspen_leaves"}, {["x"] = 8, ["y"] = 15, ["param1"] = 14, ["z"] = 15, ["name"] = "default:aspen_leaves"}, {["x"] = 8, ["y"] = 16, ["param1"] = 14, ["z"] = 5, ["name"] = "default:aspen_leaves"}, {["x"] = 8, ["y"] = 16, ["param1"] = 14, ["z"] = 6, ["name"] = "default:aspen_leaves"}, {["x"] = 8, ["y"] = 16, ["param1"] = 14, ["z"] = 7, ["name"] = "default:aspen_leaves"}, {["x"] = 8, ["y"] = 16, ["param1"] = 14, ["z"] = 8, ["name"] = "default:aspen_leaves"}, {["x"] = 8, ["y"] = 16, ["param1"] = 13, ["z"] = 9, ["name"] = "default:aspen_leaves"}, {["x"] = 8, ["param2"] = 3, ["y"] = 16, ["z"] = 10, ["name"] = "default:tree"}, {["x"] = 8, ["param2"] = 7, ["y"] = 16, ["z"] = 11, ["name"] = "default:tree"}, {["x"] = 8, ["param2"] = 7, ["y"] = 16, ["z"] = 12, ["name"] = "default:tree"}, {["x"] = 8, ["param2"] = 7, ["y"] = 16, ["z"] = 13, ["name"] = "default:tree"}, {["x"] = 8, ["y"] = 16, ["param1"] = 13, ["z"] = 14, ["name"] = "default:aspen_leaves"}, {["x"] = 8, ["y"] = 16, ["param1"] = 14, ["z"] = 15, ["name"] = "default:aspen_leaves"}, {["x"] = 8, ["y"] = 17, ["param1"] = 14, ["z"] = 9, ["name"] = "default:aspen_leaves"}, {["x"] = 8, ["y"] = 17, ["param1"] = 13, ["z"] = 10, ["name"] = "default:aspen_leaves"}, {["x"] = 8, ["y"] = 17, ["param1"] = 12, ["z"] = 11, ["name"] = "default:aspen_leaves"}, {["x"] = 8, ["y"] = 17, ["param1"] = 12, ["z"] = 12, ["name"] = "default:aspen_leaves"}, {["x"] = 8, ["y"] = 17, ["param1"] = 13, ["z"] = 13, ["name"] = "default:aspen_leaves"}, {["x"] = 8, ["y"] = 17, ["param1"] = 14, ["z"] = 14, ["name"] = "default:aspen_leaves"}, {["x"] = 8, ["y"] = 17, ["param1"] = 14, ["z"] = 15, ["name"] = "default:aspen_leaves"}, {["x"] = 8, ["y"] = 18, ["param1"] = 14, ["z"] = 9, ["name"] = "default:aspen_leaves"}, {["x"] = 8, ["y"] = 18, ["param1"] = 13, ["z"] = 10, ["name"] = "default:aspen_leaves"}, {["x"] = 8, ["y"] = 18, ["param1"] = 13, ["z"] = 11, ["name"] = "default:aspen_leaves"}, {["x"] = 8, ["y"] = 18, ["param1"] = 13, ["z"] = 12, ["name"] = "default:aspen_leaves"}, {["x"] = 8, ["y"] = 18, ["param1"] = 14, ["z"] = 13, ["name"] = "default:aspen_leaves"}, {["x"] = 8, ["y"] = 19, ["param1"] = 14, ["z"] = 10, ["name"] = "default:aspen_leaves"}, {["x"] = 8, ["y"] = 19, ["param1"] = 14, ["z"] = 11, ["name"] = "default:aspen_leaves"}, {["x"] = 8, ["y"] = 19, ["param1"] = 14, ["z"] = 12, ["name"] = "default:aspen_leaves"}, {["x"] = 9, ["y"] = 0, ["param1"] = 43, ["z"] = 8, ["name"] = "default:tree"}, {["x"] = 9, ["y"] = 0, ["param1"] = 43, ["z"] = 9, ["name"] = "default:tree"}, {["x"] = 9, ["param2"] = 2, ["y"] = 1, ["param1"] = 43, ["z"] = 8, ["name"] = "default:tree"}, {["x"] = 9, ["param2"] = 2, ["y"] = 1, ["param1"] = 43, ["z"] = 9, ["name"] = "default:tree"}, {["x"] = 9, ["param2"] = 2, ["y"] = 2, ["param1"] = 43, ["z"] = 8, ["name"] = "default:tree"}, {["x"] = 9, ["param2"] = 2, ["y"] = 2, ["param1"] = 43, ["z"] = 9, ["name"] = "default:tree"}, {["x"] = 9, ["y"] = 3, ["param1"] = 13, ["z"] = 6, ["name"] = "default:aspen_leaves"}, {["x"] = 9, ["y"] = 3, ["param1"] = 12, ["z"] = 7, ["name"] = "default:aspen_leaves"}, {["x"] = 9, ["param2"] = 2, ["y"] = 3, ["param1"] = 43, ["z"] = 8, ["name"] = "default:tree"}, {["x"] = 9, ["y"] = 3, ["param1"] = 43, ["z"] = 9, ["name"] = "default:tree"}, {["x"] = 9, ["param2"] = 2, ["y"] = 3, ["param1"] = 43, ["z"] = 10, ["name"] = "default:tree"}, {["x"] = 9, ["y"] = 4, ["param1"] = 14, ["z"] = 5, ["name"] = "default:aspen_leaves"}, {["x"] = 9, ["y"] = 4, ["param1"] = 13, ["z"] = 6, ["name"] = "default:aspen_leaves"}, {["x"] = 9, ["y"] = 4, ["param1"] = 12, ["z"] = 7, ["name"] = "default:aspen_leaves"}, {["x"] = 9, ["param2"] = 18, ["y"] = 4, ["param1"] = 43, ["z"] = 8, ["name"] = "default:tree"}, {["x"] = 9, ["param2"] = 12, ["y"] = 4, ["param1"] = 43, ["z"] = 9, ["name"] = "default:tree"}, {["x"] = 9, ["y"] = 4, ["param1"] = 43, ["z"] = 10, ["name"] = "default:tree"}, {["x"] = 9, ["y"] = 5, ["param1"] = 13, ["z"] = 6, ["name"] = "default:aspen_leaves"}, {["x"] = 9, ["y"] = 5, ["param1"] = 43, ["z"] = 9, ["name"] = "default:tree"}, {["x"] = 9, ["y"] = 5, ["param1"] = 43, ["z"] = 10, ["name"] = "default:tree"}, {["x"] = 9, ["y"] = 6, ["z"] = 9, ["name"] = "default:tree"}, {["x"] = 9, ["y"] = 6, ["z"] = 10, ["name"] = "default:tree"}, {["x"] = 9, ["param2"] = 2, ["y"] = 7, ["z"] = 9, ["name"] = "default:tree"}, {["x"] = 9, ["param2"] = 12, ["y"] = 7, ["z"] = 10, ["name"] = "default:tree"}, {["x"] = 9, ["param2"] = 12, ["y"] = 8, ["z"] = 7, ["name"] = "default:tree"}, {["x"] = 9, ["param2"] = 9, ["y"] = 8, ["z"] = 8, ["name"] = "default:tree"}, {["x"] = 9, ["param2"] = 2, ["y"] = 8, ["z"] = 9, ["name"] = "default:tree"}, {["x"] = 9, ["param2"] = 12, ["y"] = 8, ["z"] = 12, ["name"] = "default:tree"}, {["x"] = 9, ["y"] = 8, ["param1"] = 13, ["z"] = 15, ["name"] = "default:aspen_leaves"}, {["x"] = 9, ["y"] = 8, ["param1"] = 14, ["z"] = 16, ["name"] = "default:aspen_leaves"}, {["x"] = 9, ["param2"] = 2, ["y"] = 9, ["z"] = 9, ["name"] = "default:tree"}, {["x"] = 9, ["y"] = 9, ["param1"] = 11, ["z"] = 13, ["name"] = "default:aspen_leaves"}, {["x"] = 9, ["y"] = 9, ["param1"] = 12, ["z"] = 14, ["name"] = "default:aspen_leaves"}, {["x"] = 9, ["y"] = 9, ["param1"] = 13, ["z"] = 15, ["name"] = "default:aspen_leaves"}, {["x"] = 9, ["y"] = 9, ["param1"] = 14, ["z"] = 16, ["name"] = "default:aspen_leaves"}, {["x"] = 9, ["y"] = 9, ["param1"] = 14, ["z"] = 17, ["name"] = "default:aspen_leaves"}, {["x"] = 9, ["param2"] = 2, ["y"] = 10, ["z"] = 9, ["name"] = "default:tree"}, {["x"] = 9, ["y"] = 10, ["param1"] = 11, ["z"] = 13, ["name"] = "default:aspen_leaves"}, {["x"] = 9, ["y"] = 10, ["param1"] = 12, ["z"] = 14, ["name"] = "default:aspen_leaves"}, {["x"] = 9, ["y"] = 10, ["param1"] = 13, ["z"] = 15, ["name"] = "default:aspen_leaves"}, {["x"] = 9, ["y"] = 10, ["param1"] = 14, ["z"] = 16, ["name"] = "default:aspen_leaves"}, {["x"] = 9, ["param2"] = 2, ["y"] = 11, ["z"] = 9, ["name"] = "default:tree"}, {["x"] = 9, ["y"] = 11, ["param1"] = 12, ["z"] = 14, ["name"] = "default:aspen_leaves"}, {["x"] = 9, ["y"] = 11, ["param1"] = 14, ["z"] = 16, ["name"] = "default:aspen_leaves"}, {["x"] = 9, ["y"] = 12, ["z"] = 9, ["name"] = "default:tree"}, {["x"] = 9, ["param2"] = 12, ["y"] = 13, ["z"] = 10, ["name"] = "default:tree"}, {["x"] = 9, ["y"] = 14, ["param1"] = 14, ["z"] = 5, ["name"] = "default:aspen_leaves"}, {["x"] = 9, ["y"] = 14, ["param1"] = 14, ["z"] = 6, ["name"] = "default:aspen_leaves"}, {["x"] = 9, ["y"] = 15, ["param1"] = 14, ["z"] = 5, ["name"] = "default:aspen_leaves"}, {["x"] = 9, ["y"] = 15, ["param1"] = 14, ["z"] = 6, ["name"] = "default:aspen_leaves"}, {["x"] = 9, ["y"] = 15, ["param1"] = 13, ["z"] = 14, ["name"] = "default:aspen_leaves"}, {["x"] = 9, ["y"] = 16, ["param1"] = 14, ["z"] = 6, ["name"] = "default:aspen_leaves"}, {["x"] = 9, ["y"] = 16, ["param1"] = 14, ["z"] = 9, ["name"] = "default:aspen_leaves"}, {["x"] = 9, ["param2"] = 12, ["y"] = 16, ["z"] = 12, ["name"] = "default:tree"}, {["x"] = 9, ["y"] = 16, ["param1"] = 12, ["z"] = 13, ["name"] = "default:aspen_leaves"}, {["x"] = 9, ["y"] = 16, ["param1"] = 13, ["z"] = 14, ["name"] = "default:aspen_leaves"}, {["x"] = 9, ["y"] = 16, ["param1"] = 14, ["z"] = 15, ["name"] = "default:aspen_leaves"}, {["x"] = 9, ["y"] = 17, ["param1"] = 14, ["z"] = 9, ["name"] = "default:aspen_leaves"}, {["x"] = 9, ["y"] = 17, ["param1"] = 13, ["z"] = 10, ["name"] = "default:aspen_leaves"}, {["x"] = 9, ["y"] = 17, ["param1"] = 13, ["z"] = 11, ["name"] = "default:aspen_leaves"}, {["x"] = 9, ["y"] = 17, ["param1"] = 12, ["z"] = 12, ["name"] = "default:aspen_leaves"}, {["x"] = 9, ["y"] = 17, ["param1"] = 13, ["z"] = 13, ["name"] = "default:aspen_leaves"}, {["x"] = 9, ["y"] = 17, ["param1"] = 14, ["z"] = 14, ["name"] = "default:aspen_leaves"}, {["x"] = 9, ["y"] = 18, ["param1"] = 14, ["z"] = 10, ["name"] = "default:aspen_leaves"}, {["x"] = 9, ["y"] = 18, ["param1"] = 14, ["z"] = 11, ["name"] = "default:aspen_leaves"}, {["x"] = 9, ["y"] = 18, ["param1"] = 13, ["z"] = 12, ["name"] = "default:aspen_leaves"}, {["x"] = 9, ["y"] = 18, ["param1"] = 14, ["z"] = 13, ["name"] = "default:aspen_leaves"}, {["x"] = 9, ["y"] = 19, ["param1"] = 14, ["z"] = 10, ["name"] = "default:aspen_leaves"}, {["x"] = 9, ["y"] = 19, ["param1"] = 14, ["z"] = 11, ["name"] = "default:aspen_leaves"}, {["x"] = 9, ["y"] = 19, ["param1"] = 14, ["z"] = 12, ["name"] = "default:aspen_leaves"}, {["x"] = 10, ["y"] = 0, ["param1"] = 43, ["z"] = 8, ["name"] = "default:tree"}, {["x"] = 10, ["y"] = 0, ["param1"] = 43, ["z"] = 9, ["name"] = "default:tree"}, {["x"] = 10, ["param2"] = 2, ["y"] = 1, ["param1"] = 43, ["z"] = 8, ["name"] = "default:tree"}, {["x"] = 10, ["param2"] = 3, ["y"] = 1, ["param1"] = 43, ["z"] = 9, ["name"] = "default:tree"}, {["x"] = 10, ["param2"] = 3, ["y"] = 2, ["param1"] = 43, ["z"] = 8, ["name"] = "default:tree"}, {["x"] = 10, ["param2"] = 2, ["y"] = 2, ["param1"] = 43, ["z"] = 9, ["name"] = "default:tree"}, {["x"] = 10, ["param2"] = 2, ["y"] = 3, ["param1"] = 43, ["z"] = 8, ["name"] = "default:tree"}, {["x"] = 10, ["param2"] = 2, ["y"] = 3, ["param1"] = 43, ["z"] = 9, ["name"] = "default:tree"}, {["x"] = 10, ["y"] = 4, ["param1"] = 12, ["z"] = 6, ["name"] = "default:aspen_leaves"}, {["x"] = 10, ["param2"] = 3, ["y"] = 4, ["param1"] = 43, ["z"] = 8, ["name"] = "default:tree"}, {["x"] = 10, ["param2"] = 3, ["y"] = 4, ["param1"] = 43, ["z"] = 9, ["name"] = "default:tree"}, {["x"] = 10, ["y"] = 7, ["param1"] = 13, ["z"] = 6, ["name"] = "default:aspen_leaves"}, {["x"] = 10, ["y"] = 7, ["param1"] = 14, ["z"] = 7, ["name"] = "default:aspen_leaves"}, {["x"] = 10, ["param2"] = 12, ["y"] = 7, ["z"] = 10, ["name"] = "default:tree"}, {["x"] = 10, ["y"] = 7, ["param1"] = 11, ["z"] = 11, ["name"] = "default:aspen_leaves"}, {["x"] = 10, ["y"] = 8, ["param1"] = 14, ["z"] = 2, ["name"] = "default:aspen_leaves"}, {["x"] = 10, ["y"] = 8, ["param1"] = 14, ["z"] = 3, ["name"] = "default:aspen_leaves"}, {["x"] = 10, ["y"] = 8, ["param1"] = 14, ["z"] = 4, ["name"] = "default:aspen_leaves"}, {["x"] = 10, ["y"] = 8, ["param1"] = 13, ["z"] = 6, ["name"] = "default:aspen_leaves"}, {["x"] = 10, ["y"] = 8, ["param1"] = 14, ["z"] = 7, ["name"] = "default:aspen_leaves"}, {["x"] = 10, ["param2"] = 21, ["y"] = 8, ["z"] = 12, ["name"] = "default:tree"}, {["x"] = 10, ["y"] = 8, ["param1"] = 12, ["z"] = 15, ["name"] = "default:aspen_leaves"}, {["x"] = 10, ["y"] = 8, ["param1"] = 13, ["z"] = 16, ["name"] = "default:aspen_leaves"}, {["x"] = 10, ["y"] = 8, ["param1"] = 14, ["z"] = 17, ["name"] = "default:aspen_leaves"}, {["x"] = 10, ["y"] = 9, ["param1"] = 13, ["z"] = 5, ["name"] = "default:aspen_leaves"}, {["x"] = 10, ["y"] = 9, ["param1"] = 13, ["z"] = 6, ["name"] = "default:aspen_leaves"}, {["x"] = 10, ["y"] = 9, ["param1"] = 14, ["z"] = 7, ["name"] = "default:aspen_leaves"}, {["x"] = 10, ["param2"] = 2, ["y"] = 9, ["z"] = 12, ["name"] = "default:tree"}, {["x"] = 10, ["param2"] = 7, ["y"] = 9, ["z"] = 13, ["name"] = "default:tree"}, {["x"] = 10, ["param2"] = 7, ["y"] = 9, ["z"] = 14, ["name"] = "default:tree"}, {["x"] = 10, ["param2"] = 7, ["y"] = 9, ["z"] = 15, ["name"] = "default:tree"}, {["x"] = 10, ["y"] = 9, ["param1"] = 13, ["z"] = 16, ["name"] = "default:aspen_leaves"}, {["x"] = 10, ["y"] = 9, ["param1"] = 14, ["z"] = 17, ["name"] = "default:aspen_leaves"}, {["x"] = 10, ["y"] = 10, ["param1"] = 11, ["z"] = 13, ["name"] = "default:aspen_leaves"}, {["x"] = 10, ["y"] = 10, ["param1"] = 12, ["z"] = 14, ["name"] = "default:aspen_leaves"}, {["x"] = 10, ["y"] = 10, ["param1"] = 13, ["z"] = 15, ["name"] = "default:aspen_leaves"}, {["x"] = 10, ["y"] = 10, ["param1"] = 13, ["z"] = 16, ["name"] = "default:aspen_leaves"}, {["x"] = 10, ["y"] = 10, ["param1"] = 14, ["z"] = 17, ["name"] = "default:aspen_leaves"}, {["x"] = 10, ["y"] = 11, ["param1"] = 13, ["z"] = 14, ["name"] = "default:aspen_leaves"}, {["x"] = 10, ["y"] = 11, ["param1"] = 14, ["z"] = 15, ["name"] = "default:aspen_leaves"}, {["x"] = 10, ["y"] = 11, ["param1"] = 14, ["z"] = 16, ["name"] = "default:aspen_leaves"}, {["x"] = 10, ["y"] = 12, ["param1"] = 13, ["z"] = 6, ["name"] = "default:aspen_leaves"}, {["x"] = 10, ["y"] = 13, ["param1"] = 13, ["z"] = 5, ["name"] = "default:aspen_leaves"}, {["x"] = 10, ["y"] = 13, ["param1"] = 14, ["z"] = 6, ["name"] = "default:aspen_leaves"}, {["x"] = 10, ["y"] = 13, ["param1"] = 14, ["z"] = 7, ["name"] = "default:aspen_leaves"}, {["x"] = 10, ["param2"] = 12, ["y"] = 13, ["z"] = 10, ["name"] = "default:tree"}, {["x"] = 10, ["y"] = 14, ["param1"] = 14, ["z"] = 4, ["name"] = "default:aspen_leaves"}, {["x"] = 10, ["y"] = 14, ["param1"] = 14, ["z"] = 5, ["name"] = "default:aspen_leaves"}, {["x"] = 10, ["y"] = 14, ["param1"] = 14, ["z"] = 7, ["name"] = "default:aspen_leaves"}, {["x"] = 10, ["y"] = 15, ["param1"] = 14, ["z"] = 5, ["name"] = "default:aspen_leaves"}, {["x"] = 10, ["y"] = 16, ["param1"] = 14, ["z"] = 9, ["name"] = "default:aspen_leaves"}, {["x"] = 10, ["y"] = 16, ["param1"] = 13, ["z"] = 10, ["name"] = "default:aspen_leaves"}, {["x"] = 10, ["param2"] = 12, ["y"] = 16, ["z"] = 12, ["name"] = "default:tree"}, {["x"] = 10, ["y"] = 16, ["param1"] = 14, ["z"] = 14, ["name"] = "default:aspen_leaves"}, {["x"] = 10, ["y"] = 17, ["param1"] = 14, ["z"] = 9, ["name"] = "default:aspen_leaves"}, {["x"] = 10, ["y"] = 17, ["param1"] = 14, ["z"] = 10, ["name"] = "default:aspen_leaves"}, {["x"] = 10, ["y"] = 17, ["param1"] = 14, ["z"] = 11, ["name"] = "default:aspen_leaves"}, {["x"] = 10, ["y"] = 17, ["param1"] = 13, ["z"] = 12, ["name"] = "default:aspen_leaves"}, {["x"] = 10, ["y"] = 17, ["param1"] = 14, ["z"] = 13, ["name"] = "default:aspen_leaves"}, {["x"] = 10, ["y"] = 18, ["param1"] = 14, ["z"] = 12, ["name"] = "default:aspen_leaves"}, {["x"] = 11, ["y"] = 6, ["param1"] = 13, ["z"] = 10, ["name"] = "default:aspen_leaves"}, {["x"] = 11, ["y"] = 6, ["param1"] = 12, ["z"] = 11, ["name"] = "default:aspen_leaves"}, {["x"] = 11, ["y"] = 7, ["param1"] = 13, ["z"] = 2, ["name"] = "default:aspen_leaves"}, {["x"] = 11, ["y"] = 7, ["param1"] = 13, ["z"] = 3, ["name"] = "default:aspen_leaves"}, {["x"] = 11, ["y"] = 7, ["param1"] = 13, ["z"] = 7, ["name"] = "default:aspen_leaves"}, {["x"] = 11, ["param2"] = 20, ["y"] = 7, ["z"] = 8, ["name"] = "default:tree"}, {["x"] = 11, ["param2"] = 9, ["y"] = 7, ["z"] = 9, ["name"] = "default:tree"}, {["x"] = 11, ["param2"] = 7, ["y"] = 7, ["z"] = 10, ["name"] = "default:tree"}, {["x"] = 11, ["y"] = 7, ["param1"] = 12, ["z"] = 11, ["name"] = "default:aspen_leaves"}, {["x"] = 11, ["y"] = 7, ["param1"] = 11, ["z"] = 12, ["name"] = "default:aspen_leaves"}, {["x"] = 11, ["y"] = 8, ["param1"] = 14, ["z"] = 1, ["name"] = "default:aspen_leaves"}, {["x"] = 11, ["y"] = 8, ["param1"] = 14, ["z"] = 2, ["name"] = "default:aspen_leaves"}, {["x"] = 11, ["y"] = 8, ["param1"] = 13, ["z"] = 3, ["name"] = "default:aspen_leaves"}, {["x"] = 11, ["y"] = 8, ["param1"] = 13, ["z"] = 4, ["name"] = "default:aspen_leaves"}, {["x"] = 11, ["y"] = 8, ["param1"] = 12, ["z"] = 5, ["name"] = "default:aspen_leaves"}, {["x"] = 11, ["y"] = 8, ["param1"] = 12, ["z"] = 6, ["name"] = "default:aspen_leaves"}, {["x"] = 11, ["y"] = 8, ["param1"] = 13, ["z"] = 7, ["name"] = "default:aspen_leaves"}, {["x"] = 11, ["y"] = 8, ["z"] = 8, ["name"] = "default:tree"}, {["x"] = 11, ["y"] = 8, ["param1"] = 13, ["z"] = 10, ["name"] = "default:aspen_leaves"}, {["x"] = 11, ["y"] = 8, ["param1"] = 12, ["z"] = 11, ["name"] = "default:aspen_leaves"}, {["x"] = 11, ["y"] = 8, ["param1"] = 12, ["z"] = 15, ["name"] = "default:aspen_leaves"}, {["x"] = 11, ["y"] = 8, ["param1"] = 13, ["z"] = 16, ["name"] = "default:aspen_leaves"}, {["x"] = 11, ["y"] = 9, ["param1"] = 14, ["z"] = 3, ["name"] = "default:aspen_leaves"}, {["x"] = 11, ["y"] = 9, ["param1"] = 13, ["z"] = 4, ["name"] = "default:aspen_leaves"}, {["x"] = 11, ["y"] = 9, ["param1"] = 12, ["z"] = 5, ["name"] = "default:aspen_leaves"}, {["x"] = 11, ["param2"] = 12, ["y"] = 9, ["z"] = 13, ["name"] = "default:tree"}, {["x"] = 11, ["y"] = 9, ["param1"] = 12, ["z"] = 15, ["name"] = "default:aspen_leaves"}, {["x"] = 11, ["y"] = 9, ["param1"] = 13, ["z"] = 16, ["name"] = "default:aspen_leaves"}, {["x"] = 11, ["y"] = 9, ["param1"] = 14, ["z"] = 17, ["name"] = "default:aspen_leaves"}, {["x"] = 11, ["y"] = 10, ["param1"] = 13, ["z"] = 4, ["name"] = "default:aspen_leaves"}, {["x"] = 11, ["y"] = 10, ["param1"] = 12, ["z"] = 5, ["name"] = "default:aspen_leaves"}, {["x"] = 11, ["y"] = 10, ["param1"] = 11, ["z"] = 13, ["name"] = "default:aspen_leaves"}, {["x"] = 11, ["y"] = 10, ["param1"] = 13, ["z"] = 15, ["name"] = "default:aspen_leaves"}, {["x"] = 11, ["y"] = 10, ["param1"] = 14, ["z"] = 16, ["name"] = "default:aspen_leaves"}, {["x"] = 11, ["y"] = 11, ["param1"] = 14, ["z"] = 15, ["name"] = "default:aspen_leaves"}, {["x"] = 11, ["y"] = 12, ["param1"] = 12, ["z"] = 5, ["name"] = "default:aspen_leaves"}, {["x"] = 11, ["y"] = 12, ["param1"] = 12, ["z"] = 6, ["name"] = "default:aspen_leaves"}, {["x"] = 11, ["y"] = 12, ["param1"] = 13, ["z"] = 7, ["name"] = "default:aspen_leaves"}, {["x"] = 11, ["y"] = 12, ["param1"] = 14, ["z"] = 8, ["name"] = "default:aspen_leaves"}, {["x"] = 11, ["y"] = 13, ["param1"] = 14, ["z"] = 3, ["name"] = "default:aspen_leaves"}, {["x"] = 11, ["y"] = 13, ["param1"] = 13, ["z"] = 4, ["name"] = "default:aspen_leaves"}, {["x"] = 11, ["y"] = 13, ["param1"] = 12, ["z"] = 5, ["name"] = "default:aspen_leaves"}, {["x"] = 11, ["y"] = 13, ["param1"] = 13, ["z"] = 6, ["name"] = "default:aspen_leaves"}, {["x"] = 11, ["param2"] = 9, ["y"] = 13, ["z"] = 7, ["name"] = "default:tree"}, {["x"] = 11, ["param2"] = 9, ["y"] = 13, ["z"] = 8, ["name"] = "default:tree"}, {["x"] = 11, ["param2"] = 9, ["y"] = 13, ["z"] = 9, ["name"] = "default:tree"}, {["x"] = 11, ["param2"] = 12, ["y"] = 13, ["z"] = 10, ["name"] = "default:tree"}, {["x"] = 11, ["y"] = 14, ["param1"] = 14, ["z"] = 3, ["name"] = "default:aspen_leaves"}, {["x"] = 11, ["y"] = 14, ["param1"] = 13, ["z"] = 4, ["name"] = "default:aspen_leaves"}, {["x"] = 11, ["param2"] = 9, ["y"] = 14, ["z"] = 5, ["name"] = "default:tree"}, {["x"] = 11, ["param2"] = 9, ["y"] = 14, ["z"] = 6, ["name"] = "default:tree"}, {["x"] = 11, ["y"] = 14, ["z"] = 7, ["name"] = "default:tree"}, {["x"] = 11, ["y"] = 14, ["param1"] = 14, ["z"] = 8, ["name"] = "default:aspen_leaves"}, {["x"] = 11, ["y"] = 15, ["param1"] = 14, ["z"] = 4, ["name"] = "default:aspen_leaves"}, {["x"] = 11, ["y"] = 15, ["param1"] = 14, ["z"] = 5, ["name"] = "default:aspen_leaves"}, {["x"] = 11, ["y"] = 15, ["param1"] = 14, ["z"] = 6, ["name"] = "default:aspen_leaves"}, {["x"] = 11, ["y"] = 15, ["param1"] = 14, ["z"] = 7, ["name"] = "default:aspen_leaves"}, {["x"] = 11, ["y"] = 15, ["param1"] = 14, ["z"] = 8, ["name"] = "default:aspen_leaves"}, {["x"] = 11, ["y"] = 15, ["param1"] = 12, ["z"] = 12, ["name"] = "default:aspen_leaves"}, {["x"] = 11, ["y"] = 15, ["param1"] = 13, ["z"] = 13, ["name"] = "default:aspen_leaves"}, {["x"] = 11, ["y"] = 16, ["param1"] = 14, ["z"] = 6, ["name"] = "default:aspen_leaves"}, {["x"] = 11, ["y"] = 16, ["param1"] = 14, ["z"] = 7, ["name"] = "default:aspen_leaves"}, {["x"] = 11, ["y"] = 16, ["param1"] = 14, ["z"] = 10, ["name"] = "default:aspen_leaves"}, {["x"] = 11, ["y"] = 16, ["param1"] = 13, ["z"] = 11, ["name"] = "default:aspen_leaves"}, {["x"] = 11, ["param2"] = 12, ["y"] = 16, ["z"] = 12, ["name"] = "default:tree"}, {["x"] = 11, ["y"] = 16, ["param1"] = 13, ["z"] = 13, ["name"] = "default:aspen_leaves"}, {["x"] = 11, ["y"] = 17, ["param1"] = 14, ["z"] = 10, ["name"] = "default:aspen_leaves"}, {["x"] = 11, ["y"] = 17, ["param1"] = 13, ["z"] = 11, ["name"] = "default:aspen_leaves"}, {["x"] = 11, ["y"] = 17, ["param1"] = 13, ["z"] = 12, ["name"] = "default:aspen_leaves"}, {["x"] = 11, ["y"] = 17, ["param1"] = 13, ["z"] = 13, ["name"] = "default:aspen_leaves"}, {["x"] = 11, ["y"] = 17, ["param1"] = 14, ["z"] = 14, ["name"] = "default:aspen_leaves"}, {["x"] = 11, ["y"] = 18, ["param1"] = 14, ["z"] = 11, ["name"] = "default:aspen_leaves"}, {["x"] = 11, ["y"] = 18, ["param1"] = 14, ["z"] = 12, ["name"] = "default:aspen_leaves"}, {["x"] = 11, ["y"] = 18, ["param1"] = 14, ["z"] = 13, ["name"] = "default:aspen_leaves"}, {["x"] = 12, ["y"] = 7, ["param1"] = 13, ["z"] = 1, ["name"] = "default:aspen_leaves"}, {["x"] = 12, ["y"] = 7, ["param1"] = 12, ["z"] = 2, ["name"] = "default:aspen_leaves"}, {["x"] = 12, ["y"] = 7, ["param1"] = 12, ["z"] = 3, ["name"] = "default:aspen_leaves"}, {["x"] = 12, ["y"] = 7, ["param1"] = 12, ["z"] = 4, ["name"] = "default:aspen_leaves"}, {["x"] = 12, ["y"] = 7, ["param1"] = 14, ["z"] = 10, ["name"] = "default:aspen_leaves"}, {["x"] = 12, ["y"] = 7, ["param1"] = 13, ["z"] = 11, ["name"] = "default:aspen_leaves"}, {["x"] = 12, ["y"] = 8, ["param1"] = 14, ["z"] = 0, ["name"] = "default:aspen_leaves"}, {["x"] = 12, ["y"] = 8, ["param1"] = 13, ["z"] = 1, ["name"] = "default:aspen_leaves"}, {["x"] = 12, ["y"] = 8, ["param1"] = 13, ["z"] = 2, ["name"] = "default:aspen_leaves"}, {["x"] = 12, ["param2"] = 9, ["y"] = 8, ["z"] = 3, ["name"] = "default:tree"}, {["x"] = 12, ["param2"] = 9, ["y"] = 8, ["z"] = 4, ["name"] = "default:tree"}, {["x"] = 12, ["param2"] = 9, ["y"] = 8, ["z"] = 5, ["name"] = "default:tree"}, {["x"] = 12, ["param2"] = 9, ["y"] = 8, ["z"] = 6, ["name"] = "default:tree"}, {["x"] = 12, ["param2"] = 9, ["y"] = 8, ["z"] = 7, ["name"] = "default:tree"}, {["x"] = 12, ["param2"] = 12, ["y"] = 8, ["z"] = 8, ["name"] = "default:tree"}, {["x"] = 12, ["y"] = 8, ["param1"] = 13, ["z"] = 16, ["name"] = "default:aspen_leaves"}, {["x"] = 12, ["y"] = 9, ["param1"] = 14, ["z"] = 1, ["name"] = "default:aspen_leaves"}, {["x"] = 12, ["y"] = 9, ["param1"] = 14, ["z"] = 2, ["name"] = "default:aspen_leaves"}, {["x"] = 12, ["y"] = 9, ["param1"] = 13, ["z"] = 3, ["name"] = "default:aspen_leaves"}, {["x"] = 12, ["y"] = 9, ["param1"] = 12, ["z"] = 4, ["name"] = "default:aspen_leaves"}, {["x"] = 12, ["param2"] = 3, ["y"] = 9, ["z"] = 5, ["name"] = "default:tree"}, {["x"] = 12, ["param2"] = 12, ["y"] = 9, ["z"] = 13, ["name"] = "default:tree"}, {["x"] = 12, ["y"] = 9, ["param1"] = 12, ["z"] = 15, ["name"] = "default:aspen_leaves"}, {["x"] = 12, ["y"] = 9, ["param1"] = 13, ["z"] = 16, ["name"] = "default:aspen_leaves"}, {["x"] = 12, ["y"] = 9, ["param1"] = 14, ["z"] = 17, ["name"] = "default:aspen_leaves"}, {["x"] = 12, ["y"] = 10, ["param1"] = 14, ["z"] = 3, ["name"] = "default:aspen_leaves"}, {["x"] = 12, ["y"] = 10, ["param1"] = 13, ["z"] = 4, ["name"] = "default:aspen_leaves"}, {["x"] = 12, ["y"] = 10, ["param1"] = 12, ["z"] = 5, ["name"] = "default:aspen_leaves"}, {["x"] = 12, ["y"] = 10, ["param1"] = 12, ["z"] = 6, ["name"] = "default:aspen_leaves"}, {["x"] = 12, ["y"] = 10, ["param1"] = 11, ["z"] = 13, ["name"] = "default:aspen_leaves"}, {["x"] = 12, ["y"] = 10, ["param1"] = 12, ["z"] = 14, ["name"] = "default:aspen_leaves"}, {["x"] = 12, ["y"] = 10, ["param1"] = 13, ["z"] = 15, ["name"] = "default:aspen_leaves"}, {["x"] = 12, ["y"] = 10, ["param1"] = 13, ["z"] = 16, ["name"] = "default:aspen_leaves"}, {["x"] = 12, ["y"] = 10, ["param1"] = 14, ["z"] = 17, ["name"] = "default:aspen_leaves"}, {["x"] = 12, ["y"] = 11, ["param1"] = 13, ["z"] = 4, ["name"] = "default:aspen_leaves"}, {["x"] = 12, ["y"] = 11, ["param1"] = 12, ["z"] = 5, ["name"] = "default:aspen_leaves"}, {["x"] = 12, ["y"] = 11, ["param1"] = 12, ["z"] = 13, ["name"] = "default:aspen_leaves"}, {["x"] = 12, ["y"] = 11, ["param1"] = 13, ["z"] = 14, ["name"] = "default:aspen_leaves"}, {["x"] = 12, ["y"] = 11, ["param1"] = 14, ["z"] = 15, ["name"] = "default:aspen_leaves"}, {["x"] = 12, ["y"] = 11, ["param1"] = 14, ["z"] = 16, ["name"] = "default:aspen_leaves"}, {["x"] = 12, ["y"] = 11, ["param1"] = 14, ["z"] = 17, ["name"] = "default:aspen_leaves"}, {["x"] = 12, ["y"] = 12, ["param1"] = 13, ["z"] = 4, ["name"] = "default:aspen_leaves"}, {["x"] = 12, ["y"] = 12, ["param1"] = 12, ["z"] = 5, ["name"] = "default:aspen_leaves"}, {["x"] = 12, ["y"] = 12, ["param1"] = 12, ["z"] = 6, ["name"] = "default:aspen_leaves"}, {["x"] = 12, ["y"] = 12, ["param1"] = 14, ["z"] = 10, ["name"] = "default:aspen_leaves"}, {["x"] = 12, ["y"] = 13, ["param1"] = 14, ["z"] = 3, ["name"] = "default:aspen_leaves"}, {["x"] = 12, ["y"] = 13, ["param1"] = 13, ["z"] = 4, ["name"] = "default:aspen_leaves"}, {["x"] = 12, ["y"] = 13, ["param1"] = 12, ["z"] = 5, ["name"] = "default:aspen_leaves"}, {["x"] = 12, ["y"] = 13, ["param1"] = 12, ["z"] = 6, ["name"] = "default:aspen_leaves"}, {["x"] = 12, ["y"] = 13, ["param1"] = 13, ["z"] = 7, ["name"] = "default:aspen_leaves"}, {["x"] = 12, ["param2"] = 12, ["y"] = 13, ["z"] = 10, ["name"] = "default:tree"}, {["x"] = 12, ["y"] = 13, ["param1"] = 12, ["z"] = 11, ["name"] = "default:aspen_leaves"}, {["x"] = 12, ["y"] = 14, ["param1"] = 14, ["z"] = 3, ["name"] = "default:aspen_leaves"}, {["x"] = 12, ["y"] = 14, ["param1"] = 13, ["z"] = 4, ["name"] = "default:aspen_leaves"}, {["x"] = 12, ["y"] = 14, ["param1"] = 12, ["z"] = 5, ["name"] = "default:aspen_leaves"}, {["x"] = 12, ["y"] = 14, ["param1"] = 12, ["z"] = 6, ["name"] = "default:aspen_leaves"}, {["x"] = 12, ["param2"] = 12, ["y"] = 14, ["z"] = 7, ["name"] = "default:tree"}, {["x"] = 12, ["y"] = 14, ["param1"] = 14, ["z"] = 8, ["name"] = "default:aspen_leaves"}, {["x"] = 12, ["y"] = 14, ["param1"] = 14, ["z"] = 10, ["name"] = "default:aspen_leaves"}, {["x"] = 12, ["y"] = 15, ["param1"] = 14, ["z"] = 4, ["name"] = "default:aspen_leaves"}, {["x"] = 12, ["y"] = 15, ["param1"] = 13, ["z"] = 5, ["name"] = "default:aspen_leaves"}, {["x"] = 12, ["y"] = 15, ["param1"] = 13, ["z"] = 6, ["name"] = "default:aspen_leaves"}, {["x"] = 12, ["y"] = 15, ["param1"] = 14, ["z"] = 7, ["name"] = "default:aspen_leaves"}, {["x"] = 12, ["y"] = 15, ["param1"] = 14, ["z"] = 11, ["name"] = "default:aspen_leaves"}, {["x"] = 12, ["y"] = 15, ["param1"] = 13, ["z"] = 12, ["name"] = "default:aspen_leaves"}, {["x"] = 12, ["y"] = 15, ["param1"] = 13, ["z"] = 13, ["name"] = "default:aspen_leaves"}, {["x"] = 12, ["y"] = 16, ["param1"] = 14, ["z"] = 5, ["name"] = "default:aspen_leaves"}, {["x"] = 12, ["y"] = 16, ["param1"] = 14, ["z"] = 6, ["name"] = "default:aspen_leaves"}, {["x"] = 12, ["y"] = 16, ["param1"] = 14, ["z"] = 7, ["name"] = "default:aspen_leaves"}, {["x"] = 12, ["y"] = 16, ["param1"] = 14, ["z"] = 11, ["name"] = "default:aspen_leaves"}, {["x"] = 12, ["y"] = 16, ["param1"] = 13, ["z"] = 12, ["name"] = "default:aspen_leaves"}, {["x"] = 12, ["y"] = 16, ["param1"] = 13, ["z"] = 13, ["name"] = "default:aspen_leaves"}, {["x"] = 12, ["y"] = 16, ["param1"] = 14, ["z"] = 14, ["name"] = "default:aspen_leaves"}, {["x"] = 12, ["y"] = 17, ["param1"] = 14, ["z"] = 11, ["name"] = "default:aspen_leaves"}, {["x"] = 12, ["y"] = 17, ["param1"] = 14, ["z"] = 12, ["name"] = "default:aspen_leaves"}, {["x"] = 12, ["y"] = 17, ["param1"] = 14, ["z"] = 13, ["name"] = "default:aspen_leaves"}, {["x"] = 13, ["y"] = 7, ["param1"] = 13, ["z"] = 1, ["name"] = "default:aspen_leaves"}, {["x"] = 13, ["y"] = 7, ["param1"] = 12, ["z"] = 2, ["name"] = "default:aspen_leaves"}, {["x"] = 13, ["y"] = 7, ["param1"] = 11, ["z"] = 3, ["name"] = "default:aspen_leaves"}, {["x"] = 13, ["y"] = 7, ["param1"] = 10, ["z"] = 5, ["name"] = "default:aspen_leaves"}, {["x"] = 13, ["y"] = 8, ["param1"] = 14, ["z"] = 0, ["name"] = "default:aspen_leaves"}, {["x"] = 13, ["y"] = 8, ["param1"] = 13, ["z"] = 1, ["name"] = "default:aspen_leaves"}, {["x"] = 13, ["y"] = 8, ["param1"] = 12, ["z"] = 2, ["name"] = "default:aspen_leaves"}, {["x"] = 13, ["y"] = 8, ["param1"] = 11, ["z"] = 3, ["name"] = "default:aspen_leaves"}, {["x"] = 13, ["y"] = 8, ["param1"] = 10, ["z"] = 4, ["name"] = "default:aspen_leaves"}, {["x"] = 13, ["y"] = 8, ["param1"] = 10, ["z"] = 5, ["name"] = "default:aspen_leaves"}, {["x"] = 13, ["y"] = 8, ["param1"] = 10, ["z"] = 6, ["name"] = "default:aspen_leaves"}, {["x"] = 13, ["param2"] = 12, ["y"] = 8, ["z"] = 8, ["name"] = "default:tree"}, {["x"] = 13, ["y"] = 8, ["param1"] = 11, ["z"] = 13, ["name"] = "default:aspen_leaves"}, {["x"] = 13, ["y"] = 8, ["param1"] = 11, ["z"] = 14, ["name"] = "default:aspen_leaves"}, {["x"] = 13, ["y"] = 8, ["param1"] = 12, ["z"] = 15, ["name"] = "default:aspen_leaves"}, {["x"] = 13, ["y"] = 9, ["param1"] = 14, ["z"] = 0, ["name"] = "default:aspen_leaves"}, {["x"] = 13, ["y"] = 9, ["param1"] = 14, ["z"] = 1, ["name"] = "default:aspen_leaves"}, {["x"] = 13, ["y"] = 9, ["param1"] = 13, ["z"] = 2, ["name"] = "default:aspen_leaves"}, {["x"] = 13, ["y"] = 9, ["param1"] = 12, ["z"] = 3, ["name"] = "default:aspen_leaves"}, {["x"] = 13, ["y"] = 9, ["param1"] = 11, ["z"] = 4, ["name"] = "default:aspen_leaves"}, {["x"] = 13, ["param2"] = 12, ["y"] = 9, ["z"] = 5, ["name"] = "default:tree"}, {["x"] = 13, ["y"] = 9, ["param1"] = 11, ["z"] = 6, ["name"] = "default:aspen_leaves"}, {["x"] = 13, ["param2"] = 12, ["y"] = 9, ["z"] = 13, ["name"] = "default:tree"}, {["x"] = 13, ["y"] = 9, ["param1"] = 11, ["z"] = 14, ["name"] = "default:aspen_leaves"}, {["x"] = 13, ["y"] = 9, ["param1"] = 12, ["z"] = 15, ["name"] = "default:aspen_leaves"}, {["x"] = 13, ["y"] = 9, ["param1"] = 13, ["z"] = 16, ["name"] = "default:aspen_leaves"}, {["x"] = 13, ["y"] = 9, ["param1"] = 14, ["z"] = 17, ["name"] = "default:aspen_leaves"}, {["x"] = 13, ["y"] = 10, ["param1"] = 14, ["z"] = 2, ["name"] = "default:aspen_leaves"}, {["x"] = 13, ["y"] = 10, ["param1"] = 13, ["z"] = 3, ["name"] = "default:aspen_leaves"}, {["x"] = 13, ["y"] = 10, ["param1"] = 12, ["z"] = 4, ["name"] = "default:aspen_leaves"}, {["x"] = 13, ["y"] = 10, ["param1"] = 11, ["z"] = 5, ["name"] = "default:aspen_leaves"}, {["x"] = 13, ["y"] = 10, ["param1"] = 11, ["z"] = 6, ["name"] = "default:aspen_leaves"}, {["x"] = 13, ["y"] = 10, ["param1"] = 12, ["z"] = 7, ["name"] = "default:aspen_leaves"}, {["x"] = 13, ["y"] = 10, ["param1"] = 13, ["z"] = 8, ["name"] = "default:aspen_leaves"}, {["x"] = 13, ["y"] = 10, ["param1"] = 14, ["z"] = 9, ["name"] = "default:aspen_leaves"}, {["x"] = 13, ["y"] = 10, ["param1"] = 12, ["z"] = 12, ["name"] = "default:aspen_leaves"}, {["x"] = 13, ["param2"] = 3, ["y"] = 10, ["z"] = 13, ["name"] = "default:tree"}, {["x"] = 13, ["param2"] = 7, ["y"] = 10, ["z"] = 14, ["name"] = "default:tree"}, {["x"] = 13, ["param2"] = 7, ["y"] = 10, ["z"] = 15, ["name"] = "default:tree"}, {["x"] = 13, ["y"] = 10, ["param1"] = 13, ["z"] = 16, ["name"] = "default:aspen_leaves"}, {["x"] = 13, ["y"] = 10, ["param1"] = 14, ["z"] = 17, ["name"] = "default:aspen_leaves"}, {["x"] = 13, ["y"] = 11, ["param1"] = 13, ["z"] = 4, ["name"] = "default:aspen_leaves"}, {["x"] = 13, ["y"] = 11, ["param1"] = 12, ["z"] = 5, ["name"] = "default:aspen_leaves"}, {["x"] = 13, ["y"] = 11, ["param1"] = 13, ["z"] = 8, ["name"] = "default:aspen_leaves"}, {["x"] = 13, ["y"] = 11, ["param1"] = 13, ["z"] = 13, ["name"] = "default:aspen_leaves"}, {["x"] = 13, ["y"] = 11, ["param1"] = 14, ["z"] = 14, ["name"] = "default:aspen_leaves"}, {["x"] = 13, ["y"] = 11, ["param1"] = 14, ["z"] = 15, ["name"] = "default:aspen_leaves"}, {["x"] = 13, ["y"] = 11, ["param1"] = 14, ["z"] = 16, ["name"] = "default:aspen_leaves"}, {["x"] = 13, ["y"] = 11, ["param1"] = 14, ["z"] = 17, ["name"] = "default:aspen_leaves"}, {["x"] = 13, ["y"] = 12, ["param1"] = 12, ["z"] = 5, ["name"] = "default:aspen_leaves"}, {["x"] = 13, ["y"] = 12, ["param1"] = 13, ["z"] = 10, ["name"] = "default:aspen_leaves"}, {["x"] = 13, ["y"] = 12, ["param1"] = 13, ["z"] = 11, ["name"] = "default:aspen_leaves"}, {["x"] = 13, ["y"] = 13, ["param1"] = 13, ["z"] = 4, ["name"] = "default:aspen_leaves"}, {["x"] = 13, ["y"] = 13, ["param1"] = 12, ["z"] = 5, ["name"] = "default:aspen_leaves"}, {["x"] = 13, ["y"] = 13, ["param1"] = 12, ["z"] = 6, ["name"] = "default:aspen_leaves"}, {["x"] = 13, ["y"] = 13, ["param1"] = 12, ["z"] = 7, ["name"] = "default:aspen_leaves"}, {["x"] = 13, ["y"] = 13, ["param1"] = 14, ["z"] = 9, ["name"] = "default:aspen_leaves"}, {["x"] = 13, ["param2"] = 12, ["y"] = 13, ["z"] = 10, ["name"] = "default:tree"}, {["x"] = 13, ["y"] = 13, ["param1"] = 13, ["z"] = 11, ["name"] = "default:aspen_leaves"}, {["x"] = 13, ["y"] = 14, ["param1"] = 14, ["z"] = 3, ["name"] = "default:aspen_leaves"}, {["x"] = 13, ["y"] = 14, ["param1"] = 13, ["z"] = 4, ["name"] = "default:aspen_leaves"}, {["x"] = 13, ["y"] = 14, ["param1"] = 13, ["z"] = 5, ["name"] = "default:aspen_leaves"}, {["x"] = 13, ["y"] = 14, ["param1"] = 12, ["z"] = 6, ["name"] = "default:aspen_leaves"}, {["x"] = 13, ["param2"] = 12, ["y"] = 14, ["z"] = 7, ["name"] = "default:tree"}, {["x"] = 13, ["y"] = 14, ["param1"] = 13, ["z"] = 8, ["name"] = "default:aspen_leaves"}, {["x"] = 13, ["y"] = 14, ["param1"] = 14, ["z"] = 9, ["name"] = "default:aspen_leaves"}, {["x"] = 13, ["y"] = 14, ["param1"] = 13, ["z"] = 10, ["name"] = "default:aspen_leaves"}, {["x"] = 13, ["y"] = 14, ["param1"] = 14, ["z"] = 11, ["name"] = "default:aspen_leaves"}, {["x"] = 13, ["y"] = 15, ["param1"] = 14, ["z"] = 4, ["name"] = "default:aspen_leaves"}, {["x"] = 13, ["y"] = 15, ["param1"] = 14, ["z"] = 5, ["name"] = "default:aspen_leaves"}, {["x"] = 13, ["y"] = 15, ["param1"] = 13, ["z"] = 6, ["name"] = "default:aspen_leaves"}, {["x"] = 13, ["y"] = 15, ["param1"] = 14, ["z"] = 7, ["name"] = "default:aspen_leaves"}, {["x"] = 13, ["y"] = 15, ["param1"] = 14, ["z"] = 8, ["name"] = "default:aspen_leaves"}, {["x"] = 13, ["y"] = 15, ["param1"] = 14, ["z"] = 10, ["name"] = "default:aspen_leaves"}, {["x"] = 13, ["y"] = 16, ["param1"] = 14, ["z"] = 6, ["name"] = "default:aspen_leaves"}, {["x"] = 13, ["y"] = 16, ["param1"] = 14, ["z"] = 12, ["name"] = "default:aspen_leaves"}, {["x"] = 13, ["y"] = 16, ["param1"] = 14, ["z"] = 13, ["name"] = "default:aspen_leaves"}, {["x"] = 14, ["y"] = 7, ["param1"] = 12, ["z"] = 2, ["name"] = "default:aspen_leaves"}, {["x"] = 14, ["y"] = 7, ["param1"] = 12, ["z"] = 3, ["name"] = "default:aspen_leaves"}, {["x"] = 14, ["y"] = 7, ["param1"] = 11, ["z"] = 7, ["name"] = "default:aspen_leaves"}, {["x"] = 14, ["y"] = 7, ["param1"] = 12, ["z"] = 8, ["name"] = "default:aspen_leaves"}, {["x"] = 14, ["y"] = 8, ["param1"] = 13, ["z"] = 1, ["name"] = "default:aspen_leaves"}, {["x"] = 14, ["y"] = 8, ["param1"] = 13, ["z"] = 2, ["name"] = "default:aspen_leaves"}, {["x"] = 14, ["y"] = 8, ["param1"] = 12, ["z"] = 3, ["name"] = "default:aspen_leaves"}, {["x"] = 14, ["y"] = 8, ["param1"] = 11, ["z"] = 4, ["name"] = "default:aspen_leaves"}, {["x"] = 14, ["y"] = 8, ["param1"] = 11, ["z"] = 5, ["name"] = "default:aspen_leaves"}, {["x"] = 14, ["y"] = 8, ["param1"] = 11, ["z"] = 6, ["name"] = "default:aspen_leaves"}, {["x"] = 14, ["y"] = 8, ["param1"] = 11, ["z"] = 7, ["name"] = "default:aspen_leaves"}, {["x"] = 14, ["param2"] = 12, ["y"] = 8, ["z"] = 8, ["name"] = "default:tree"}, {["x"] = 14, ["y"] = 8, ["param1"] = 12, ["z"] = 13, ["name"] = "default:aspen_leaves"}, {["x"] = 14, ["y"] = 8, ["param1"] = 11, ["z"] = 14, ["name"] = "default:aspen_leaves"}, {["x"] = 14, ["y"] = 9, ["param1"] = 14, ["z"] = 0, ["name"] = "default:aspen_leaves"}, {["x"] = 14, ["y"] = 9, ["param1"] = 14, ["z"] = 1, ["name"] = "default:aspen_leaves"}, {["x"] = 14, ["y"] = 9, ["param1"] = 14, ["z"] = 2, ["name"] = "default:aspen_leaves"}, {["x"] = 14, ["y"] = 9, ["param1"] = 13, ["z"] = 3, ["name"] = "default:aspen_leaves"}, {["x"] = 14, ["y"] = 9, ["param1"] = 12, ["z"] = 4, ["name"] = "default:aspen_leaves"}, {["x"] = 14, ["param2"] = 12, ["y"] = 9, ["z"] = 5, ["name"] = "default:tree"}, {["x"] = 14, ["y"] = 9, ["param1"] = 11, ["z"] = 6, ["name"] = "default:aspen_leaves"}, {["x"] = 14, ["y"] = 9, ["param1"] = 11, ["z"] = 7, ["name"] = "default:aspen_leaves"}, {["x"] = 14, ["param2"] = 3, ["y"] = 9, ["z"] = 8, ["name"] = "default:tree"}, {["x"] = 14, ["y"] = 9, ["param1"] = 13, ["z"] = 9, ["name"] = "default:aspen_leaves"}, {["x"] = 14, ["y"] = 9, ["param1"] = 13, ["z"] = 12, ["name"] = "default:aspen_leaves"}, {["x"] = 14, ["y"] = 9, ["param1"] = 12, ["z"] = 13, ["name"] = "default:aspen_leaves"}, {["x"] = 14, ["y"] = 9, ["param1"] = 12, ["z"] = 14, ["name"] = "default:aspen_leaves"}, {["x"] = 14, ["y"] = 9, ["param1"] = 13, ["z"] = 15, ["name"] = "default:aspen_leaves"}, {["x"] = 14, ["y"] = 9, ["param1"] = 13, ["z"] = 16, ["name"] = "default:aspen_leaves"}, {["x"] = 14, ["y"] = 10, ["param1"] = 14, ["z"] = 3, ["name"] = "default:aspen_leaves"}, {["x"] = 14, ["y"] = 10, ["param1"] = 13, ["z"] = 4, ["name"] = "default:aspen_leaves"}, {["x"] = 14, ["y"] = 10, ["param1"] = 12, ["z"] = 5, ["name"] = "default:aspen_leaves"}, {["x"] = 14, ["y"] = 10, ["param1"] = 12, ["z"] = 6, ["name"] = "default:aspen_leaves"}, {["x"] = 14, ["y"] = 10, ["param1"] = 12, ["z"] = 7, ["name"] = "default:aspen_leaves"}, {["x"] = 14, ["y"] = 10, ["param1"] = 12, ["z"] = 8, ["name"] = "default:aspen_leaves"}, {["x"] = 14, ["y"] = 10, ["param1"] = 13, ["z"] = 9, ["name"] = "default:aspen_leaves"}, {["x"] = 14, ["param2"] = 12, ["y"] = 10, ["z"] = 13, ["name"] = "default:tree"}, {["x"] = 14, ["y"] = 10, ["param1"] = 13, ["z"] = 14, ["name"] = "default:aspen_leaves"}, {["x"] = 14, ["y"] = 10, ["param1"] = 14, ["z"] = 15, ["name"] = "default:aspen_leaves"}, {["x"] = 14, ["y"] = 10, ["param1"] = 13, ["z"] = 16, ["name"] = "default:aspen_leaves"}, {["x"] = 14, ["y"] = 10, ["param1"] = 14, ["z"] = 17, ["name"] = "default:aspen_leaves"}, {["x"] = 14, ["y"] = 11, ["param1"] = 13, ["z"] = 7, ["name"] = "default:aspen_leaves"}, {["x"] = 14, ["y"] = 11, ["param1"] = 13, ["z"] = 8, ["name"] = "default:aspen_leaves"}, {["x"] = 14, ["y"] = 11, ["param1"] = 14, ["z"] = 12, ["name"] = "default:aspen_leaves"}, {["x"] = 14, ["y"] = 11, ["param1"] = 14, ["z"] = 13, ["name"] = "default:aspen_leaves"}, {["x"] = 14, ["y"] = 11, ["param1"] = 14, ["z"] = 14, ["name"] = "default:aspen_leaves"}, {["x"] = 14, ["y"] = 11, ["param1"] = 14, ["z"] = 16, ["name"] = "default:aspen_leaves"}, {["x"] = 14, ["y"] = 12, ["param1"] = 14, ["z"] = 9, ["name"] = "default:aspen_leaves"}, {["x"] = 14, ["y"] = 12, ["param1"] = 13, ["z"] = 10, ["name"] = "default:aspen_leaves"}, {["x"] = 14, ["y"] = 13, ["param1"] = 13, ["z"] = 5, ["name"] = "default:aspen_leaves"}, {["x"] = 14, ["y"] = 13, ["param1"] = 13, ["z"] = 6, ["name"] = "default:aspen_leaves"}, {["x"] = 14, ["y"] = 13, ["param1"] = 13, ["z"] = 7, ["name"] = "default:aspen_leaves"}, {["x"] = 14, ["y"] = 13, ["param1"] = 14, ["z"] = 9, ["name"] = "default:aspen_leaves"}, {["x"] = 14, ["y"] = 13, ["param1"] = 13, ["z"] = 10, ["name"] = "default:aspen_leaves"}, {["x"] = 14, ["y"] = 13, ["param1"] = 14, ["z"] = 11, ["name"] = "default:aspen_leaves"}, {["x"] = 14, ["y"] = 14, ["param1"] = 14, ["z"] = 4, ["name"] = "default:aspen_leaves"}, {["x"] = 14, ["y"] = 14, ["param1"] = 13, ["z"] = 5, ["name"] = "default:aspen_leaves"}, {["x"] = 14, ["y"] = 14, ["param1"] = 13, ["z"] = 6, ["name"] = "default:aspen_leaves"}, {["x"] = 14, ["y"] = 14, ["param1"] = 13, ["z"] = 7, ["name"] = "default:aspen_leaves"}, {["x"] = 14, ["y"] = 14, ["param1"] = 14, ["z"] = 8, ["name"] = "default:aspen_leaves"}, {["x"] = 14, ["y"] = 14, ["param1"] = 14, ["z"] = 10, ["name"] = "default:aspen_leaves"}, {["x"] = 14, ["y"] = 15, ["param1"] = 14, ["z"] = 5, ["name"] = "default:aspen_leaves"}, {["x"] = 14, ["y"] = 15, ["param1"] = 14, ["z"] = 6, ["name"] = "default:aspen_leaves"}, {["x"] = 14, ["y"] = 15, ["param1"] = 14, ["z"] = 7, ["name"] = "default:aspen_leaves"}, {["x"] = 15, ["y"] = 7, ["param1"] = 12, ["z"] = 5, ["name"] = "default:aspen_leaves"}, {["x"] = 15, ["y"] = 7, ["param1"] = 12, ["z"] = 6, ["name"] = "default:aspen_leaves"}, {["x"] = 15, ["y"] = 7, ["param1"] = 12, ["z"] = 7, ["name"] = "default:aspen_leaves"}, {["x"] = 15, ["y"] = 7, ["param1"] = 12, ["z"] = 8, ["name"] = "default:aspen_leaves"}, {["x"] = 15, ["y"] = 7, ["param1"] = 13, ["z"] = 9, ["name"] = "default:aspen_leaves"}, {["x"] = 15, ["y"] = 8, ["param1"] = 14, ["z"] = 1, ["name"] = "default:aspen_leaves"}, {["x"] = 15, ["y"] = 8, ["param1"] = 13, ["z"] = 2, ["name"] = "default:aspen_leaves"}, {["x"] = 15, ["y"] = 8, ["param1"] = 13, ["z"] = 3, ["name"] = "default:aspen_leaves"}, {["x"] = 15, ["y"] = 8, ["param1"] = 12, ["z"] = 4, ["name"] = "default:aspen_leaves"}, {["x"] = 15, ["y"] = 8, ["param1"] = 12, ["z"] = 5, ["name"] = "default:aspen_leaves"}, {["x"] = 15, ["y"] = 8, ["param1"] = 12, ["z"] = 6, ["name"] = "default:aspen_leaves"}, {["x"] = 15, ["y"] = 8, ["param1"] = 12, ["z"] = 7, ["name"] = "default:aspen_leaves"}, {["x"] = 15, ["y"] = 8, ["param1"] = 12, ["z"] = 8, ["name"] = "default:aspen_leaves"}, {["x"] = 15, ["y"] = 8, ["param1"] = 13, ["z"] = 9, ["name"] = "default:aspen_leaves"}, {["x"] = 15, ["y"] = 8, ["param1"] = 13, ["z"] = 13, ["name"] = "default:aspen_leaves"}, {["x"] = 15, ["y"] = 9, ["param1"] = 14, ["z"] = 2, ["name"] = "default:aspen_leaves"}, {["x"] = 15, ["y"] = 9, ["param1"] = 13, ["z"] = 3, ["name"] = "default:aspen_leaves"}, {["x"] = 15, ["y"] = 9, ["param1"] = 13, ["z"] = 4, ["name"] = "default:aspen_leaves"}, {["x"] = 15, ["y"] = 9, ["param1"] = 13, ["z"] = 5, ["name"] = "default:aspen_leaves"}, {["x"] = 15, ["y"] = 9, ["param1"] = 12, ["z"] = 6, ["name"] = "default:aspen_leaves"}, {["x"] = 15, ["y"] = 9, ["param1"] = 12, ["z"] = 7, ["name"] = "default:aspen_leaves"}, {["x"] = 15, ["param2"] = 12, ["y"] = 9, ["param1"] = 43, ["z"] = 8, ["name"] = "default:tree"}, {["x"] = 15, ["y"] = 9, ["param1"] = 13, ["z"] = 9, ["name"] = "default:aspen_leaves"}, {["x"] = 15, ["y"] = 9, ["param1"] = 14, ["z"] = 10, ["name"] = "default:aspen_leaves"}, {["x"] = 15, ["y"] = 9, ["param1"] = 14, ["z"] = 12, ["name"] = "default:aspen_leaves"}, {["x"] = 15, ["y"] = 9, ["param1"] = 13, ["z"] = 13, ["name"] = "default:aspen_leaves"}, {["x"] = 15, ["y"] = 9, ["param1"] = 12, ["z"] = 14, ["name"] = "default:aspen_leaves"}, {["x"] = 15, ["y"] = 9, ["param1"] = 13, ["z"] = 15, ["name"] = "default:aspen_leaves"}, {["x"] = 15, ["y"] = 10, ["param1"] = 14, ["z"] = 3, ["name"] = "default:aspen_leaves"}, {["x"] = 15, ["y"] = 10, ["param1"] = 14, ["z"] = 4, ["name"] = "default:aspen_leaves"}, {["x"] = 15, ["y"] = 10, ["param1"] = 13, ["z"] = 5, ["name"] = "default:aspen_leaves"}, {["x"] = 15, ["y"] = 10, ["param1"] = 13, ["z"] = 6, ["name"] = "default:aspen_leaves"}, {["x"] = 15, ["y"] = 10, ["param1"] = 13, ["z"] = 7, ["name"] = "default:aspen_leaves"}, {["x"] = 15, ["y"] = 10, ["param1"] = 13, ["z"] = 8, ["name"] = "default:aspen_leaves"}, {["x"] = 15, ["y"] = 10, ["param1"] = 14, ["z"] = 9, ["name"] = "default:aspen_leaves"}, {["x"] = 15, ["y"] = 10, ["param1"] = 14, ["z"] = 12, ["name"] = "default:aspen_leaves"}, {["x"] = 15, ["param2"] = 12, ["y"] = 10, ["param1"] = 43, ["z"] = 13, ["name"] = "default:tree"}, {["x"] = 15, ["y"] = 10, ["param1"] = 13, ["z"] = 14, ["name"] = "default:aspen_leaves"}, {["x"] = 15, ["y"] = 10, ["param1"] = 13, ["z"] = 15, ["name"] = "default:aspen_leaves"}, {["x"] = 15, ["y"] = 10, ["param1"] = 14, ["z"] = 16, ["name"] = "default:aspen_leaves"}, {["x"] = 15, ["y"] = 11, ["param1"] = 14, ["z"] = 7, ["name"] = "default:aspen_leaves"}, {["x"] = 15, ["y"] = 11, ["param1"] = 14, ["z"] = 8, ["name"] = "default:aspen_leaves"}, {["x"] = 15, ["y"] = 11, ["param1"] = 14, ["z"] = 12, ["name"] = "default:aspen_leaves"}, {["x"] = 15, ["y"] = 11, ["param1"] = 14, ["z"] = 13, ["name"] = "default:aspen_leaves"}, {["x"] = 15, ["y"] = 11, ["param1"] = 14, ["z"] = 14, ["name"] = "default:aspen_leaves"}, {["x"] = 15, ["y"] = 11, ["param1"] = 14, ["z"] = 15, ["name"] = "default:aspen_leaves"}, {["x"] = 15, ["y"] = 13, ["param1"] = 14, ["z"] = 6, ["name"] = "default:aspen_leaves"}, {["x"] = 15, ["y"] = 13, ["param1"] = 14, ["z"] = 10, ["name"] = "default:aspen_leaves"}, {["x"] = 15, ["y"] = 14, ["param1"] = 14, ["z"] = 5, ["name"] = "default:aspen_leaves"}, {["x"] = 15, ["y"] = 14, ["param1"] = 14, ["z"] = 7, ["name"] = "default:aspen_leaves"}, {["x"] = 15, ["y"] = 15, ["param1"] = 14, ["z"] = 6, ["name"] = "default:aspen_leaves"}, {["x"] = 15, ["y"] = 15, ["param1"] = 14, ["z"] = 7, ["name"] = "default:aspen_leaves"}, {["x"] = 16, ["y"] = 7, ["param1"] = 13, ["z"] = 7, ["name"] = "default:aspen_leaves"}, {["x"] = 16, ["y"] = 7, ["param1"] = 13, ["z"] = 8, ["name"] = "default:aspen_leaves"}, {["x"] = 16, ["y"] = 8, ["param1"] = 14, ["z"] = 3, ["name"] = "default:aspen_leaves"}, {["x"] = 16, ["y"] = 8, ["param1"] = 13, ["z"] = 4, ["name"] = "default:aspen_leaves"}, {["x"] = 16, ["y"] = 8, ["param1"] = 13, ["z"] = 5, ["name"] = "default:aspen_leaves"}, {["x"] = 16, ["y"] = 8, ["param1"] = 13, ["z"] = 6, ["name"] = "default:aspen_leaves"}, {["x"] = 16, ["y"] = 8, ["param1"] = 13, ["z"] = 7, ["name"] = "default:aspen_leaves"}, {["x"] = 16, ["y"] = 8, ["param1"] = 13, ["z"] = 8, ["name"] = "default:aspen_leaves"}, {["x"] = 16, ["y"] = 8, ["param1"] = 13, ["z"] = 9, ["name"] = "default:aspen_leaves"}, {["x"] = 16, ["y"] = 9, ["param1"] = 14, ["z"] = 2, ["name"] = "default:aspen_leaves"}, {["x"] = 16, ["y"] = 9, ["param1"] = 14, ["z"] = 3, ["name"] = "default:aspen_leaves"}, {["x"] = 16, ["y"] = 9, ["param1"] = 13, ["z"] = 4, ["name"] = "default:aspen_leaves"}, {["x"] = 16, ["y"] = 9, ["param1"] = 14, ["z"] = 5, ["name"] = "default:aspen_leaves"}, {["x"] = 16, ["y"] = 9, ["param1"] = 13, ["z"] = 6, ["name"] = "default:aspen_leaves"}, {["x"] = 16, ["y"] = 9, ["param1"] = 13, ["z"] = 7, ["name"] = "default:aspen_leaves"}, {["x"] = 16, ["param2"] = 12, ["y"] = 9, ["param1"] = 43, ["z"] = 8, ["name"] = "default:tree"}, {["x"] = 16, ["y"] = 9, ["param1"] = 13, ["z"] = 9, ["name"] = "default:aspen_leaves"}, {["x"] = 16, ["y"] = 9, ["param1"] = 14, ["z"] = 10, ["name"] = "default:aspen_leaves"}, {["x"] = 16, ["y"] = 9, ["param1"] = 13, ["z"] = 13, ["name"] = "default:aspen_leaves"}, {["x"] = 16, ["y"] = 9, ["param1"] = 13, ["z"] = 14, ["name"] = "default:aspen_leaves"}, {["x"] = 16, ["y"] = 10, ["param1"] = 14, ["z"] = 4, ["name"] = "default:aspen_leaves"}, {["x"] = 16, ["y"] = 10, ["param1"] = 14, ["z"] = 5, ["name"] = "default:aspen_leaves"}, {["x"] = 16, ["y"] = 10, ["param1"] = 14, ["z"] = 6, ["name"] = "default:aspen_leaves"}, {["x"] = 16, ["y"] = 10, ["param1"] = 14, ["z"] = 7, ["name"] = "default:aspen_leaves"}, {["x"] = 16, ["y"] = 10, ["param1"] = 14, ["z"] = 8, ["name"] = "default:aspen_leaves"}, {["x"] = 16, ["y"] = 10, ["param1"] = 14, ["z"] = 9, ["name"] = "default:aspen_leaves"}, {["x"] = 16, ["y"] = 10, ["param1"] = 14, ["z"] = 12, ["name"] = "default:aspen_leaves"}, {["x"] = 16, ["y"] = 10, ["param1"] = 13, ["z"] = 13, ["name"] = "default:aspen_leaves"}, {["x"] = 16, ["y"] = 10, ["param1"] = 14, ["z"] = 14, ["name"] = "default:aspen_leaves"}, {["x"] = 16, ["y"] = 10, ["param1"] = 14, ["z"] = 15, ["name"] = "default:aspen_leaves"}, {["x"] = 16, ["y"] = 11, ["param1"] = 14, ["z"] = 13, ["name"] = "default:aspen_leaves"}, {["x"] = 17, ["y"] = 8, ["param1"] = 14, ["z"] = 5, ["name"] = "default:aspen_leaves"}, {["x"] = 17, ["y"] = 8, ["param1"] = 14, ["z"] = 7, ["name"] = "default:aspen_leaves"}, {["x"] = 17, ["y"] = 8, ["param1"] = 14, ["z"] = 8, ["name"] = "default:aspen_leaves"}, {["x"] = 17, ["y"] = 9, ["param1"] = 14, ["z"] = 4, ["name"] = "default:aspen_leaves"}, {["x"] = 17, ["y"] = 9, ["param1"] = 14, ["z"] = 6, ["name"] = "default:aspen_leaves"}, {["x"] = 17, ["y"] = 9, ["param1"] = 14, ["z"] = 7, ["name"] = "default:aspen_leaves"}, {["x"] = 17, ["y"] = 9, ["param1"] = 14, ["z"] = 8, ["name"] = "default:aspen_leaves"}, {["x"] = 17, ["y"] = 9, ["param1"] = 14, ["z"] = 9, ["name"] = "default:aspen_leaves"}, {["x"] = 17, ["y"] = 10, ["param1"] = 14, ["z"] = 7, ["name"] = "default:aspen_leaves"}, {["x"] = 17, ["y"] = 10, ["param1"] = 14, ["z"] = 8, ["name"] = "default:aspen_leaves"}, {["x"] = 17, ["y"] = 10, ["param1"] = 14, ["z"] = 13, ["name"] = "default:aspen_leaves"}, {["x"] = 17, ["y"] = 10, ["param1"] = 14, ["z"] = 14, ["name"] = "default:aspen_leaves"}}