5:return {{["x"] = 0, ["y"] = 8, ["param1"] = 14, ["z"] = 4, ["name"] = "default:jungleleaves"}, {["x"] = 0, ["y"] = 8, ["param1"] = 14, ["z"] = 5, ["name"] = "default:jungleleaves"}, {["x"] = 0, ["y"] = 8, ["param1"] = 14, ["z"] = 6, ["name"] = "default:jungleleaves"}, {["x"] = 0, ["y"] = 8, ["param1"] = 14, ["z"] = 7, ["name"] = "default:jungleleaves"}, {["x"] = 0, ["y"] = 9, ["param1"] = 14, ["z"] = 4, ["name"] = "default:jungleleaves"}, {["x"] = 0, ["y"] = 9, ["param1"] = 14, ["z"] = 5, ["name"] = "default:jungleleaves"}, {["x"] = 0, ["y"] = 9, ["param1"] = 14, ["z"] = 6, ["name"] = "default:jungleleaves"}, {["x"] = 0, ["y"] = 9, ["param1"] = 14, ["z"] = 8, ["name"] = "default:jungleleaves"}, {["x"] = 0, ["y"] = 10, ["param1"] = 14, ["z"] = 1, ["name"] = "default:jungleleaves"}, {["x"] = 0, ["y"] = 10, ["param1"] = 14, ["z"] = 2, ["name"] = "default:jungleleaves"}, {["x"] = 0, ["y"] = 10, ["param1"] = 14, ["z"] = 3, ["name"] = "default:jungleleaves"}, {["x"] = 0, ["y"] = 10, ["param1"] = 14, ["z"] = 4, ["name"] = "default:jungleleaves"}, {["x"] = 0, ["y"] = 10, ["param1"] = 14, ["z"] = 6, ["name"] = "default:jungleleaves"}, {["x"] = 0, ["y"] = 10, ["param1"] = 14, ["z"] = 7, ["name"] = "default:jungleleaves"}, {["x"] = 0, ["y"] = 10, ["param1"] = 14, ["z"] = 8, ["name"] = "default:jungleleaves"}, {["x"] = 0, ["y"] = 11, ["param1"] = 14, ["z"] = 2, ["name"] = "default:jungleleaves"}, {["x"] = 0, ["y"] = 11, ["param1"] = 14, ["z"] = 3, ["name"] = "default:jungleleaves"}, {["x"] = 0, ["y"] = 11, ["param1"] = 14, ["z"] = 7, ["name"] = "default:jungleleaves"}, {["x"] = 0, ["y"] = 12, ["param1"] = 14, ["z"] = 3, ["name"] = "default:jungleleaves"}, {["x"] = 0, ["y"] = 12, ["param1"] = 14, ["z"] = 5, ["name"] = "default:jungleleaves"}, {["x"] = 0, ["y"] = 12, ["param1"] = 14, ["z"] = 6, ["name"] = "default:jungleleaves"}, {["x"] = 0, ["y"] = 13, ["param1"] = 14, ["z"] = 1, ["name"] = "default:jungleleaves"}, {["x"] = 0, ["y"] = 13, ["param1"] = 14, ["z"] = 3, ["name"] = "default:jungleleaves"}, {["x"] = 0, ["y"] = 13, ["param1"] = 14, ["z"] = 4, ["name"] = "default:jungleleaves"}, {["x"] = 0, ["y"] = 13, ["param1"] = 14, ["z"] = 5, ["name"] = "default:jungleleaves"}, {["x"] = 0, ["y"] = 14, ["param1"] = 14, ["z"] = 2, ["name"] = "default:jungleleaves"}, {["x"] = 0, ["y"] = 14, ["param1"] = 14, ["z"] = 3, ["name"] = "default:jungleleaves"}, {["x"] = 0, ["y"] = 14, ["param1"] = 14, ["z"] = 4, ["name"] = "default:jungleleaves"}, {["x"] = 0, ["y"] = 14, ["param1"] = 14, ["z"] = 5, ["name"] = "default:jungleleaves"}, {["x"] = 0, ["y"] = 14, ["param1"] = 14, ["z"] = 6, ["name"] = "default:jungleleaves"}, {["x"] = 0, ["y"] = 15, ["param1"] = 14, ["z"] = 2, ["name"] = "default:jungleleaves"}, {["x"] = 0, ["y"] = 15, ["param1"] = 14, ["z"] = 3, ["name"] = "default:jungleleaves"}, {["x"] = 0, ["y"] = 15, ["param1"] = 14, ["z"] = 5, ["name"] = "default:jungleleaves"}, {["x"] = 0, ["y"] = 15, ["param1"] = 14, ["z"] = 6, ["name"] = "default:jungleleaves"}, {["x"] = 0, ["y"] = 15, ["param1"] = 14, ["z"] = 7, ["name"] = "default:jungleleaves"}, {["x"] = 0, ["y"] = 16, ["param1"] = 14, ["z"] = 3, ["name"] = "default:jungleleaves"}, {["x"] = 0, ["y"] = 16, ["param1"] = 14, ["z"] = 4, ["name"] = "default:jungleleaves"}, {["x"] = 0, ["y"] = 16, ["param1"] = 14, ["z"] = 6, ["name"] = "default:jungleleaves"}, {["x"] = 0, ["y"] = 16, ["param1"] = 14, ["z"] = 7, ["name"] = "default:jungleleaves"}, {["x"] = 0, ["y"] = 17, ["param1"] = 14, ["z"] = 4, ["name"] = "default:jungleleaves"}, {["x"] = 0, ["y"] = 17, ["param1"] = 14, ["z"] = 6, ["name"] = "default:jungleleaves"}, {["x"] = 1, ["y"] = 6, ["param1"] = 13, ["z"] = 5, ["name"] = "default:jungleleaves"}, {["x"] = 1, ["y"] = 7, ["param1"] = 13, ["z"] = 4, ["name"] = "default:jungleleaves"}, {["x"] = 1, ["y"] = 7, ["param1"] = 13, ["z"] = 5, ["name"] = "default:jungleleaves"}, {["x"] = 1, ["y"] = 7, ["param1"] = 13, ["z"] = 6, ["name"] = "default:jungleleaves"}, {["x"] = 1, ["y"] = 8, ["param1"] = 13, ["z"] = 4, ["name"] = "default:jungleleaves"}, {["x"] = 1, ["y"] = 8, ["z"] = 5, ["name"] = "default:jungletree"}, {["x"] = 1, ["y"] = 8, ["param1"] = 13, ["z"] = 6, ["name"] = "default:jungleleaves"}, {["x"] = 1, ["y"] = 9, ["param1"] = 13, ["z"] = 3, ["name"] = "default:jungleleaves"}, {["x"] = 1, ["y"] = 9, ["z"] = 4, ["name"] = "default:jungletree"}, {["x"] = 1, ["y"] = 9, ["param1"] = 13, ["z"] = 5, ["name"] = "default:jungleleaves"}, {["x"] = 1, ["y"] = 9, ["param1"] = 13, ["z"] = 6, ["name"] = "default:jungleleaves"}, {["x"] = 1, ["y"] = 9, ["param1"] = 13, ["z"] = 7, ["name"] = "default:jungleleaves"}, {["x"] = 1, ["y"] = 9, ["param1"] = 14, ["z"] = 8, ["name"] = "default:jungleleaves"}, {["x"] = 1, ["y"] = 10, ["param1"] = 13, ["z"] = 3, ["name"] = "default:jungleleaves"}, {["x"] = 1, ["y"] = 10, ["param1"] = 13, ["z"] = 4, ["name"] = "default:jungleleaves"}, {["x"] = 1, ["y"] = 10, ["param1"] = 13, ["z"] = 5, ["name"] = "default:jungleleaves"}, {["x"] = 1, ["y"] = 10, ["z"] = 6, ["name"] = "default:jungletree"}, {["x"] = 1, ["y"] = 10, ["param1"] = 13, ["z"] = 7, ["name"] = "default:jungleleaves"}, {["x"] = 1, ["y"] = 10, ["param1"] = 14, ["z"] = 8, ["name"] = "default:jungleleaves"}, {["x"] = 1, ["y"] = 11, ["param1"] = 13, ["z"] = 2, ["name"] = "default:jungleleaves"}, {["x"] = 1, ["y"] = 11, ["z"] = 3, ["name"] = "default:jungletree"}, {["x"] = 1, ["y"] = 11, ["param1"] = 13, ["z"] = 4, ["name"] = "default:jungleleaves"}, {["x"] = 1, ["y"] = 11, ["param1"] = 13, ["z"] = 5, ["name"] = "default:jungleleaves"}, {["x"] = 1, ["y"] = 11, ["param1"] = 13, ["z"] = 6, ["name"] = "default:jungleleaves"}, {["x"] = 1, ["y"] = 11, ["param1"] = 13, ["z"] = 7, ["name"] = "default:jungleleaves"}, {["x"] = 1, ["y"] = 11, ["param1"] = 14, ["z"] = 8, ["name"] = "default:jungleleaves"}, {["x"] = 1, ["y"] = 12, ["param1"] = 14, ["z"] = 0, ["name"] = "default:jungleleaves"}, {["x"] = 1, ["y"] = 12, ["param1"] = 13, ["z"] = 1, ["name"] = "default:jungleleaves"}, {["x"] = 1, ["y"] = 12, ["param1"] = 13, ["z"] = 2, ["name"] = "default:jungleleaves"}, {["x"] = 1, ["y"] = 12, ["param1"] = 13, ["z"] = 3, ["name"] = "default:jungleleaves"}, {["x"] = 1, ["y"] = 12, ["z"] = 5, ["name"] = "default:jungletree"}, {["x"] = 1, ["y"] = 12, ["param1"] = 13, ["z"] = 6, ["name"] = "default:jungleleaves"}, {["x"] = 1, ["y"] = 12, ["param1"] = 13, ["z"] = 7, ["name"] = "default:jungleleaves"}, {["x"] = 1, ["y"] = 13, ["param1"] = 14, ["z"] = 0, ["name"] = "default:jungleleaves"}, {["x"] = 1, ["y"] = 13, ["param1"] = 13, ["z"] = 1, ["name"] = "default:jungleleaves"}, {["x"] = 1, ["y"] = 13, ["param1"] = 13, ["z"] = 2, ["name"] = "default:jungleleaves"}, {["x"] = 1, ["y"] = 13, ["param1"] = 13, ["z"] = 3, ["name"] = "default:jungleleaves"}, {["x"] = 1, ["y"] = 13, ["param1"] = 13, ["z"] = 4, ["name"] = "default:jungleleaves"}, {["x"] = 1, ["y"] = 13, ["param1"] = 13, ["z"] = 5, ["name"] = "default:jungleleaves"}, {["x"] = 1, ["y"] = 13, ["param1"] = 13, ["z"] = 6, ["name"] = "default:jungleleaves"}, {["x"] = 1, ["y"] = 14, ["param1"] = 13, ["z"] = 2, ["name"] = "default:jungleleaves"}, {["x"] = 1, ["y"] = 14, ["z"] = 3, ["name"] = "default:jungletree"}, {["x"] = 1, ["y"] = 14, ["z"] = 4, ["name"] = "default:jungletree"}, {["x"] = 1, ["y"] = 14, ["z"] = 5, ["name"] = "default:jungletree"}, {["x"] = 1, ["y"] = 14, ["z"] = 6, ["name"] = "default:jungletree"}, {["x"] = 1, ["y"] = 14, ["param1"] = 13, ["z"] = 7, ["name"] = "default:jungleleaves"}, {["x"] = 1, ["y"] = 14, ["param1"] = 14, ["z"] = 8, ["name"] = "default:jungleleaves"}, {["x"] = 1, ["y"] = 15, ["param1"] = 13, ["z"] = 2, ["name"] = "default:jungleleaves"}, {["x"] = 1, ["y"] = 15, ["param1"] = 13, ["z"] = 3, ["name"] = "default:jungleleaves"}, {["x"] = 1, ["y"] = 15, ["param1"] = 13, ["z"] = 4, ["name"] = "default:jungleleaves"}, {["x"] = 1, ["y"] = 15, ["param1"] = 13, ["z"] = 5, ["name"] = "default:jungleleaves"}, {["x"] = 1, ["y"] = 15, ["param1"] = 13, ["z"] = 6, ["name"] = "default:jungleleaves"}, {["x"] = 1, ["y"] = 15, ["param1"] = 13, ["z"] = 7, ["name"] = "default:jungleleaves"}, {["x"] = 1, ["y"] = 16, ["param1"] = 13, ["z"] = 3, ["name"] = "default:jungleleaves"}, {["x"] = 1, ["y"] = 16, ["param1"] = 13, ["z"] = 4, ["name"] = "default:jungleleaves"}, {["x"] = 1, ["y"] = 16, ["param1"] = 14, ["z"] = 5, ["name"] = "default:jungleleaves"}, {["x"] = 1, ["y"] = 16, ["param1"] = 13, ["z"] = 6, ["name"] = "default:jungleleaves"}, {["x"] = 1, ["y"] = 16, ["param1"] = 13, ["z"] = 7, ["name"] = "default:jungleleaves"}, {["x"] = 1, ["y"] = 16, ["param1"] = 14, ["z"] = 8, ["name"] = "default:jungleleaves"}, {["x"] = 1, ["y"] = 17, ["param1"] = 14, ["z"] = 5, ["name"] = "default:jungleleaves"}, {["x"] = 1, ["y"] = 17, ["param1"] = 13, ["z"] = 6, ["name"] = "default:jungleleaves"}, {["x"] = 1, ["y"] = 17, ["param1"] = 14, ["z"] = 7, ["name"] = "default:jungleleaves"}, {["x"] = 1, ["y"] = 18, ["param1"] = 14, ["z"] = 2, ["name"] = "default:jungleleaves"}, {["x"] = 1, ["y"] = 18, ["param1"] = 14, ["z"] = 4, ["name"] = "default:jungleleaves"}, {["x"] = 1, ["y"] = 18, ["param1"] = 14, ["z"] = 5, ["name"] = "default:jungleleaves"}, {["x"] = 1, ["y"] = 18, ["param1"] = 14, ["z"] = 6, ["name"] = "default:jungleleaves"}, {["x"] = 1, ["y"] = 18, ["param1"] = 14, ["z"] = 7, ["name"] = "default:jungleleaves"}, {["x"] = 1, ["y"] = 19, ["param1"] = 14, ["z"] = 3, ["name"] = "default:jungleleaves"}, {["x"] = 1, ["y"] = 19, ["param1"] = 14, ["z"] = 6, ["name"] = "default:jungleleaves"}, {["x"] = 1, ["y"] = 19, ["param1"] = 14, ["z"] = 7, ["name"] = "default:jungleleaves"}, {["x"] = 1, ["y"] = 20, ["param1"] = 14, ["z"] = 1, ["name"] = "default:jungleleaves"}, {["x"] = 1, ["y"] = 20, ["param1"] = 14, ["z"] = 2, ["name"] = "default:jungleleaves"}, {["x"] = 1, ["y"] = 22, ["param1"] = 14, ["z"] = 3, ["name"] = "default:jungleleaves"}, {["x"] = 1, ["y"] = 22, ["param1"] = 14, ["z"] = 5, ["name"] = "default:jungleleaves"}, {["x"] = 1, ["y"] = 23, ["param1"] = 14, ["z"] = 2, ["name"] = "default:jungleleaves"}, {["x"] = 1, ["y"] = 23, ["param1"] = 14, ["z"] = 3, ["name"] = "default:jungleleaves"}, {["x"] = 1, ["y"] = 23, ["param1"] = 14, ["z"] = 4, ["name"] = "default:jungleleaves"}, {["x"] = 1, ["y"] = 23, ["param1"] = 14, ["z"] = 5, ["name"] = "default:jungleleaves"}, {["x"] = 1, ["y"] = 23, ["param1"] = 14, ["z"] = 6, ["name"] = "default:jungleleaves"}, {["x"] = 1, ["y"] = 24, ["param1"] = 14, ["z"] = 2, ["name"] = "default:jungleleaves"}, {["x"] = 1, ["y"] = 24, ["param1"] = 14, ["z"] = 4, ["name"] = "default:jungleleaves"}, {["x"] = 1, ["y"] = 24, ["param1"] = 14, ["z"] = 5, ["name"] = "default:jungleleaves"}, {["x"] = 1, ["y"] = 24, ["param1"] = 14, ["z"] = 6, ["name"] = "default:jungleleaves"}, {["x"] = 1, ["y"] = 25, ["param1"] = 14, ["z"] = 3, ["name"] = "default:jungleleaves"}, {["x"] = 1, ["y"] = 25, ["param1"] = 14, ["z"] = 4, ["name"] = "default:jungleleaves"}, {["x"] = 2, ["y"] = 0, ["z"] = 3, ["name"] = "default:jungletree"}, {["x"] = 2, ["param2"] = 1, ["y"] = 0, ["z"] = 4, ["name"] = "default:jungletree"}, {["x"] = 2, ["param2"] = 2, ["y"] = 0, ["z"] = 5, ["name"] = "default:jungletree"}, {["x"] = 2, ["param2"] = 1, ["y"] = 1, ["z"] = 4, ["name"] = "default:jungletree"}, {["x"] = 2, ["y"] = 7, ["param1"] = 12, ["z"] = 4, ["name"] = "default:jungleleaves"}, {["x"] = 2, ["y"] = 8, ["param1"] = 12, ["z"] = 4, ["name"] = "default:jungleleaves"}, {["x"] = 2, ["y"] = 8, ["param1"] = 11, ["z"] = 5, ["name"] = "default:jungleleaves"}, {["x"] = 2, ["y"] = 8, ["param1"] = 12, ["z"] = 6, ["name"] = "default:jungleleaves"}, {["x"] = 2, ["y"] = 8, ["param1"] = 14, ["z"] = 8, ["name"] = "default:jungleleaves"}, {["x"] = 2, ["y"] = 9, ["param1"] = 12, ["z"] = 3, ["name"] = "default:jungleleaves"}, {["x"] = 2, ["y"] = 9, ["param1"] = 11, ["z"] = 4, ["name"] = "default:jungleleaves"}, {["x"] = 2, ["y"] = 9, ["param1"] = 12, ["z"] = 5, ["name"] = "default:jungleleaves"}, {["x"] = 2, ["y"] = 9, ["param1"] = 12, ["z"] = 6, ["name"] = "default:jungleleaves"}, {["x"] = 2, ["y"] = 9, ["param1"] = 14, ["z"] = 8, ["name"] = "default:jungleleaves"}, {["x"] = 2, ["y"] = 10, ["param1"] = 12, ["z"] = 3, ["name"] = "default:jungleleaves"}, {["x"] = 2, ["y"] = 10, ["param1"] = 12, ["z"] = 5, ["name"] = "default:jungleleaves"}, {["x"] = 2, ["y"] = 10, ["param1"] = 12, ["z"] = 6, ["name"] = "default:jungleleaves"}, {["x"] = 2, ["y"] = 10, ["param1"] = 13, ["z"] = 7, ["name"] = "default:jungleleaves"}, {["x"] = 2, ["y"] = 10, ["param1"] = 14, ["z"] = 8, ["name"] = "default:jungleleaves"}, {["x"] = 2, ["y"] = 11, ["param1"] = 12, ["z"] = 2, ["name"] = "default:jungleleaves"}, {["x"] = 2, ["y"] = 11, ["param1"] = 11, ["z"] = 3, ["name"] = "default:jungleleaves"}, {["x"] = 2, ["y"] = 11, ["param1"] = 12, ["z"] = 4, ["name"] = "default:jungleleaves"}, {["x"] = 2, ["y"] = 11, ["param1"] = 12, ["z"] = 5, ["name"] = "default:jungleleaves"}, {["x"] = 2, ["y"] = 11, ["z"] = 6, ["name"] = "default:jungletree"}, {["x"] = 2, ["y"] = 11, ["param1"] = 13, ["z"] = 7, ["name"] = "default:jungleleaves"}, {["x"] = 2, ["y"] = 11, ["param1"] = 14, ["z"] = 8, ["name"] = "default:jungleleaves"}, {["x"] = 2, ["y"] = 12, ["param1"] = 14, ["z"] = 0, ["name"] = "default:jungleleaves"}, {["x"] = 2, ["y"] = 12, ["param1"] = 13, ["z"] = 1, ["name"] = "default:jungleleaves"}, {["x"] = 2, ["y"] = 12, ["z"] = 2, ["name"] = "default:jungletree"}, {["x"] = 2, ["y"] = 12, ["param1"] = 11, ["z"] = 5, ["name"] = "default:jungleleaves"}, {["x"] = 2, ["y"] = 12, ["param1"] = 12, ["z"] = 6, ["name"] = "default:jungleleaves"}, {["x"] = 2, ["y"] = 12, ["param1"] = 14, ["z"] = 8, ["name"] = "default:jungleleaves"}, {["x"] = 2, ["y"] = 13, ["param1"] = 14, ["z"] = 0, ["name"] = "default:jungleleaves"}, {["x"] = 2, ["y"] = 13, ["param1"] = 13, ["z"] = 1, ["name"] = "default:jungleleaves"}, {["x"] = 2, ["y"] = 13, ["param1"] = 12, ["z"] = 2, ["name"] = "default:jungleleaves"}, {["x"] = 2, ["y"] = 13, ["param1"] = 12, ["z"] = 5, ["name"] = "default:jungleleaves"}, {["x"] = 2, ["y"] = 13, ["param1"] = 12, ["z"] = 6, ["name"] = "default:jungleleaves"}, {["x"] = 2, ["y"] = 13, ["param1"] = 13, ["z"] = 7, ["name"] = "default:jungleleaves"}, {["x"] = 2, ["y"] = 14, ["param1"] = 14, ["z"] = 1, ["name"] = "default:jungleleaves"}, {["x"] = 2, ["y"] = 14, ["param1"] = 13, ["z"] = 2, ["name"] = "default:jungleleaves"}, {["x"] = 2, ["y"] = 14, ["param1"] = 12, ["z"] = 3, ["name"] = "default:jungleleaves"}, {["x"] = 2, ["y"] = 14, ["z"] = 4, ["name"] = "default:jungletree"}, {["x"] = 2, ["y"] = 14, ["param1"] = 11, ["z"] = 5, ["name"] = "default:jungleleaves"}, {["x"] = 2, ["y"] = 14, ["param1"] = 11, ["z"] = 6, ["name"] = "default:jungleleaves"}, {["x"] = 2, ["y"] = 14, ["z"] = 7, ["name"] = "default:jungletree"}, {["x"] = 2, ["y"] = 14, ["param1"] = 14, ["z"] = 8, ["name"] = "default:jungleleaves"}, {["x"] = 2, ["y"] = 15, ["param1"] = 13, ["z"] = 2, ["name"] = "default:jungleleaves"}, {["x"] = 2, ["y"] = 15, ["param1"] = 12, ["z"] = 3, ["name"] = "default:jungleleaves"}, {["x"] = 2, ["y"] = 15, ["param1"] = 12, ["z"] = 4, ["name"] = "default:jungleleaves"}, {["x"] = 2, ["y"] = 15, ["param1"] = 12, ["z"] = 5, ["name"] = "default:jungleleaves"}, {["x"] = 2, ["y"] = 15, ["param1"] = 12, ["z"] = 6, ["name"] = "default:jungleleaves"}, {["x"] = 2, ["y"] = 15, ["param1"] = 13, ["z"] = 7, ["name"] = "default:jungleleaves"}, {["x"] = 2, ["y"] = 15, ["param1"] = 14, ["z"] = 8, ["name"] = "default:jungleleaves"}, {["x"] = 2, ["y"] = 16, ["param1"] = 12, ["z"] = 4, ["name"] = "default:jungleleaves"}, {["x"] = 2, ["y"] = 16, ["param1"] = 13, ["z"] = 5, ["name"] = "default:jungleleaves"}, {["x"] = 2, ["y"] = 16, ["param1"] = 13, ["z"] = 7, ["name"] = "default:jungleleaves"}, {["x"] = 2, ["y"] = 16, ["param1"] = 14, ["z"] = 8, ["name"] = "default:jungleleaves"}, {["x"] = 2, ["y"] = 17, ["param1"] = 13, ["z"] = 2, ["name"] = "default:jungleleaves"}, {["x"] = 2, ["y"] = 17, ["param1"] = 12, ["z"] = 4, ["name"] = "default:jungleleaves"}, {["x"] = 2, ["y"] = 17, ["param1"] = 13, ["z"] = 5, ["name"] = "default:jungleleaves"}, {["x"] = 2, ["y"] = 17, ["z"] = 6, ["name"] = "default:jungletree"}, {["x"] = 2, ["y"] = 17, ["param1"] = 14, ["z"] = 7, ["name"] = "default:jungleleaves"}, {["x"] = 2, ["y"] = 18, ["param1"] = 13, ["z"] = 2, ["name"] = "default:jungleleaves"}, {["x"] = 2, ["y"] = 18, ["param1"] = 13, ["z"] = 4, ["name"] = "default:jungleleaves"}, {["x"] = 2, ["y"] = 18, ["param1"] = 13, ["z"] = 5, ["name"] = "default:jungleleaves"}, {["x"] = 2, ["y"] = 18, ["param1"] = 13, ["z"] = 6, ["name"] = "default:jungleleaves"}, {["x"] = 2, ["y"] = 18, ["param1"] = 14, ["z"] = 7, ["name"] = "default:jungleleaves"}, {["x"] = 2, ["y"] = 19, ["param1"] = 14, ["z"] = 1, ["name"] = "default:jungleleaves"}, {["x"] = 2, ["y"] = 19, ["param1"] = 13, ["z"] = 2, ["name"] = "default:jungleleaves"}, {["x"] = 2, ["y"] = 19, ["param1"] = 13, ["z"] = 3, ["name"] = "default:jungleleaves"}, {["x"] = 2, ["y"] = 19, ["param1"] = 13, ["z"] = 5, ["name"] = "default:jungleleaves"}, {["x"] = 2, ["y"] = 19, ["param1"] = 13, ["z"] = 6, ["name"] = "default:jungleleaves"}, {["x"] = 2, ["y"] = 19, ["param1"] = 14, ["z"] = 7, ["name"] = "default:jungleleaves"}, {["x"] = 2, ["y"] = 20, ["param1"] = 14, ["z"] = 1, ["name"] = "default:jungleleaves"}, {["x"] = 2, ["y"] = 20, ["param1"] = 13, ["z"] = 2, ["name"] = "default:jungleleaves"}, {["x"] = 2, ["y"] = 20, ["param1"] = 13, ["z"] = 5, ["name"] = "default:jungleleaves"}, {["x"] = 2, ["y"] = 20, ["param1"] = 13, ["z"] = 6, ["name"] = "default:jungleleaves"}, {["x"] = 2, ["y"] = 21, ["param1"] = 14, ["z"] = 1, ["name"] = "default:jungleleaves"}, {["x"] = 2, ["y"] = 21, ["param1"] = 13, ["z"] = 2, ["name"] = "default:jungleleaves"}, {["x"] = 2, ["y"] = 21, ["param1"] = 13, ["z"] = 3, ["name"] = "default:jungleleaves"}, {["x"] = 2, ["y"] = 21, ["param1"] = 13, ["z"] = 5, ["name"] = "default:jungleleaves"}, {["x"] = 2, ["y"] = 21, ["param1"] = 13, ["z"] = 6, ["name"] = "default:jungleleaves"}, {["x"] = 2, ["y"] = 22, ["param1"] = 14, ["z"] = 1, ["name"] = "default:jungleleaves"}, {["x"] = 2, ["y"] = 22, ["param1"] = 13, ["z"] = 5, ["name"] = "default:jungleleaves"}, {["x"] = 2, ["y"] = 22, ["param1"] = 14, ["z"] = 7, ["name"] = "default:jungleleaves"}, {["x"] = 2, ["y"] = 23, ["param1"] = 14, ["z"] = 1, ["name"] = "default:jungleleaves"}, {["x"] = 2, ["y"] = 23, ["param1"] = 13, ["z"] = 2, ["name"] = "default:jungleleaves"}, {["x"] = 2, ["y"] = 23, ["param1"] = 13, ["z"] = 6, ["name"] = "default:jungleleaves"}, {["x"] = 2, ["y"] = 23, ["param1"] = 14, ["z"] = 7, ["name"] = "default:jungleleaves"}, {["x"] = 2, ["y"] = 24, ["param1"] = 14, ["z"] = 1, ["name"] = "default:jungleleaves"}, {["x"] = 2, ["y"] = 24, ["param1"] = 13, ["z"] = 3, ["name"] = "default:jungleleaves"}, {["x"] = 2, ["y"] = 24, ["param1"] = 13, ["z"] = 4, ["name"] = "default:jungleleaves"}, {["x"] = 2, ["y"] = 24, ["param1"] = 13, ["z"] = 5, ["name"] = "default:jungleleaves"}, {["x"] = 2, ["y"] = 24, ["param1"] = 13, ["z"] = 6, ["name"] = "default:jungleleaves"}, {["x"] = 2, ["y"] = 24, ["param1"] = 14, ["z"] = 7, ["name"] = "default:jungleleaves"}, {["x"] = 2, ["y"] = 25, ["param1"] = 14, ["z"] = 2, ["name"] = "default:jungleleaves"}, {["x"] = 2, ["y"] = 25, ["param1"] = 14, ["z"] = 3, ["name"] = "default:jungleleaves"}, {["x"] = 2, ["y"] = 25, ["param1"] = 14, ["z"] = 4, ["name"] = "default:jungleleaves"}, {["x"] = 2, ["y"] = 25, ["param1"] = 14, ["z"] = 5, ["name"] = "default:jungleleaves"}, {["x"] = 2, ["y"] = 25, ["param1"] = 14, ["z"] = 6, ["name"] = "default:jungleleaves"}, {["x"] = 2, ["y"] = 25, ["param1"] = 14, ["z"] = 7, ["name"] = "default:jungleleaves"}, {["x"] = 3, ["y"] = 0, ["z"] = 2, ["name"] = "default:jungletree"}, {["x"] = 3, ["y"] = 0, ["z"] = 3, ["name"] = "default:jungletree"}, {["x"] = 3, ["y"] = 0, ["z"] = 4, ["name"] = "default:jungletree"}, {["x"] = 3, ["param2"] = 1, ["y"] = 0, ["z"] = 5, ["name"] = "default:jungletree"}, {["x"] = 3, ["param2"] = 2, ["y"] = 0, ["z"] = 6, ["name"] = "default:jungletree"}, {["x"] = 3, ["y"] = 1, ["z"] = 3, ["name"] = "default:jungletree"}, {["x"] = 3, ["y"] = 1, ["z"] = 4, ["name"] = "default:jungletree"}, {["x"] = 3, ["param2"] = 1, ["y"] = 1, ["z"] = 5, ["name"] = "default:jungletree"}, {["x"] = 3, ["y"] = 2, ["z"] = 3, ["name"] = "default:jungletree"}, {["x"] = 3, ["y"] = 2, ["z"] = 4, ["name"] = "default:jungletree"}, {["x"] = 3, ["param2"] = 1, ["y"] = 2, ["z"] = 5, ["name"] = "default:jungletree"}, {["x"] = 3, ["y"] = 3, ["z"] = 4, ["name"] = "default:jungletree"}, {["x"] = 3, ["y"] = 4, ["z"] = 4, ["name"] = "default:jungletree"}, {["x"] = 3, ["y"] = 5, ["z"] = 4, ["name"] = "default:jungletree"}, {["x"] = 3, ["y"] = 6, ["z"] = 4, ["name"] = "default:jungletree"}, {["x"] = 3, ["y"] = 7, ["param1"] = 12, ["z"] = 2, ["name"] = "default:jungleleaves"}, {["x"] = 3, ["y"] = 7, ["z"] = 4, ["name"] = "default:jungletree"}, {["x"] = 3, ["y"] = 8, ["param1"] = 12, ["z"] = 2, ["name"] = "default:jungleleaves"}, {["x"] = 3, ["y"] = 8, ["z"] = 4, ["name"] = "default:jungletree"}, {["x"] = 3, ["y"] = 8, ["param1"] = 11, ["z"] = 5, ["name"] = "default:jungleleaves"}, {["x"] = 3, ["y"] = 8, ["param1"] = 13, ["z"] = 7, ["name"] = "default:jungleleaves"}, {["x"] = 3, ["y"] = 9, ["param1"] = 12, ["z"] = 2, ["name"] = "default:jungleleaves"}, {["x"] = 3, ["y"] = 9, ["param1"] = 11, ["z"] = 3, ["name"] = "default:jungleleaves"}, {["x"] = 3, ["y"] = 9, ["z"] = 4, ["name"] = "default:jungletree"}, {["x"] = 3, ["y"] = 9, ["param1"] = 11, ["z"] = 5, ["name"] = "default:jungleleaves"}, {["x"] = 3, ["y"] = 9, ["param1"] = 12, ["z"] = 6, ["name"] = "default:jungleleaves"}, {["x"] = 3, ["y"] = 9, ["param1"] = 13, ["z"] = 7, ["name"] = "default:jungleleaves"}, {["x"] = 3, ["y"] = 9, ["param1"] = 14, ["z"] = 8, ["name"] = "default:jungleleaves"}, {["x"] = 3, ["y"] = 10, ["param1"] = 12, ["z"] = 2, ["name"] = "default:jungleleaves"}, {["x"] = 3, ["y"] = 10, ["param1"] = 11, ["z"] = 3, ["name"] = "default:jungleleaves"}, {["x"] = 3, ["y"] = 10, ["z"] = 4, ["name"] = "default:jungletree"}, {["x"] = 3, ["y"] = 10, ["param1"] = 11, ["z"] = 5, ["name"] = "default:jungleleaves"}, {["x"] = 3, ["y"] = 10, ["param1"] = 14, ["z"] = 8, ["name"] = "default:jungleleaves"}, {["x"] = 3, ["y"] = 11, ["param1"] = 13, ["z"] = 1, ["name"] = "default:jungleleaves"}, {["x"] = 3, ["y"] = 11, ["param1"] = 12, ["z"] = 2, ["name"] = "default:jungleleaves"}, {["x"] = 3, ["y"] = 11, ["z"] = 3, ["name"] = "default:jungletree"}, {["x"] = 3, ["y"] = 11, ["z"] = 4, ["name"] = "default:jungletree"}, {["x"] = 3, ["y"] = 11, ["param1"] = 11, ["z"] = 5, ["name"] = "default:jungleleaves"}, {["x"] = 3, ["y"] = 11, ["param1"] = 13, ["z"] = 7, ["name"] = "default:jungleleaves"}, {["x"] = 3, ["y"] = 12, ["param1"] = 13, ["z"] = 1, ["name"] = "default:jungleleaves"}, {["x"] = 3, ["y"] = 12, ["param1"] = 12, ["z"] = 2, ["name"] = "default:jungleleaves"}, {["x"] = 3, ["y"] = 12, ["z"] = 4, ["name"] = "default:jungletree"}, {["x"] = 3, ["y"] = 12, ["z"] = 5, ["name"] = "default:jungletree"}, {["x"] = 3, ["y"] = 12, ["param1"] = 12, ["z"] = 6, ["name"] = "default:jungleleaves"}, {["x"] = 3, ["y"] = 12, ["param1"] = 13, ["z"] = 7, ["name"] = "default:jungleleaves"}, {["x"] = 3, ["y"] = 13, ["param1"] = 14, ["z"] = 0, ["name"] = "default:jungleleaves"}, {["x"] = 3, ["y"] = 13, ["param1"] = 13, ["z"] = 1, ["name"] = "default:jungleleaves"}, {["x"] = 3, ["y"] = 13, ["param1"] = 12, ["z"] = 2, ["name"] = "default:jungleleaves"}, {["x"] = 3, ["y"] = 13, ["z"] = 4, ["name"] = "default:jungletree"}, {["x"] = 3, ["y"] = 13, ["z"] = 5, ["name"] = "default:jungletree"}, {["x"] = 3, ["y"] = 13, ["z"] = 6, ["name"] = "default:jungletree"}, {["x"] = 3, ["y"] = 13, ["param1"] = 13, ["z"] = 7, ["name"] = "default:jungleleaves"}, {["x"] = 3, ["y"] = 14, ["param1"] = 12, ["z"] = 2, ["name"] = "default:jungleleaves"}, {["x"] = 3, ["y"] = 14, ["param1"] = 11, ["z"] = 3, ["name"] = "default:jungleleaves"}, {["x"] = 3, ["y"] = 14, ["z"] = 4, ["name"] = "default:jungletree"}, {["x"] = 3, ["y"] = 14, ["z"] = 5, ["name"] = "default:jungletree"}, {["x"] = 3, ["y"] = 14, ["param1"] = 12, ["z"] = 6, ["name"] = "default:jungleleaves"}, {["x"] = 3, ["y"] = 14, ["param1"] = 13, ["z"] = 7, ["name"] = "default:jungleleaves"}, {["x"] = 3, ["y"] = 14, ["param1"] = 14, ["z"] = 8, ["name"] = "default:jungleleaves"}, {["x"] = 3, ["y"] = 15, ["param1"] = 13, ["z"] = 1, ["name"] = "default:jungleleaves"}, {["x"] = 3, ["y"] = 15, ["param1"] = 12, ["z"] = 2, ["name"] = "default:jungleleaves"}, {["x"] = 3, ["y"] = 15, ["param1"] = 11, ["z"] = 3, ["name"] = "default:jungleleaves"}, {["x"] = 3, ["y"] = 15, ["z"] = 4, ["name"] = "default:jungletree"}, {["x"] = 3, ["y"] = 15, ["z"] = 5, ["name"] = "default:jungletree"}, {["x"] = 3, ["y"] = 15, ["param1"] = 12, ["z"] = 6, ["name"] = "default:jungleleaves"}, {["x"] = 3, ["y"] = 15, ["param1"] = 13, ["z"] = 7, ["name"] = "default:jungleleaves"}, {["x"] = 3, ["y"] = 15, ["param1"] = 14, ["z"] = 8, ["name"] = "default:jungleleaves"}, {["x"] = 3, ["y"] = 16, ["param1"] = 12, ["z"] = 2, ["name"] = "default:jungleleaves"}, {["x"] = 3, ["y"] = 16, ["param1"] = 11, ["z"] = 3, ["name"] = "default:jungleleaves"}, {["x"] = 3, ["y"] = 16, ["z"] = 4, ["name"] = "default:jungletree"}, {["x"] = 3, ["y"] = 16, ["z"] = 5, ["name"] = "default:jungletree"}, {["x"] = 3, ["y"] = 16, ["param1"] = 12, ["z"] = 6, ["name"] = "default:jungleleaves"}, {["x"] = 3, ["y"] = 16, ["param1"] = 13, ["z"] = 7, ["name"] = "default:jungleleaves"}, {["x"] = 3, ["y"] = 17, ["param1"] = 12, ["z"] = 2, ["name"] = "default:jungleleaves"}, {["x"] = 3, ["y"] = 17, ["param1"] = 12, ["z"] = 3, ["name"] = "default:jungleleaves"}, {["x"] = 3, ["y"] = 17, ["z"] = 4, ["name"] = "default:jungletree"}, {["x"] = 3, ["y"] = 17, ["z"] = 5, ["name"] = "default:jungletree"}, {["x"] = 3, ["y"] = 17, ["param1"] = 12, ["z"] = 6, ["name"] = "default:jungleleaves"}, {["x"] = 3, ["y"] = 17, ["param1"] = 13, ["z"] = 7, ["name"] = "default:jungleleaves"}, {["x"] = 3, ["y"] = 18, ["param1"] = 12, ["z"] = 3, ["name"] = "default:jungleleaves"}, {["x"] = 3, ["y"] = 18, ["z"] = 4, ["name"] = "default:jungletree"}, {["x"] = 3, ["y"] = 18, ["param1"] = 12, ["z"] = 5, ["name"] = "default:jungleleaves"}, {["x"] = 3, ["y"] = 18, ["param1"] = 12, ["z"] = 6, ["name"] = "default:jungleleaves"}, {["x"] = 3, ["y"] = 18, ["param1"] = 13, ["z"] = 7, ["name"] = "default:jungleleaves"}, {["x"] = 3, ["y"] = 19, ["param1"] = 13, ["z"] = 1, ["name"] = "default:jungleleaves"}, {["x"] = 3, ["y"] = 19, ["param1"] = 12, ["z"] = 2, ["name"] = "default:jungleleaves"}, {["x"] = 3, ["y"] = 19, ["z"] = 3, ["name"] = "default:jungletree"}, {["x"] = 3, ["y"] = 19, ["z"] = 4, ["name"] = "default:jungletree"}, {["x"] = 3, ["y"] = 19, ["param1"] = 12, ["z"] = 5, ["name"] = "default:jungleleaves"}, {["x"] = 3, ["y"] = 19, ["param1"] = 12, ["z"] = 6, ["name"] = "default:jungleleaves"}, {["x"] = 3, ["y"] = 19, ["param1"] = 13, ["z"] = 7, ["name"] = "default:jungleleaves"}, {["x"] = 3, ["y"] = 20, ["param1"] = 13, ["z"] = 1, ["name"] = "default:jungleleaves"}, {["x"] = 3, ["y"] = 20, ["param1"] = 12, ["z"] = 2, ["name"] = "default:jungleleaves"}, {["x"] = 3, ["y"] = 20, ["param1"] = 12, ["z"] = 3, ["name"] = "default:jungleleaves"}, {["x"] = 3, ["y"] = 20, ["z"] = 4, ["name"] = "default:jungletree"}, {["x"] = 3, ["y"] = 20, ["param1"] = 12, ["z"] = 5, ["name"] = "default:jungleleaves"}, {["x"] = 3, ["y"] = 20, ["param1"] = 12, ["z"] = 6, ["name"] = "default:jungleleaves"}, {["x"] = 3, ["y"] = 20, ["param1"] = 13, ["z"] = 7, ["name"] = "default:jungleleaves"}, {["x"] = 3, ["y"] = 21, ["param1"] = 13, ["z"] = 1, ["name"] = "default:jungleleaves"}, {["x"] = 3, ["y"] = 21, ["param1"] = 12, ["z"] = 3, ["name"] = "default:jungleleaves"}, {["x"] = 3, ["y"] = 21, ["z"] = 4, ["name"] = "default:jungletree"}, {["x"] = 3, ["y"] = 21, ["param1"] = 12, ["z"] = 5, ["name"] = "default:jungleleaves"}, {["x"] = 3, ["y"] = 21, ["param1"] = 12, ["z"] = 6, ["name"] = "default:jungleleaves"}, {["x"] = 3, ["y"] = 22, ["param1"] = 13, ["z"] = 1, ["name"] = "default:jungleleaves"}, {["x"] = 3, ["y"] = 22, ["param1"] = 12, ["z"] = 2, ["name"] = "default:jungleleaves"}, {["x"] = 3, ["y"] = 22, ["z"] = 3, ["name"] = "default:jungletree"}, {["x"] = 3, ["y"] = 22, ["z"] = 4, ["name"] = "default:jungletree"}, {["x"] = 3, ["y"] = 22, ["z"] = 5, ["name"] = "default:jungletree"}, {["x"] = 3, ["y"] = 22, ["param1"] = 12, ["z"] = 6, ["name"] = "default:jungleleaves"}, {["x"] = 3, ["y"] = 23, ["param1"] = 14, ["z"] = 0, ["name"] = "default:jungleleaves"}, {["x"] = 3, ["y"] = 23, ["param1"] = 13, ["z"] = 1, ["name"] = "default:jungleleaves"}, {["x"] = 3, ["y"] = 23, ["z"] = 3, ["name"] = "default:jungletree"}, {["x"] = 3, ["y"] = 23, ["param1"] = 12, ["z"] = 4, ["name"] = "default:jungleleaves"}, {["x"] = 3, ["y"] = 23, ["z"] = 5, ["name"] = "default:jungletree"}, {["x"] = 3, ["y"] = 23, ["param1"] = 12, ["z"] = 6, ["name"] = "default:jungleleaves"}, {["x"] = 3, ["y"] = 23, ["param1"] = 13, ["z"] = 7, ["name"] = "default:jungleleaves"}, {["x"] = 3, ["y"] = 24, ["param1"] = 14, ["z"] = 1, ["name"] = "default:jungleleaves"}, {["x"] = 3, ["y"] = 24, ["param1"] = 13, ["z"] = 2, ["name"] = "default:jungleleaves"}, {["x"] = 3, ["y"] = 24, ["param1"] = 12, ["z"] = 3, ["name"] = "default:jungleleaves"}, {["x"] = 3, ["y"] = 24, ["param1"] = 12, ["z"] = 4, ["name"] = "default:jungleleaves"}, {["x"] = 3, ["y"] = 24, ["param1"] = 13, ["z"] = 5, ["name"] = "default:jungleleaves"}, {["x"] = 3, ["y"] = 24, ["param1"] = 12, ["z"] = 6, ["name"] = "default:jungleleaves"}, {["x"] = 3, ["y"] = 24, ["param1"] = 13, ["z"] = 7, ["name"] = "default:jungleleaves"}, {["x"] = 3, ["y"] = 24, ["param1"] = 14, ["z"] = 8, ["name"] = "default:jungleleaves"}, {["x"] = 3, ["y"] = 25, ["param1"] = 14, ["z"] = 1, ["name"] = "default:jungleleaves"}, {["x"] = 3, ["y"] = 25, ["param1"] = 14, ["z"] = 2, ["name"] = "default:jungleleaves"}, {["x"] = 3, ["y"] = 25, ["param1"] = 13, ["z"] = 3, ["name"] = "default:jungleleaves"}, {["x"] = 3, ["y"] = 25, ["param1"] = 13, ["z"] = 4, ["name"] = "default:jungleleaves"}, {["x"] = 3, ["y"] = 25, ["param1"] = 14, ["z"] = 5, ["name"] = "default:jungleleaves"}, {["x"] = 3, ["y"] = 25, ["param1"] = 13, ["z"] = 6, ["name"] = "default:jungleleaves"}, {["x"] = 3, ["y"] = 25, ["param1"] = 14, ["z"] = 7, ["name"] = "default:jungleleaves"}, {["x"] = 3, ["param2"] = 1, ["y"] = 26, ["param1"] = 14, ["z"] = 3, ["name"] = "default:jungleleaves"}, {["x"] = 3, ["y"] = 26, ["param1"] = 14, ["z"] = 4, ["name"] = "default:jungleleaves"}, {["x"] = 3, ["y"] = 26, ["param1"] = 14, ["z"] = 6, ["name"] = "default:jungleleaves"}, {["x"] = 4, ["param2"] = 3, ["y"] = 0, ["z"] = 2, ["name"] = "default:jungletree"}, {["x"] = 4, ["y"] = 0, ["z"] = 3, ["name"] = "default:jungletree"}, {["x"] = 4, ["y"] = 0, ["z"] = 4, ["name"] = "default:jungletree"}, {["x"] = 4, ["y"] = 0, ["z"] = 5, ["name"] = "default:jungletree"}, {["x"] = 4, ["param2"] = 2, ["y"] = 0, ["z"] = 6, ["name"] = "default:jungletree"}, {["x"] = 4, ["param2"] = 3, ["y"] = 1, ["z"] = 2, ["name"] = "default:jungletree"}, {["x"] = 4, ["y"] = 1, ["z"] = 3, ["name"] = "default:jungletree"}, {["x"] = 4, ["y"] = 1, ["z"] = 4, ["name"] = "default:jungletree"}, {["x"] = 4, ["y"] = 1, ["z"] = 5, ["name"] = "default:jungletree"}, {["x"] = 4, ["param2"] = 2, ["y"] = 1, ["z"] = 6, ["name"] = "default:jungletree"}, {["x"] = 4, ["y"] = 2, ["z"] = 3, ["name"] = "default:jungletree"}, {["x"] = 4, ["y"] = 2, ["z"] = 4, ["name"] = "default:jungletree"}, {["x"] = 4, ["y"] = 2, ["z"] = 5, ["name"] = "default:jungletree"}, {["x"] = 4, ["y"] = 3, ["z"] = 3, ["name"] = "default:jungletree"}, {["x"] = 4, ["y"] = 3, ["z"] = 4, ["name"] = "default:jungletree"}, {["x"] = 4, ["y"] = 3, ["z"] = 5, ["name"] = "default:jungletree"}, {["x"] = 4, ["y"] = 4, ["z"] = 3, ["name"] = "default:jungletree"}, {["x"] = 4, ["y"] = 4, ["z"] = 4, ["name"] = "default:jungletree"}, {["x"] = 4, ["y"] = 4, ["z"] = 5, ["name"] = "default:jungletree"}, {["x"] = 4, ["y"] = 5, ["z"] = 3, ["name"] = "default:jungletree"}, {["x"] = 4, ["y"] = 5, ["z"] = 4, ["name"] = "default:jungletree"}, {["x"] = 4, ["y"] = 5, ["z"] = 5, ["name"] = "default:jungletree"}, {["x"] = 4, ["y"] = 6, ["z"] = 3, ["name"] = "default:jungletree"}, {["x"] = 4, ["y"] = 6, ["z"] = 4, ["name"] = "default:jungletree"}, {["x"] = 4, ["y"] = 6, ["z"] = 5, ["name"] = "default:jungletree"}, {["x"] = 4, ["y"] = 7, ["z"] = 3, ["name"] = "default:jungletree"}, {["x"] = 4, ["y"] = 7, ["z"] = 4, ["name"] = "default:jungletree"}, {["x"] = 4, ["y"] = 7, ["z"] = 5, ["name"] = "default:jungletree"}, {["x"] = 4, ["y"] = 8, ["z"] = 3, ["name"] = "default:jungletree"}, {["x"] = 4, ["y"] = 8, ["z"] = 4, ["name"] = "default:jungletree"}, {["x"] = 4, ["y"] = 8, ["z"] = 5, ["name"] = "default:jungletree"}, {["x"] = 4, ["y"] = 8, ["param1"] = 14, ["z"] = 8, ["name"] = "default:jungleleaves"}, {["x"] = 4, ["y"] = 9, ["param1"] = 13, ["z"] = 1, ["name"] = "default:jungleleaves"}, {["x"] = 4, ["y"] = 9, ["param1"] = 12, ["z"] = 2, ["name"] = "default:jungleleaves"}, {["x"] = 4, ["y"] = 9, ["z"] = 3, ["name"] = "default:jungletree"}, {["x"] = 4, ["y"] = 9, ["z"] = 4, ["name"] = "default:jungletree"}, {["x"] = 4, ["y"] = 9, ["z"] = 5, ["name"] = "default:jungletree"}, {["x"] = 4, ["y"] = 9, ["param1"] = 12, ["z"] = 6, ["name"] = "default:jungleleaves"}, {["x"] = 4, ["y"] = 10, ["param1"] = 12, ["z"] = 2, ["name"] = "default:jungleleaves"}, {["x"] = 4, ["y"] = 10, ["z"] = 3, ["name"] = "default:jungletree"}, {["x"] = 4, ["y"] = 10, ["z"] = 4, ["name"] = "default:jungletree"}, {["x"] = 4, ["y"] = 10, ["z"] = 5, ["name"] = "default:jungletree"}, {["x"] = 4, ["y"] = 10, ["param1"] = 14, ["z"] = 8, ["name"] = "default:jungleleaves"}, {["x"] = 4, ["y"] = 11, ["z"] = 3, ["name"] = "default:jungletree"}, {["x"] = 4, ["y"] = 11, ["z"] = 4, ["name"] = "default:jungletree"}, {["x"] = 4, ["y"] = 11, ["z"] = 5, ["name"] = "default:jungletree"}, {["x"] = 4, ["y"] = 11, ["param1"] = 14, ["z"] = 8, ["name"] = "default:jungleleaves"}, {["x"] = 4, ["y"] = 12, ["param1"] = 14, ["z"] = 0, ["name"] = "default:jungleleaves"}, {["x"] = 4, ["y"] = 12, ["param1"] = 13, ["z"] = 1, ["name"] = "default:jungleleaves"}, {["x"] = 4, ["y"] = 12, ["param1"] = 12, ["z"] = 2, ["name"] = "default:jungleleaves"}, {["x"] = 4, ["y"] = 12, ["z"] = 3, ["name"] = "default:jungletree"}, {["x"] = 4, ["y"] = 12, ["z"] = 4, ["name"] = "default:jungletree"}, {["x"] = 4, ["y"] = 12, ["z"] = 5, ["name"] = "default:jungletree"}, {["x"] = 4, ["y"] = 12, ["param1"] = 14, ["z"] = 8, ["name"] = "default:jungleleaves"}, {["x"] = 4, ["y"] = 13, ["param1"] = 12, ["z"] = 2, ["name"] = "default:jungleleaves"}, {["x"] = 4, ["y"] = 13, ["z"] = 3, ["name"] = "default:jungletree"}, {["x"] = 4, ["y"] = 13, ["z"] = 4, ["name"] = "default:jungletree"}, {["x"] = 4, ["y"] = 13, ["z"] = 5, ["name"] = "default:jungletree"}, {["x"] = 4, ["y"] = 13, ["param1"] = 12, ["z"] = 6, ["name"] = "default:jungleleaves"}, {["x"] = 4, ["y"] = 13, ["param1"] = 14, ["z"] = 8, ["name"] = "default:jungleleaves"}, {["x"] = 4, ["y"] = 14, ["param1"] = 13, ["z"] = 1, ["name"] = "default:jungleleaves"}, {["x"] = 4, ["y"] = 14, ["param1"] = 12, ["z"] = 2, ["name"] = "default:jungleleaves"}, {["x"] = 4, ["y"] = 14, ["z"] = 3, ["name"] = "default:jungletree"}, {["x"] = 4, ["y"] = 14, ["z"] = 4, ["name"] = "default:jungletree"}, {["x"] = 4, ["y"] = 14, ["z"] = 5, ["name"] = "default:jungletree"}, {["x"] = 4, ["y"] = 14, ["param1"] = 12, ["z"] = 6, ["name"] = "default:jungleleaves"}, {["x"] = 4, ["y"] = 14, ["param1"] = 13, ["z"] = 7, ["name"] = "default:jungleleaves"}, {["x"] = 4, ["y"] = 14, ["param1"] = 14, ["z"] = 8, ["name"] = "default:jungleleaves"}, {["x"] = 4, ["y"] = 15, ["param1"] = 13, ["z"] = 1, ["name"] = "default:jungleleaves"}, {["x"] = 4, ["y"] = 15, ["param1"] = 12, ["z"] = 2, ["name"] = "default:jungleleaves"}, {["x"] = 4, ["y"] = 15, ["z"] = 3, ["name"] = "default:jungletree"}, {["x"] = 4, ["y"] = 15, ["z"] = 4, ["name"] = "default:jungletree"}, {["x"] = 4, ["y"] = 15, ["z"] = 5, ["name"] = "default:jungletree"}, {["x"] = 4, ["y"] = 15, ["param1"] = 12, ["z"] = 6, ["name"] = "default:jungleleaves"}, {["x"] = 4, ["y"] = 15, ["param1"] = 13, ["z"] = 7, ["name"] = "default:jungleleaves"}, {["x"] = 4, ["y"] = 15, ["param1"] = 14, ["z"] = 8, ["name"] = "default:jungleleaves"}, {["x"] = 4, ["y"] = 16, ["param1"] = 13, ["z"] = 1, ["name"] = "default:jungleleaves"}, {["x"] = 4, ["y"] = 16, ["z"] = 2, ["name"] = "default:jungletree"}, {["x"] = 4, ["y"] = 16, ["z"] = 3, ["name"] = "default:jungletree"}, {["x"] = 4, ["y"] = 16, ["z"] = 4, ["name"] = "default:jungletree"}, {["x"] = 4, ["y"] = 16, ["z"] = 5, ["name"] = "default:jungletree"}, {["x"] = 4, ["y"] = 16, ["param1"] = 12, ["z"] = 6, ["name"] = "default:jungleleaves"}, {["x"] = 4, ["y"] = 17, ["param1"] = 13, ["z"] = 1, ["name"] = "default:jungleleaves"}, {["x"] = 4, ["y"] = 17, ["param1"] = 12, ["z"] = 2, ["name"] = "default:jungleleaves"}, {["x"] = 4, ["y"] = 17, ["z"] = 3, ["name"] = "default:jungletree"}, {["x"] = 4, ["y"] = 17, ["z"] = 4, ["name"] = "default:jungletree"}, {["x"] = 4, ["y"] = 17, ["z"] = 5, ["name"] = "default:jungletree"}, {["x"] = 4, ["y"] = 17, ["param1"] = 12, ["z"] = 6, ["name"] = "default:jungleleaves"}, {["x"] = 4, ["y"] = 17, ["param1"] = 13, ["z"] = 7, ["name"] = "default:jungleleaves"}, {["x"] = 4, ["y"] = 18, ["param1"] = 13, ["z"] = 1, ["name"] = "default:jungleleaves"}, {["x"] = 4, ["y"] = 18, ["param1"] = 12, ["z"] = 2, ["name"] = "default:jungleleaves"}, {["x"] = 4, ["y"] = 18, ["z"] = 3, ["name"] = "default:jungletree"}, {["x"] = 4, ["y"] = 18, ["z"] = 4, ["name"] = "default:jungletree"}, {["x"] = 4, ["y"] = 18, ["z"] = 5, ["name"] = "default:jungletree"}, {["x"] = 4, ["y"] = 18, ["param1"] = 13, ["z"] = 7, ["name"] = "default:jungleleaves"}, {["x"] = 4, ["y"] = 19, ["param1"] = 12, ["z"] = 2, ["name"] = "default:jungleleaves"}, {["x"] = 4, ["y"] = 19, ["z"] = 3, ["name"] = "default:jungletree"}, {["x"] = 4, ["y"] = 19, ["z"] = 4, ["name"] = "default:jungletree"}, {["x"] = 4, ["y"] = 19, ["z"] = 5, ["name"] = "default:jungletree"}, {["x"] = 4, ["y"] = 19, ["param1"] = 12, ["z"] = 6, ["name"] = "default:jungleleaves"}, {["x"] = 4, ["y"] = 19, ["param1"] = 13, ["z"] = 7, ["name"] = "default:jungleleaves"}, {["x"] = 4, ["y"] = 20, ["z"] = 3, ["name"] = "default:jungletree"}, {["x"] = 4, ["y"] = 20, ["z"] = 4, ["name"] = "default:jungletree"}, {["x"] = 4, ["y"] = 20, ["z"] = 5, ["name"] = "default:jungletree"}, {["x"] = 4, ["y"] = 20, ["z"] = 6, ["name"] = "default:jungletree"}, {["x"] = 4, ["y"] = 20, ["param1"] = 13, ["z"] = 7, ["name"] = "default:jungleleaves"}, {["x"] = 4, ["y"] = 21, ["param1"] = 12, ["z"] = 2, ["name"] = "default:jungleleaves"}, {["x"] = 4, ["y"] = 21, ["z"] = 3, ["name"] = "default:jungletree"}, {["x"] = 4, ["y"] = 21, ["z"] = 4, ["name"] = "default:jungletree"}, {["x"] = 4, ["y"] = 21, ["z"] = 5, ["name"] = "default:jungletree"}, {["x"] = 4, ["y"] = 21, ["param1"] = 12, ["z"] = 6, ["name"] = "default:jungleleaves"}, {["x"] = 4, ["y"] = 21, ["param1"] = 13, ["z"] = 7, ["name"] = "default:jungleleaves"}, {["x"] = 4, ["y"] = 22, ["param1"] = 14, ["z"] = 0, ["name"] = "default:jungleleaves"}, {["x"] = 4, ["y"] = 22, ["param1"] = 13, ["z"] = 1, ["name"] = "default:jungleleaves"}, {["x"] = 4, ["y"] = 22, ["z"] = 3, ["name"] = "default:jungletree"}, {["x"] = 4, ["y"] = 22, ["z"] = 5, ["name"] = "default:jungletree"}, {["x"] = 4, ["y"] = 22, ["param1"] = 13, ["z"] = 7, ["name"] = "default:jungleleaves"}, {["x"] = 4, ["y"] = 23, ["param1"] = 14, ["z"] = 0, ["name"] = "default:jungleleaves"}, {["x"] = 4, ["y"] = 23, ["param1"] = 13, ["z"] = 1, ["name"] = "default:jungleleaves"}, {["x"] = 4, ["y"] = 23, ["param1"] = 11, ["z"] = 3, ["name"] = "default:jungleleaves"}, {["x"] = 4, ["y"] = 23, ["param1"] = 13, ["z"] = 7, ["name"] = "default:jungleleaves"}, {["x"] = 4, ["y"] = 23, ["param1"] = 14, ["z"] = 8, ["name"] = "default:jungleleaves"}, {["x"] = 4, ["y"] = 24, ["param1"] = 13, ["z"] = 2, ["name"] = "default:jungleleaves"}, {["x"] = 4, ["y"] = 24, ["param1"] = 12, ["z"] = 3, ["name"] = "default:jungleleaves"}, {["x"] = 4, ["y"] = 24, ["param1"] = 13, ["z"] = 6, ["name"] = "default:jungleleaves"}, {["x"] = 4, ["y"] = 24, ["param1"] = 13, ["z"] = 7, ["name"] = "default:jungleleaves"}, {["x"] = 4, ["y"] = 24, ["param1"] = 14, ["z"] = 8, ["name"] = "default:jungleleaves"}, {["x"] = 4, ["y"] = 25, ["param1"] = 14, ["z"] = 1, ["name"] = "default:jungleleaves"}, {["x"] = 4, ["y"] = 25, ["param1"] = 13, ["z"] = 2, ["name"] = "default:jungleleaves"}, {["x"] = 4, ["y"] = 25, ["param1"] = 13, ["z"] = 3, ["name"] = "default:jungleleaves"}, {["x"] = 4, ["y"] = 25, ["param1"] = 13, ["z"] = 4, ["name"] = "default:jungleleaves"}, {["x"] = 4, ["y"] = 25, ["param1"] = 13, ["z"] = 5, ["name"] = "default:jungleleaves"}, {["x"] = 4, ["y"] = 25, ["param1"] = 14, ["z"] = 6, ["name"] = "default:jungleleaves"}, {["x"] = 4, ["y"] = 25, ["param1"] = 14, ["z"] = 7, ["name"] = "default:jungleleaves"}, {["x"] = 4, ["y"] = 25, ["param1"] = 14, ["z"] = 8, ["name"] = "default:jungleleaves"}, {["x"] = 4, ["param2"] = 1, ["y"] = 26, ["param1"] = 14, ["z"] = 2, ["name"] = "default:jungleleaves"}, {["x"] = 4, ["param2"] = 1, ["y"] = 26, ["param1"] = 14, ["z"] = 3, ["name"] = "default:jungleleaves"}, {["x"] = 4, ["y"] = 26, ["param1"] = 14, ["z"] = 4, ["name"] = "default:jungleleaves"}, {["x"] = 4, ["y"] = 26, ["param1"] = 14, ["z"] = 5, ["name"] = "default:jungleleaves"}, {["x"] = 5, ["param2"] = 3, ["y"] = 0, ["z"] = 2, ["name"] = "default:jungletree"}, {["x"] = 5, ["y"] = 0, ["z"] = 3, ["name"] = "default:jungletree"}, {["x"] = 5, ["y"] = 0, ["z"] = 4, ["name"] = "default:jungletree"}, {["x"] = 5, ["param2"] = 2, ["y"] = 0, ["z"] = 5, ["name"] = "default:jungletree"}, {["x"] = 5, ["param2"] = 3, ["y"] = 0, ["z"] = 6, ["name"] = "default:jungletree"}, {["x"] = 5, ["y"] = 1, ["z"] = 3, ["name"] = "default:jungletree"}, {["x"] = 5, ["y"] = 1, ["z"] = 4, ["name"] = "default:jungletree"}, {["x"] = 5, ["param2"] = 2, ["y"] = 1, ["z"] = 5, ["name"] = "default:jungletree"}, {["x"] = 5, ["y"] = 2, ["z"] = 3, ["name"] = "default:jungletree"}, {["x"] = 5, ["y"] = 2, ["z"] = 4, ["name"] = "default:jungletree"}, {["x"] = 5, ["param2"] = 3, ["y"] = 2, ["z"] = 5, ["name"] = "default:jungletree"}, {["x"] = 5, ["y"] = 3, ["z"] = 4, ["name"] = "default:jungletree"}, {["x"] = 5, ["y"] = 4, ["z"] = 4, ["name"] = "default:jungletree"}, {["x"] = 5, ["y"] = 5, ["z"] = 4, ["name"] = "default:jungletree"}, {["x"] = 5, ["y"] = 6, ["z"] = 4, ["name"] = "default:jungletree"}, {["x"] = 5, ["y"] = 7, ["param1"] = 12, ["z"] = 2, ["name"] = "default:jungleleaves"}, {["x"] = 5, ["y"] = 7, ["z"] = 4, ["name"] = "default:jungletree"}, {["x"] = 5, ["y"] = 7, ["param1"] = 12, ["z"] = 6, ["name"] = "default:jungleleaves"}, {["x"] = 5, ["y"] = 8, ["param1"] = 13, ["z"] = 1, ["name"] = "default:jungleleaves"}, {["x"] = 5, ["y"] = 8, ["param1"] = 12, ["z"] = 2, ["name"] = "default:jungleleaves"}, {["x"] = 5, ["y"] = 8, ["z"] = 4, ["name"] = "default:jungletree"}, {["x"] = 5, ["y"] = 8, ["param1"] = 11, ["z"] = 5, ["name"] = "default:jungleleaves"}, {["x"] = 5, ["y"] = 8, ["param1"] = 12, ["z"] = 6, ["name"] = "default:jungleleaves"}, {["x"] = 5, ["y"] = 8, ["param1"] = 13, ["z"] = 7, ["name"] = "default:jungleleaves"}, {["x"] = 5, ["y"] = 9, ["param1"] = 13, ["z"] = 1, ["name"] = "default:jungleleaves"}, {["x"] = 5, ["y"] = 9, ["param1"] = 12, ["z"] = 2, ["name"] = "default:jungleleaves"}, {["x"] = 5, ["y"] = 9, ["z"] = 4, ["name"] = "default:jungletree"}, {["x"] = 5, ["y"] = 9, ["param1"] = 11, ["z"] = 5, ["name"] = "default:jungleleaves"}, {["x"] = 5, ["y"] = 9, ["z"] = 6, ["name"] = "default:jungletree"}, {["x"] = 5, ["y"] = 9, ["param1"] = 13, ["z"] = 7, ["name"] = "default:jungleleaves"}, {["x"] = 5, ["y"] = 9, ["param1"] = 14, ["z"] = 8, ["name"] = "default:jungleleaves"}, {["x"] = 5, ["y"] = 10, ["param1"] = 12, ["z"] = 2, ["name"] = "default:jungleleaves"}, {["x"] = 5, ["y"] = 10, ["param1"] = 11, ["z"] = 3, ["name"] = "default:jungleleaves"}, {["x"] = 5, ["y"] = 10, ["z"] = 4, ["name"] = "default:jungletree"}, {["x"] = 5, ["y"] = 10, ["param1"] = 11, ["z"] = 5, ["name"] = "default:jungleleaves"}, {["x"] = 5, ["y"] = 10, ["param1"] = 12, ["z"] = 6, ["name"] = "default:jungleleaves"}, {["x"] = 5, ["y"] = 10, ["param1"] = 13, ["z"] = 7, ["name"] = "default:jungleleaves"}, {["x"] = 5, ["y"] = 11, ["param1"] = 12, ["z"] = 2, ["name"] = "default:jungleleaves"}, {["x"] = 5, ["y"] = 11, ["param1"] = 11, ["z"] = 3, ["name"] = "default:jungleleaves"}, {["x"] = 5, ["y"] = 11, ["z"] = 4, ["name"] = "default:jungletree"}, {["x"] = 5, ["y"] = 11, ["z"] = 5, ["name"] = "default:jungletree"}, {["x"] = 5, ["y"] = 11, ["param1"] = 12, ["z"] = 6, ["name"] = "default:jungleleaves"}, {["x"] = 5, ["y"] = 12, ["param1"] = 14, ["z"] = 0, ["name"] = "default:jungleleaves"}, {["x"] = 5, ["y"] = 12, ["param1"] = 12, ["z"] = 2, ["name"] = "default:jungleleaves"}, {["x"] = 5, ["y"] = 12, ["param1"] = 11, ["z"] = 3, ["name"] = "default:jungleleaves"}, {["x"] = 5, ["y"] = 12, ["z"] = 4, ["name"] = "default:jungletree"}, {["x"] = 5, ["y"] = 12, ["param1"] = 11, ["z"] = 5, ["name"] = "default:jungleleaves"}, {["x"] = 5, ["y"] = 12, ["param1"] = 12, ["z"] = 6, ["name"] = "default:jungleleaves"}, {["x"] = 5, ["y"] = 12, ["param1"] = 13, ["z"] = 7, ["name"] = "default:jungleleaves"}, {["x"] = 5, ["y"] = 13, ["param1"] = 14, ["z"] = 1, ["name"] = "default:jungleleaves"}, {["x"] = 5, ["y"] = 13, ["param1"] = 13, ["z"] = 2, ["name"] = "default:jungleleaves"}, {["x"] = 5, ["y"] = 13, ["z"] = 3, ["name"] = "default:jungletree"}, {["x"] = 5, ["y"] = 13, ["z"] = 4, ["name"] = "default:jungletree"}, {["x"] = 5, ["y"] = 13, ["param1"] = 12, ["z"] = 5, ["name"] = "default:jungleleaves"}, {["x"] = 5, ["y"] = 13, ["z"] = 6, ["name"] = "default:jungletree"}, {["x"] = 5, ["y"] = 13, ["param1"] = 13, ["z"] = 7, ["name"] = "default:jungleleaves"}, {["x"] = 5, ["y"] = 14, ["param1"] = 13, ["z"] = 2, ["name"] = "default:jungleleaves"}, {["x"] = 5, ["y"] = 14, ["param1"] = 12, ["z"] = 3, ["name"] = "default:jungleleaves"}, {["x"] = 5, ["y"] = 14, ["z"] = 4, ["name"] = "default:jungletree"}, {["x"] = 5, ["y"] = 14, ["param1"] = 12, ["z"] = 5, ["name"] = "default:jungleleaves"}, {["x"] = 5, ["y"] = 14, ["param1"] = 12, ["z"] = 6, ["name"] = "default:jungleleaves"}, {["x"] = 5, ["y"] = 14, ["param1"] = 13, ["z"] = 7, ["name"] = "default:jungleleaves"}, {["x"] = 5, ["y"] = 14, ["param1"] = 14, ["z"] = 8, ["name"] = "default:jungleleaves"}, {["x"] = 5, ["y"] = 15, ["param1"] = 13, ["z"] = 2, ["name"] = "default:jungleleaves"}, {["x"] = 5, ["y"] = 15, ["z"] = 4, ["name"] = "default:jungletree"}, {["x"] = 5, ["y"] = 15, ["z"] = 5, ["name"] = "default:jungletree"}, {["x"] = 5, ["y"] = 15, ["param1"] = 12, ["z"] = 6, ["name"] = "default:jungleleaves"}, {["x"] = 5, ["y"] = 15, ["param1"] = 13, ["z"] = 7, ["name"] = "default:jungleleaves"}, {["x"] = 5, ["y"] = 16, ["param1"] = 14, ["z"] = 1, ["name"] = "default:jungleleaves"}, {["x"] = 5, ["y"] = 16, ["param1"] = 13, ["z"] = 2, ["name"] = "default:jungleleaves"}, {["x"] = 5, ["y"] = 16, ["param1"] = 12, ["z"] = 3, ["name"] = "default:jungleleaves"}, {["x"] = 5, ["y"] = 16, ["z"] = 4, ["name"] = "default:jungletree"}, {["x"] = 5, ["y"] = 16, ["param1"] = 12, ["z"] = 5, ["name"] = "default:jungleleaves"}, {["x"] = 5, ["y"] = 16, ["param1"] = 12, ["z"] = 6, ["name"] = "default:jungleleaves"}, {["x"] = 5, ["y"] = 16, ["param1"] = 13, ["z"] = 7, ["name"] = "default:jungleleaves"}, {["x"] = 5, ["y"] = 16, ["param1"] = 14, ["z"] = 8, ["name"] = "default:jungleleaves"}, {["x"] = 5, ["y"] = 17, ["param1"] = 14, ["z"] = 1, ["name"] = "default:jungleleaves"}, {["x"] = 5, ["y"] = 17, ["param1"] = 13, ["z"] = 2, ["name"] = "default:jungleleaves"}, {["x"] = 5, ["y"] = 17, ["param1"] = 12, ["z"] = 3, ["name"] = "default:jungleleaves"}, {["x"] = 5, ["y"] = 17, ["z"] = 4, ["name"] = "default:jungletree"}, {["x"] = 5, ["y"] = 17, ["param1"] = 12, ["z"] = 5, ["name"] = "default:jungleleaves"}, {["x"] = 5, ["y"] = 17, ["param1"] = 13, ["z"] = 7, ["name"] = "default:jungleleaves"}, {["x"] = 5, ["y"] = 18, ["param1"] = 12, ["z"] = 3, ["name"] = "default:jungleleaves"}, {["x"] = 5, ["y"] = 18, ["z"] = 4, ["name"] = "default:jungletree"}, {["x"] = 5, ["y"] = 18, ["param1"] = 12, ["z"] = 5, ["name"] = "default:jungleleaves"}, {["x"] = 5, ["y"] = 19, ["z"] = 4, ["name"] = "default:jungletree"}, {["x"] = 5, ["y"] = 20, ["param1"] = 13, ["z"] = 2, ["name"] = "default:jungleleaves"}, {["x"] = 5, ["y"] = 20, ["param1"] = 12, ["z"] = 3, ["name"] = "default:jungleleaves"}, {["x"] = 5, ["y"] = 20, ["z"] = 4, ["name"] = "default:jungletree"}, {["x"] = 5, ["y"] = 20, ["param1"] = 12, ["z"] = 5, ["name"] = "default:jungleleaves"}, {["x"] = 5, ["y"] = 20, ["param1"] = 12, ["z"] = 6, ["name"] = "default:jungleleaves"}, {["x"] = 5, ["y"] = 20, ["param1"] = 13, ["z"] = 7, ["name"] = "default:jungleleaves"}, {["x"] = 5, ["y"] = 21, ["param1"] = 14, ["z"] = 1, ["name"] = "default:jungleleaves"}, {["x"] = 5, ["y"] = 21, ["param1"] = 13, ["z"] = 2, ["name"] = "default:jungleleaves"}, {["x"] = 5, ["y"] = 21, ["param1"] = 12, ["z"] = 3, ["name"] = "default:jungleleaves"}, {["x"] = 5, ["y"] = 21, ["z"] = 4, ["name"] = "default:jungletree"}, {["x"] = 5, ["y"] = 21, ["param1"] = 12, ["z"] = 5, ["name"] = "default:jungleleaves"}, {["x"] = 5, ["y"] = 21, ["param1"] = 12, ["z"] = 6, ["name"] = "default:jungleleaves"}, {["x"] = 5, ["y"] = 22, ["param1"] = 12, ["z"] = 3, ["name"] = "default:jungleleaves"}, {["x"] = 5, ["y"] = 22, ["z"] = 4, ["name"] = "default:jungletree"}, {["x"] = 5, ["y"] = 22, ["param1"] = 12, ["z"] = 5, ["name"] = "default:jungleleaves"}, {["x"] = 5, ["y"] = 22, ["param1"] = 12, ["z"] = 6, ["name"] = "default:jungleleaves"}, {["x"] = 5, ["y"] = 23, ["param1"] = 14, ["z"] = 1, ["name"] = "default:jungleleaves"}, {["x"] = 5, ["y"] = 23, ["param1"] = 12, ["z"] = 3, ["name"] = "default:jungleleaves"}, {["x"] = 5, ["y"] = 23, ["z"] = 5, ["name"] = "default:jungletree"}, {["x"] = 5, ["y"] = 23, ["param1"] = 13, ["z"] = 7, ["name"] = "default:jungleleaves"}, {["x"] = 5, ["y"] = 23, ["param1"] = 14, ["z"] = 8, ["name"] = "default:jungleleaves"}, {["x"] = 5, ["y"] = 24, ["param1"] = 14, ["z"] = 1, ["name"] = "default:jungleleaves"}, {["x"] = 5, ["y"] = 24, ["param1"] = 13, ["z"] = 2, ["name"] = "default:jungleleaves"}, {["x"] = 5, ["y"] = 24, ["param1"] = 12, ["z"] = 3, ["name"] = "default:jungleleaves"}, {["x"] = 5, ["y"] = 24, ["param1"] = 12, ["z"] = 5, ["name"] = "default:jungleleaves"}, {["x"] = 5, ["y"] = 24, ["param1"] = 12, ["z"] = 6, ["name"] = "default:jungleleaves"}, {["x"] = 5, ["y"] = 24, ["param1"] = 13, ["z"] = 7, ["name"] = "default:jungleleaves"}, {["x"] = 5, ["y"] = 24, ["param1"] = 14, ["z"] = 8, ["name"] = "default:jungleleaves"}, {["x"] = 5, ["y"] = 25, ["param1"] = 14, ["z"] = 2, ["name"] = "default:jungleleaves"}, {["x"] = 5, ["y"] = 25, ["param1"] = 13, ["z"] = 3, ["name"] = "default:jungleleaves"}, {["x"] = 5, ["y"] = 25, ["param1"] = 13, ["z"] = 4, ["name"] = "default:jungleleaves"}, {["x"] = 5, ["y"] = 25, ["param1"] = 13, ["z"] = 5, ["name"] = "default:jungleleaves"}, {["x"] = 5, ["y"] = 25, ["param1"] = 13, ["z"] = 6, ["name"] = "default:jungleleaves"}, {["x"] = 5, ["y"] = 25, ["param1"] = 14, ["z"] = 7, ["name"] = "default:jungleleaves"}, {["x"] = 5, ["param2"] = 1, ["y"] = 26, ["param1"] = 14, ["z"] = 3, ["name"] = "default:jungleleaves"}, {["x"] = 5, ["param2"] = 1, ["y"] = 26, ["param1"] = 14, ["z"] = 4, ["name"] = "default:jungleleaves"}, {["x"] = 5, ["y"] = 26, ["param1"] = 14, ["z"] = 5, ["name"] = "default:jungleleaves"}, {["x"] = 5, ["param2"] = 1, ["y"] = 26, ["param1"] = 14, ["z"] = 6, ["name"] = "default:jungleleaves"}, {["x"] = 6, ["param2"] = 3, ["y"] = 0, ["z"] = 3, ["name"] = "default:jungletree"}, {["x"] = 6, ["param2"] = 3, ["y"] = 0, ["z"] = 4, ["name"] = "default:jungletree"}, {["x"] = 6, ["param2"] = 2, ["y"] = 0, ["z"] = 5, ["name"] = "default:jungletree"}, {["x"] = 6, ["param2"] = 3, ["y"] = 1, ["z"] = 4, ["name"] = "default:jungletree"}, {["x"] = 6, ["y"] = 7, ["param1"] = 12, ["z"] = 2, ["name"] = "default:jungleleaves"}, {["x"] = 6, ["y"] = 7, ["param1"] = 12, ["z"] = 6, ["name"] = "default:jungleleaves"}, {["x"] = 6, ["y"] = 8, ["param1"] = 13, ["z"] = 1, ["name"] = "default:jungleleaves"}, {["x"] = 6, ["y"] = 8, ["param1"] = 12, ["z"] = 2, ["name"] = "default:jungleleaves"}, {["x"] = 6, ["y"] = 8, ["param1"] = 12, ["z"] = 3, ["name"] = "default:jungleleaves"}, {["x"] = 6, ["y"] = 8, ["param1"] = 12, ["z"] = 6, ["name"] = "default:jungleleaves"}, {["x"] = 6, ["y"] = 8, ["param1"] = 13, ["z"] = 7, ["name"] = "default:jungleleaves"}, {["x"] = 6, ["y"] = 9, ["param1"] = 14, ["z"] = 0, ["name"] = "default:jungleleaves"}, {["x"] = 6, ["y"] = 9, ["param1"] = 13, ["z"] = 1, ["name"] = "default:jungleleaves"}, {["x"] = 6, ["y"] = 9, ["param1"] = 12, ["z"] = 2, ["name"] = "default:jungleleaves"}, {["x"] = 6, ["y"] = 9, ["param1"] = 12, ["z"] = 3, ["name"] = "default:jungleleaves"}, {["x"] = 6, ["y"] = 9, ["param1"] = 11, ["z"] = 4, ["name"] = "default:jungleleaves"}, {["x"] = 6, ["y"] = 9, ["param1"] = 12, ["z"] = 5, ["name"] = "default:jungleleaves"}, {["x"] = 6, ["y"] = 9, ["param1"] = 12, ["z"] = 6, ["name"] = "default:jungleleaves"}, {["x"] = 6, ["y"] = 9, ["param1"] = 13, ["z"] = 7, ["name"] = "default:jungleleaves"}, {["x"] = 6, ["y"] = 9, ["param1"] = 14, ["z"] = 8, ["name"] = "default:jungleleaves"}, {["x"] = 6, ["y"] = 10, ["param1"] = 14, ["z"] = 0, ["name"] = "default:jungleleaves"}, {["x"] = 6, ["y"] = 10, ["param1"] = 13, ["z"] = 1, ["name"] = "default:jungleleaves"}, {["x"] = 6, ["y"] = 10, ["param1"] = 12, ["z"] = 2, ["name"] = "default:jungleleaves"}, {["x"] = 6, ["y"] = 10, ["param1"] = 12, ["z"] = 3, ["name"] = "default:jungleleaves"}, {["x"] = 6, ["y"] = 10, ["param1"] = 12, ["z"] = 6, ["name"] = "default:jungleleaves"}, {["x"] = 6, ["y"] = 10, ["param1"] = 14, ["z"] = 8, ["name"] = "default:jungleleaves"}, {["x"] = 6, ["y"] = 11, ["param1"] = 14, ["z"] = 1, ["name"] = "default:jungleleaves"}, {["x"] = 6, ["y"] = 11, ["param1"] = 13, ["z"] = 2, ["name"] = "default:jungleleaves"}, {["x"] = 6, ["y"] = 11, ["param1"] = 12, ["z"] = 3, ["name"] = "default:jungleleaves"}, {["x"] = 6, ["y"] = 11, ["param1"] = 12, ["z"] = 4, ["name"] = "default:jungleleaves"}, {["x"] = 6, ["y"] = 11, ["param1"] = 12, ["z"] = 5, ["name"] = "default:jungleleaves"}, {["x"] = 6, ["y"] = 12, ["param1"] = 14, ["z"] = 1, ["name"] = "default:jungleleaves"}, {["x"] = 6, ["y"] = 12, ["param1"] = 13, ["z"] = 2, ["name"] = "default:jungleleaves"}, {["x"] = 6, ["y"] = 12, ["param1"] = 11, ["z"] = 4, ["name"] = "default:jungleleaves"}, {["x"] = 6, ["y"] = 12, ["param1"] = 12, ["z"] = 5, ["name"] = "default:jungleleaves"}, {["x"] = 6, ["y"] = 13, ["param1"] = 14, ["z"] = 1, ["name"] = "default:jungleleaves"}, {["x"] = 6, ["y"] = 13, ["z"] = 2, ["name"] = "default:jungletree"}, {["x"] = 6, ["y"] = 13, ["param1"] = 12, ["z"] = 3, ["name"] = "default:jungleleaves"}, {["x"] = 6, ["y"] = 13, ["param1"] = 12, ["z"] = 4, ["name"] = "default:jungleleaves"}, {["x"] = 6, ["y"] = 13, ["param1"] = 13, ["z"] = 5, ["name"] = "default:jungleleaves"}, {["x"] = 6, ["y"] = 13, ["param1"] = 12, ["z"] = 6, ["name"] = "default:jungleleaves"}, {["x"] = 6, ["y"] = 13, ["param1"] = 13, ["z"] = 7, ["name"] = "default:jungleleaves"}, {["x"] = 6, ["y"] = 13, ["param1"] = 14, ["z"] = 8, ["name"] = "default:jungleleaves"}, {["x"] = 6, ["y"] = 14, ["param1"] = 14, ["z"] = 1, ["name"] = "default:jungleleaves"}, {["x"] = 6, ["y"] = 14, ["param1"] = 13, ["z"] = 2, ["name"] = "default:jungleleaves"}, {["x"] = 6, ["y"] = 14, ["param1"] = 13, ["z"] = 5, ["name"] = "default:jungleleaves"}, {["x"] = 6, ["y"] = 14, ["param1"] = 13, ["z"] = 6, ["name"] = "default:jungleleaves"}, {["x"] = 6, ["y"] = 14, ["param1"] = 13, ["z"] = 7, ["name"] = "default:jungleleaves"}, {["x"] = 6, ["y"] = 14, ["param1"] = 14, ["z"] = 8, ["name"] = "default:jungleleaves"}, {["x"] = 6, ["y"] = 15, ["param1"] = 13, ["z"] = 2, ["name"] = "default:jungleleaves"}, {["x"] = 6, ["y"] = 15, ["param1"] = 12, ["z"] = 4, ["name"] = "default:jungleleaves"}, {["x"] = 6, ["y"] = 15, ["param1"] = 13, ["z"] = 5, ["name"] = "default:jungleleaves"}, {["x"] = 6, ["y"] = 15, ["z"] = 6, ["name"] = "default:jungletree"}, {["x"] = 6, ["y"] = 15, ["param1"] = 13, ["z"] = 7, ["name"] = "default:jungleleaves"}, {["x"] = 6, ["y"] = 15, ["param1"] = 14, ["z"] = 8, ["name"] = "default:jungleleaves"}, {["x"] = 6, ["y"] = 16, ["param1"] = 13, ["z"] = 2, ["name"] = "default:jungleleaves"}, {["x"] = 6, ["y"] = 16, ["param1"] = 12, ["z"] = 3, ["name"] = "default:jungleleaves"}, {["x"] = 6, ["y"] = 16, ["param1"] = 13, ["z"] = 5, ["name"] = "default:jungleleaves"}, {["x"] = 6, ["y"] = 16, ["param1"] = 13, ["z"] = 6, ["name"] = "default:jungleleaves"}, {["x"] = 6, ["y"] = 16, ["param1"] = 14, ["z"] = 7, ["name"] = "default:jungleleaves"}, {["x"] = 6, ["y"] = 16, ["param1"] = 14, ["z"] = 8, ["name"] = "default:jungleleaves"}, {["x"] = 6, ["y"] = 17, ["param1"] = 12, ["z"] = 3, ["name"] = "default:jungleleaves"}, {["x"] = 6, ["y"] = 17, ["param1"] = 12, ["z"] = 4, ["name"] = "default:jungleleaves"}, {["x"] = 6, ["y"] = 17, ["param1"] = 13, ["z"] = 5, ["name"] = "default:jungleleaves"}, {["x"] = 6, ["y"] = 17, ["param1"] = 13, ["z"] = 6, ["name"] = "default:jungleleaves"}, {["x"] = 6, ["y"] = 17, ["param1"] = 14, ["z"] = 7, ["name"] = "default:jungleleaves"}, {["x"] = 6, ["y"] = 18, ["param1"] = 13, ["z"] = 2, ["name"] = "default:jungleleaves"}, {["x"] = 6, ["y"] = 18, ["param1"] = 12, ["z"] = 3, ["name"] = "default:jungleleaves"}, {["x"] = 6, ["y"] = 18, ["z"] = 4, ["name"] = "default:jungletree"}, {["x"] = 6, ["y"] = 18, ["param1"] = 13, ["z"] = 5, ["name"] = "default:jungleleaves"}, {["x"] = 6, ["y"] = 19, ["param1"] = 12, ["z"] = 3, ["name"] = "default:jungleleaves"}, {["x"] = 6, ["y"] = 19, ["param1"] = 12, ["z"] = 4, ["name"] = "default:jungleleaves"}, {["x"] = 6, ["y"] = 19, ["param1"] = 13, ["z"] = 5, ["name"] = "default:jungleleaves"}, {["x"] = 6, ["y"] = 20, ["param1"] = 13, ["z"] = 3, ["name"] = "default:jungleleaves"}, {["x"] = 6, ["y"] = 20, ["param1"] = 13, ["z"] = 4, ["name"] = "default:jungleleaves"}, {["x"] = 6, ["y"] = 20, ["param1"] = 13, ["z"] = 6, ["name"] = "default:jungleleaves"}, {["x"] = 6, ["y"] = 21, ["param1"] = 13, ["z"] = 2, ["name"] = "default:jungleleaves"}, {["x"] = 6, ["y"] = 21, ["param1"] = 13, ["z"] = 3, ["name"] = "default:jungleleaves"}, {["x"] = 6, ["y"] = 21, ["param1"] = 13, ["z"] = 4, ["name"] = "default:jungleleaves"}, {["x"] = 6, ["y"] = 21, ["param1"] = 13, ["z"] = 5, ["name"] = "default:jungleleaves"}, {["x"] = 6, ["y"] = 21, ["param1"] = 13, ["z"] = 6, ["name"] = "default:jungleleaves"}, {["x"] = 6, ["y"] = 22, ["param1"] = 13, ["z"] = 3, ["name"] = "default:jungleleaves"}, {["x"] = 6, ["y"] = 22, ["param1"] = 13, ["z"] = 4, ["name"] = "default:jungleleaves"}, {["x"] = 6, ["y"] = 22, ["param1"] = 14, ["z"] = 7, ["name"] = "default:jungleleaves"}, {["x"] = 6, ["y"] = 23, ["param1"] = 14, ["z"] = 1, ["name"] = "default:jungleleaves"}, {["x"] = 6, ["y"] = 23, ["param1"] = 13, ["z"] = 2, ["name"] = "default:jungleleaves"}, {["x"] = 6, ["y"] = 23, ["param1"] = 13, ["z"] = 3, ["name"] = "default:jungleleaves"}, {["x"] = 6, ["y"] = 23, ["param1"] = 13, ["z"] = 5, ["name"] = "default:jungleleaves"}, {["x"] = 6, ["y"] = 23, ["param1"] = 13, ["z"] = 6, ["name"] = "default:jungleleaves"}, {["x"] = 6, ["y"] = 24, ["param1"] = 14, ["z"] = 2, ["name"] = "default:jungleleaves"}, {["x"] = 6, ["y"] = 24, ["param1"] = 13, ["z"] = 3, ["name"] = "default:jungleleaves"}, {["x"] = 6, ["y"] = 24, ["param1"] = 13, ["z"] = 4, ["name"] = "default:jungleleaves"}, {["x"] = 6, ["y"] = 24, ["param1"] = 13, ["z"] = 5, ["name"] = "default:jungleleaves"}, {["x"] = 6, ["y"] = 24, ["param1"] = 13, ["z"] = 6, ["name"] = "default:jungleleaves"}, {["x"] = 6, ["y"] = 24, ["param1"] = 14, ["z"] = 7, ["name"] = "default:jungleleaves"}, {["x"] = 6, ["y"] = 25, ["param1"] = 14, ["z"] = 3, ["name"] = "default:jungleleaves"}, {["x"] = 6, ["y"] = 25, ["param1"] = 14, ["z"] = 4, ["name"] = "default:jungleleaves"}, {["x"] = 6, ["y"] = 25, ["param1"] = 13, ["z"] = 5, ["name"] = "default:jungleleaves"}, {["x"] = 6, ["y"] = 25, ["param1"] = 14, ["z"] = 6, ["name"] = "default:jungleleaves"}, {["x"] = 6, ["param2"] = 1, ["y"] = 26, ["param1"] = 14, ["z"] = 5, ["name"] = "default:jungleleaves"}, {["x"] = 7, ["y"] = 7, ["param1"] = 13, ["z"] = 2, ["name"] = "default:jungleleaves"}, {["x"] = 7, ["y"] = 7, ["param1"] = 13, ["z"] = 3, ["name"] = "default:jungleleaves"}, {["x"] = 7, ["y"] = 7, ["param1"] = 13, ["z"] = 4, ["name"] = "default:jungleleaves"}, {["x"] = 7, ["y"] = 7, ["param1"] = 13, ["z"] = 5, ["name"] = "default:jungleleaves"}, {["x"] = 7, ["y"] = 7, ["param1"] = 13, ["z"] = 6, ["name"] = "default:jungleleaves"}, {["x"] = 7, ["y"] = 7, ["param1"] = 13, ["z"] = 7, ["name"] = "default:jungleleaves"}, {["x"] = 7, ["y"] = 8, ["param1"] = 14, ["z"] = 0, ["name"] = "default:jungleleaves"}, {["x"] = 7, ["y"] = 8, ["param1"] = 13, ["z"] = 2, ["name"] = "default:jungleleaves"}, {["x"] = 7, ["y"] = 8, ["param1"] = 13, ["z"] = 3, ["name"] = "default:jungleleaves"}, {["x"] = 7, ["y"] = 8, ["param1"] = 13, ["z"] = 4, ["name"] = "default:jungleleaves"}, {["x"] = 7, ["y"] = 8, ["param1"] = 13, ["z"] = 5, ["name"] = "default:jungleleaves"}, {["x"] = 7, ["y"] = 8, ["param1"] = 13, ["z"] = 7, ["name"] = "default:jungleleaves"}, {["x"] = 7, ["y"] = 9, ["param1"] = 13, ["z"] = 2, ["name"] = "default:jungleleaves"}, {["x"] = 7, ["y"] = 9, ["param1"] = 13, ["z"] = 3, ["name"] = "default:jungleleaves"}, {["x"] = 7, ["y"] = 9, ["z"] = 4, ["name"] = "default:jungletree"}, {["x"] = 7, ["y"] = 9, ["param1"] = 13, ["z"] = 5, ["name"] = "default:jungleleaves"}, {["x"] = 7, ["y"] = 9, ["param1"] = 13, ["z"] = 7, ["name"] = "default:jungleleaves"}, {["x"] = 7, ["y"] = 9, ["param1"] = 14, ["z"] = 8, ["name"] = "default:jungleleaves"}, {["x"] = 7, ["y"] = 10, ["param1"] = 14, ["z"] = 0, ["name"] = "default:jungleleaves"}, {["x"] = 7, ["y"] = 10, ["param1"] = 13, ["z"] = 1, ["name"] = "default:jungleleaves"}, {["x"] = 7, ["y"] = 10, ["z"] = 2, ["name"] = "default:jungletree"}, {["x"] = 7, ["y"] = 10, ["param1"] = 13, ["z"] = 3, ["name"] = "default:jungleleaves"}, {["x"] = 7, ["y"] = 10, ["param1"] = 13, ["z"] = 4, ["name"] = "default:jungleleaves"}, {["x"] = 7, ["y"] = 10, ["param1"] = 13, ["z"] = 5, ["name"] = "default:jungleleaves"}, {["x"] = 7, ["y"] = 10, ["param1"] = 13, ["z"] = 6, ["name"] = "default:jungleleaves"}, {["x"] = 7, ["y"] = 10, ["param1"] = 13, ["z"] = 7, ["name"] = "default:jungleleaves"}, {["x"] = 7, ["y"] = 10, ["param1"] = 14, ["z"] = 8, ["name"] = "default:jungleleaves"}, {["x"] = 7, ["y"] = 11, ["param1"] = 14, ["z"] = 1, ["name"] = "default:jungleleaves"}, {["x"] = 7, ["y"] = 11, ["param1"] = 13, ["z"] = 2, ["name"] = "default:jungleleaves"}, {["x"] = 7, ["y"] = 11, ["param1"] = 13, ["z"] = 3, ["name"] = "default:jungleleaves"}, {["x"] = 7, ["y"] = 11, ["param1"] = 13, ["z"] = 5, ["name"] = "default:jungleleaves"}, {["x"] = 7, ["y"] = 11, ["param1"] = 13, ["z"] = 6, ["name"] = "default:jungleleaves"}, {["x"] = 7, ["y"] = 11, ["param1"] = 13, ["z"] = 7, ["name"] = "default:jungleleaves"}, {["x"] = 7, ["y"] = 12, ["param1"] = 14, ["z"] = 1, ["name"] = "default:jungleleaves"}, {["x"] = 7, ["y"] = 12, ["z"] = 2, ["name"] = "default:jungletree"}, {["x"] = 7, ["y"] = 12, ["param1"] = 13, ["z"] = 3, ["name"] = "default:jungleleaves"}, {["x"] = 7, ["y"] = 12, ["z"] = 4, ["name"] = "default:jungletree"}, {["x"] = 7, ["y"] = 12, ["param1"] = 13, ["z"] = 5, ["name"] = "default:jungleleaves"}, {["x"] = 7, ["y"] = 12, ["param1"] = 13, ["z"] = 6, ["name"] = "default:jungleleaves"}, {["x"] = 7, ["y"] = 12, ["param1"] = 13, ["z"] = 7, ["name"] = "default:jungleleaves"}, {["x"] = 7, ["y"] = 12, ["param1"] = 14, ["z"] = 8, ["name"] = "default:jungleleaves"}, {["x"] = 7, ["y"] = 13, ["param1"] = 14, ["z"] = 1, ["name"] = "default:jungleleaves"}, {["x"] = 7, ["y"] = 13, ["param1"] = 13, ["z"] = 2, ["name"] = "default:jungleleaves"}, {["x"] = 7, ["y"] = 13, ["param1"] = 13, ["z"] = 3, ["name"] = "default:jungleleaves"}, {["x"] = 7, ["y"] = 13, ["param1"] = 13, ["z"] = 4, ["name"] = "default:jungleleaves"}, {["x"] = 7, ["y"] = 13, ["param1"] = 14, ["z"] = 5, ["name"] = "default:jungleleaves"}, {["x"] = 7, ["y"] = 13, ["param1"] = 13, ["z"] = 7, ["name"] = "default:jungleleaves"}, {["x"] = 7, ["y"] = 14, ["param1"] = 14, ["z"] = 2, ["name"] = "default:jungleleaves"}, {["x"] = 7, ["y"] = 14, ["param1"] = 13, ["z"] = 3, ["name"] = "default:jungleleaves"}, {["x"] = 7, ["y"] = 14, ["param1"] = 13, ["z"] = 4, ["name"] = "default:jungleleaves"}, {["x"] = 7, ["y"] = 14, ["param1"] = 13, ["z"] = 7, ["name"] = "default:jungleleaves"}, {["x"] = 7, ["y"] = 14, ["param1"] = 14, ["z"] = 8, ["name"] = "default:jungleleaves"}, {["x"] = 7, ["y"] = 15, ["param1"] = 14, ["z"] = 2, ["name"] = "default:jungleleaves"}, {["x"] = 7, ["y"] = 15, ["param1"] = 13, ["z"] = 4, ["name"] = "default:jungleleaves"}, {["x"] = 7, ["y"] = 15, ["param1"] = 14, ["z"] = 5, ["name"] = "default:jungleleaves"}, {["x"] = 7, ["y"] = 15, ["param1"] = 14, ["z"] = 6, ["name"] = "default:jungleleaves"}, {["x"] = 7, ["y"] = 15, ["param1"] = 14, ["z"] = 7, ["name"] = "default:jungleleaves"}, {["x"] = 7, ["y"] = 15, ["param1"] = 14, ["z"] = 8, ["name"] = "default:jungleleaves"}, {["x"] = 7, ["y"] = 16, ["param1"] = 14, ["z"] = 2, ["name"] = "default:jungleleaves"}, {["x"] = 7, ["y"] = 16, ["param1"] = 14, ["z"] = 6, ["name"] = "default:jungleleaves"}, {["x"] = 7, ["y"] = 17, ["param1"] = 13, ["z"] = 4, ["name"] = "default:jungleleaves"}, {["x"] = 7, ["y"] = 17, ["param1"] = 14, ["z"] = 5, ["name"] = "default:jungleleaves"}, {["x"] = 7, ["y"] = 18, ["param1"] = 13, ["z"] = 3, ["name"] = "default:jungleleaves"}, {["x"] = 7, ["y"] = 18, ["param1"] = 13, ["z"] = 4, ["name"] = "default:jungleleaves"}, {["x"] = 7, ["y"] = 18, ["param1"] = 14, ["z"] = 5, ["name"] = "default:jungleleaves"}, {["x"] = 7, ["y"] = 19, ["param1"] = 13, ["z"] = 3, ["name"] = "default:jungleleaves"}, {["x"] = 7, ["y"] = 19, ["param1"] = 13, ["z"] = 4, ["name"] = "default:jungleleaves"}, {["x"] = 7, ["y"] = 19, ["param1"] = 14, ["z"] = 5, ["name"] = "default:jungleleaves"}, {["x"] = 7, ["y"] = 22, ["param1"] = 14, ["z"] = 4, ["name"] = "default:jungleleaves"}, {["x"] = 7, ["y"] = 22, ["param1"] = 14, ["z"] = 5, ["name"] = "default:jungleleaves"}, {["x"] = 7, ["y"] = 22, ["param1"] = 14, ["z"] = 6, ["name"] = "default:jungleleaves"}, {["x"] = 7, ["y"] = 23, ["param1"] = 14, ["z"] = 2, ["name"] = "default:jungleleaves"}, {["x"] = 7, ["y"] = 23, ["param1"] = 14, ["z"] = 4, ["name"] = "default:jungleleaves"}, {["x"] = 7, ["y"] = 23, ["param1"] = 14, ["z"] = 5, ["name"] = "default:jungleleaves"}, {["x"] = 7, ["y"] = 23, ["param1"] = 14, ["z"] = 6, ["name"] = "default:jungleleaves"}, {["x"] = 7, ["y"] = 24, ["param1"] = 14, ["z"] = 2, ["name"] = "default:jungleleaves"}, {["x"] = 7, ["y"] = 24, ["param1"] = 14, ["z"] = 3, ["name"] = "default:jungleleaves"}, {["x"] = 7, ["y"] = 24, ["param1"] = 14, ["z"] = 4, ["name"] = "default:jungleleaves"}, {["x"] = 7, ["y"] = 24, ["param1"] = 14, ["z"] = 5, ["name"] = "default:jungleleaves"}, {["x"] = 7, ["y"] = 24, ["param1"] = 14, ["z"] = 6, ["name"] = "default:jungleleaves"}, {["x"] = 7, ["y"] = 25, ["param1"] = 14, ["z"] = 3, ["name"] = "default:jungleleaves"}, {["x"] = 7, ["y"] = 25, ["param1"] = 14, ["z"] = 5, ["name"] = "default:jungleleaves"}, {["x"] = 8, ["y"] = 7, ["param1"] = 14, ["z"] = 2, ["name"] = "default:jungleleaves"}, {["x"] = 8, ["y"] = 7, ["param1"] = 14, ["z"] = 4, ["name"] = "default:jungleleaves"}, {["x"] = 8, ["y"] = 7, ["param1"] = 14, ["z"] = 5, ["name"] = "default:jungleleaves"}, {["x"] = 8, ["y"] = 8, ["param1"] = 14, ["z"] = 1, ["name"] = "default:jungleleaves"}, {["x"] = 8, ["y"] = 8, ["param1"] = 14, ["z"] = 4, ["name"] = "default:jungleleaves"}, {["x"] = 8, ["y"] = 8, ["param1"] = 14, ["z"] = 5, ["name"] = "default:jungleleaves"}, {["x"] = 8, ["y"] = 9, ["param1"] = 14, ["z"] = 1, ["name"] = "default:jungleleaves"}, {["x"] = 8, ["y"] = 9, ["param1"] = 14, ["z"] = 2, ["name"] = "default:jungleleaves"}, {["x"] = 8, ["y"] = 9, ["param1"] = 14, ["z"] = 3, ["name"] = "default:jungleleaves"}, {["x"] = 8, ["y"] = 9, ["param1"] = 14, ["z"] = 4, ["name"] = "default:jungleleaves"}, {["x"] = 8, ["y"] = 9, ["param1"] = 14, ["z"] = 5, ["name"] = "default:jungleleaves"}, {["x"] = 8, ["y"] = 10, ["param1"] = 14, ["z"] = 1, ["name"] = "default:jungleleaves"}, {["x"] = 8, ["y"] = 10, ["param1"] = 14, ["z"] = 2, ["name"] = "default:jungleleaves"}, {["x"] = 8, ["y"] = 10, ["param1"] = 14, ["z"] = 4, ["name"] = "default:jungleleaves"}, {["x"] = 8, ["y"] = 10, ["param1"] = 14, ["z"] = 5, ["name"] = "default:jungleleaves"}, {["x"] = 8, ["y"] = 11, ["param1"] = 14, ["z"] = 2, ["name"] = "default:jungleleaves"}, {["x"] = 8, ["y"] = 11, ["param1"] = 14, ["z"] = 4, ["name"] = "default:jungleleaves"}, {["x"] = 8, ["y"] = 11, ["param1"] = 14, ["z"] = 5, ["name"] = "default:jungleleaves"}, {["x"] = 8, ["y"] = 12, ["param1"] = 14, ["z"] = 1, ["name"] = "default:jungleleaves"}, {["x"] = 8, ["y"] = 12, ["param1"] = 14, ["z"] = 2, ["name"] = "default:jungleleaves"}, {["x"] = 8, ["y"] = 12, ["param1"] = 14, ["z"] = 3, ["name"] = "default:jungleleaves"}, {["x"] = 8, ["y"] = 12, ["param1"] = 14, ["z"] = 4, ["name"] = "default:jungleleaves"}, {["x"] = 8, ["y"] = 12, ["param1"] = 14, ["z"] = 5, ["name"] = "default:jungleleaves"}, {["x"] = 8, ["y"] = 12, ["param1"] = 14, ["z"] = 6, ["name"] = "default:jungleleaves"}, {["x"] = 8, ["y"] = 13, ["param1"] = 14, ["z"] = 1, ["name"] = "default:jungleleaves"}, {["x"] = 8, ["y"] = 13, ["param1"] = 14, ["z"] = 2, ["name"] = "default:jungleleaves"}, {["x"] = 8, ["y"] = 13, ["param1"] = 14, ["z"] = 3, ["name"] = "default:jungleleaves"}, {["x"] = 8, ["y"] = 13, ["param1"] = 14, ["z"] = 4, ["name"] = "default:jungleleaves"}, {["x"] = 8, ["y"] = 13, ["param1"] = 14, ["z"] = 6, ["name"] = "default:jungleleaves"}, {["x"] = 8, ["y"] = 13, ["param1"] = 14, ["z"] = 7, ["name"] = "default:jungleleaves"}, {["x"] = 8, ["y"] = 14, ["param1"] = 14, ["z"] = 2, ["name"] = "default:jungleleaves"}, {["x"] = 8, ["y"] = 14, ["param1"] = 14, ["z"] = 3, ["name"] = "default:jungleleaves"}, {["x"] = 8, ["y"] = 14, ["param1"] = 14, ["z"] = 4, ["name"] = "default:jungleleaves"}, {["x"] = 8, ["y"] = 14, ["param1"] = 14, ["z"] = 7, ["name"] = "default:jungleleaves"}, {["x"] = 8, ["y"] = 18, ["param1"] = 14, ["z"] = 3, ["name"] = "default:jungleleaves"}, {["x"] = 8, ["y"] = 19, ["param1"] = 14, ["z"] = 3, ["name"] = "default:jungleleaves"}, {["x"] = 8, ["y"] = 19, ["param1"] = 14, ["z"] = 4, ["name"] = "default:jungleleaves"}}