5:return {{["x"] = 0, ["y"] = 9, ["param1"] = 14, ["z"] = 1, ["name"] = "default:acacia_leaves"}, {["x"] = 0, ["y"] = 9, ["param1"] = 14, ["z"] = 2, ["name"] = "default:acacia_leaves"}, {["x"] = 0, ["y"] = 9, ["param1"] = 14, ["z"] = 3, ["name"] = "default:acacia_leaves"}, {["x"] = 0, ["y"] = 9, ["param1"] = 14, ["z"] = 4, ["name"] = "default:acacia_leaves"}, {["x"] = 0, ["y"] = 9, ["param1"] = 14, ["z"] = 6, ["name"] = "default:acacia_leaves"}, {["x"] = 0, ["y"] = 9, ["param1"] = 14, ["z"] = 7, ["name"] = "default:acacia_leaves"}, {["x"] = 0, ["y"] = 9, ["param1"] = 14, ["z"] = 8, ["name"] = "default:acacia_leaves"}, {["x"] = 0, ["y"] = 9, ["param1"] = 14, ["z"] = 10, ["name"] = "default:acacia_leaves"}, {["x"] = 0, ["y"] = 9, ["param1"] = 14, ["z"] = 11, ["name"] = "default:acacia_leaves"}, {["x"] = 0, ["y"] = 9, ["param1"] = 14, ["z"] = 12, ["name"] = "default:acacia_leaves"}, {["x"] = 1, ["y"] = 8, ["param1"] = 58, ["z"] = 7, ["name"] = "default:acacia_tree"}, {["x"] = 1, ["y"] = 9, ["param1"] = 14, ["z"] = 0, ["name"] = "default:acacia_leaves"}, {["x"] = 1, ["y"] = 9, ["param1"] = 14, ["z"] = 1, ["name"] = "default:acacia_leaves"}, {["x"] = 1, ["y"] = 9, ["param1"] = 14, ["z"] = 2, ["name"] = "default:acacia_leaves"}, {["x"] = 1, ["y"] = 9, ["param1"] = 14, ["z"] = 3, ["name"] = "default:acacia_leaves"}, {["x"] = 1, ["y"] = 9, ["param1"] = 14, ["z"] = 4, ["name"] = "default:acacia_leaves"}, {["x"] = 1, ["y"] = 9, ["param1"] = 14, ["z"] = 5, ["name"] = "default:acacia_leaves"}, {["x"] = 1, ["y"] = 9, ["param1"] = 14, ["z"] = 6, ["name"] = "default:acacia_leaves"}, {["x"] = 1, ["y"] = 9, ["param1"] = 14, ["z"] = 7, ["name"] = "default:acacia_leaves"}, {["x"] = 1, ["y"] = 9, ["param1"] = 14, ["z"] = 8, ["name"] = "default:acacia_leaves"}, {["x"] = 1, ["y"] = 9, ["param1"] = 14, ["z"] = 9, ["name"] = "default:acacia_leaves"}, {["x"] = 1, ["y"] = 9, ["param1"] = 14, ["z"] = 10, ["name"] = "default:acacia_leaves"}, {["x"] = 1, ["y"] = 9, ["param1"] = 14, ["z"] = 11, ["name"] = "default:acacia_leaves"}, {["x"] = 1, ["y"] = 9, ["param1"] = 14, ["z"] = 12, ["name"] = "default:acacia_leaves"}, {["x"] = 2, ["param2"] = 2, ["y"] = 7, ["param1"] = 58, ["z"] = 8, ["name"] = "default:acacia_tree"}, {["x"] = 2, ["y"] = 8, ["param1"] = 58, ["z"] = 9, ["name"] = "default:acacia_tree"}, {["x"] = 2, ["y"] = 9, ["param1"] = 14, ["z"] = 0, ["name"] = "default:acacia_leaves"}, {["x"] = 2, ["y"] = 9, ["param1"] = 14, ["z"] = 1, ["name"] = "default:acacia_leaves"}, {["x"] = 2, ["y"] = 9, ["param1"] = 14, ["z"] = 2, ["name"] = "default:acacia_leaves"}, {["x"] = 2, ["y"] = 9, ["param1"] = 14, ["z"] = 3, ["name"] = "default:acacia_leaves"}, {["x"] = 2, ["y"] = 9, ["param1"] = 14, ["z"] = 6, ["name"] = "default:acacia_leaves"}, {["x"] = 2, ["y"] = 9, ["param1"] = 14, ["z"] = 7, ["name"] = "default:acacia_leaves"}, {["x"] = 2, ["y"] = 9, ["param1"] = 14, ["z"] = 8, ["name"] = "default:acacia_leaves"}, {["x"] = 2, ["y"] = 9, ["param1"] = 14, ["z"] = 9, ["name"] = "default:acacia_leaves"}, {["x"] = 2, ["y"] = 9, ["param1"] = 14, ["z"] = 10, ["name"] = "default:acacia_leaves"}, {["x"] = 2, ["y"] = 9, ["param1"] = 14, ["z"] = 11, ["name"] = "default:acacia_leaves"}, {["x"] = 3, ["y"] = 6, ["param1"] = 58, ["z"] = 7, ["name"] = "default:acacia_tree"}, {["x"] = 3, ["y"] = 7, ["param1"] = 58, ["z"] = 4, ["name"] = "default:acacia_tree"}, {["x"] = 3, ["y"] = 8, ["param1"] = 58, ["z"] = 3, ["name"] = "default:acacia_tree"}, {["x"] = 3, ["y"] = 9, ["param1"] = 14, ["z"] = 0, ["name"] = "default:acacia_leaves"}, {["x"] = 3, ["y"] = 9, ["param1"] = 14, ["z"] = 1, ["name"] = "default:acacia_leaves"}, {["x"] = 3, ["y"] = 9, ["param1"] = 14, ["z"] = 2, ["name"] = "default:acacia_leaves"}, {["x"] = 3, ["y"] = 9, ["param1"] = 14, ["z"] = 3, ["name"] = "default:acacia_leaves"}, {["x"] = 3, ["y"] = 9, ["param1"] = 14, ["z"] = 4, ["name"] = "default:acacia_leaves"}, {["x"] = 3, ["y"] = 9, ["param1"] = 14, ["z"] = 6, ["name"] = "default:acacia_leaves"}, {["x"] = 3, ["y"] = 9, ["param1"] = 14, ["z"] = 7, ["name"] = "default:acacia_leaves"}, {["x"] = 3, ["y"] = 9, ["param1"] = 14, ["z"] = 8, ["name"] = "default:acacia_leaves"}, {["x"] = 3, ["y"] = 9, ["param1"] = 14, ["z"] = 9, ["name"] = "default:acacia_leaves"}, {["x"] = 3, ["y"] = 9, ["param1"] = 14, ["z"] = 10, ["name"] = "default:acacia_leaves"}, {["x"] = 3, ["y"] = 9, ["param1"] = 14, ["z"] = 12, ["name"] = "default:acacia_leaves"}, {["x"] = 3, ["y"] = 9, ["param1"] = 14, ["z"] = 13, ["name"] = "default:acacia_leaves"}, {["x"] = 4, ["y"] = 5, ["param1"] = 58, ["z"] = 6, ["name"] = "default:acacia_tree"}, {["x"] = 4, ["y"] = 6, ["param1"] = 58, ["z"] = 5, ["name"] = "default:acacia_tree"}, {["x"] = 4, ["y"] = 8, ["param1"] = 13, ["z"] = 3, ["name"] = "default:acacia_leaves"}, {["x"] = 4, ["y"] = 8, ["param1"] = 14, ["z"] = 4, ["name"] = "default:acacia_leaves"}, {["x"] = 4, ["y"] = 8, ["param1"] = 14, ["z"] = 5, ["name"] = "default:acacia_leaves"}, {["x"] = 4, ["y"] = 8, ["param1"] = 14, ["z"] = 6, ["name"] = "default:acacia_leaves"}, {["x"] = 4, ["y"] = 8, ["param1"] = 13, ["z"] = 7, ["name"] = "default:acacia_leaves"}, {["x"] = 4, ["y"] = 9, ["param1"] = 14, ["z"] = 0, ["name"] = "default:acacia_leaves"}, {["x"] = 4, ["y"] = 9, ["param1"] = 14, ["z"] = 1, ["name"] = "default:acacia_leaves"}, {["x"] = 4, ["y"] = 9, ["param1"] = 14, ["z"] = 2, ["name"] = "default:acacia_leaves"}, {["x"] = 4, ["y"] = 9, ["param1"] = 14, ["z"] = 3, ["name"] = "default:acacia_leaves"}, {["x"] = 4, ["y"] = 9, ["param1"] = 14, ["z"] = 4, ["name"] = "default:acacia_leaves"}, {["x"] = 4, ["y"] = 9, ["param1"] = 14, ["z"] = 7, ["name"] = "default:acacia_leaves"}, {["x"] = 4, ["y"] = 9, ["param1"] = 14, ["z"] = 8, ["name"] = "default:acacia_leaves"}, {["x"] = 4, ["y"] = 9, ["param1"] = 14, ["z"] = 9, ["name"] = "default:acacia_leaves"}, {["x"] = 4, ["y"] = 9, ["param1"] = 14, ["z"] = 10, ["name"] = "default:acacia_leaves"}, {["x"] = 4, ["y"] = 9, ["param1"] = 14, ["z"] = 11, ["name"] = "default:acacia_leaves"}, {["x"] = 4, ["y"] = 9, ["param1"] = 14, ["z"] = 12, ["name"] = "default:acacia_leaves"}, {["x"] = 4, ["y"] = 9, ["param1"] = 14, ["z"] = 13, ["name"] = "default:acacia_leaves"}, {["x"] = 5, ["y"] = 4, ["param1"] = 58, ["z"] = 6, ["name"] = "default:acacia_tree"}, {["x"] = 5, ["param2"] = 3, ["y"] = 7, ["param1"] = 58, ["z"] = 6, ["name"] = "default:acacia_tree"}, {["x"] = 5, ["y"] = 8, ["param1"] = 14, ["z"] = 3, ["name"] = "default:acacia_leaves"}, {["x"] = 5, ["y"] = 8, ["param1"] = 14, ["z"] = 5, ["name"] = "default:acacia_leaves"}, {["x"] = 5, ["y"] = 8, ["param1"] = 14, ["z"] = 6, ["name"] = "default:acacia_leaves"}, {["x"] = 5, ["y"] = 8, ["param1"] = 14, ["z"] = 7, ["name"] = "default:acacia_leaves"}, {["x"] = 5, ["param2"] = 2, ["y"] = 8, ["param1"] = 58, ["z"] = 11, ["name"] = "default:acacia_tree"}, {["x"] = 5, ["y"] = 9, ["param1"] = 14, ["z"] = 1, ["name"] = "default:acacia_leaves"}, {["x"] = 5, ["y"] = 9, ["param1"] = 14, ["z"] = 2, ["name"] = "default:acacia_leaves"}, {["x"] = 5, ["y"] = 9, ["param1"] = 14, ["z"] = 9, ["name"] = "default:acacia_leaves"}, {["x"] = 5, ["y"] = 9, ["param1"] = 14, ["z"] = 10, ["name"] = "default:acacia_leaves"}, {["x"] = 5, ["y"] = 9, ["param1"] = 14, ["z"] = 11, ["name"] = "default:acacia_leaves"}, {["x"] = 5, ["y"] = 9, ["param1"] = 14, ["z"] = 12, ["name"] = "default:acacia_leaves"}, {["x"] = 5, ["y"] = 9, ["param1"] = 14, ["z"] = 13, ["name"] = "default:acacia_leaves"}, {["x"] = 6, ["y"] = 0, ["z"] = 6, ["name"] = "default:acacia_tree"}, {["x"] = 6, ["y"] = 0, ["z"] = 7, ["name"] = "default:acacia_tree"}, {["x"] = 6, ["y"] = 1, ["param1"] = 58, ["z"] = 6, ["name"] = "default:acacia_tree"}, {["x"] = 6, ["param2"] = 2, ["y"] = 1, ["param1"] = 58, ["z"] = 7, ["name"] = "default:acacia_tree"}, {["x"] = 6, ["y"] = 2, ["param1"] = 58, ["z"] = 6, ["name"] = "default:acacia_tree"}, {["x"] = 6, ["param2"] = 2, ["y"] = 2, ["param1"] = 58, ["z"] = 7, ["name"] = "default:acacia_tree"}, {["x"] = 6, ["y"] = 3, ["param1"] = 58, ["z"] = 6, ["name"] = "default:acacia_tree"}, {["x"] = 6, ["param2"] = 2, ["y"] = 3, ["param1"] = 58, ["z"] = 7, ["name"] = "default:acacia_tree"}, {["x"] = 6, ["param2"] = 2, ["y"] = 4, ["param1"] = 58, ["z"] = 7, ["name"] = "default:acacia_tree"}, {["x"] = 6, ["param2"] = 2, ["y"] = 5, ["param1"] = 58, ["z"] = 7, ["name"] = "default:acacia_tree"}, {["x"] = 6, ["y"] = 5, ["param1"] = 58, ["z"] = 8, ["name"] = "default:acacia_tree"}, {["x"] = 6, ["y"] = 6, ["param1"] = 58, ["z"] = 9, ["name"] = "default:acacia_tree"}, {["x"] = 6, ["param2"] = 3, ["y"] = 7, ["param1"] = 58, ["z"] = 10, ["name"] = "default:acacia_tree"}, {["x"] = 6, ["y"] = 8, ["param1"] = 14, ["z"] = 2, ["name"] = "default:acacia_leaves"}, {["x"] = 6, ["y"] = 8, ["param1"] = 14, ["z"] = 3, ["name"] = "default:acacia_leaves"}, {["x"] = 6, ["y"] = 8, ["param1"] = 14, ["z"] = 4, ["name"] = "default:acacia_leaves"}, {["x"] = 6, ["y"] = 8, ["param1"] = 14, ["z"] = 5, ["name"] = "default:acacia_leaves"}, {["x"] = 6, ["y"] = 8, ["param1"] = 14, ["z"] = 6, ["name"] = "default:acacia_leaves"}, {["x"] = 6, ["y"] = 8, ["param1"] = 14, ["z"] = 7, ["name"] = "default:acacia_leaves"}, {["x"] = 6, ["y"] = 9, ["param1"] = 14, ["z"] = 9, ["name"] = "default:acacia_leaves"}, {["x"] = 6, ["y"] = 9, ["param1"] = 14, ["z"] = 10, ["name"] = "default:acacia_leaves"}, {["x"] = 6, ["y"] = 9, ["param1"] = 14, ["z"] = 11, ["name"] = "default:acacia_leaves"}, {["x"] = 6, ["y"] = 9, ["param1"] = 14, ["z"] = 12, ["name"] = "default:acacia_leaves"}, {["x"] = 6, ["y"] = 9, ["param1"] = 14, ["z"] = 13, ["name"] = "default:acacia_leaves"}, {["x"] = 7, ["y"] = 0, ["z"] = 6, ["name"] = "default:acacia_tree"}, {["x"] = 7, ["param2"] = 3, ["y"] = 0, ["z"] = 7, ["name"] = "default:acacia_tree"}, {["x"] = 7, ["y"] = 1, ["param1"] = 58, ["z"] = 6, ["name"] = "default:acacia_tree"}, {["x"] = 7, ["param2"] = 2, ["y"] = 1, ["param1"] = 58, ["z"] = 7, ["name"] = "default:acacia_tree"}, {["x"] = 7, ["y"] = 2, ["param1"] = 58, ["z"] = 6, ["name"] = "default:acacia_tree"}, {["x"] = 7, ["param2"] = 2, ["y"] = 2, ["param1"] = 58, ["z"] = 7, ["name"] = "default:acacia_tree"}, {["x"] = 7, ["y"] = 3, ["param1"] = 58, ["z"] = 6, ["name"] = "default:acacia_tree"}, {["x"] = 7, ["param2"] = 2, ["y"] = 3, ["param1"] = 58, ["z"] = 7, ["name"] = "default:acacia_tree"}, {["x"] = 7, ["y"] = 4, ["param1"] = 58, ["z"] = 6, ["name"] = "default:acacia_tree"}, {["x"] = 7, ["param2"] = 2, ["y"] = 4, ["param1"] = 58, ["z"] = 7, ["name"] = "default:acacia_tree"}, {["x"] = 7, ["param2"] = 3, ["y"] = 5, ["param1"] = 58, ["z"] = 5, ["name"] = "default:acacia_tree"}, {["x"] = 7, ["param2"] = 3, ["y"] = 6, ["param1"] = 58, ["z"] = 4, ["name"] = "default:acacia_tree"}, {["x"] = 7, ["y"] = 8, ["param1"] = 14, ["z"] = 2, ["name"] = "default:acacia_leaves"}, {["x"] = 7, ["y"] = 8, ["param1"] = 14, ["z"] = 3, ["name"] = "default:acacia_leaves"}, {["x"] = 7, ["y"] = 8, ["param1"] = 14, ["z"] = 4, ["name"] = "default:acacia_leaves"}, {["x"] = 7, ["y"] = 8, ["param1"] = 14, ["z"] = 5, ["name"] = "default:acacia_leaves"}, {["x"] = 7, ["y"] = 8, ["param1"] = 14, ["z"] = 6, ["name"] = "default:acacia_leaves"}, {["x"] = 7, ["param2"] = 3, ["y"] = 8, ["param1"] = 58, ["z"] = 11, ["name"] = "default:acacia_tree"}, {["x"] = 7, ["y"] = 9, ["param1"] = 14, ["z"] = 9, ["name"] = "default:acacia_leaves"}, {["x"] = 7, ["y"] = 9, ["param1"] = 14, ["z"] = 10, ["name"] = "default:acacia_leaves"}, {["x"] = 7, ["y"] = 9, ["param1"] = 14, ["z"] = 11, ["name"] = "default:acacia_leaves"}, {["x"] = 7, ["y"] = 9, ["param1"] = 14, ["z"] = 12, ["name"] = "default:acacia_leaves"}, {["x"] = 8, ["param2"] = 2, ["y"] = 4, ["param1"] = 58, ["z"] = 7, ["name"] = "default:acacia_tree"}, {["x"] = 8, ["param2"] = 2, ["y"] = 5, ["param1"] = 58, ["z"] = 7, ["name"] = "default:acacia_tree"}, {["x"] = 8, ["y"] = 7, ["param1"] = 58, ["z"] = 3, ["name"] = "default:acacia_tree"}, {["x"] = 8, ["y"] = 8, ["param1"] = 13, ["z"] = 2, ["name"] = "default:acacia_leaves"}, {["x"] = 8, ["y"] = 8, ["param1"] = 13, ["z"] = 3, ["name"] = "default:acacia_leaves"}, {["x"] = 8, ["y"] = 8, ["param1"] = 14, ["z"] = 4, ["name"] = "default:acacia_leaves"}, {["x"] = 8, ["y"] = 8, ["param1"] = 13, ["z"] = 5, ["name"] = "default:acacia_leaves"}, {["x"] = 8, ["y"] = 8, ["param1"] = 14, ["z"] = 6, ["name"] = "default:acacia_leaves"}, {["x"] = 8, ["y"] = 8, ["param1"] = 14, ["z"] = 7, ["name"] = "default:acacia_leaves"}, {["x"] = 8, ["y"] = 9, ["param1"] = 14, ["z"] = 1, ["name"] = "default:acacia_leaves"}, {["x"] = 8, ["y"] = 9, ["param1"] = 14, ["z"] = 2, ["name"] = "default:acacia_leaves"}, {["x"] = 8, ["y"] = 9, ["param1"] = 14, ["z"] = 3, ["name"] = "default:acacia_leaves"}, {["x"] = 8, ["y"] = 9, ["param1"] = 14, ["z"] = 4, ["name"] = "default:acacia_leaves"}, {["x"] = 8, ["y"] = 9, ["param1"] = 14, ["z"] = 5, ["name"] = "default:acacia_leaves"}, {["x"] = 8, ["y"] = 9, ["param1"] = 14, ["z"] = 9, ["name"] = "default:acacia_leaves"}, {["x"] = 8, ["y"] = 9, ["param1"] = 14, ["z"] = 10, ["name"] = "default:acacia_leaves"}, {["x"] = 8, ["y"] = 9, ["param1"] = 14, ["z"] = 11, ["name"] = "default:acacia_leaves"}, {["x"] = 8, ["y"] = 9, ["param1"] = 14, ["z"] = 12, ["name"] = "default:acacia_leaves"}, {["x"] = 8, ["y"] = 9, ["param1"] = 14, ["z"] = 13, ["name"] = "default:acacia_leaves"}, {["x"] = 9, ["param2"] = 2, ["y"] = 5, ["param1"] = 58, ["z"] = 7, ["name"] = "default:acacia_tree"}, {["x"] = 9, ["param2"] = 2, ["y"] = 6, ["param1"] = 58, ["z"] = 7, ["name"] = "default:acacia_tree"}, {["x"] = 9, ["param2"] = 3, ["y"] = 7, ["param1"] = 58, ["z"] = 8, ["name"] = "default:acacia_tree"}, {["x"] = 9, ["y"] = 8, ["param1"] = 13, ["z"] = 2, ["name"] = "default:acacia_leaves"}, {["x"] = 9, ["y"] = 8, ["param1"] = 14, ["z"] = 3, ["name"] = "default:acacia_leaves"}, {["x"] = 9, ["y"] = 8, ["param1"] = 14, ["z"] = 5, ["name"] = "default:acacia_leaves"}, {["x"] = 9, ["y"] = 9, ["param1"] = 14, ["z"] = 1, ["name"] = "default:acacia_leaves"}, {["x"] = 9, ["y"] = 9, ["param1"] = 14, ["z"] = 2, ["name"] = "default:acacia_leaves"}, {["x"] = 9, ["y"] = 9, ["param1"] = 14, ["z"] = 3, ["name"] = "default:acacia_leaves"}, {["x"] = 9, ["y"] = 9, ["param1"] = 14, ["z"] = 5, ["name"] = "default:acacia_leaves"}, {["x"] = 9, ["y"] = 9, ["param1"] = 14, ["z"] = 6, ["name"] = "default:acacia_leaves"}, {["x"] = 9, ["y"] = 9, ["param1"] = 14, ["z"] = 7, ["name"] = "default:acacia_leaves"}, {["x"] = 9, ["y"] = 9, ["param1"] = 14, ["z"] = 8, ["name"] = "default:acacia_leaves"}, {["x"] = 9, ["y"] = 9, ["param1"] = 14, ["z"] = 9, ["name"] = "default:acacia_leaves"}, {["x"] = 9, ["y"] = 9, ["param1"] = 14, ["z"] = 10, ["name"] = "default:acacia_leaves"}, {["x"] = 10, ["y"] = 7, ["param1"] = 58, ["z"] = 6, ["name"] = "default:acacia_tree"}, {["x"] = 10, ["param2"] = 3, ["y"] = 8, ["param1"] = 58, ["z"] = 9, ["name"] = "default:acacia_tree"}, {["x"] = 10, ["y"] = 9, ["param1"] = 14, ["z"] = 1, ["name"] = "default:acacia_leaves"}, {["x"] = 10, ["y"] = 9, ["param1"] = 14, ["z"] = 2, ["name"] = "default:acacia_leaves"}, {["x"] = 10, ["y"] = 9, ["param1"] = 14, ["z"] = 3, ["name"] = "default:acacia_leaves"}, {["x"] = 10, ["y"] = 9, ["param1"] = 14, ["z"] = 4, ["name"] = "default:acacia_leaves"}, {["x"] = 10, ["y"] = 9, ["param1"] = 14, ["z"] = 5, ["name"] = "default:acacia_leaves"}, {["x"] = 10, ["y"] = 9, ["param1"] = 14, ["z"] = 6, ["name"] = "default:acacia_leaves"}, {["x"] = 10, ["y"] = 9, ["param1"] = 14, ["z"] = 7, ["name"] = "default:acacia_leaves"}, {["x"] = 10, ["y"] = 9, ["param1"] = 14, ["z"] = 8, ["name"] = "default:acacia_leaves"}, {["x"] = 10, ["y"] = 9, ["param1"] = 14, ["z"] = 9, ["name"] = "default:acacia_leaves"}, {["x"] = 10, ["y"] = 9, ["param1"] = 14, ["z"] = 10, ["name"] = "default:acacia_leaves"}, {["x"] = 10, ["y"] = 9, ["param1"] = 14, ["z"] = 11, ["name"] = "default:acacia_leaves"}, {["x"] = 10, ["y"] = 9, ["param1"] = 14, ["z"] = 12, ["name"] = "default:acacia_leaves"}, {["x"] = 11, ["y"] = 8, ["param1"] = 58, ["z"] = 5, ["name"] = "default:acacia_tree"}, {["x"] = 11, ["y"] = 9, ["param1"] = 14, ["z"] = 1, ["name"] = "default:acacia_leaves"}, {["x"] = 11, ["y"] = 9, ["param1"] = 14, ["z"] = 2, ["name"] = "default:acacia_leaves"}, {["x"] = 11, ["y"] = 9, ["param1"] = 14, ["z"] = 3, ["name"] = "default:acacia_leaves"}, {["x"] = 11, ["y"] = 9, ["param1"] = 14, ["z"] = 4, ["name"] = "default:acacia_leaves"}, {["x"] = 11, ["y"] = 9, ["param1"] = 14, ["z"] = 6, ["name"] = "default:acacia_leaves"}, {["x"] = 11, ["y"] = 9, ["param1"] = 14, ["z"] = 7, ["name"] = "default:acacia_leaves"}, {["x"] = 11, ["y"] = 9, ["param1"] = 14, ["z"] = 9, ["name"] = "default:acacia_leaves"}, {["x"] = 11, ["y"] = 9, ["param1"] = 14, ["z"] = 10, ["name"] = "default:acacia_leaves"}, {["x"] = 11, ["y"] = 9, ["param1"] = 14, ["z"] = 11, ["name"] = "default:acacia_leaves"}, {["x"] = 11, ["y"] = 9, ["param1"] = 14, ["z"] = 12, ["name"] = "default:acacia_leaves"}, {["x"] = 12, ["y"] = 9, ["param1"] = 14, ["z"] = 1, ["name"] = "default:acacia_leaves"}, {["x"] = 12, ["y"] = 9, ["param1"] = 14, ["z"] = 2, ["name"] = "default:acacia_leaves"}, {["x"] = 12, ["y"] = 9, ["param1"] = 14, ["z"] = 3, ["name"] = "default:acacia_leaves"}, {["x"] = 12, ["y"] = 9, ["param1"] = 14, ["z"] = 4, ["name"] = "default:acacia_leaves"}, {["x"] = 12, ["y"] = 9, ["param1"] = 14, ["z"] = 5, ["name"] = "default:acacia_leaves"}, {["x"] = 12, ["y"] = 9, ["param1"] = 14, ["z"] = 6, ["name"] = "default:acacia_leaves"}, {["x"] = 12, ["y"] = 9, ["param1"] = 14, ["z"] = 8, ["name"] = "default:acacia_leaves"}, {["x"] = 12, ["y"] = 9, ["param1"] = 14, ["z"] = 9, ["name"] = "default:acacia_leaves"}, {["x"] = 12, ["y"] = 9, ["param1"] = 14, ["z"] = 11, ["name"] = "default:acacia_leaves"}, {["x"] = 12, ["y"] = 9, ["param1"] = 14, ["z"] = 12, ["name"] = "default:acacia_leaves"}, {["x"] = 13, ["y"] = 9, ["param1"] = 14, ["z"] = 2, ["name"] = "default:acacia_leaves"}, {["x"] = 13, ["y"] = 9, ["param1"] = 14, ["z"] = 4, ["name"] = "default:acacia_leaves"}, {["x"] = 13, ["y"] = 9, ["param1"] = 14, ["z"] = 5, ["name"] = "default:acacia_leaves"}, {["x"] = 13, ["y"] = 9, ["param1"] = 14, ["z"] = 6, ["name"] = "default:acacia_leaves"}, {["x"] = 13, ["y"] = 9, ["param1"] = 14, ["z"] = 8, ["name"] = "default:acacia_leaves"}, {["x"] = 13, ["y"] = 9, ["param1"] = 14, ["z"] = 9, ["name"] = "default:acacia_leaves"}, {["x"] = 13, ["y"] = 9, ["param1"] = 14, ["z"] = 10, ["name"] = "default:acacia_leaves"}, {["x"] = 13, ["y"] = 9, ["param1"] = 14, ["z"] = 12, ["name"] = "default:acacia_leaves"}}