5:return {{["x"] = 0, ["y"] = 6, ["param1"] = 14, ["z"] = 0, ["name"] = "default:pine_needles"}, {["x"] = 0, ["y"] = 6, ["param1"] = 14, ["z"] = 2, ["name"] = "default:pine_needles"}, {["x"] = 0, ["y"] = 6, ["param1"] = 14, ["z"] = 3, ["name"] = "default:pine_needles"}, {["x"] = 0, ["y"] = 7, ["param1"] = 14, ["z"] = 5, ["name"] = "default:pine_needles"}, {["x"] = 0, ["y"] = 7, ["param1"] = 14, ["z"] = 6, ["name"] = "default:pine_needles"}, {["x"] = 0, ["y"] = 7, ["param1"] = 14, ["z"] = 7, ["name"] = "default:pine_needles"}, {["x"] = 1, ["y"] = 6, ["param1"] = 14, ["z"] = 0, ["name"] = "default:pine_needles"}, {["x"] = 1, ["y"] = 6, ["param1"] = 14, ["z"] = 1, ["name"] = "default:pine_needles"}, {["x"] = 1, ["y"] = 6, ["param1"] = 14, ["z"] = 2, ["name"] = "default:pine_needles"}, {["x"] = 1, ["y"] = 6, ["param1"] = 14, ["z"] = 3, ["name"] = "default:pine_needles"}, {["x"] = 1, ["y"] = 7, ["param1"] = 14, ["z"] = 1, ["name"] = "default:pine_needles"}, {["x"] = 1, ["y"] = 7, ["param1"] = 14, ["z"] = 4, ["name"] = "default:pine_needles"}, {["x"] = 1, ["y"] = 7, ["param1"] = 13, ["z"] = 5, ["name"] = "default:pine_needles"}, {["x"] = 1, ["y"] = 7, ["param1"] = 13, ["z"] = 6, ["name"] = "default:pine_needles"}, {["x"] = 1, ["y"] = 7, ["param1"] = 13, ["z"] = 7, ["name"] = "default:pine_needles"}, {["x"] = 1, ["y"] = 7, ["param1"] = 14, ["z"] = 8, ["name"] = "default:pine_needles"}, {["x"] = 1, ["y"] = 8, ["param1"] = 14, ["z"] = 5, ["name"] = "default:pine_needles"}, {["x"] = 1, ["y"] = 8, ["param1"] = 14, ["z"] = 6, ["name"] = "default:pine_needles"}, {["x"] = 1, ["y"] = 8, ["param1"] = 14, ["z"] = 7, ["name"] = "default:pine_needles"}, {["x"] = 2, ["param2"] = 23, ["y"] = 5, ["param1"] = 54, ["z"] = 2, ["name"] = "default:pine_tree"}, {["x"] = 2, ["y"] = 6, ["param1"] = 14, ["z"] = 0, ["name"] = "default:pine_needles"}, {["x"] = 2, ["y"] = 6, ["param1"] = 13, ["z"] = 1, ["name"] = "default:pine_needles"}, {["x"] = 2, ["y"] = 6, ["param1"] = 13, ["z"] = 2, ["name"] = "default:pine_needles"}, {["x"] = 2, ["y"] = 6, ["param1"] = 14, ["z"] = 3, ["name"] = "default:pine_needles"}, {["x"] = 2, ["param2"] = 22, ["y"] = 6, ["param1"] = 54, ["z"] = 6, ["name"] = "default:pine_tree"}, {["x"] = 2, ["y"] = 7, ["param1"] = 14, ["z"] = 1, ["name"] = "default:pine_needles"}, {["x"] = 2, ["y"] = 7, ["param1"] = 14, ["z"] = 2, ["name"] = "default:pine_needles"}, {["x"] = 2, ["y"] = 7, ["param1"] = 14, ["z"] = 4, ["name"] = "default:pine_needles"}, {["x"] = 2, ["y"] = 7, ["param1"] = 13, ["z"] = 5, ["name"] = "default:pine_needles"}, {["x"] = 2, ["y"] = 7, ["param1"] = 13, ["z"] = 6, ["name"] = "default:pine_needles"}, {["x"] = 2, ["y"] = 7, ["param1"] = 13, ["z"] = 7, ["name"] = "default:pine_needles"}, {["x"] = 2, ["y"] = 7, ["param1"] = 14, ["z"] = 8, ["name"] = "default:pine_needles"}, {["x"] = 2, ["y"] = 8, ["param1"] = 14, ["z"] = 5, ["name"] = "default:pine_needles"}, {["x"] = 2, ["y"] = 8, ["param1"] = 14, ["z"] = 6, ["name"] = "default:pine_needles"}, {["x"] = 2, ["y"] = 8, ["param1"] = 14, ["z"] = 7, ["name"] = "default:pine_needles"}, {["x"] = 3, ["param2"] = 23, ["y"] = 4, ["param1"] = 54, ["z"] = 3, ["name"] = "default:pine_tree"}, {["x"] = 3, ["param2"] = 22, ["y"] = 5, ["param1"] = 54, ["z"] = 5, ["name"] = "default:pine_tree"}, {["x"] = 3, ["y"] = 6, ["param1"] = 14, ["z"] = 0, ["name"] = "default:pine_needles"}, {["x"] = 3, ["y"] = 6, ["param1"] = 14, ["z"] = 1, ["name"] = "default:pine_needles"}, {["x"] = 3, ["y"] = 6, ["param1"] = 14, ["z"] = 2, ["name"] = "default:pine_needles"}, {["x"] = 3, ["y"] = 7, ["param1"] = 14, ["z"] = 4, ["name"] = "default:pine_needles"}, {["x"] = 3, ["y"] = 7, ["param1"] = 13, ["z"] = 5, ["name"] = "default:pine_needles"}, {["x"] = 3, ["y"] = 7, ["param1"] = 13, ["z"] = 6, ["name"] = "default:pine_needles"}, {["x"] = 3, ["y"] = 7, ["param1"] = 13, ["z"] = 7, ["name"] = "default:pine_needles"}, {["x"] = 3, ["y"] = 7, ["param1"] = 14, ["z"] = 8, ["name"] = "default:pine_needles"}, {["x"] = 3, ["y"] = 8, ["param1"] = 14, ["z"] = 5, ["name"] = "default:pine_needles"}, {["x"] = 3, ["y"] = 8, ["param1"] = 14, ["z"] = 6, ["name"] = "default:pine_needles"}, {["x"] = 3, ["y"] = 8, ["param1"] = 14, ["z"] = 7, ["name"] = "default:pine_needles"}, {["x"] = 4, ["param2"] = 1, ["y"] = 0, ["param1"] = 54, ["z"] = 4, ["name"] = "default:pine_tree"}, {["x"] = 4, ["param2"] = 1, ["y"] = 1, ["param1"] = 54, ["z"] = 4, ["name"] = "default:pine_tree"}, {["x"] = 4, ["param2"] = 22, ["y"] = 1, ["param1"] = 54, ["z"] = 5, ["name"] = "default:pine_tree"}, {["x"] = 4, ["param2"] = 23, ["y"] = 2, ["param1"] = 54, ["z"] = 5, ["name"] = "default:pine_tree"}, {["x"] = 4, ["y"] = 4, ["param1"] = 54, ["z"] = 4, ["name"] = "default:pine_tree"}, {["x"] = 4, ["y"] = 7, ["param1"] = 14, ["z"] = 0, ["name"] = "default:pine_needles"}, {["x"] = 4, ["y"] = 7, ["param1"] = 14, ["z"] = 1, ["name"] = "default:pine_needles"}, {["x"] = 4, ["y"] = 7, ["param1"] = 14, ["z"] = 2, ["name"] = "default:pine_needles"}, {["x"] = 4, ["y"] = 7, ["param1"] = 14, ["z"] = 4, ["name"] = "default:pine_needles"}, {["x"] = 4, ["y"] = 7, ["param1"] = 14, ["z"] = 5, ["name"] = "default:pine_needles"}, {["x"] = 4, ["y"] = 7, ["param1"] = 14, ["z"] = 6, ["name"] = "default:pine_needles"}, {["x"] = 4, ["y"] = 7, ["param1"] = 14, ["z"] = 7, ["name"] = "default:pine_needles"}, {["x"] = 5, ["param2"] = 22, ["y"] = 2, ["param1"] = 54, ["z"] = 5, ["name"] = "default:pine_tree"}, {["x"] = 5, ["param2"] = 23, ["y"] = 3, ["param1"] = 54, ["z"] = 5, ["name"] = "default:pine_tree"}, {["x"] = 5, ["param2"] = 21, ["y"] = 4, ["param1"] = 54, ["z"] = 5, ["name"] = "default:pine_tree"}, {["x"] = 5, ["param2"] = 21, ["y"] = 5, ["param1"] = 54, ["z"] = 3, ["name"] = "default:pine_tree"}, {["x"] = 5, ["y"] = 6, ["param1"] = 14, ["z"] = 6, ["name"] = "default:pine_needles"}, {["x"] = 5, ["y"] = 6, ["param1"] = 14, ["z"] = 7, ["name"] = "default:pine_needles"}, {["x"] = 5, ["y"] = 6, ["param1"] = 14, ["z"] = 8, ["name"] = "default:pine_needles"}, {["x"] = 5, ["y"] = 7, ["param1"] = 14, ["z"] = 1, ["name"] = "default:pine_needles"}, {["x"] = 5, ["y"] = 7, ["param1"] = 13, ["z"] = 2, ["name"] = "default:pine_needles"}, {["x"] = 5, ["y"] = 7, ["param1"] = 14, ["z"] = 3, ["name"] = "default:pine_needles"}, {["x"] = 5, ["y"] = 8, ["param1"] = 14, ["z"] = 2, ["name"] = "default:pine_needles"}, {["x"] = 6, ["param2"] = 22, ["y"] = 5, ["param1"] = 54, ["z"] = 6, ["name"] = "default:pine_tree"}, {["x"] = 6, ["param2"] = 21, ["y"] = 6, ["param1"] = 54, ["z"] = 2, ["name"] = "default:pine_tree"}, {["x"] = 6, ["y"] = 6, ["param1"] = 14, ["z"] = 5, ["name"] = "default:pine_needles"}, {["x"] = 6, ["y"] = 6, ["param1"] = 13, ["z"] = 6, ["name"] = "default:pine_needles"}, {["x"] = 6, ["y"] = 6, ["param1"] = 13, ["z"] = 7, ["name"] = "default:pine_needles"}, {["x"] = 6, ["y"] = 6, ["param1"] = 14, ["z"] = 8, ["name"] = "default:pine_needles"}, {["x"] = 6, ["y"] = 7, ["param1"] = 14, ["z"] = 0, ["name"] = "default:pine_needles"}, {["x"] = 6, ["y"] = 7, ["param1"] = 14, ["z"] = 1, ["name"] = "default:pine_needles"}, {["x"] = 6, ["y"] = 7, ["param1"] = 13, ["z"] = 2, ["name"] = "default:pine_needles"}, {["x"] = 6, ["y"] = 7, ["param1"] = 13, ["z"] = 3, ["name"] = "default:pine_needles"}, {["x"] = 6, ["y"] = 7, ["param1"] = 14, ["z"] = 4, ["name"] = "default:pine_needles"}, {["x"] = 6, ["y"] = 7, ["param1"] = 14, ["z"] = 6, ["name"] = "default:pine_needles"}, {["x"] = 6, ["y"] = 7, ["param1"] = 14, ["z"] = 7, ["name"] = "default:pine_needles"}, {["x"] = 6, ["y"] = 8, ["param1"] = 14, ["z"] = 2, ["name"] = "default:pine_needles"}, {["x"] = 6, ["y"] = 8, ["param1"] = 14, ["z"] = 3, ["name"] = "default:pine_needles"}, {["x"] = 7, ["y"] = 6, ["param1"] = 14, ["z"] = 5, ["name"] = "default:pine_needles"}, {["x"] = 7, ["y"] = 6, ["param1"] = 13, ["z"] = 6, ["name"] = "default:pine_needles"}, {["x"] = 7, ["y"] = 6, ["param1"] = 13, ["z"] = 7, ["name"] = "default:pine_needles"}, {["x"] = 7, ["y"] = 6, ["param1"] = 14, ["z"] = 8, ["name"] = "default:pine_needles"}, {["x"] = 7, ["y"] = 7, ["param1"] = 14, ["z"] = 0, ["name"] = "default:pine_needles"}, {["x"] = 7, ["y"] = 7, ["param1"] = 13, ["z"] = 1, ["name"] = "default:pine_needles"}, {["x"] = 7, ["y"] = 7, ["param1"] = 14, ["z"] = 2, ["name"] = "default:pine_needles"}, {["x"] = 7, ["y"] = 7, ["param1"] = 14, ["z"] = 3, ["name"] = "default:pine_needles"}, {["x"] = 7, ["y"] = 7, ["param1"] = 14, ["z"] = 4, ["name"] = "default:pine_needles"}, {["x"] = 7, ["y"] = 7, ["param1"] = 14, ["z"] = 6, ["name"] = "default:pine_needles"}, {["x"] = 7, ["y"] = 7, ["param1"] = 14, ["z"] = 7, ["name"] = "default:pine_needles"}, {["x"] = 7, ["y"] = 8, ["param1"] = 14, ["z"] = 1, ["name"] = "default:pine_needles"}, {["x"] = 8, ["y"] = 6, ["param1"] = 14, ["z"] = 6, ["name"] = "default:pine_needles"}, {["x"] = 8, ["y"] = 6, ["param1"] = 14, ["z"] = 7, ["name"] = "default:pine_needles"}, {["x"] = 8, ["y"] = 7, ["param1"] = 14, ["z"] = 0, ["name"] = "default:pine_needles"}, {["x"] = 8, ["y"] = 7, ["param1"] = 14, ["z"] = 1, ["name"] = "default:pine_needles"}, {["x"] = 8, ["y"] = 7, ["param1"] = 14, ["z"] = 3, ["name"] = "default:pine_needles"}, {["x"] = 8, ["y"] = 7, ["param1"] = 14, ["z"] = 4, ["name"] = "default:pine_needles"}}