5:return {{["x"] = 2, ["y"] = 1, ["param1"] = 1, ["z"] = 4, ["name"] = "default:stone"}, {["x"] = 2, ["y"] = 2, ["param1"] = 1, ["z"] = 3, ["name"] = "default:stone"}, {["x"] = 2, ["y"] = 2, ["param1"] = 1, ["z"] = 4, ["name"] = "default:stone"}, {["x"] = 2, ["y"] = 2, ["param1"] = 1, ["z"] = 5, ["name"] = "default:stone"}, {["x"] = 2, ["y"] = 3, ["param1"] = 1, ["z"] = 3, ["name"] = "default:stone"}, {["x"] = 2, ["y"] = 3, ["param1"] = 1, ["z"] = 4, ["name"] = "default:stone"}, {["x"] = 2, ["y"] = 3, ["param1"] = 5, ["z"] = 5, ["name"] = "default:mossycobble"}, {["x"] = 2, ["param2"] = 1, ["y"] = 4, ["param1"] = 14, ["z"] = 3, ["name"] = "stairs:slab_mossycobble"}, {["x"] = 2, ["y"] = 4, ["param1"] = 5, ["z"] = 4, ["name"] = "default:mossycobble"}, {["x"] = 2, ["y"] = 4, ["param1"] = 15, ["z"] = 5, ["name"] = "default:grass_4"}, {["x"] = 2, ["y"] = 5, ["param1"] = 15, ["z"] = 4, ["name"] = "default:grass_5"}, {["x"] = 3, ["param2"] = 23, ["y"] = 0, ["param1"] = 13, ["z"] = 3, ["name"] = "stairs:slab_stone"}, {["x"] = 3, ["y"] = 0, ["param1"] = 1, ["z"] = 4, ["name"] = "default:stone"}, {["x"] = 3, ["param2"] = 22, ["y"] = 0, ["param1"] = 13, ["z"] = 5, ["name"] = "stairs:slab_stone"}, {["x"] = 3, ["y"] = 1, ["param1"] = 1, ["z"] = 2, ["name"] = "default:stone"}, {["x"] = 3, ["y"] = 1, ["param1"] = 1, ["z"] = 3, ["name"] = "default:stone"}, {["x"] = 3, ["y"] = 1, ["param1"] = 1, ["z"] = 4, ["name"] = "default:stone"}, {["x"] = 3, ["y"] = 1, ["param1"] = 1, ["z"] = 5, ["name"] = "default:stone"}, {["x"] = 3, ["y"] = 2, ["param1"] = 1, ["z"] = 2, ["name"] = "default:stone"}, {["x"] = 3, ["y"] = 2, ["param1"] = 1, ["z"] = 3, ["name"] = "default:stone"}, {["x"] = 3, ["y"] = 2, ["param1"] = 1, ["z"] = 4, ["name"] = "default:stone"}, {["x"] = 3, ["y"] = 2, ["param1"] = 1, ["z"] = 5, ["name"] = "default:stone"}, {["x"] = 3, ["y"] = 2, ["param1"] = 1, ["z"] = 6, ["name"] = "default:stone"}, {["x"] = 3, ["y"] = 3, ["param1"] = 1, ["z"] = 2, ["name"] = "default:stone"}, {["x"] = 3, ["y"] = 3, ["param1"] = 1, ["z"] = 3, ["name"] = "default:stone"}, {["x"] = 3, ["y"] = 3, ["param1"] = 1, ["z"] = 4, ["name"] = "default:stone"}, {["x"] = 3, ["y"] = 3, ["param1"] = 1, ["z"] = 5, ["name"] = "default:stone"}, {["x"] = 3, ["y"] = 3, ["param1"] = 1, ["z"] = 6, ["name"] = "default:stone"}, {["x"] = 3, ["y"] = 4, ["param1"] = 5, ["z"] = 2, ["name"] = "default:mossycobble"}, {["x"] = 3, ["y"] = 4, ["param1"] = 1, ["z"] = 3, ["name"] = "default:stone"}, {["x"] = 3, ["y"] = 4, ["param1"] = 1, ["z"] = 4, ["name"] = "default:stone"}, {["x"] = 3, ["y"] = 4, ["param1"] = 5, ["z"] = 5, ["name"] = "default:mossycobble"}, {["x"] = 3, ["y"] = 4, ["param1"] = 15, ["z"] = 6, ["name"] = "default:grass_3"}, {["x"] = 3, ["y"] = 5, ["param1"] = 15, ["z"] = 2, ["name"] = "default:grass_2"}, {["x"] = 3, ["param2"] = 1, ["y"] = 5, ["param1"] = 14, ["z"] = 3, ["name"] = "stairs:slab_mossycobble"}, {["x"] = 3, ["y"] = 5, ["param1"] = 5, ["z"] = 4, ["name"] = "default:mossycobble"}, {["x"] = 3, ["y"] = 5, ["param1"] = 15, ["z"] = 5, ["name"] = "default:grass_2"}, {["x"] = 3, ["y"] = 6, ["param1"] = 15, ["z"] = 4, ["name"] = "default:grass_5"}, {["x"] = 4, ["param2"] = 20, ["y"] = 0, ["param1"] = 14, ["z"] = 2, ["name"] = "stairs:slab_stone"}, {["x"] = 4, ["y"] = 0, ["param1"] = 1, ["z"] = 3, ["name"] = "default:stone"}, {["x"] = 4, ["y"] = 0, ["param1"] = 1, ["z"] = 4, ["name"] = "default:stone"}, {["x"] = 4, ["param2"] = 22, ["y"] = 0, ["param1"] = 13, ["z"] = 5, ["name"] = "stairs:slab_stone"}, {["x"] = 4, ["y"] = 1, ["param1"] = 1, ["z"] = 2, ["name"] = "default:stone"}, {["x"] = 4, ["y"] = 1, ["param1"] = 1, ["z"] = 3, ["name"] = "default:stone"}, {["x"] = 4, ["y"] = 1, ["param1"] = 1, ["z"] = 4, ["name"] = "default:stone"}, {["x"] = 4, ["y"] = 1, ["param1"] = 1, ["z"] = 5, ["name"] = "default:stone"}, {["x"] = 4, ["y"] = 1, ["param1"] = 1, ["z"] = 6, ["name"] = "default:stone"}, {["x"] = 4, ["y"] = 2, ["param1"] = 5, ["z"] = 2, ["name"] = "default:mossycobble"}, {["x"] = 4, ["y"] = 2, ["param1"] = 1, ["z"] = 3, ["name"] = "default:stone"}, {["x"] = 4, ["y"] = 2, ["param1"] = 1, ["z"] = 4, ["name"] = "default:stone"}, {["x"] = 4, ["y"] = 2, ["param1"] = 1, ["z"] = 5, ["name"] = "default:stone"}, {["x"] = 4, ["y"] = 2, ["param1"] = 5, ["z"] = 6, ["name"] = "default:mossycobble"}, {["x"] = 4, ["y"] = 3, ["param1"] = 1, ["z"] = 2, ["name"] = "default:stone"}, {["x"] = 4, ["y"] = 3, ["param1"] = 1, ["z"] = 3, ["name"] = "default:stone"}, {["x"] = 4, ["y"] = 3, ["param1"] = 1, ["z"] = 4, ["name"] = "default:stone"}, {["x"] = 4, ["y"] = 3, ["param1"] = 1, ["z"] = 5, ["name"] = "default:stone"}, {["x"] = 4, ["y"] = 3, ["param1"] = 1, ["z"] = 6, ["name"] = "default:stone"}, {["x"] = 4, ["y"] = 4, ["param1"] = 1, ["z"] = 2, ["name"] = "default:stone"}, {["x"] = 4, ["y"] = 4, ["param1"] = 1, ["z"] = 3, ["name"] = "default:stone"}, {["x"] = 4, ["y"] = 4, ["param1"] = 1, ["z"] = 4, ["name"] = "default:stone"}, {["x"] = 4, ["y"] = 4, ["param1"] = 1, ["z"] = 5, ["name"] = "default:stone"}, {["x"] = 4, ["param2"] = 2, ["y"] = 4, ["param1"] = 14, ["z"] = 6, ["name"] = "stairs:slab_mossycobble"}, {["x"] = 4, ["y"] = 5, ["param1"] = 14, ["z"] = 2, ["name"] = "stairs:slab_mossycobble"}, {["x"] = 4, ["y"] = 5, ["param1"] = 5, ["z"] = 3, ["name"] = "default:mossycobble"}, {["x"] = 4, ["y"] = 5, ["param1"] = 1, ["z"] = 4, ["name"] = "default:stone"}, {["x"] = 4, ["param2"] = 2, ["y"] = 5, ["param1"] = 14, ["z"] = 5, ["name"] = "stairs:slab_mossycobble"}, {["x"] = 4, ["y"] = 6, ["param1"] = 15, ["z"] = 3, ["name"] = "default:grass_4"}, {["x"] = 4, ["y"] = 6, ["param1"] = 14, ["z"] = 4, ["name"] = "stairs:slab_mossycobble"}, {["x"] = 5, ["param2"] = 21, ["y"] = 0, ["param1"] = 13, ["z"] = 3, ["name"] = "stairs:slab_stone"}, {["x"] = 5, ["y"] = 0, ["param1"] = 1, ["z"] = 4, ["name"] = "default:stone"}, {["x"] = 5, ["param2"] = 20, ["y"] = 1, ["param1"] = 14, ["z"] = 2, ["name"] = "stairs:slab_stone"}, {["x"] = 5, ["y"] = 1, ["param1"] = 1, ["z"] = 3, ["name"] = "default:stone"}, {["x"] = 5, ["y"] = 1, ["param1"] = 1, ["z"] = 4, ["name"] = "default:stone"}, {["x"] = 5, ["y"] = 1, ["param1"] = 1, ["z"] = 5, ["name"] = "default:stone"}, {["x"] = 5, ["y"] = 1, ["param1"] = 1, ["z"] = 6, ["name"] = "default:stone"}, {["x"] = 5, ["y"] = 2, ["param1"] = 1, ["z"] = 2, ["name"] = "default:stone"}, {["x"] = 5, ["y"] = 2, ["param1"] = 1, ["z"] = 3, ["name"] = "default:stone"}, {["x"] = 5, ["y"] = 2, ["param1"] = 1, ["z"] = 4, ["name"] = "default:stone"}, {["x"] = 5, ["y"] = 2, ["param1"] = 1, ["z"] = 5, ["name"] = "default:stone"}, {["x"] = 5, ["y"] = 2, ["param1"] = 1, ["z"] = 6, ["name"] = "default:stone"}, {["x"] = 5, ["y"] = 3, ["param1"] = 1, ["z"] = 2, ["name"] = "default:stone"}, {["x"] = 5, ["y"] = 3, ["param1"] = 1, ["z"] = 3, ["name"] = "default:stone"}, {["x"] = 5, ["y"] = 3, ["param1"] = 1, ["z"] = 4, ["name"] = "default:stone"}, {["x"] = 5, ["y"] = 3, ["param1"] = 1, ["z"] = 5, ["name"] = "default:stone"}, {["x"] = 5, ["param2"] = 3, ["y"] = 3, ["param1"] = 14, ["z"] = 6, ["name"] = "stairs:slab_mossycobble"}, {["x"] = 5, ["y"] = 4, ["param1"] = 5, ["z"] = 2, ["name"] = "default:mossycobble"}, {["x"] = 5, ["y"] = 4, ["param1"] = 1, ["z"] = 3, ["name"] = "default:stone"}, {["x"] = 5, ["y"] = 4, ["param1"] = 1, ["z"] = 4, ["name"] = "default:stone"}, {["x"] = 5, ["param2"] = 2, ["y"] = 4, ["param1"] = 14, ["z"] = 5, ["name"] = "stairs:slab_mossycobble"}, {["x"] = 5, ["y"] = 5, ["param1"] = 15, ["z"] = 2, ["name"] = "default:grass_5"}, {["x"] = 5, ["y"] = 5, ["param1"] = 5, ["z"] = 3, ["name"] = "default:mossycobble"}, {["x"] = 5, ["y"] = 5, ["param1"] = 5, ["z"] = 4, ["name"] = "default:mossycobble"}, {["x"] = 5, ["y"] = 6, ["param1"] = 15, ["z"] = 3, ["name"] = "default:grass_1"}, {["x"] = 5, ["y"] = 6, ["param1"] = 15, ["z"] = 4, ["name"] = "default:grass_3"}, {["x"] = 6, ["y"] = 1, ["param1"] = 1, ["z"] = 3, ["name"] = "default:stone"}, {["x"] = 6, ["y"] = 1, ["param1"] = 1, ["z"] = 4, ["name"] = "default:stone"}, {["x"] = 6, ["y"] = 2, ["param1"] = 1, ["z"] = 3, ["name"] = "default:stone"}, {["x"] = 6, ["y"] = 2, ["param1"] = 1, ["z"] = 4, ["name"] = "default:stone"}, {["x"] = 6, ["y"] = 2, ["param1"] = 5, ["z"] = 5, ["name"] = "default:mossycobble"}, {["x"] = 6, ["y"] = 3, ["param1"] = 1, ["z"] = 3, ["name"] = "default:stone"}, {["x"] = 6, ["y"] = 3, ["param1"] = 5, ["z"] = 4, ["name"] = "default:mossycobble"}, {["x"] = 6, ["y"] = 3, ["param1"] = 1, ["z"] = 5, ["name"] = "default:stone"}, {["x"] = 6, ["param2"] = 3, ["y"] = 4, ["param1"] = 14, ["z"] = 3, ["name"] = "stairs:slab_mossycobble"}, {["x"] = 6, ["y"] = 4, ["param1"] = 15, ["z"] = 4, ["name"] = "default:grass_1"}}