5:return {{["x"] = 0, ["y"] = 2, ["param1"] = 5, ["z"] = 3, ["name"] = "default:mossycobble"}, {["x"] = 0, ["y"] = 2, ["param1"] = 1, ["z"] = 4, ["name"] = "default:stone"}, {["x"] = 0, ["y"] = 2, ["param1"] = 1, ["z"] = 5, ["name"] = "default:stone"}, {["x"] = 0, ["y"] = 2, ["param1"] = 1, ["z"] = 6, ["name"] = "default:stone"}, {["x"] = 0, ["y"] = 3, ["param1"] = 15, ["z"] = 3, ["name"] = "default:grass_1"}, {["x"] = 0, ["y"] = 3, ["param1"] = 5, ["z"] = 4, ["name"] = "default:mossycobble"}, {["x"] = 0, ["param2"] = 1, ["y"] = 3, ["param1"] = 14, ["z"] = 5, ["name"] = "stairs:slab_mossycobble"}, {["x"] = 0, ["y"] = 3, ["param1"] = 15, ["z"] = 6, ["name"] = "default:grass_3"}, {["x"] = 1, ["param2"] = 23, ["y"] = 1, ["param1"] = 13, ["z"] = 4, ["name"] = "stairs:slab_stone"}, {["x"] = 1, ["param2"] = 20, ["y"] = 1, ["param1"] = 13, ["z"] = 5, ["name"] = "stairs:slab_stone"}, {["x"] = 1, ["y"] = 2, ["param1"] = 1, ["z"] = 3, ["name"] = "default:stone"}, {["x"] = 1, ["y"] = 2, ["param1"] = 1, ["z"] = 4, ["name"] = "default:stone"}, {["x"] = 1, ["y"] = 2, ["param1"] = 1, ["z"] = 5, ["name"] = "default:stone"}, {["x"] = 1, ["y"] = 2, ["param1"] = 1, ["z"] = 6, ["name"] = "default:stone"}, {["x"] = 1, ["param2"] = 1, ["y"] = 2, ["param1"] = 14, ["z"] = 7, ["name"] = "stairs:slab_stone"}, {["x"] = 1, ["y"] = 3, ["param1"] = 5, ["z"] = 3, ["name"] = "default:mossycobble"}, {["x"] = 1, ["y"] = 3, ["param1"] = 5, ["z"] = 4, ["name"] = "default:mossycobble"}, {["x"] = 1, ["y"] = 3, ["param1"] = 1, ["z"] = 5, ["name"] = "default:stone"}, {["x"] = 1, ["param2"] = 1, ["y"] = 3, ["param1"] = 14, ["z"] = 6, ["name"] = "stairs:slab_mossycobble"}, {["x"] = 1, ["y"] = 4, ["param1"] = 15, ["z"] = 3, ["name"] = "default:grass_1"}, {["x"] = 1, ["y"] = 4, ["param1"] = 15, ["z"] = 4, ["name"] = "default:grass_3"}, {["x"] = 1, ["y"] = 4, ["param1"] = 15, ["z"] = 5, ["name"] = "default:grass_5"}, {["x"] = 2, ["param2"] = 23, ["y"] = 0, ["param1"] = 12, ["z"] = 4, ["name"] = "stairs:slab_stone"}, {["x"] = 2, ["param2"] = 23, ["y"] = 1, ["param1"] = 14, ["z"] = 2, ["name"] = "stairs:slab_stone"}, {["x"] = 2, ["y"] = 1, ["param1"] = 1, ["z"] = 3, ["name"] = "default:stone"}, {["x"] = 2, ["y"] = 1, ["param1"] = 1, ["z"] = 4, ["name"] = "default:stone"}, {["x"] = 2, ["y"] = 1, ["param1"] = 1, ["z"] = 5, ["name"] = "default:stone"}, {["x"] = 2, ["y"] = 1, ["param1"] = 1, ["z"] = 6, ["name"] = "default:stone"}, {["x"] = 2, ["y"] = 2, ["param1"] = 1, ["z"] = 2, ["name"] = "default:stone"}, {["x"] = 2, ["y"] = 2, ["param1"] = 1, ["z"] = 3, ["name"] = "default:stone"}, {["x"] = 2, ["y"] = 2, ["param1"] = 1, ["z"] = 4, ["name"] = "default:stone"}, {["x"] = 2, ["y"] = 2, ["param1"] = 1, ["z"] = 5, ["name"] = "default:stone"}, {["x"] = 2, ["y"] = 2, ["param1"] = 1, ["z"] = 6, ["name"] = "default:stone"}, {["x"] = 2, ["y"] = 2, ["param1"] = 1, ["z"] = 7, ["name"] = "default:stone"}, {["x"] = 2, ["y"] = 3, ["param1"] = 1, ["z"] = 2, ["name"] = "default:stone"}, {["x"] = 2, ["y"] = 3, ["param1"] = 1, ["z"] = 3, ["name"] = "default:stone"}, {["x"] = 2, ["y"] = 3, ["param1"] = 1, ["z"] = 4, ["name"] = "default:stone"}, {["x"] = 2, ["y"] = 3, ["param1"] = 1, ["z"] = 5, ["name"] = "default:stone"}, {["x"] = 2, ["y"] = 3, ["param1"] = 5, ["z"] = 6, ["name"] = "default:mossycobble"}, {["x"] = 2, ["y"] = 4, ["param1"] = 15, ["z"] = 2, ["name"] = "default:grass_5"}, {["x"] = 2, ["param2"] = 3, ["y"] = 4, ["param1"] = 14, ["z"] = 3, ["name"] = "stairs:slab_mossycobble"}, {["x"] = 2, ["param2"] = 2, ["y"] = 4, ["param1"] = 14, ["z"] = 4, ["name"] = "stairs:slab_mossycobble"}, {["x"] = 2, ["param2"] = 3, ["y"] = 4, ["param1"] = 14, ["z"] = 5, ["name"] = "stairs:slab_mossycobble"}, {["x"] = 2, ["y"] = 4, ["param1"] = 15, ["z"] = 6, ["name"] = "default:grass_5"}, {["x"] = 3, ["param2"] = 20, ["y"] = 0, ["param1"] = 12, ["z"] = 3, ["name"] = "stairs:slab_stone"}, {["x"] = 3, ["y"] = 0, ["param1"] = 1, ["z"] = 4, ["name"] = "default:stone"}, {["x"] = 3, ["param2"] = 22, ["y"] = 0, ["param1"] = 12, ["z"] = 5, ["name"] = "stairs:slab_stone"}, {["x"] = 3, ["y"] = 1, ["param1"] = 1, ["z"] = 2, ["name"] = "default:stone"}, {["x"] = 3, ["y"] = 1, ["param1"] = 1, ["z"] = 3, ["name"] = "default:stone"}, {["x"] = 3, ["y"] = 1, ["param1"] = 1, ["z"] = 4, ["name"] = "default:stone"}, {["x"] = 3, ["y"] = 1, ["param1"] = 1, ["z"] = 5, ["name"] = "default:stone"}, {["x"] = 3, ["y"] = 1, ["param1"] = 1, ["z"] = 6, ["name"] = "default:stone"}, {["x"] = 3, ["param2"] = 22, ["y"] = 1, ["param1"] = 14, ["z"] = 7, ["name"] = "stairs:slab_stone"}, {["x"] = 3, ["y"] = 2, ["param1"] = 1, ["z"] = 1, ["name"] = "default:stone"}, {["x"] = 3, ["y"] = 2, ["param1"] = 1, ["z"] = 2, ["name"] = "default:stone"}, {["x"] = 3, ["y"] = 2, ["param1"] = 1, ["z"] = 3, ["name"] = "default:stone"}, {["x"] = 3, ["y"] = 2, ["param1"] = 1, ["z"] = 4, ["name"] = "default:stone"}, {["x"] = 3, ["y"] = 2, ["param1"] = 1, ["z"] = 5, ["name"] = "default:stone"}, {["x"] = 3, ["y"] = 2, ["param1"] = 1, ["z"] = 6, ["name"] = "default:stone"}, {["x"] = 3, ["y"] = 2, ["param1"] = 5, ["z"] = 7, ["name"] = "default:mossycobble"}, {["x"] = 3, ["y"] = 3, ["param1"] = 5, ["z"] = 2, ["name"] = "default:mossycobble"}, {["x"] = 3, ["y"] = 3, ["param1"] = 1, ["z"] = 3, ["name"] = "default:stone"}, {["x"] = 3, ["y"] = 3, ["param1"] = 1, ["z"] = 4, ["name"] = "default:stone"}, {["x"] = 3, ["y"] = 3, ["param1"] = 1, ["z"] = 5, ["name"] = "default:stone"}, {["x"] = 3, ["y"] = 3, ["param1"] = 5, ["z"] = 6, ["name"] = "default:mossycobble"}, {["x"] = 3, ["y"] = 3, ["param1"] = 15, ["z"] = 7, ["name"] = "default:grass_5"}, {["x"] = 3, ["y"] = 4, ["param1"] = 15, ["z"] = 2, ["name"] = "default:grass_4"}, {["x"] = 3, ["param2"] = 3, ["y"] = 4, ["param1"] = 14, ["z"] = 3, ["name"] = "stairs:slab_mossycobble"}, {["x"] = 3, ["y"] = 4, ["param1"] = 5, ["z"] = 4, ["name"] = "default:mossycobble"}, {["x"] = 3, ["param2"] = 3, ["y"] = 4, ["param1"] = 14, ["z"] = 5, ["name"] = "stairs:slab_mossycobble"}, {["x"] = 3, ["y"] = 4, ["param1"] = 15, ["z"] = 6, ["name"] = "default:grass_3"}, {["x"] = 3, ["y"] = 5, ["param1"] = 15, ["z"] = 4, ["name"] = "default:grass_4"}, {["x"] = 4, ["y"] = 0, ["param1"] = 1, ["z"] = 3, ["name"] = "default:stone"}, {["x"] = 4, ["y"] = 0, ["param1"] = 1, ["z"] = 4, ["name"] = "default:stone"}, {["x"] = 4, ["param2"] = 22, ["y"] = 0, ["param1"] = 12, ["z"] = 5, ["name"] = "stairs:slab_stone"}, {["x"] = 4, ["param2"] = 22, ["y"] = 0, ["param1"] = 13, ["z"] = 6, ["name"] = "stairs:slab_stone"}, {["x"] = 4, ["param2"] = 20, ["y"] = 1, ["param1"] = 14, ["z"] = 1, ["name"] = "stairs:slab_stone"}, {["x"] = 4, ["y"] = 1, ["param1"] = 1, ["z"] = 2, ["name"] = "default:stone"}, {["x"] = 4, ["y"] = 1, ["param1"] = 1, ["z"] = 3, ["name"] = "default:stone"}, {["x"] = 4, ["y"] = 1, ["param1"] = 1, ["z"] = 4, ["name"] = "default:stone"}, {["x"] = 4, ["y"] = 1, ["param1"] = 1, ["z"] = 5, ["name"] = "default:stone"}, {["x"] = 4, ["y"] = 1, ["param1"] = 1, ["z"] = 6, ["name"] = "default:stone"}, {["x"] = 4, ["param2"] = 22, ["y"] = 1, ["param1"] = 14, ["z"] = 7, ["name"] = "stairs:slab_stone"}, {["x"] = 4, ["y"] = 2, ["param1"] = 1, ["z"] = 1, ["name"] = "default:stone"}, {["x"] = 4, ["y"] = 2, ["param1"] = 1, ["z"] = 2, ["name"] = "default:stone"}, {["x"] = 4, ["y"] = 2, ["param1"] = 1, ["z"] = 3, ["name"] = "default:stone"}, {["x"] = 4, ["y"] = 2, ["param1"] = 1, ["z"] = 4, ["name"] = "default:stone"}, {["x"] = 4, ["y"] = 2, ["param1"] = 1, ["z"] = 5, ["name"] = "default:stone"}, {["x"] = 4, ["y"] = 2, ["param1"] = 1, ["z"] = 6, ["name"] = "default:stone"}, {["x"] = 4, ["y"] = 2, ["param1"] = 5, ["z"] = 7, ["name"] = "default:mossycobble"}, {["x"] = 4, ["y"] = 3, ["param1"] = 14, ["z"] = 1, ["name"] = "stairs:slab_mossycobble"}, {["x"] = 4, ["y"] = 3, ["param1"] = 5, ["z"] = 2, ["name"] = "default:mossycobble"}, {["x"] = 4, ["y"] = 3, ["param1"] = 1, ["z"] = 3, ["name"] = "default:stone"}, {["x"] = 4, ["y"] = 3, ["param1"] = 1, ["z"] = 4, ["name"] = "default:stone"}, {["x"] = 4, ["y"] = 3, ["param1"] = 1, ["z"] = 5, ["name"] = "default:stone"}, {["x"] = 4, ["y"] = 3, ["param1"] = 1, ["z"] = 6, ["name"] = "default:stone"}, {["x"] = 4, ["y"] = 3, ["param1"] = 15, ["z"] = 7, ["name"] = "default:grass_3"}, {["x"] = 4, ["y"] = 4, ["param1"] = 15, ["z"] = 2, ["name"] = "default:grass_3"}, {["x"] = 4, ["y"] = 4, ["param1"] = 15, ["z"] = 3, ["name"] = "default:grass_5"}, {["x"] = 4, ["y"] = 4, ["param1"] = 5, ["z"] = 4, ["name"] = "default:mossycobble"}, {["x"] = 4, ["param2"] = 3, ["y"] = 4, ["param1"] = 14, ["z"] = 5, ["name"] = "stairs:slab_mossycobble"}, {["x"] = 4, ["y"] = 5, ["param1"] = 15, ["z"] = 4, ["name"] = "default:grass_3"}, {["x"] = 5, ["param2"] = 20, ["y"] = 0, ["param1"] = 13, ["z"] = 2, ["name"] = "stairs:slab_stone"}, {["x"] = 5, ["param2"] = 21, ["y"] = 0, ["param1"] = 12, ["z"] = 3, ["name"] = "stairs:slab_stone"}, {["x"] = 5, ["param2"] = 21, ["y"] = 0, ["param1"] = 11, ["z"] = 4, ["name"] = "stairs:slab_stone"}, {["x"] = 5, ["param2"] = 20, ["y"] = 1, ["param1"] = 14, ["z"] = 1, ["name"] = "stairs:slab_stone"}, {["x"] = 5, ["y"] = 1, ["param1"] = 1, ["z"] = 2, ["name"] = "default:stone"}, {["x"] = 5, ["y"] = 1, ["param1"] = 1, ["z"] = 3, ["name"] = "default:stone"}, {["x"] = 5, ["y"] = 1, ["param1"] = 1, ["z"] = 4, ["name"] = "default:stone"}, {["x"] = 5, ["y"] = 1, ["param1"] = 1, ["z"] = 5, ["name"] = "default:stone"}, {["x"] = 5, ["y"] = 1, ["param1"] = 1, ["z"] = 6, ["name"] = "default:stone"}, {["x"] = 5, ["param2"] = 22, ["y"] = 1, ["param1"] = 14, ["z"] = 7, ["name"] = "stairs:slab_stone"}, {["x"] = 5, ["y"] = 2, ["param1"] = 5, ["z"] = 1, ["name"] = "default:mossycobble"}, {["x"] = 5, ["y"] = 2, ["param1"] = 1, ["z"] = 2, ["name"] = "default:stone"}, {["x"] = 5, ["y"] = 2, ["param1"] = 1, ["z"] = 3, ["name"] = "default:stone"}, {["x"] = 5, ["y"] = 2, ["param1"] = 1, ["z"] = 4, ["name"] = "default:stone"}, {["x"] = 5, ["y"] = 2, ["param1"] = 1, ["z"] = 5, ["name"] = "default:stone"}, {["x"] = 5, ["y"] = 2, ["param1"] = 1, ["z"] = 6, ["name"] = "default:stone"}, {["x"] = 5, ["y"] = 2, ["param1"] = 1, ["z"] = 7, ["name"] = "default:stone"}, {["x"] = 5, ["y"] = 3, ["param1"] = 15, ["z"] = 1, ["name"] = "default:grass_1"}, {["x"] = 5, ["y"] = 3, ["param1"] = 1, ["z"] = 2, ["name"] = "default:stone"}, {["x"] = 5, ["y"] = 3, ["param1"] = 1, ["z"] = 3, ["name"] = "default:stone"}, {["x"] = 5, ["y"] = 3, ["param1"] = 5, ["z"] = 4, ["name"] = "default:mossycobble"}, {["x"] = 5, ["y"] = 3, ["param1"] = 1, ["z"] = 5, ["name"] = "default:stone"}, {["x"] = 5, ["y"] = 3, ["param1"] = 5, ["z"] = 6, ["name"] = "default:mossycobble"}, {["x"] = 5, ["y"] = 4, ["param1"] = 15, ["z"] = 2, ["name"] = "default:grass_5"}, {["x"] = 5, ["param2"] = 3, ["y"] = 4, ["param1"] = 14, ["z"] = 3, ["name"] = "stairs:slab_mossycobble"}, {["x"] = 5, ["y"] = 4, ["param1"] = 15, ["z"] = 4, ["name"] = "default:grass_5"}, {["x"] = 5, ["param2"] = 3, ["y"] = 4, ["param1"] = 14, ["z"] = 5, ["name"] = "stairs:slab_mossycobble"}, {["x"] = 5, ["y"] = 4, ["param1"] = 15, ["z"] = 6, ["name"] = "default:grass_4"}, {["x"] = 6, ["param2"] = 20, ["y"] = 1, ["param1"] = 13, ["z"] = 2, ["name"] = "stairs:slab_stone"}, {["x"] = 6, ["y"] = 1, ["param1"] = 1, ["z"] = 3, ["name"] = "default:stone"}, {["x"] = 6, ["y"] = 1, ["param1"] = 1, ["z"] = 4, ["name"] = "default:stone"}, {["x"] = 6, ["y"] = 1, ["param1"] = 1, ["z"] = 5, ["name"] = "default:stone"}, {["x"] = 6, ["param2"] = 21, ["y"] = 1, ["param1"] = 13, ["z"] = 6, ["name"] = "stairs:slab_stone"}, {["x"] = 6, ["y"] = 2, ["param1"] = 5, ["z"] = 1, ["name"] = "default:mossycobble"}, {["x"] = 6, ["y"] = 2, ["param1"] = 1, ["z"] = 2, ["name"] = "default:stone"}, {["x"] = 6, ["y"] = 2, ["param1"] = 1, ["z"] = 3, ["name"] = "default:stone"}, {["x"] = 6, ["y"] = 2, ["param1"] = 1, ["z"] = 4, ["name"] = "default:stone"}, {["x"] = 6, ["y"] = 2, ["param1"] = 1, ["z"] = 5, ["name"] = "default:stone"}, {["x"] = 6, ["y"] = 2, ["param1"] = 1, ["z"] = 6, ["name"] = "default:stone"}, {["x"] = 6, ["y"] = 2, ["param1"] = 1, ["z"] = 7, ["name"] = "default:stone"}, {["x"] = 6, ["y"] = 3, ["param1"] = 15, ["z"] = 1, ["name"] = "default:grass_5"}, {["x"] = 6, ["param2"] = 3, ["y"] = 3, ["param1"] = 14, ["z"] = 2, ["name"] = "stairs:slab_mossycobble"}, {["x"] = 6, ["y"] = 3, ["param1"] = 1, ["z"] = 3, ["name"] = "default:stone"}, {["x"] = 6, ["y"] = 3, ["param1"] = 1, ["z"] = 4, ["name"] = "default:stone"}, {["x"] = 6, ["y"] = 3, ["param1"] = 1, ["z"] = 5, ["name"] = "default:stone"}, {["x"] = 6, ["y"] = 3, ["param1"] = 5, ["z"] = 6, ["name"] = "default:mossycobble"}, {["x"] = 6, ["param2"] = 3, ["y"] = 4, ["param1"] = 14, ["z"] = 4, ["name"] = "stairs:slab_mossycobble"}, {["x"] = 6, ["y"] = 4, ["param1"] = 15, ["z"] = 6, ["name"] = "default:grass_3"}, {["x"] = 7, ["param2"] = 21, ["y"] = 1, ["param1"] = 14, ["z"] = 3, ["name"] = "stairs:slab_stone"}, {["x"] = 7, ["param2"] = 21, ["y"] = 1, ["param1"] = 13, ["z"] = 4, ["name"] = "stairs:slab_stone"}, {["x"] = 7, ["param2"] = 21, ["y"] = 1, ["param1"] = 13, ["z"] = 5, ["name"] = "stairs:slab_stone"}, {["x"] = 7, ["y"] = 2, ["param1"] = 5, ["z"] = 2, ["name"] = "default:mossycobble"}, {["x"] = 7, ["y"] = 2, ["param1"] = 1, ["z"] = 3, ["name"] = "default:stone"}, {["x"] = 7, ["y"] = 2, ["param1"] = 1, ["z"] = 4, ["name"] = "default:stone"}, {["x"] = 7, ["y"] = 2, ["param1"] = 1, ["z"] = 5, ["name"] = "default:stone"}, {["x"] = 7, ["y"] = 2, ["param1"] = 5, ["z"] = 6, ["name"] = "default:mossycobble"}, {["x"] = 7, ["y"] = 3, ["param1"] = 15, ["z"] = 2, ["name"] = "default:grass_2"}, {["x"] = 7, ["y"] = 3, ["param1"] = 5, ["z"] = 3, ["name"] = "default:mossycobble"}, {["x"] = 7, ["y"] = 3, ["param1"] = 1, ["z"] = 4, ["name"] = "default:stone"}, {["x"] = 7, ["param2"] = 3, ["y"] = 3, ["param1"] = 14, ["z"] = 5, ["name"] = "stairs:slab_mossycobble"}, {["x"] = 7, ["y"] = 3, ["param1"] = 15, ["z"] = 6, ["name"] = "default:grass_1"}, {["x"] = 7, ["y"] = 4, ["param1"] = 15, ["z"] = 3, ["name"] = "default:grass_1"}, {["x"] = 8, ["y"] = 2, ["param1"] = 5, ["z"] = 4, ["name"] = "default:mossycobble"}, {["x"] = 8, ["y"] = 2, ["param1"] = 5, ["z"] = 5, ["name"] = "default:mossycobble"}, {["x"] = 8, ["y"] = 3, ["param1"] = 15, ["z"] = 4, ["name"] = "default:grass_1"}, {["x"] = 8, ["y"] = 3, ["param1"] = 15, ["z"] = 5, ["name"] = "default:grass_1"}}