5:return {{["x"] = 0, ["y"] = 1, ["z"] = 3, ["name"] = "default:desert_stone"}, {["x"] = 0, ["param2"] = 23, ["y"] = 1, ["param1"] = 14, ["z"] = 4, ["name"] = "stairs:slab_desert_stone"}, {["x"] = 0, ["y"] = 2, ["z"] = 3, ["name"] = "default:desert_sand"}, {["x"] = 0, ["y"] = 2, ["z"] = 4, ["name"] = "default:desert_sand"}, {["x"] = 1, ["param2"] = 20, ["y"] = 1, ["param1"] = 14, ["z"] = 2, ["name"] = "stairs:slab_desert_stone"}, {["x"] = 1, ["y"] = 1, ["z"] = 3, ["name"] = "default:desert_stone"}, {["x"] = 1, ["y"] = 1, ["z"] = 4, ["name"] = "default:desert_stone"}, {["x"] = 1, ["y"] = 2, ["z"] = 2, ["name"] = "default:desert_stone"}, {["x"] = 1, ["y"] = 2, ["z"] = 3, ["name"] = "default:desert_stone"}, {["x"] = 1, ["y"] = 2, ["z"] = 4, ["name"] = "default:desert_stone"}, {["x"] = 1, ["y"] = 2, ["z"] = 5, ["name"] = "default:desert_stone"}, {["x"] = 1, ["y"] = 3, ["z"] = 2, ["name"] = "default:desert_sand"}, {["x"] = 1, ["y"] = 3, ["z"] = 3, ["name"] = "default:desert_sand"}, {["x"] = 1, ["y"] = 3, ["z"] = 4, ["name"] = "default:desert_sand"}, {["x"] = 1, ["y"] = 3, ["z"] = 5, ["name"] = "default:desert_sand"}, {["x"] = 2, ["param2"] = 20, ["y"] = 0, ["param1"] = 13, ["z"] = 2, ["name"] = "stairs:slab_desert_stone"}, {["x"] = 2, ["y"] = 0, ["z"] = 3, ["name"] = "default:desert_stone"}, {["x"] = 2, ["y"] = 0, ["z"] = 4, ["name"] = "default:desert_sand"}, {["x"] = 2, ["y"] = 1, ["z"] = 2, ["name"] = "default:desert_stone"}, {["x"] = 2, ["y"] = 1, ["z"] = 3, ["name"] = "default:desert_stone"}, {["x"] = 2, ["y"] = 1, ["z"] = 4, ["name"] = "default:desert_stone"}, {["x"] = 2, ["param2"] = 22, ["y"] = 1, ["param1"] = 13, ["z"] = 5, ["name"] = "stairs:slab_desert_stone"}, {["x"] = 2, ["y"] = 2, ["z"] = 1, ["name"] = "default:desert_stone"}, {["x"] = 2, ["y"] = 2, ["z"] = 2, ["name"] = "default:desert_stone"}, {["x"] = 2, ["y"] = 2, ["z"] = 3, ["name"] = "default:desert_stone"}, {["x"] = 2, ["y"] = 2, ["z"] = 4, ["name"] = "default:desert_stone"}, {["x"] = 2, ["y"] = 2, ["z"] = 5, ["name"] = "default:desert_stone"}, {["x"] = 2, ["param2"] = 22, ["y"] = 2, ["param1"] = 14, ["z"] = 6, ["name"] = "stairs:slab_desert_stone"}, {["x"] = 2, ["y"] = 3, ["z"] = 1, ["name"] = "default:desert_sand"}, {["x"] = 2, ["y"] = 3, ["z"] = 2, ["name"] = "default:desert_sand"}, {["x"] = 2, ["y"] = 3, ["z"] = 3, ["name"] = "default:desert_stone"}, {["x"] = 2, ["y"] = 3, ["z"] = 4, ["name"] = "default:desert_sand"}, {["x"] = 2, ["y"] = 3, ["z"] = 5, ["name"] = "default:desert_sand"}, {["x"] = 2, ["y"] = 3, ["z"] = 6, ["name"] = "default:desert_sand"}, {["x"] = 2, ["y"] = 4, ["z"] = 3, ["name"] = "default:desert_sand"}, {["x"] = 3, ["y"] = 0, ["z"] = 2, ["name"] = "default:desert_stone"}, {["x"] = 3, ["y"] = 0, ["z"] = 3, ["name"] = "default:desert_stone"}, {["x"] = 3, ["y"] = 0, ["z"] = 4, ["name"] = "default:desert_stone"}, {["x"] = 3, ["param2"] = 20, ["y"] = 1, ["param1"] = 13, ["z"] = 1, ["name"] = "stairs:slab_desert_stone"}, {["x"] = 3, ["y"] = 1, ["z"] = 2, ["name"] = "default:desert_stone"}, {["x"] = 3, ["y"] = 1, ["z"] = 3, ["name"] = "default:desert_stone"}, {["x"] = 3, ["y"] = 1, ["z"] = 4, ["name"] = "default:desert_stone"}, {["x"] = 3, ["y"] = 1, ["z"] = 5, ["name"] = "default:desert_stone"}, {["x"] = 3, ["param2"] = 20, ["y"] = 2, ["param1"] = 14, ["z"] = 0, ["name"] = "stairs:slab_desert_stone"}, {["x"] = 3, ["y"] = 2, ["z"] = 1, ["name"] = "default:desert_stone"}, {["x"] = 3, ["y"] = 2, ["z"] = 2, ["name"] = "default:desert_stone"}, {["x"] = 3, ["y"] = 2, ["z"] = 3, ["name"] = "default:desert_stone"}, {["x"] = 3, ["y"] = 2, ["z"] = 4, ["name"] = "default:desert_stone"}, {["x"] = 3, ["y"] = 2, ["z"] = 5, ["name"] = "default:desert_stone"}, {["x"] = 3, ["y"] = 2, ["z"] = 6, ["name"] = "default:desert_stone"}, {["x"] = 3, ["y"] = 3, ["z"] = 0, ["name"] = "default:desert_sand"}, {["x"] = 3, ["y"] = 3, ["z"] = 1, ["name"] = "default:desert_sand"}, {["x"] = 3, ["y"] = 3, ["z"] = 2, ["name"] = "default:desert_stone"}, {["x"] = 3, ["y"] = 3, ["z"] = 3, ["name"] = "default:desert_stone"}, {["x"] = 3, ["y"] = 3, ["z"] = 4, ["name"] = "default:desert_stone"}, {["x"] = 3, ["y"] = 3, ["z"] = 5, ["name"] = "default:desert_sand"}, {["x"] = 3, ["y"] = 3, ["z"] = 6, ["name"] = "default:desert_sand"}, {["x"] = 3, ["y"] = 4, ["z"] = 2, ["name"] = "default:desert_sand"}, {["x"] = 3, ["y"] = 4, ["z"] = 3, ["name"] = "default:desert_sand"}, {["x"] = 3, ["y"] = 4, ["z"] = 4, ["name"] = "default:desert_sand"}, {["x"] = 4, ["y"] = 0, ["z"] = 2, ["name"] = "default:desert_sand"}, {["x"] = 4, ["param2"] = 22, ["y"] = 0, ["param1"] = 12, ["z"] = 3, ["name"] = "stairs:slab_desert_stone"}, {["x"] = 4, ["param2"] = 20, ["y"] = 1, ["param1"] = 13, ["z"] = 1, ["name"] = "stairs:slab_desert_stone"}, {["x"] = 4, ["y"] = 1, ["z"] = 2, ["name"] = "default:desert_stone"}, {["x"] = 4, ["y"] = 1, ["z"] = 3, ["name"] = "default:desert_stone"}, {["x"] = 4, ["y"] = 1, ["z"] = 4, ["name"] = "default:desert_stone"}, {["x"] = 4, ["param2"] = 22, ["y"] = 1, ["param1"] = 13, ["z"] = 5, ["name"] = "stairs:slab_desert_stone"}, {["x"] = 4, ["param2"] = 20, ["y"] = 2, ["param1"] = 14, ["z"] = 0, ["name"] = "stairs:slab_desert_stone"}, {["x"] = 4, ["y"] = 2, ["z"] = 1, ["name"] = "default:desert_stone"}, {["x"] = 4, ["y"] = 2, ["z"] = 2, ["name"] = "default:desert_stone"}, {["x"] = 4, ["y"] = 2, ["z"] = 3, ["name"] = "default:desert_stone"}, {["x"] = 4, ["y"] = 2, ["z"] = 4, ["name"] = "default:desert_stone"}, {["x"] = 4, ["y"] = 2, ["z"] = 5, ["name"] = "default:desert_stone"}, {["x"] = 4, ["param2"] = 22, ["y"] = 2, ["param1"] = 14, ["z"] = 6, ["name"] = "stairs:slab_desert_stone"}, {["x"] = 4, ["y"] = 3, ["z"] = 0, ["name"] = "default:desert_sand"}, {["x"] = 4, ["y"] = 3, ["z"] = 1, ["name"] = "default:desert_sand"}, {["x"] = 4, ["y"] = 3, ["z"] = 2, ["name"] = "default:desert_stone"}, {["x"] = 4, ["y"] = 3, ["z"] = 3, ["name"] = "default:desert_stone"}, {["x"] = 4, ["y"] = 3, ["z"] = 4, ["name"] = "default:desert_stone"}, {["x"] = 4, ["y"] = 3, ["z"] = 5, ["name"] = "default:desert_sand"}, {["x"] = 4, ["y"] = 3, ["z"] = 6, ["name"] = "default:desert_sand"}, {["x"] = 4, ["y"] = 4, ["z"] = 2, ["name"] = "default:desert_sand"}, {["x"] = 4, ["y"] = 4, ["z"] = 3, ["name"] = "default:desert_sand"}, {["x"] = 4, ["y"] = 4, ["z"] = 4, ["name"] = "default:desert_sand"}, {["x"] = 5, ["param2"] = 20, ["y"] = 1, ["param1"] = 13, ["z"] = 2, ["name"] = "stairs:slab_desert_stone"}, {["x"] = 5, ["y"] = 1, ["z"] = 3, ["name"] = "default:desert_stone"}, {["x"] = 5, ["y"] = 2, ["z"] = 1, ["name"] = "default:desert_stone"}, {["x"] = 5, ["y"] = 2, ["z"] = 2, ["name"] = "default:desert_stone"}, {["x"] = 5, ["y"] = 2, ["z"] = 3, ["name"] = "default:desert_stone"}, {["x"] = 5, ["y"] = 2, ["z"] = 4, ["name"] = "default:desert_stone"}, {["x"] = 5, ["y"] = 2, ["z"] = 5, ["name"] = "default:desert_stone"}, {["x"] = 5, ["y"] = 3, ["z"] = 1, ["name"] = "default:desert_sand"}, {["x"] = 5, ["y"] = 3, ["z"] = 2, ["name"] = "default:desert_sand"}, {["x"] = 5, ["y"] = 3, ["z"] = 3, ["name"] = "default:desert_stone"}, {["x"] = 5, ["y"] = 3, ["z"] = 4, ["name"] = "default:desert_stone"}, {["x"] = 5, ["y"] = 3, ["z"] = 5, ["name"] = "default:desert_sand"}, {["x"] = 5, ["y"] = 4, ["z"] = 3, ["name"] = "default:desert_sand"}, {["x"] = 5, ["y"] = 4, ["z"] = 4, ["name"] = "default:desert_sand"}, {["x"] = 6, ["param2"] = 20, ["y"] = 2, ["param1"] = 14, ["z"] = 2, ["name"] = "stairs:slab_desert_stone"}, {["x"] = 6, ["y"] = 2, ["z"] = 3, ["name"] = "default:desert_stone"}, {["x"] = 6, ["y"] = 2, ["z"] = 4, ["name"] = "default:desert_stone"}, {["x"] = 6, ["y"] = 3, ["z"] = 2, ["name"] = "default:desert_sand"}, {["x"] = 6, ["y"] = 3, ["z"] = 3, ["name"] = "default:desert_sand"}, {["x"] = 6, ["y"] = 3, ["z"] = 4, ["name"] = "default:desert_sand"}}