5:return {{["x"] = 0, ["y"] = 2, ["param1"] = 14, ["z"] = 4, ["name"] = "default:bush_leaves"}, {["x"] = 0, ["y"] = 3, ["param1"] = 14, ["z"] = 2, ["name"] = "default:bush_leaves"}, {["x"] = 0, ["y"] = 3, ["param1"] = 14, ["z"] = 3, ["name"] = "default:bush_leaves"}, {["x"] = 0, ["y"] = 3, ["param1"] = 14, ["z"] = 5, ["name"] = "default:bush_leaves"}, {["x"] = 0, ["y"] = 4, ["param1"] = 14, ["z"] = 3, ["name"] = "default:bush_leaves"}, {["x"] = 0, ["y"] = 4, ["param1"] = 14, ["z"] = 4, ["name"] = "default:bush_leaves"}, {["x"] = 1, ["y"] = 2, ["param1"] = 14, ["z"] = 0, ["name"] = "default:bush_leaves"}, {["x"] = 1, ["y"] = 2, ["param1"] = 13, ["z"] = 2, ["name"] = "default:bush_leaves"}, {["x"] = 1, ["y"] = 2, ["param1"] = 13, ["z"] = 4, ["name"] = "default:bush_leaves"}, {["x"] = 1, ["y"] = 2, ["param1"] = 13, ["z"] = 5, ["name"] = "default:bush_leaves"}, {["x"] = 1, ["y"] = 3, ["param1"] = 14, ["z"] = 0, ["name"] = "default:bush_leaves"}, {["x"] = 1, ["y"] = 3, ["param1"] = 14, ["z"] = 1, ["name"] = "default:bush_leaves"}, {["x"] = 1, ["y"] = 3, ["param1"] = 13, ["z"] = 2, ["name"] = "default:bush_leaves"}, {["x"] = 1, ["y"] = 3, ["param1"] = 13, ["z"] = 3, ["name"] = "default:bush_leaves"}, {["x"] = 1, ["y"] = 3, ["param1"] = 13, ["z"] = 4, ["name"] = "default:bush_leaves"}, {["x"] = 1, ["y"] = 3, ["param1"] = 13, ["z"] = 5, ["name"] = "default:bush_leaves"}, {["x"] = 1, ["y"] = 3, ["param1"] = 14, ["z"] = 6, ["name"] = "default:bush_leaves"}, {["x"] = 1, ["y"] = 4, ["param1"] = 14, ["z"] = 1, ["name"] = "default:bush_leaves"}, {["x"] = 1, ["y"] = 4, ["param1"] = 30, ["z"] = 2, ["name"] = "default:bush_leaves"}, {["x"] = 1, ["y"] = 4, ["param1"] = 14, ["z"] = 3, ["name"] = "default:bush_leaves"}, {["x"] = 1, ["y"] = 4, ["param1"] = 13, ["z"] = 4, ["name"] = "default:bush_leaves"}, {["x"] = 1, ["y"] = 4, ["param1"] = 14, ["z"] = 5, ["name"] = "default:bush_leaves"}, {["x"] = 1, ["y"] = 5, ["param1"] = 31, ["z"] = 3, ["name"] = "flowers:dandelion_white"}, {["x"] = 1, ["y"] = 5, ["param1"] = 14, ["z"] = 4, ["name"] = "default:bush_leaves"}, {["x"] = 1, ["y"] = 5, ["param1"] = 15, ["z"] = 5, ["name"] = "flowers:dandelion_white"}, {["x"] = 2, ["y"] = 0, ["param1"] = 12, ["z"] = 3, ["name"] = "default:bush_leaves"}, {["x"] = 2, ["y"] = 1, ["param1"] = 14, ["z"] = 0, ["name"] = "default:bush_leaves"}, {["x"] = 2, ["y"] = 1, ["param1"] = 12, ["z"] = 4, ["name"] = "default:bush_leaves"}, {["x"] = 2, ["y"] = 2, ["param1"] = 14, ["z"] = 0, ["name"] = "default:bush_leaves"}, {["x"] = 2, ["y"] = 2, ["param1"] = 13, ["z"] = 1, ["name"] = "default:bush_leaves"}, {["x"] = 2, ["y"] = 2, ["param1"] = 12, ["z"] = 2, ["name"] = "default:bush_leaves"}, {["x"] = 2, ["y"] = 2, ["param1"] = 12, ["z"] = 3, ["name"] = "default:bush_leaves"}, {["x"] = 2, ["y"] = 2, ["param1"] = 12, ["z"] = 4, ["name"] = "default:bush_stem"}, {["x"] = 2, ["y"] = 2, ["param1"] = 13, ["z"] = 5, ["name"] = "default:bush_leaves"}, {["x"] = 2, ["y"] = 2, ["param1"] = 14, ["z"] = 6, ["name"] = "default:bush_leaves"}, {["x"] = 2, ["y"] = 3, ["param1"] = 13, ["z"] = 1, ["name"] = "default:bush_leaves"}, {["x"] = 2, ["y"] = 3, ["param1"] = 29, ["z"] = 2, ["name"] = "default:bush_leaves"}, {["x"] = 2, ["y"] = 3, ["param1"] = 12, ["z"] = 3, ["name"] = "default:bush_stem"}, {["x"] = 2, ["y"] = 3, ["param1"] = 12, ["z"] = 4, ["name"] = "default:bush_stem"}, {["x"] = 2, ["y"] = 3, ["param1"] = 13, ["z"] = 5, ["name"] = "default:bush_stem"}, {["x"] = 2, ["y"] = 3, ["param1"] = 14, ["z"] = 6, ["name"] = "default:bush_leaves"}, {["x"] = 2, ["y"] = 4, ["param1"] = 14, ["z"] = 0, ["name"] = "default:bush_leaves"}, {["x"] = 2, ["y"] = 4, ["param1"] = 30, ["z"] = 1, ["name"] = "default:bush_leaves"}, {["x"] = 2, ["y"] = 4, ["param1"] = 46, ["z"] = 2, ["name"] = "default:bush_leaves"}, {["x"] = 2, ["y"] = 4, ["param1"] = 29, ["z"] = 3, ["name"] = "default:bush_leaves"}, {["x"] = 2, ["y"] = 4, ["param1"] = 13, ["z"] = 4, ["name"] = "default:bush_leaves"}, {["x"] = 2, ["y"] = 4, ["param1"] = 13, ["z"] = 5, ["name"] = "default:bush_leaves"}, {["x"] = 2, ["y"] = 4, ["param1"] = 14, ["z"] = 6, ["name"] = "default:bush_leaves"}, {["x"] = 2, ["y"] = 5, ["param1"] = 47, ["z"] = 1, ["name"] = "flowers:dandelion_white"}, {["x"] = 2, ["y"] = 5, ["param1"] = 46, ["z"] = 3, ["name"] = "default:bush_leaves"}, {["x"] = 2, ["y"] = 5, ["param1"] = 30, ["z"] = 4, ["name"] = "default:bush_leaves"}, {["x"] = 2, ["y"] = 5, ["param1"] = 14, ["z"] = 5, ["name"] = "default:bush_leaves"}, {["x"] = 2, ["y"] = 6, ["param1"] = 15, ["z"] = 4, ["name"] = "flowers:dandelion_white"}, {["x"] = 3, ["y"] = 0, ["param1"] = 12, ["z"] = 2, ["name"] = "default:bush_leaves"}, {["x"] = 3, ["y"] = 0, ["param1"] = 11, ["z"] = 3, ["name"] = "default:bush_stem"}, {["x"] = 3, ["y"] = 0, ["param1"] = 12, ["z"] = 4, ["name"] = "default:bush_leaves"}, {["x"] = 3, ["y"] = 1, ["param1"] = 12, ["z"] = 2, ["name"] = "default:bush_leaves"}, {["x"] = 3, ["y"] = 1, ["param1"] = 11, ["z"] = 3, ["name"] = "default:bush_stem"}, {["x"] = 3, ["y"] = 2, ["param1"] = 14, ["z"] = 0, ["name"] = "default:bush_leaves"}, {["x"] = 3, ["y"] = 2, ["param1"] = 13, ["z"] = 1, ["name"] = "default:bush_leaves"}, {["x"] = 3, ["y"] = 2, ["param1"] = 29, ["z"] = 2, ["name"] = "default:bush_stem"}, {["x"] = 3, ["y"] = 2, ["param1"] = 12, ["z"] = 4, ["name"] = "default:bush_leaves"}, {["x"] = 3, ["y"] = 2, ["param1"] = 13, ["z"] = 5, ["name"] = "default:bush_leaves"}, {["x"] = 3, ["y"] = 3, ["param1"] = 14, ["z"] = 0, ["name"] = "default:bush_leaves"}, {["x"] = 3, ["y"] = 3, ["param1"] = 29, ["z"] = 1, ["name"] = "default:bush_leaves"}, {["x"] = 3, ["y"] = 3, ["param1"] = 46, ["z"] = 2, ["name"] = "default:bush_leaves"}, {["x"] = 3, ["y"] = 3, ["param1"] = 29, ["z"] = 3, ["name"] = "default:bush_leaves"}, {["x"] = 3, ["y"] = 3, ["param1"] = 12, ["z"] = 4, ["name"] = "default:bush_leaves"}, {["x"] = 3, ["y"] = 3, ["param1"] = 13, ["z"] = 5, ["name"] = "default:bush_leaves"}, {["x"] = 3, ["y"] = 3, ["param1"] = 14, ["z"] = 6, ["name"] = "default:bush_leaves"}, {["x"] = 3, ["y"] = 4, ["param1"] = 46, ["z"] = 1, ["name"] = "default:bush_leaves"}, {["x"] = 3, ["y"] = 4, ["param1"] = 46, ["z"] = 3, ["name"] = "default:bush_leaves"}, {["x"] = 3, ["y"] = 4, ["param1"] = 29, ["z"] = 4, ["name"] = "default:bush_leaves"}, {["x"] = 3, ["y"] = 4, ["param1"] = 13, ["z"] = 5, ["name"] = "default:bush_leaves"}, {["x"] = 3, ["y"] = 4, ["param1"] = 14, ["z"] = 6, ["name"] = "default:bush_leaves"}, {["x"] = 3, ["y"] = 5, ["param1"] = 46, ["z"] = 4, ["name"] = "default:bush_leaves"}, {["x"] = 3, ["y"] = 5, ["param1"] = 30, ["z"] = 5, ["name"] = "default:bush_leaves"}, {["x"] = 4, ["y"] = 0, ["param1"] = 12, ["z"] = 3, ["name"] = "default:bush_leaves"}, {["x"] = 4, ["y"] = 1, ["param1"] = 12, ["z"] = 3, ["name"] = "default:bush_leaves"}, {["x"] = 4, ["y"] = 1, ["param1"] = 13, ["z"] = 5, ["name"] = "default:bush_leaves"}, {["x"] = 4, ["y"] = 2, ["param1"] = 29, ["z"] = 1, ["name"] = "default:bush_leaves"}, {["x"] = 4, ["y"] = 2, ["param1"] = 44, ["z"] = 2, ["name"] = "default:bush_leaves"}, {["x"] = 4, ["y"] = 2, ["param1"] = 28, ["z"] = 3, ["name"] = "default:bush_stem"}, {["x"] = 4, ["y"] = 2, ["param1"] = 12, ["z"] = 4, ["name"] = "default:bush_leaves"}, {["x"] = 4, ["y"] = 2, ["param1"] = 13, ["z"] = 5, ["name"] = "default:bush_stem"}, {["x"] = 4, ["y"] = 2, ["param1"] = 14, ["z"] = 6, ["name"] = "default:bush_leaves"}, {["x"] = 4, ["y"] = 3, ["param1"] = 30, ["z"] = 0, ["name"] = "default:bush_leaves"}, {["x"] = 4, ["y"] = 3, ["param1"] = 45, ["z"] = 1, ["name"] = "default:bush_leaves"}, {["x"] = 4, ["y"] = 3, ["param1"] = 61, ["z"] = 2, ["name"] = "default:bush_leaves"}, {["x"] = 4, ["y"] = 3, ["param1"] = 45, ["z"] = 3, ["name"] = "default:bush_leaves"}, {["x"] = 4, ["y"] = 3, ["param1"] = 28, ["z"] = 4, ["name"] = "default:bush_leaves"}, {["x"] = 4, ["y"] = 3, ["param1"] = 13, ["z"] = 5, ["name"] = "default:bush_leaves"}, {["x"] = 4, ["y"] = 4, ["param1"] = 62, ["z"] = 1, ["name"] = "default:bush_leaves"}, {["x"] = 4, ["y"] = 4, ["param1"] = 78, ["z"] = 2, ["name"] = "default:bush_leaves"}, {["x"] = 4, ["y"] = 4, ["param1"] = 62, ["z"] = 3, ["name"] = "default:bush_leaves"}, {["x"] = 4, ["y"] = 4, ["param1"] = 45, ["z"] = 4, ["name"] = "default:bush_leaves"}, {["x"] = 4, ["y"] = 4, ["param1"] = 30, ["z"] = 5, ["name"] = "default:bush_leaves"}, {["x"] = 4, ["y"] = 4, ["param1"] = 14, ["z"] = 6, ["name"] = "default:bush_leaves"}, {["x"] = 4, ["y"] = 5, ["param1"] = 79, ["z"] = 3, ["name"] = "flowers:dandelion_white"}, {["x"] = 4, ["y"] = 5, ["param1"] = 62, ["z"] = 4, ["name"] = "default:bush_leaves"}, {["x"] = 4, ["y"] = 5, ["param1"] = 47, ["z"] = 5, ["name"] = "flowers:dandelion_white"}, {["x"] = 5, ["y"] = 1, ["param1"] = 45, ["z"] = 2, ["name"] = "default:bush_leaves"}, {["x"] = 5, ["y"] = 1, ["param1"] = 13, ["z"] = 4, ["name"] = "default:bush_leaves"}, {["x"] = 5, ["y"] = 1, ["param1"] = 13, ["z"] = 5, ["name"] = "default:bush_leaves"}, {["x"] = 5, ["y"] = 1, ["param1"] = 14, ["z"] = 6, ["name"] = "default:bush_leaves"}, {["x"] = 5, ["y"] = 2, ["param1"] = 45, ["z"] = 1, ["name"] = "default:bush_leaves"}, {["x"] = 5, ["y"] = 2, ["param1"] = 61, ["z"] = 2, ["name"] = "default:bush_leaves"}, {["x"] = 5, ["y"] = 2, ["param1"] = 29, ["z"] = 4, ["name"] = "default:bush_leaves"}, {["x"] = 5, ["y"] = 2, ["param1"] = 13, ["z"] = 5, ["name"] = "default:bush_leaves"}, {["x"] = 5, ["y"] = 3, ["param1"] = 46, ["z"] = 0, ["name"] = "default:bush_leaves"}, {["x"] = 5, ["y"] = 3, ["param1"] = 61, ["z"] = 1, ["name"] = "default:bush_leaves"}, {["x"] = 5, ["y"] = 3, ["param1"] = 77, ["z"] = 2, ["name"] = "default:bush_leaves"}, {["x"] = 5, ["y"] = 3, ["param1"] = 61, ["z"] = 3, ["name"] = "default:bush_stem"}, {["x"] = 5, ["y"] = 3, ["param1"] = 45, ["z"] = 4, ["name"] = "default:bush_leaves"}, {["x"] = 5, ["y"] = 3, ["param1"] = 29, ["z"] = 5, ["name"] = "default:bush_leaves"}, {["x"] = 5, ["y"] = 3, ["param1"] = 14, ["z"] = 6, ["name"] = "default:bush_leaves"}, {["x"] = 5, ["y"] = 4, ["param1"] = 62, ["z"] = 0, ["name"] = "default:bush_leaves"}, {["x"] = 5, ["y"] = 4, ["param1"] = 77, ["z"] = 1, ["name"] = "default:bush_leaves"}, {["x"] = 5, ["y"] = 4, ["param1"] = 94, ["z"] = 2, ["name"] = "default:bush_leaves"}, {["x"] = 5, ["y"] = 4, ["param1"] = 78, ["z"] = 3, ["name"] = "default:bush_leaves"}, {["x"] = 5, ["y"] = 4, ["param1"] = 62, ["z"] = 4, ["name"] = "default:bush_leaves"}, {["x"] = 5, ["y"] = 4, ["param1"] = 46, ["z"] = 5, ["name"] = "default:bush_leaves"}, {["x"] = 5, ["y"] = 5, ["param1"] = 94, ["z"] = 1, ["name"] = "default:bush_leaves"}, {["x"] = 5, ["y"] = 5, ["param1"] = 111, ["z"] = 2, ["name"] = "fireflies:firefly"}, {["x"] = 5, ["y"] = 5, ["param1"] = 94, ["z"] = 3, ["name"] = "default:bush_leaves"}, {["x"] = 5, ["y"] = 5, ["param1"] = 79, ["z"] = 4, ["name"] = "butterflies:hidden_butterfly_white"}, {["x"] = 6, ["y"] = 1, ["param1"] = 14, ["z"] = 3, ["name"] = "default:bush_leaves"}, {["x"] = 6, ["y"] = 2, ["param1"] = 46, ["z"] = 2, ["name"] = "default:bush_leaves"}, {["x"] = 6, ["y"] = 2, ["param1"] = 30, ["z"] = 3, ["name"] = "default:bush_leaves"}, {["x"] = 6, ["y"] = 2, ["param1"] = 14, ["z"] = 4, ["name"] = "default:bush_leaves"}, {["x"] = 6, ["y"] = 3, ["param1"] = 46, ["z"] = 1, ["name"] = "default:bush_leaves"}, {["x"] = 6, ["y"] = 3, ["param1"] = 46, ["z"] = 3, ["name"] = "default:bush_leaves"}, {["x"] = 6, ["y"] = 3, ["param1"] = 14, ["z"] = 5, ["name"] = "default:bush_leaves"}, {["x"] = 6, ["y"] = 4, ["param1"] = 62, ["z"] = 1, ["name"] = "default:bush_leaves"}, {["x"] = 6, ["y"] = 4, ["param1"] = 78, ["z"] = 2, ["name"] = "default:bush_leaves"}, {["x"] = 6, ["y"] = 4, ["param1"] = 46, ["z"] = 4, ["name"] = "default:bush_leaves"}, {["x"] = 6, ["y"] = 5, ["param1"] = 95, ["z"] = 2, ["name"] = "flowers:dandelion_white"}}