5:return {{["x"] = 0, ["y"] = 11, ["param1"] = 14, ["z"] = 2, ["name"] = "default:pine_bush_needles"}, {["x"] = 0, ["y"] = 14, ["param1"] = 14, ["z"] = 2, ["name"] = "default:pine_bush_stem"}, {["x"] = 0, ["param2"] = 1, ["y"] = 14, ["param1"] = 14, ["z"] = 3, ["name"] = "default:pine_needles"}, {["x"] = 0, ["y"] = 15, ["param1"] = 14, ["z"] = 2, ["name"] = "default:pine_bush_needles"}, {["x"] = 1, ["y"] = 9, ["param1"] = 13, ["z"] = 2, ["name"] = "default:pine_bush_stem"}, {["x"] = 1, ["y"] = 10, ["param1"] = 13, ["z"] = 2, ["name"] = "default:pine_bush_needles"}, {["x"] = 1, ["y"] = 11, ["param1"] = 14, ["z"] = 1, ["name"] = "default:pine_bush_needles"}, {["x"] = 1, ["y"] = 11, ["param1"] = 13, ["z"] = 2, ["name"] = "default:pine_bush_stem"}, {["x"] = 1, ["y"] = 11, ["param1"] = 13, ["z"] = 3, ["name"] = "default:pine_bush_needles"}, {["x"] = 1, ["y"] = 12, ["param1"] = 13, ["z"] = 2, ["name"] = "default:pine_bush_needles"}, {["x"] = 1, ["y"] = 13, ["param1"] = 14, ["z"] = 1, ["name"] = "default:pine_bush_stem"}, {["x"] = 1, ["param2"] = 1, ["y"] = 14, ["param1"] = 14, ["z"] = 0, ["name"] = "default:pine_needles"}, {["x"] = 1, ["y"] = 14, ["param1"] = 14, ["z"] = 1, ["name"] = "default:pine_bush_needles"}, {["x"] = 1, ["y"] = 14, ["param1"] = 13, ["z"] = 2, ["name"] = "default:pine_bush_stem"}, {["x"] = 1, ["y"] = 14, ["param1"] = 13, ["z"] = 3, ["name"] = "default:pine_bush_stem"}, {["x"] = 1, ["y"] = 14, ["param1"] = 14, ["z"] = 4, ["name"] = "default:pine_bush_needles"}, {["x"] = 1, ["y"] = 15, ["param1"] = 14, ["z"] = 2, ["name"] = "default:pine_bush_needles"}, {["x"] = 1, ["y"] = 15, ["param1"] = 14, ["z"] = 3, ["name"] = "default:pine_bush_needles"}, {["x"] = 1, ["y"] = 16, ["param1"] = 14, ["z"] = 2, ["name"] = "default:pine_bush_needles"}, {["x"] = 2, ["y"] = 0, ["param1"] = 54, ["z"] = 2, ["name"] = "default:pine_tree"}, {["x"] = 2, ["y"] = 1, ["param1"] = 54, ["z"] = 2, ["name"] = "default:pine_tree"}, {["x"] = 2, ["y"] = 2, ["param1"] = 54, ["z"] = 2, ["name"] = "default:pine_tree"}, {["x"] = 2, ["y"] = 3, ["param1"] = 54, ["z"] = 2, ["name"] = "default:pine_tree"}, {["x"] = 2, ["y"] = 4, ["param1"] = 54, ["z"] = 2, ["name"] = "default:pine_tree"}, {["x"] = 2, ["y"] = 5, ["param1"] = 54, ["z"] = 2, ["name"] = "default:pine_tree"}, {["x"] = 2, ["y"] = 6, ["param1"] = 54, ["z"] = 2, ["name"] = "default:pine_tree"}, {["x"] = 2, ["y"] = 7, ["param1"] = 54, ["z"] = 2, ["name"] = "default:pine_tree"}, {["x"] = 2, ["y"] = 8, ["param1"] = 54, ["z"] = 2, ["name"] = "default:pine_tree"}, {["x"] = 2, ["y"] = 9, ["param1"] = 54, ["z"] = 2, ["name"] = "default:pine_tree"}, {["x"] = 2, ["y"] = 10, ["param1"] = 13, ["z"] = 1, ["name"] = "default:pine_bush_stem"}, {["x"] = 2, ["param2"] = 20, ["y"] = 10, ["param1"] = 54, ["z"] = 2, ["name"] = "default:pine_tree"}, {["x"] = 2, ["y"] = 11, ["param1"] = 13, ["z"] = 1, ["name"] = "default:pine_bush_needles"}, {["x"] = 2, ["param2"] = 3, ["y"] = 11, ["param1"] = 54, ["z"] = 2, ["name"] = "default:pine_tree"}, {["x"] = 2, ["y"] = 11, ["param1"] = 13, ["z"] = 3, ["name"] = "default:pine_bush_stem"}, {["x"] = 2, ["y"] = 11, ["param1"] = 14, ["z"] = 4, ["name"] = "default:pine_bush_needles"}, {["x"] = 2, ["param2"] = 3, ["y"] = 12, ["param1"] = 54, ["z"] = 2, ["name"] = "default:pine_tree"}, {["x"] = 2, ["y"] = 12, ["param1"] = 13, ["z"] = 3, ["name"] = "default:pine_bush_needles"}, {["x"] = 2, ["param2"] = 20, ["y"] = 13, ["param1"] = 54, ["z"] = 2, ["name"] = "default:pine_tree"}, {["x"] = 2, ["y"] = 14, ["param1"] = 14, ["z"] = 0, ["name"] = "default:pine_bush_stem"}, {["x"] = 2, ["y"] = 14, ["param1"] = 13, ["z"] = 1, ["name"] = "default:pine_bush_stem"}, {["x"] = 2, ["param2"] = 20, ["y"] = 14, ["param1"] = 54, ["z"] = 2, ["name"] = "default:pine_tree"}, {["x"] = 2, ["y"] = 14, ["param1"] = 13, ["z"] = 3, ["name"] = "default:pine_bush_stem"}, {["x"] = 2, ["y"] = 14, ["param1"] = 14, ["z"] = 4, ["name"] = "default:pine_bush_stem"}, {["x"] = 2, ["y"] = 15, ["param1"] = 14, ["z"] = 0, ["name"] = "default:pine_bush_needles"}, {["x"] = 2, ["y"] = 15, ["param1"] = 14, ["z"] = 1, ["name"] = "default:pine_bush_needles"}, {["x"] = 2, ["y"] = 15, ["param1"] = 13, ["z"] = 2, ["name"] = "default:pine_bush_needles"}, {["x"] = 2, ["y"] = 15, ["param1"] = 13, ["z"] = 3, ["name"] = "default:pine_bush_needles"}, {["x"] = 2, ["y"] = 15, ["param1"] = 14, ["z"] = 4, ["name"] = "default:pine_bush_needles"}, {["x"] = 2, ["y"] = 16, ["param1"] = 14, ["z"] = 1, ["name"] = "default:pine_bush_needles"}, {["x"] = 2, ["y"] = 16, ["param1"] = 14, ["z"] = 2, ["name"] = "default:pine_bush_needles"}, {["x"] = 2, ["y"] = 16, ["param1"] = 14, ["z"] = 3, ["name"] = "default:pine_bush_needles"}, {["x"] = 3, ["y"] = 8, ["param1"] = 13, ["z"] = 1, ["name"] = "default:pine_bush_stem"}, {["x"] = 3, ["y"] = 10, ["param1"] = 13, ["z"] = 2, ["name"] = "default:pine_bush_stem"}, {["x"] = 3, ["y"] = 12, ["param1"] = 13, ["z"] = 1, ["name"] = "default:pine_bush_needles"}, {["x"] = 3, ["y"] = 12, ["param1"] = 13, ["z"] = 2, ["name"] = "default:pine_bush_stem"}, {["x"] = 3, ["y"] = 12, ["param1"] = 14, ["z"] = 3, ["name"] = "default:pine_bush_needles"}, {["x"] = 3, ["y"] = 13, ["param1"] = 13, ["z"] = 2, ["name"] = "default:pine_bush_needles"}, {["x"] = 3, ["y"] = 14, ["param1"] = 14, ["z"] = 0, ["name"] = "default:pine_bush_needles"}, {["x"] = 3, ["y"] = 14, ["param1"] = 13, ["z"] = 1, ["name"] = "default:pine_bush_stem"}, {["x"] = 3, ["y"] = 14, ["param1"] = 13, ["z"] = 2, ["name"] = "default:pine_bush_stem"}, {["x"] = 3, ["y"] = 14, ["param1"] = 14, ["z"] = 3, ["name"] = "default:pine_bush_needles"}, {["x"] = 3, ["param2"] = 1, ["y"] = 14, ["param1"] = 14, ["z"] = 4, ["name"] = "default:pine_needles"}, {["x"] = 3, ["y"] = 15, ["param1"] = 14, ["z"] = 1, ["name"] = "default:pine_bush_needles"}, {["x"] = 3, ["y"] = 15, ["param1"] = 13, ["z"] = 2, ["name"] = "default:pine_bush_needles"}, {["x"] = 3, ["y"] = 15, ["param1"] = 14, ["z"] = 3, ["name"] = "default:pine_bush_needles"}, {["x"] = 3, ["y"] = 16, ["param1"] = 14, ["z"] = 2, ["name"] = "default:pine_bush_needles"}, {["x"] = 4, ["y"] = 12, ["param1"] = 14, ["z"] = 2, ["name"] = "default:pine_bush_needles"}, {["x"] = 4, ["y"] = 13, ["param1"] = 14, ["z"] = 2, ["name"] = "default:pine_bush_needles"}, {["x"] = 4, ["y"] = 14, ["param1"] = 14, ["z"] = 1, ["name"] = "default:pine_bush_needles"}, {["x"] = 4, ["y"] = 14, ["param1"] = 14, ["z"] = 2, ["name"] = "default:pine_bush_stem"}, {["x"] = 4, ["y"] = 15, ["param1"] = 14, ["z"] = 2, ["name"] = "default:pine_bush_needles"}}