5:return {{["x"] = 0, ["y"] = 12, ["param1"] = 14, ["z"] = 1, ["name"] = "default:aspen_leaves"}, {["x"] = 0, ["y"] = 12, ["param1"] = 14, ["z"] = 2, ["name"] = "default:aspen_leaves"}, {["x"] = 0, ["y"] = 12, ["param1"] = 14, ["z"] = 6, ["name"] = "default:aspen_leaves"}, {["x"] = 0, ["y"] = 13, ["param1"] = 14, ["z"] = 1, ["name"] = "default:aspen_leaves"}, {["x"] = 0, ["y"] = 13, ["param1"] = 14, ["z"] = 2, ["name"] = "default:aspen_leaves"}, {["x"] = 0, ["y"] = 13, ["param1"] = 14, ["z"] = 4, ["name"] = "default:aspen_leaves"}, {["x"] = 0, ["y"] = 13, ["param1"] = 14, ["z"] = 6, ["name"] = "default:aspen_leaves"}, {["x"] = 0, ["y"] = 13, ["param1"] = 14, ["z"] = 7, ["name"] = "default:aspen_leaves"}, {["x"] = 0, ["y"] = 14, ["param1"] = 14, ["z"] = 2, ["name"] = "default:aspen_leaves"}, {["x"] = 0, ["y"] = 14, ["param1"] = 14, ["z"] = 4, ["name"] = "default:aspen_leaves"}, {["x"] = 0, ["y"] = 14, ["param1"] = 14, ["z"] = 6, ["name"] = "default:aspen_leaves"}, {["x"] = 1, ["y"] = 11, ["param1"] = 14, ["z"] = 5, ["name"] = "default:aspen_leaves"}, {["x"] = 1, ["y"] = 11, ["param1"] = 13, ["z"] = 6, ["name"] = "default:aspen_leaves"}, {["x"] = 1, ["y"] = 12, ["param1"] = 14, ["z"] = 0, ["name"] = "default:aspen_leaves"}, {["x"] = 1, ["y"] = 12, ["param1"] = 13, ["z"] = 2, ["name"] = "default:aspen_leaves"}, {["x"] = 1, ["y"] = 12, ["param1"] = 14, ["z"] = 3, ["name"] = "default:aspen_leaves"}, {["x"] = 1, ["y"] = 12, ["param1"] = 13, ["z"] = 4, ["name"] = "default:aspen_leaves"}, {["x"] = 1, ["y"] = 12, ["param1"] = 14, ["z"] = 5, ["name"] = "default:aspen_leaves"}, {["x"] = 1, ["y"] = 12, ["param1"] = 13, ["z"] = 6, ["name"] = "default:bush_stem"}, {["x"] = 1, ["y"] = 12, ["param1"] = 13, ["z"] = 7, ["name"] = "default:aspen_leaves"}, {["x"] = 1, ["y"] = 13, ["param1"] = 13, ["z"] = 1, ["name"] = "default:aspen_leaves"}, {["x"] = 1, ["y"] = 13, ["param1"] = 13, ["z"] = 2, ["name"] = "default:aspen_leaves"}, {["x"] = 1, ["y"] = 13, ["param1"] = 14, ["z"] = 3, ["name"] = "default:aspen_leaves"}, {["x"] = 1, ["y"] = 13, ["param1"] = 14, ["z"] = 5, ["name"] = "default:aspen_leaves"}, {["x"] = 1, ["y"] = 13, ["param1"] = 13, ["z"] = 6, ["name"] = "default:bush_stem"}, {["x"] = 1, ["y"] = 13, ["param1"] = 13, ["z"] = 7, ["name"] = "default:aspen_leaves"}, {["x"] = 1, ["y"] = 13, ["param1"] = 14, ["z"] = 8, ["name"] = "default:aspen_leaves"}, {["x"] = 1, ["y"] = 14, ["param1"] = 14, ["z"] = 0, ["name"] = "default:aspen_leaves"}, {["x"] = 1, ["y"] = 14, ["param1"] = 14, ["z"] = 1, ["name"] = "default:aspen_leaves"}, {["x"] = 1, ["y"] = 14, ["param1"] = 13, ["z"] = 2, ["name"] = "default:aspen_leaves"}, {["x"] = 1, ["y"] = 14, ["param1"] = 14, ["z"] = 3, ["name"] = "default:aspen_leaves"}, {["x"] = 1, ["y"] = 14, ["param1"] = 14, ["z"] = 5, ["name"] = "default:aspen_leaves"}, {["x"] = 1, ["y"] = 14, ["param1"] = 13, ["z"] = 6, ["name"] = "default:aspen_leaves"}, {["x"] = 1, ["y"] = 14, ["param1"] = 14, ["z"] = 7, ["name"] = "default:aspen_leaves"}, {["x"] = 1, ["y"] = 15, ["param1"] = 14, ["z"] = 2, ["name"] = "default:aspen_leaves"}, {["x"] = 1, ["y"] = 15, ["param1"] = 14, ["z"] = 4, ["name"] = "default:aspen_leaves"}, {["x"] = 1, ["y"] = 15, ["param1"] = 14, ["z"] = 5, ["name"] = "default:aspen_leaves"}, {["x"] = 1, ["y"] = 15, ["param1"] = 14, ["z"] = 6, ["name"] = "default:aspen_leaves"}, {["x"] = 2, ["y"] = 11, ["param1"] = 13, ["z"] = 5, ["name"] = "default:aspen_leaves"}, {["x"] = 2, ["y"] = 12, ["param1"] = 14, ["z"] = 1, ["name"] = "default:aspen_leaves"}, {["x"] = 2, ["y"] = 12, ["param1"] = 13, ["z"] = 2, ["name"] = "default:aspen_leaves"}, {["x"] = 2, ["y"] = 12, ["param1"] = 12, ["z"] = 4, ["name"] = "default:aspen_leaves"}, {["x"] = 2, ["param2"] = 18, ["y"] = 12, ["param1"] = 43, ["z"] = 5, ["name"] = "default:tree"}, {["x"] = 2, ["y"] = 12, ["param1"] = 13, ["z"] = 6, ["name"] = "default:aspen_leaves"}, {["x"] = 2, ["y"] = 12, ["param1"] = 13, ["z"] = 7, ["name"] = "default:aspen_leaves"}, {["x"] = 2, ["y"] = 13, ["param1"] = 14, ["z"] = 1, ["name"] = "default:aspen_leaves"}, {["x"] = 2, ["y"] = 13, ["param1"] = 13, ["z"] = 2, ["name"] = "default:bush_stem"}, {["x"] = 2, ["y"] = 13, ["param1"] = 13, ["z"] = 3, ["name"] = "default:aspen_leaves"}, {["x"] = 2, ["y"] = 13, ["param1"] = 12, ["z"] = 4, ["name"] = "default:aspen_leaves"}, {["x"] = 2, ["y"] = 13, ["param1"] = 43, ["z"] = 5, ["name"] = "default:tree"}, {["x"] = 2, ["param2"] = 7, ["y"] = 13, ["param1"] = 43, ["z"] = 6, ["name"] = "default:tree"}, {["x"] = 2, ["y"] = 13, ["param1"] = 13, ["z"] = 7, ["name"] = "default:bush_stem"}, {["x"] = 2, ["y"] = 13, ["param1"] = 14, ["z"] = 8, ["name"] = "default:aspen_leaves"}, {["x"] = 2, ["y"] = 14, ["param1"] = 14, ["z"] = 1, ["name"] = "default:aspen_leaves"}, {["x"] = 2, ["y"] = 14, ["param1"] = 14, ["z"] = 2, ["name"] = "default:aspen_leaves"}, {["x"] = 2, ["y"] = 14, ["param1"] = 13, ["z"] = 3, ["name"] = "default:aspen_leaves"}, {["x"] = 2, ["y"] = 14, ["param1"] = 13, ["z"] = 4, ["name"] = "default:aspen_leaves"}, {["x"] = 2, ["y"] = 14, ["param1"] = 13, ["z"] = 5, ["name"] = "default:aspen_leaves"}, {["x"] = 2, ["y"] = 14, ["param1"] = 14, ["z"] = 6, ["name"] = "default:aspen_leaves"}, {["x"] = 2, ["y"] = 14, ["param1"] = 14, ["z"] = 7, ["name"] = "default:aspen_leaves"}, {["x"] = 2, ["y"] = 14, ["param1"] = 14, ["z"] = 8, ["name"] = "default:aspen_leaves"}, {["x"] = 2, ["y"] = 15, ["param1"] = 14, ["z"] = 1, ["name"] = "default:aspen_leaves"}, {["x"] = 2, ["y"] = 15, ["param1"] = 14, ["z"] = 3, ["name"] = "default:aspen_leaves"}, {["x"] = 2, ["y"] = 15, ["param1"] = 14, ["z"] = 4, ["name"] = "default:aspen_leaves"}, {["x"] = 2, ["y"] = 15, ["param1"] = 14, ["z"] = 5, ["name"] = "default:aspen_leaves"}, {["x"] = 3, ["y"] = 6, ["param1"] = 12, ["z"] = 5, ["name"] = "default:aspen_leaves"}, {["x"] = 3, ["y"] = 6, ["param1"] = 13, ["z"] = 6, ["name"] = "default:aspen_leaves"}, {["x"] = 3, ["y"] = 7, ["param1"] = 13, ["z"] = 6, ["name"] = "default:aspen_leaves"}, {["x"] = 3, ["y"] = 11, ["param1"] = 12, ["z"] = 4, ["name"] = "default:aspen_leaves"}, {["x"] = 3, ["y"] = 11, ["param1"] = 13, ["z"] = 5, ["name"] = "default:aspen_leaves"}, {["x"] = 3, ["y"] = 11, ["param1"] = 14, ["z"] = 6, ["name"] = "default:aspen_leaves"}, {["x"] = 3, ["y"] = 12, ["param1"] = 14, ["z"] = 0, ["name"] = "default:aspen_leaves"}, {["x"] = 3, ["y"] = 12, ["param1"] = 13, ["z"] = 1, ["name"] = "default:aspen_leaves"}, {["x"] = 3, ["y"] = 12, ["param1"] = 12, ["z"] = 2, ["name"] = "default:aspen_leaves"}, {["x"] = 3, ["y"] = 12, ["param1"] = 13, ["z"] = 3, ["name"] = "default:bush_stem"}, {["x"] = 3, ["param2"] = 18, ["y"] = 12, ["param1"] = 43, ["z"] = 5, ["name"] = "default:tree"}, {["x"] = 3, ["y"] = 12, ["param1"] = 14, ["z"] = 6, ["name"] = "default:bush_stem"}, {["x"] = 3, ["y"] = 12, ["param1"] = 14, ["z"] = 7, ["name"] = "default:aspen_leaves"}, {["x"] = 3, ["y"] = 13, ["param1"] = 13, ["z"] = 1, ["name"] = "default:bush_stem"}, {["x"] = 3, ["param2"] = 18, ["y"] = 13, ["param1"] = 43, ["z"] = 2, ["name"] = "default:tree"}, {["x"] = 3, ["y"] = 13, ["param1"] = 13, ["z"] = 3, ["name"] = "default:bush_stem"}, {["x"] = 3, ["y"] = 13, ["param1"] = 13, ["z"] = 4, ["name"] = "default:bush_stem"}, {["x"] = 3, ["y"] = 13, ["param1"] = 13, ["z"] = 5, ["name"] = "default:aspen_leaves"}, {["x"] = 3, ["y"] = 13, ["param1"] = 14, ["z"] = 6, ["name"] = "default:bush_stem"}, {["x"] = 3, ["y"] = 13, ["param1"] = 14, ["z"] = 7, ["name"] = "default:aspen_leaves"}, {["x"] = 3, ["y"] = 14, ["param1"] = 14, ["z"] = 0, ["name"] = "default:aspen_leaves"}, {["x"] = 3, ["y"] = 14, ["param1"] = 14, ["z"] = 1, ["name"] = "default:aspen_leaves"}, {["x"] = 3, ["y"] = 14, ["param1"] = 13, ["z"] = 2, ["name"] = "default:aspen_leaves"}, {["x"] = 3, ["y"] = 14, ["param1"] = 14, ["z"] = 3, ["name"] = "default:aspen_leaves"}, {["x"] = 3, ["y"] = 14, ["param1"] = 14, ["z"] = 4, ["name"] = "default:aspen_leaves"}, {["x"] = 3, ["y"] = 14, ["param1"] = 14, ["z"] = 5, ["name"] = "default:aspen_leaves"}, {["x"] = 3, ["y"] = 14, ["param1"] = 14, ["z"] = 6, ["name"] = "default:aspen_leaves"}, {["x"] = 3, ["y"] = 14, ["param1"] = 14, ["z"] = 7, ["name"] = "default:aspen_leaves"}, {["x"] = 3, ["y"] = 15, ["param1"] = 14, ["z"] = 2, ["name"] = "default:aspen_leaves"}, {["x"] = 3, ["y"] = 15, ["param1"] = 14, ["z"] = 6, ["name"] = "default:aspen_leaves"}, {["x"] = 3, ["y"] = 15, ["param1"] = 14, ["z"] = 7, ["name"] = "default:aspen_leaves"}, {["x"] = 4, ["y"] = 0, ["param1"] = 43, ["z"] = 4, ["name"] = "default:tree"}, {["x"] = 4, ["y"] = 1, ["param1"] = 43, ["z"] = 4, ["name"] = "default:tree"}, {["x"] = 4, ["y"] = 2, ["param1"] = 43, ["z"] = 4, ["name"] = "default:tree"}, {["x"] = 4, ["y"] = 3, ["param1"] = 43, ["z"] = 4, ["name"] = "default:tree"}, {["x"] = 4, ["y"] = 4, ["param1"] = 43, ["z"] = 4, ["name"] = "default:tree"}, {["x"] = 4, ["y"] = 5, ["param1"] = 43, ["z"] = 4, ["name"] = "default:tree"}, {["x"] = 4, ["y"] = 6, ["param1"] = 43, ["z"] = 4, ["name"] = "default:tree"}, {["x"] = 4, ["y"] = 6, ["param1"] = 12, ["z"] = 5, ["name"] = "default:bush_stem"}, {["x"] = 4, ["y"] = 6, ["param1"] = 13, ["z"] = 6, ["name"] = "default:bush_stem"}, {["x"] = 4, ["y"] = 6, ["param1"] = 13, ["z"] = 7, ["name"] = "default:aspen_leaves"}, {["x"] = 4, ["y"] = 7, ["param1"] = 43, ["z"] = 4, ["name"] = "default:tree"}, {["x"] = 4, ["y"] = 7, ["param1"] = 13, ["z"] = 5, ["name"] = "default:aspen_leaves"}, {["x"] = 4, ["y"] = 7, ["param1"] = 14, ["z"] = 6, ["name"] = "default:aspen_leaves"}, {["x"] = 4, ["y"] = 8, ["param1"] = 12, ["z"] = 3, ["name"] = "default:aspen_leaves"}, {["x"] = 4, ["y"] = 8, ["param1"] = 43, ["z"] = 4, ["name"] = "default:tree"}, {["x"] = 4, ["y"] = 9, ["param1"] = 43, ["z"] = 4, ["name"] = "default:tree"}, {["x"] = 4, ["y"] = 10, ["param1"] = 43, ["z"] = 4, ["name"] = "default:tree"}, {["x"] = 4, ["y"] = 11, ["param1"] = 14, ["z"] = 3, ["name"] = "default:aspen_leaves"}, {["x"] = 4, ["y"] = 11, ["param1"] = 43, ["z"] = 4, ["name"] = "default:tree"}, {["x"] = 4, ["y"] = 11, ["param1"] = 14, ["z"] = 5, ["name"] = "default:aspen_leaves"}, {["x"] = 4, ["y"] = 12, ["param1"] = 14, ["z"] = 0, ["name"] = "default:aspen_leaves"}, {["x"] = 4, ["y"] = 12, ["param1"] = 13, ["z"] = 1, ["name"] = "default:aspen_leaves"}, {["x"] = 4, ["y"] = 12, ["param1"] = 14, ["z"] = 3, ["name"] = "default:aspen_leaves"}, {["x"] = 4, ["y"] = 12, ["param1"] = 43, ["z"] = 4, ["name"] = "default:tree"}, {["x"] = 4, ["param2"] = 12, ["y"] = 12, ["param1"] = 43, ["z"] = 5, ["name"] = "default:tree"}, {["x"] = 4, ["y"] = 13, ["param1"] = 14, ["z"] = 0, ["name"] = "default:aspen_leaves"}, {["x"] = 4, ["y"] = 13, ["param1"] = 13, ["z"] = 1, ["name"] = "default:bush_stem"}, {["x"] = 4, ["param2"] = 9, ["y"] = 13, ["param1"] = 43, ["z"] = 2, ["name"] = "default:tree"}, {["x"] = 4, ["param2"] = 9, ["y"] = 13, ["param1"] = 43, ["z"] = 3, ["name"] = "default:tree"}, {["x"] = 4, ["y"] = 13, ["param1"] = 43, ["z"] = 4, ["name"] = "default:tree"}, {["x"] = 4, ["y"] = 13, ["param1"] = 14, ["z"] = 5, ["name"] = "default:bush_stem"}, {["x"] = 4, ["y"] = 13, ["param1"] = 14, ["z"] = 7, ["name"] = "default:aspen_leaves"}, {["x"] = 4, ["y"] = 13, ["param1"] = 14, ["z"] = 8, ["name"] = "default:aspen_leaves"}, {["x"] = 4, ["y"] = 14, ["param1"] = 14, ["z"] = 0, ["name"] = "default:aspen_leaves"}, {["x"] = 4, ["y"] = 14, ["param1"] = 13, ["z"] = 1, ["name"] = "default:aspen_leaves"}, {["x"] = 4, ["y"] = 14, ["param1"] = 13, ["z"] = 2, ["name"] = "default:aspen_leaves"}, {["x"] = 4, ["y"] = 14, ["param1"] = 14, ["z"] = 3, ["name"] = "default:aspen_leaves"}, {["x"] = 4, ["y"] = 14, ["param1"] = 13, ["z"] = 4, ["name"] = "default:aspen_leaves"}, {["x"] = 4, ["y"] = 14, ["param1"] = 14, ["z"] = 5, ["name"] = "default:aspen_leaves"}, {["x"] = 4, ["y"] = 14, ["param1"] = 14, ["z"] = 7, ["name"] = "default:aspen_leaves"}, {["x"] = 4, ["y"] = 14, ["param1"] = 14, ["z"] = 8, ["name"] = "default:aspen_leaves"}, {["x"] = 4, ["y"] = 15, ["param1"] = 14, ["z"] = 0, ["name"] = "default:aspen_leaves"}, {["x"] = 4, ["y"] = 15, ["param1"] = 14, ["z"] = 1, ["name"] = "default:aspen_leaves"}, {["x"] = 4, ["y"] = 15, ["param1"] = 14, ["z"] = 2, ["name"] = "default:aspen_leaves"}, {["x"] = 4, ["y"] = 15, ["param1"] = 14, ["z"] = 3, ["name"] = "default:aspen_leaves"}, {["x"] = 4, ["y"] = 15, ["param1"] = 14, ["z"] = 4, ["name"] = "default:aspen_leaves"}, {["x"] = 5, ["y"] = 6, ["param1"] = 11, ["z"] = 4, ["name"] = "default:aspen_leaves"}, {["x"] = 5, ["y"] = 6, ["param1"] = 11, ["z"] = 5, ["name"] = "default:aspen_leaves"}, {["x"] = 5, ["y"] = 6, ["param1"] = 12, ["z"] = 6, ["name"] = "default:aspen_leaves"}, {["x"] = 5, ["y"] = 8, ["param1"] = 13, ["z"] = 3, ["name"] = "default:aspen_leaves"}, {["x"] = 5, ["y"] = 8, ["param1"] = 12, ["z"] = 4, ["name"] = "default:bush_stem"}, {["x"] = 5, ["y"] = 8, ["param1"] = 13, ["z"] = 5, ["name"] = "default:aspen_leaves"}, {["x"] = 5, ["y"] = 9, ["param1"] = 14, ["z"] = 3, ["name"] = "default:aspen_leaves"}, {["x"] = 5, ["y"] = 9, ["param1"] = 13, ["z"] = 4, ["name"] = "default:aspen_leaves"}, {["x"] = 5, ["y"] = 9, ["param1"] = 13, ["z"] = 5, ["name"] = "default:aspen_leaves"}, {["x"] = 5, ["y"] = 11, ["param1"] = 13, ["z"] = 5, ["name"] = "default:aspen_leaves"}, {["x"] = 5, ["y"] = 11, ["param1"] = 14, ["z"] = 6, ["name"] = "default:aspen_leaves"}, {["x"] = 5, ["y"] = 12, ["param1"] = 13, ["z"] = 1, ["name"] = "default:aspen_leaves"}, {["x"] = 5, ["param2"] = 12, ["y"] = 12, ["param1"] = 43, ["z"] = 4, ["name"] = "default:tree"}, {["x"] = 5, ["y"] = 12, ["param1"] = 13, ["z"] = 5, ["name"] = "default:aspen_leaves"}, {["x"] = 5, ["y"] = 12, ["param1"] = 14, ["z"] = 6, ["name"] = "default:aspen_leaves"}, {["x"] = 5, ["y"] = 12, ["param1"] = 13, ["z"] = 7, ["name"] = "default:aspen_leaves"}, {["x"] = 5, ["y"] = 13, ["param1"] = 13, ["z"] = 1, ["name"] = "default:aspen_leaves"}, {["x"] = 5, ["y"] = 13, ["param1"] = 14, ["z"] = 2, ["name"] = "default:bush_stem"}, {["x"] = 5, ["y"] = 13, ["param1"] = 14, ["z"] = 4, ["name"] = "default:bush_stem"}, {["x"] = 5, ["y"] = 13, ["param1"] = 13, ["z"] = 5, ["name"] = "default:aspen_leaves"}, {["x"] = 5, ["y"] = 13, ["param1"] = 14, ["z"] = 6, ["name"] = "default:aspen_leaves"}, {["x"] = 5, ["y"] = 13, ["param1"] = 13, ["z"] = 7, ["name"] = "default:aspen_leaves"}, {["x"] = 5, ["y"] = 14, ["param1"] = 14, ["z"] = 0, ["name"] = "default:aspen_leaves"}, {["x"] = 5, ["y"] = 14, ["param1"] = 14, ["z"] = 1, ["name"] = "default:aspen_leaves"}, {["x"] = 5, ["y"] = 14, ["param1"] = 14, ["z"] = 2, ["name"] = "default:aspen_leaves"}, {["x"] = 5, ["y"] = 14, ["param1"] = 14, ["z"] = 4, ["name"] = "default:aspen_leaves"}, {["x"] = 5, ["y"] = 14, ["param1"] = 13, ["z"] = 5, ["name"] = "default:aspen_leaves"}, {["x"] = 5, ["y"] = 14, ["param1"] = 14, ["z"] = 6, ["name"] = "default:aspen_leaves"}, {["x"] = 5, ["y"] = 14, ["param1"] = 14, ["z"] = 8, ["name"] = "default:aspen_leaves"}, {["x"] = 5, ["y"] = 15, ["param1"] = 14, ["z"] = 0, ["name"] = "default:aspen_leaves"}, {["x"] = 5, ["y"] = 15, ["param1"] = 14, ["z"] = 2, ["name"] = "default:aspen_leaves"}, {["x"] = 5, ["y"] = 15, ["param1"] = 14, ["z"] = 4, ["name"] = "default:aspen_leaves"}, {["x"] = 5, ["y"] = 15, ["param1"] = 14, ["z"] = 5, ["name"] = "default:aspen_leaves"}, {["x"] = 5, ["y"] = 15, ["param1"] = 14, ["z"] = 7, ["name"] = "default:aspen_leaves"}, {["x"] = 6, ["y"] = 8, ["param1"] = 12, ["z"] = 3, ["name"] = "default:aspen_leaves"}, {["x"] = 6, ["y"] = 8, ["param1"] = 12, ["z"] = 4, ["name"] = "default:bush_stem"}, {["x"] = 6, ["y"] = 8, ["param1"] = 12, ["z"] = 5, ["name"] = "default:aspen_leaves"}, {["x"] = 6, ["y"] = 9, ["param1"] = 12, ["z"] = 4, ["name"] = "default:aspen_leaves"}, {["x"] = 6, ["y"] = 11, ["param1"] = 13, ["z"] = 2, ["name"] = "default:aspen_leaves"}, {["x"] = 6, ["y"] = 11, ["param1"] = 14, ["z"] = 3, ["name"] = "default:bush_stem"}, {["x"] = 6, ["y"] = 11, ["param1"] = 12, ["z"] = 5, ["name"] = "default:bush_stem"}, {["x"] = 6, ["y"] = 12, ["param1"] = 14, ["z"] = 0, ["name"] = "default:aspen_leaves"}, {["x"] = 6, ["y"] = 12, ["param1"] = 14, ["z"] = 1, ["name"] = "default:aspen_leaves"}, {["x"] = 6, ["y"] = 12, ["param1"] = 13, ["z"] = 2, ["name"] = "default:aspen_leaves"}, {["x"] = 6, ["y"] = 12, ["param1"] = 14, ["z"] = 3, ["name"] = "default:aspen_leaves"}, {["x"] = 6, ["param2"] = 12, ["y"] = 12, ["param1"] = 43, ["z"] = 4, ["name"] = "default:tree"}, {["x"] = 6, ["y"] = 12, ["param1"] = 12, ["z"] = 5, ["name"] = "default:aspen_leaves"}, {["x"] = 6, ["y"] = 12, ["param1"] = 13, ["z"] = 6, ["name"] = "default:aspen_leaves"}, {["x"] = 6, ["y"] = 13, ["param1"] = 14, ["z"] = 0, ["name"] = "default:aspen_leaves"}, {["x"] = 6, ["y"] = 13, ["param1"] = 14, ["z"] = 1, ["name"] = "default:aspen_leaves"}, {["x"] = 6, ["y"] = 13, ["param1"] = 13, ["z"] = 2, ["name"] = "default:bush_stem"}, {["x"] = 6, ["param2"] = 9, ["y"] = 13, ["param1"] = 43, ["z"] = 3, ["name"] = "default:tree"}, {["x"] = 6, ["param2"] = 3, ["y"] = 13, ["param1"] = 43, ["z"] = 4, ["name"] = "default:tree"}, {["x"] = 6, ["param2"] = 7, ["y"] = 13, ["param1"] = 43, ["z"] = 5, ["name"] = "default:tree"}, {["x"] = 6, ["y"] = 13, ["param1"] = 13, ["z"] = 6, ["name"] = "default:bush_stem"}, {["x"] = 6, ["y"] = 13, ["param1"] = 14, ["z"] = 8, ["name"] = "default:aspen_leaves"}, {["x"] = 6, ["y"] = 14, ["param1"] = 14, ["z"] = 0, ["name"] = "default:aspen_leaves"}, {["x"] = 6, ["y"] = 14, ["param1"] = 14, ["z"] = 1, ["name"] = "default:aspen_leaves"}, {["x"] = 6, ["y"] = 14, ["param1"] = 13, ["z"] = 2, ["name"] = "default:aspen_leaves"}, {["x"] = 6, ["y"] = 14, ["param1"] = 14, ["z"] = 3, ["name"] = "default:aspen_leaves"}, {["x"] = 6, ["y"] = 14, ["param1"] = 13, ["z"] = 4, ["name"] = "default:aspen_leaves"}, {["x"] = 6, ["y"] = 14, ["param1"] = 14, ["z"] = 5, ["name"] = "default:aspen_leaves"}, {["x"] = 6, ["y"] = 14, ["param1"] = 13, ["z"] = 6, ["name"] = "default:aspen_leaves"}, {["x"] = 6, ["y"] = 15, ["param1"] = 14, ["z"] = 2, ["name"] = "default:aspen_leaves"}, {["x"] = 6, ["y"] = 15, ["param1"] = 14, ["z"] = 3, ["name"] = "default:aspen_leaves"}, {["x"] = 6, ["y"] = 15, ["param1"] = 14, ["z"] = 4, ["name"] = "default:aspen_leaves"}, {["x"] = 6, ["y"] = 15, ["param1"] = 14, ["z"] = 6, ["name"] = "default:aspen_leaves"}, {["x"] = 6, ["y"] = 15, ["param1"] = 14, ["z"] = 7, ["name"] = "default:aspen_leaves"}, {["x"] = 7, ["y"] = 8, ["param1"] = 13, ["z"] = 4, ["name"] = "default:aspen_leaves"}, {["x"] = 7, ["y"] = 11, ["param1"] = 14, ["z"] = 2, ["name"] = "default:aspen_leaves"}, {["x"] = 7, ["y"] = 11, ["param1"] = 13, ["z"] = 3, ["name"] = "default:bush_stem"}, {["x"] = 7, ["y"] = 11, ["param1"] = 13, ["z"] = 4, ["name"] = "default:aspen_leaves"}, {["x"] = 7, ["y"] = 11, ["param1"] = 13, ["z"] = 5, ["name"] = "default:bush_stem"}, {["x"] = 7, ["y"] = 12, ["param1"] = 14, ["z"] = 0, ["name"] = "default:aspen_leaves"}, {["x"] = 7, ["y"] = 12, ["param1"] = 14, ["z"] = 2, ["name"] = "default:aspen_leaves"}, {["x"] = 7, ["y"] = 12, ["param1"] = 13, ["z"] = 3, ["name"] = "default:aspen_leaves"}, {["x"] = 7, ["y"] = 12, ["param1"] = 13, ["z"] = 4, ["name"] = "default:aspen_leaves"}, {["x"] = 7, ["y"] = 12, ["param1"] = 13, ["z"] = 5, ["name"] = "default:aspen_leaves"}, {["x"] = 7, ["y"] = 12, ["param1"] = 14, ["z"] = 6, ["name"] = "default:aspen_leaves"}, {["x"] = 7, ["y"] = 12, ["param1"] = 14, ["z"] = 7, ["name"] = "default:aspen_leaves"}, {["x"] = 7, ["y"] = 13, ["param1"] = 14, ["z"] = 0, ["name"] = "default:aspen_leaves"}, {["x"] = 7, ["y"] = 13, ["param1"] = 14, ["z"] = 2, ["name"] = "default:aspen_leaves"}, {["x"] = 7, ["y"] = 13, ["param1"] = 13, ["z"] = 3, ["name"] = "default:bush_stem"}, {["x"] = 7, ["y"] = 13, ["param1"] = 13, ["z"] = 4, ["name"] = "default:bush_stem"}, {["x"] = 7, ["y"] = 13, ["param1"] = 13, ["z"] = 5, ["name"] = "default:bush_stem"}, {["x"] = 7, ["y"] = 13, ["param1"] = 14, ["z"] = 6, ["name"] = "default:aspen_leaves"}, {["x"] = 7, ["y"] = 13, ["param1"] = 14, ["z"] = 7, ["name"] = "default:aspen_leaves"}, {["x"] = 7, ["y"] = 14, ["param1"] = 14, ["z"] = 0, ["name"] = "default:aspen_leaves"}, {["x"] = 7, ["y"] = 14, ["param1"] = 14, ["z"] = 3, ["name"] = "default:aspen_leaves"}, {["x"] = 7, ["y"] = 14, ["param1"] = 13, ["z"] = 4, ["name"] = "default:aspen_leaves"}, {["x"] = 7, ["y"] = 14, ["param1"] = 13, ["z"] = 5, ["name"] = "default:aspen_leaves"}, {["x"] = 7, ["y"] = 14, ["param1"] = 14, ["z"] = 6, ["name"] = "default:aspen_leaves"}, {["x"] = 7, ["y"] = 14, ["param1"] = 14, ["z"] = 7, ["name"] = "default:aspen_leaves"}, {["x"] = 7, ["y"] = 15, ["param1"] = 14, ["z"] = 2, ["name"] = "default:aspen_leaves"}, {["x"] = 7, ["y"] = 15, ["param1"] = 14, ["z"] = 4, ["name"] = "default:aspen_leaves"}, {["x"] = 7, ["y"] = 15, ["param1"] = 14, ["z"] = 5, ["name"] = "default:aspen_leaves"}, {["x"] = 7, ["y"] = 15, ["param1"] = 14, ["z"] = 6, ["name"] = "default:aspen_leaves"}, {["x"] = 8, ["y"] = 11, ["param1"] = 14, ["z"] = 3, ["name"] = "default:aspen_leaves"}, {["x"] = 8, ["y"] = 12, ["param1"] = 14, ["z"] = 3, ["name"] = "default:aspen_leaves"}, {["x"] = 8, ["y"] = 12, ["param1"] = 14, ["z"] = 4, ["name"] = "default:aspen_leaves"}, {["x"] = 8, ["y"] = 12, ["param1"] = 14, ["z"] = 5, ["name"] = "default:aspen_leaves"}, {["x"] = 8, ["y"] = 13, ["param1"] = 14, ["z"] = 1, ["name"] = "default:aspen_leaves"}, {["x"] = 8, ["y"] = 13, ["param1"] = 14, ["z"] = 2, ["name"] = "default:aspen_leaves"}, {["x"] = 8, ["y"] = 13, ["param1"] = 14, ["z"] = 3, ["name"] = "default:aspen_leaves"}, {["x"] = 8, ["y"] = 13, ["param1"] = 14, ["z"] = 5, ["name"] = "default:aspen_leaves"}, {["x"] = 8, ["y"] = 14, ["param1"] = 14, ["z"] = 1, ["name"] = "default:aspen_leaves"}, {["x"] = 8, ["y"] = 14, ["param1"] = 14, ["z"] = 4, ["name"] = "default:aspen_leaves"}, {["x"] = 8, ["y"] = 14, ["param1"] = 14, ["z"] = 5, ["name"] = "default:aspen_leaves"}, {["x"] = 8, ["y"] = 14, ["param1"] = 14, ["z"] = 7, ["name"] = "default:aspen_leaves"}, {["x"] = 8, ["y"] = 15, ["param1"] = 14, ["z"] = 3, ["name"] = "default:aspen_leaves"}}