5:return {{["x"] = 0, ["y"] = 11, ["param1"] = 14, ["z"] = 3, ["name"] = "default:jungleleaves"}, {["x"] = 0, ["y"] = 11, ["param1"] = 14, ["z"] = 5, ["name"] = "default:jungleleaves"}, {["x"] = 0, ["y"] = 12, ["param1"] = 14, ["z"] = 2, ["name"] = "default:jungleleaves"}, {["x"] = 0, ["y"] = 12, ["param1"] = 14, ["z"] = 3, ["name"] = "default:jungleleaves"}, {["x"] = 0, ["y"] = 12, ["param1"] = 14, ["z"] = 4, ["name"] = "default:jungleleaves"}, {["x"] = 0, ["y"] = 12, ["param1"] = 14, ["z"] = 5, ["name"] = "default:jungleleaves"}, {["x"] = 1, ["y"] = 6, ["param1"] = 13, ["z"] = 2, ["name"] = "default:jungleleaves"}, {["x"] = 1, ["y"] = 7, ["param1"] = 14, ["z"] = 1, ["name"] = "default:jungleleaves"}, {["x"] = 1, ["y"] = 7, ["param1"] = 13, ["z"] = 2, ["name"] = "default:jungleleaves"}, {["x"] = 1, ["y"] = 7, ["param1"] = 13, ["z"] = 3, ["name"] = "default:jungleleaves"}, {["x"] = 1, ["y"] = 8, ["param1"] = 13, ["z"] = 2, ["name"] = "default:jungleleaves"}, {["x"] = 1, ["y"] = 10, ["param1"] = 13, ["z"] = 3, ["name"] = "default:jungleleaves"}, {["x"] = 1, ["y"] = 10, ["param1"] = 13, ["z"] = 4, ["name"] = "default:jungleleaves"}, {["x"] = 1, ["y"] = 10, ["param1"] = 13, ["z"] = 5, ["name"] = "default:jungleleaves"}, {["x"] = 1, ["y"] = 11, ["param1"] = 13, ["z"] = 2, ["name"] = "default:jungleleaves"}, {["x"] = 1, ["y"] = 11, ["param1"] = 13, ["z"] = 4, ["name"] = "default:jungleleaves"}, {["x"] = 1, ["y"] = 12, ["param1"] = 14, ["z"] = 1, ["name"] = "default:jungleleaves"}, {["x"] = 1, ["y"] = 12, ["param1"] = 13, ["z"] = 2, ["name"] = "default:jungleleaves"}, {["x"] = 1, ["y"] = 12, ["param1"] = 13, ["z"] = 3, ["name"] = "default:jungleleaves"}, {["x"] = 1, ["y"] = 12, ["param1"] = 13, ["z"] = 4, ["name"] = "default:jungleleaves"}, {["x"] = 1, ["y"] = 12, ["param1"] = 14, ["z"] = 5, ["name"] = "default:jungleleaves"}, {["x"] = 1, ["y"] = 12, ["param1"] = 14, ["z"] = 6, ["name"] = "default:jungleleaves"}, {["x"] = 1, ["y"] = 13, ["param1"] = 14, ["z"] = 2, ["name"] = "default:jungleleaves"}, {["x"] = 1, ["y"] = 13, ["param1"] = 14, ["z"] = 3, ["name"] = "default:jungleleaves"}, {["x"] = 1, ["y"] = 13, ["param1"] = 14, ["z"] = 4, ["name"] = "default:jungleleaves"}, {["x"] = 1, ["y"] = 14, ["param1"] = 14, ["z"] = 3, ["name"] = "default:jungleleaves"}, {["x"] = 2, ["y"] = 0, ["param1"] = 12, ["z"] = 2, ["name"] = "default:junglegrass"}, {["x"] = 2, ["param2"] = 1, ["y"] = 0, ["z"] = 3, ["name"] = "default:jungletree"}, {["x"] = 2, ["y"] = 5, ["param1"] = 12, ["z"] = 2, ["name"] = "default:jungleleaves"}, {["x"] = 2, ["y"] = 5, ["param1"] = 12, ["z"] = 4, ["name"] = "default:jungleleaves"}, {["x"] = 2, ["y"] = 6, ["param1"] = 13, ["z"] = 1, ["name"] = "default:jungleleaves"}, {["x"] = 2, ["y"] = 6, ["param1"] = 12, ["z"] = 2, ["name"] = "default:jungleleaves"}, {["x"] = 2, ["y"] = 6, ["param1"] = 12, ["z"] = 3, ["name"] = "default:jungleleaves"}, {["x"] = 2, ["y"] = 6, ["param1"] = 12, ["z"] = 4, ["name"] = "default:jungleleaves"}, {["x"] = 2, ["y"] = 7, ["param1"] = 13, ["z"] = 1, ["name"] = "default:jungleleaves"}, {["x"] = 2, ["y"] = 7, ["param1"] = 49, ["z"] = 2, ["name"] = "default:jungletree"}, {["x"] = 2, ["y"] = 7, ["param1"] = 12, ["z"] = 3, ["name"] = "default:jungleleaves"}, {["x"] = 2, ["y"] = 7, ["param1"] = 12, ["z"] = 4, ["name"] = "default:jungleleaves"}, {["x"] = 2, ["y"] = 8, ["param1"] = 13, ["z"] = 1, ["name"] = "default:jungleleaves"}, {["x"] = 2, ["y"] = 8, ["param1"] = 12, ["z"] = 2, ["name"] = "default:jungleleaves"}, {["x"] = 2, ["y"] = 8, ["param1"] = 12, ["z"] = 4, ["name"] = "default:jungleleaves"}, {["x"] = 2, ["y"] = 9, ["param1"] = 12, ["z"] = 2, ["name"] = "default:jungleleaves"}, {["x"] = 2, ["y"] = 9, ["param1"] = 12, ["z"] = 4, ["name"] = "default:jungleleaves"}, {["x"] = 2, ["y"] = 10, ["param1"] = 12, ["z"] = 3, ["name"] = "default:jungleleaves"}, {["x"] = 2, ["y"] = 10, ["param1"] = 49, ["z"] = 4, ["name"] = "default:jungletree"}, {["x"] = 2, ["y"] = 10, ["param1"] = 13, ["z"] = 5, ["name"] = "default:jungleleaves"}, {["x"] = 2, ["y"] = 11, ["param1"] = 13, ["z"] = 1, ["name"] = "default:jungleleaves"}, {["x"] = 2, ["y"] = 11, ["param1"] = 12, ["z"] = 2, ["name"] = "default:jungleleaves"}, {["x"] = 2, ["y"] = 11, ["param1"] = 12, ["z"] = 4, ["name"] = "default:jungleleaves"}, {["x"] = 2, ["y"] = 11, ["param1"] = 13, ["z"] = 5, ["name"] = "default:jungleleaves"}, {["x"] = 2, ["y"] = 11, ["param1"] = 14, ["z"] = 6, ["name"] = "default:jungleleaves"}, {["x"] = 2, ["y"] = 12, ["param1"] = 14, ["z"] = 0, ["name"] = "default:jungleleaves"}, {["x"] = 2, ["y"] = 12, ["param1"] = 13, ["z"] = 1, ["name"] = "default:jungleleaves"}, {["x"] = 2, ["y"] = 12, ["param1"] = 49, ["z"] = 2, ["name"] = "default:jungletree"}, {["x"] = 2, ["y"] = 12, ["param1"] = 12, ["z"] = 3, ["name"] = "default:jungleleaves"}, {["x"] = 2, ["y"] = 12, ["param1"] = 49, ["z"] = 4, ["name"] = "default:jungletree"}, {["x"] = 2, ["y"] = 12, ["param1"] = 13, ["z"] = 5, ["name"] = "default:jungleleaves"}, {["x"] = 2, ["y"] = 12, ["param1"] = 14, ["z"] = 6, ["name"] = "default:jungleleaves"}, {["x"] = 2, ["y"] = 13, ["param1"] = 14, ["z"] = 1, ["name"] = "default:jungleleaves"}, {["x"] = 2, ["y"] = 13, ["param1"] = 13, ["z"] = 2, ["name"] = "default:jungleleaves"}, {["x"] = 2, ["y"] = 13, ["param1"] = 13, ["z"] = 3, ["name"] = "default:jungleleaves"}, {["x"] = 2, ["y"] = 13, ["param1"] = 13, ["z"] = 4, ["name"] = "default:jungleleaves"}, {["x"] = 2, ["y"] = 13, ["param1"] = 14, ["z"] = 5, ["name"] = "default:jungleleaves"}, {["x"] = 2, ["y"] = 14, ["param1"] = 14, ["z"] = 2, ["name"] = "default:jungleleaves"}, {["x"] = 2, ["y"] = 14, ["param1"] = 14, ["z"] = 3, ["name"] = "default:jungleleaves"}, {["x"] = 2, ["y"] = 14, ["param1"] = 14, ["z"] = 4, ["name"] = "default:jungleleaves"}, {["x"] = 3, ["y"] = 0, ["z"] = 2, ["name"] = "default:jungletree"}, {["x"] = 3, ["y"] = 0, ["param1"] = 49, ["z"] = 3, ["name"] = "default:jungletree"}, {["x"] = 3, ["param2"] = 2, ["y"] = 0, ["z"] = 4, ["name"] = "default:jungletree"}, {["x"] = 3, ["y"] = 1, ["param1"] = 49, ["z"] = 3, ["name"] = "default:jungletree"}, {["x"] = 3, ["y"] = 2, ["param1"] = 49, ["z"] = 3, ["name"] = "default:jungletree"}, {["x"] = 3, ["y"] = 3, ["param1"] = 49, ["z"] = 3, ["name"] = "default:jungletree"}, {["x"] = 3, ["y"] = 4, ["param1"] = 49, ["z"] = 3, ["name"] = "default:jungletree"}, {["x"] = 3, ["y"] = 5, ["param1"] = 13, ["z"] = 1, ["name"] = "default:jungleleaves"}, {["x"] = 3, ["y"] = 5, ["param1"] = 49, ["z"] = 3, ["name"] = "default:jungletree"}, {["x"] = 3, ["y"] = 6, ["param1"] = 13, ["z"] = 1, ["name"] = "default:jungleleaves"}, {["x"] = 3, ["y"] = 6, ["param1"] = 49, ["z"] = 3, ["name"] = "default:jungletree"}, {["x"] = 3, ["y"] = 7, ["param1"] = 13, ["z"] = 1, ["name"] = "default:jungleleaves"}, {["x"] = 3, ["y"] = 7, ["param1"] = 12, ["z"] = 2, ["name"] = "default:jungleleaves"}, {["x"] = 3, ["y"] = 7, ["param1"] = 49, ["z"] = 3, ["name"] = "default:jungletree"}, {["x"] = 3, ["y"] = 7, ["param1"] = 13, ["z"] = 5, ["name"] = "default:jungleleaves"}, {["x"] = 3, ["y"] = 8, ["param1"] = 13, ["z"] = 1, ["name"] = "default:jungleleaves"}, {["x"] = 3, ["y"] = 8, ["param1"] = 12, ["z"] = 2, ["name"] = "default:jungleleaves"}, {["x"] = 3, ["y"] = 8, ["param1"] = 49, ["z"] = 3, ["name"] = "default:jungletree"}, {["x"] = 3, ["y"] = 8, ["param1"] = 12, ["z"] = 4, ["name"] = "default:jungleleaves"}, {["x"] = 3, ["y"] = 8, ["param1"] = 13, ["z"] = 5, ["name"] = "default:jungleleaves"}, {["x"] = 3, ["y"] = 9, ["param1"] = 12, ["z"] = 2, ["name"] = "default:jungleleaves"}, {["x"] = 3, ["y"] = 9, ["param1"] = 49, ["z"] = 3, ["name"] = "default:jungletree"}, {["x"] = 3, ["y"] = 9, ["param1"] = 12, ["z"] = 4, ["name"] = "default:jungleleaves"}, {["x"] = 3, ["y"] = 9, ["param1"] = 13, ["z"] = 5, ["name"] = "default:jungleleaves"}, {["x"] = 3, ["y"] = 10, ["param1"] = 49, ["z"] = 3, ["name"] = "default:jungletree"}, {["x"] = 3, ["y"] = 10, ["param1"] = 12, ["z"] = 4, ["name"] = "default:jungleleaves"}, {["x"] = 3, ["y"] = 10, ["param1"] = 13, ["z"] = 5, ["name"] = "default:jungleleaves"}, {["x"] = 3, ["y"] = 11, ["param1"] = 13, ["z"] = 1, ["name"] = "default:jungleleaves"}, {["x"] = 3, ["y"] = 11, ["param1"] = 49, ["z"] = 3, ["name"] = "default:jungletree"}, {["x"] = 3, ["y"] = 11, ["param1"] = 13, ["z"] = 5, ["name"] = "default:jungleleaves"}, {["x"] = 3, ["y"] = 12, ["param1"] = 14, ["z"] = 0, ["name"] = "default:jungleleaves"}, {["x"] = 3, ["y"] = 12, ["param1"] = 13, ["z"] = 1, ["name"] = "default:jungleleaves"}, {["x"] = 3, ["y"] = 12, ["param1"] = 12, ["z"] = 2, ["name"] = "default:jungleleaves"}, {["x"] = 3, ["y"] = 12, ["param1"] = 12, ["z"] = 3, ["name"] = "default:jungleleaves"}, {["x"] = 3, ["y"] = 12, ["param1"] = 12, ["z"] = 4, ["name"] = "default:jungleleaves"}, {["x"] = 3, ["y"] = 12, ["param1"] = 13, ["z"] = 5, ["name"] = "default:jungleleaves"}, {["x"] = 3, ["y"] = 12, ["param1"] = 14, ["z"] = 6, ["name"] = "default:jungleleaves"}, {["x"] = 3, ["y"] = 13, ["param1"] = 14, ["z"] = 1, ["name"] = "default:jungleleaves"}, {["x"] = 3, ["y"] = 13, ["param1"] = 13, ["z"] = 2, ["name"] = "default:jungleleaves"}, {["x"] = 3, ["y"] = 13, ["param1"] = 13, ["z"] = 3, ["name"] = "default:jungleleaves"}, {["x"] = 3, ["y"] = 13, ["param1"] = 13, ["z"] = 4, ["name"] = "default:jungleleaves"}, {["x"] = 3, ["y"] = 13, ["param1"] = 14, ["z"] = 5, ["name"] = "default:jungleleaves"}, {["x"] = 3, ["y"] = 14, ["param1"] = 14, ["z"] = 2, ["name"] = "default:jungleleaves"}, {["x"] = 3, ["y"] = 14, ["param1"] = 14, ["z"] = 3, ["name"] = "default:jungleleaves"}, {["x"] = 3, ["y"] = 14, ["param1"] = 14, ["z"] = 4, ["name"] = "default:jungleleaves"}, {["x"] = 4, ["y"] = 0, ["param1"] = 12, ["z"] = 2, ["name"] = "default:junglegrass"}, {["x"] = 4, ["param2"] = 3, ["y"] = 0, ["z"] = 3, ["name"] = "default:jungletree"}, {["x"] = 4, ["y"] = 5, ["param1"] = 12, ["z"] = 2, ["name"] = "default:jungleleaves"}, {["x"] = 4, ["y"] = 5, ["param1"] = 12, ["z"] = 4, ["name"] = "default:jungleleaves"}, {["x"] = 4, ["y"] = 6, ["param1"] = 12, ["z"] = 2, ["name"] = "default:jungleleaves"}, {["x"] = 4, ["y"] = 6, ["param1"] = 12, ["z"] = 4, ["name"] = "default:jungleleaves"}, {["x"] = 4, ["y"] = 7, ["param1"] = 13, ["z"] = 1, ["name"] = "default:jungleleaves"}, {["x"] = 4, ["y"] = 7, ["param1"] = 12, ["z"] = 2, ["name"] = "default:jungleleaves"}, {["x"] = 4, ["y"] = 7, ["param1"] = 13, ["z"] = 3, ["name"] = "default:jungleleaves"}, {["x"] = 4, ["y"] = 7, ["param1"] = 12, ["z"] = 4, ["name"] = "default:jungleleaves"}, {["x"] = 4, ["y"] = 8, ["param1"] = 13, ["z"] = 1, ["name"] = "default:jungleleaves"}, {["x"] = 4, ["y"] = 8, ["param1"] = 49, ["z"] = 2, ["name"] = "default:jungletree"}, {["x"] = 4, ["y"] = 8, ["param1"] = 13, ["z"] = 3, ["name"] = "default:jungleleaves"}, {["x"] = 4, ["y"] = 8, ["param1"] = 12, ["z"] = 4, ["name"] = "default:jungleleaves"}, {["x"] = 4, ["y"] = 9, ["param1"] = 13, ["z"] = 1, ["name"] = "default:jungleleaves"}, {["x"] = 4, ["y"] = 9, ["param1"] = 12, ["z"] = 2, ["name"] = "default:jungleleaves"}, {["x"] = 4, ["y"] = 9, ["param1"] = 13, ["z"] = 3, ["name"] = "default:jungleleaves"}, {["x"] = 4, ["y"] = 9, ["param1"] = 49, ["z"] = 4, ["name"] = "default:jungletree"}, {["x"] = 4, ["y"] = 9, ["param1"] = 13, ["z"] = 5, ["name"] = "default:jungleleaves"}, {["x"] = 4, ["y"] = 10, ["param1"] = 13, ["z"] = 3, ["name"] = "default:jungleleaves"}, {["x"] = 4, ["y"] = 10, ["param1"] = 12, ["z"] = 4, ["name"] = "default:jungleleaves"}, {["x"] = 4, ["y"] = 10, ["param1"] = 13, ["z"] = 5, ["name"] = "default:jungleleaves"}, {["x"] = 4, ["y"] = 11, ["param1"] = 13, ["z"] = 1, ["name"] = "default:jungleleaves"}, {["x"] = 4, ["y"] = 11, ["param1"] = 12, ["z"] = 2, ["name"] = "default:jungleleaves"}, {["x"] = 4, ["y"] = 11, ["param1"] = 13, ["z"] = 3, ["name"] = "default:jungleleaves"}, {["x"] = 4, ["y"] = 11, ["param1"] = 12, ["z"] = 4, ["name"] = "default:jungleleaves"}, {["x"] = 4, ["y"] = 11, ["param1"] = 13, ["z"] = 5, ["name"] = "default:jungleleaves"}, {["x"] = 4, ["y"] = 11, ["param1"] = 14, ["z"] = 6, ["name"] = "default:jungleleaves"}, {["x"] = 4, ["y"] = 12, ["param1"] = 14, ["z"] = 0, ["name"] = "default:jungleleaves"}, {["x"] = 4, ["y"] = 12, ["param1"] = 14, ["z"] = 1, ["name"] = "default:jungleleaves"}, {["x"] = 4, ["y"] = 12, ["param1"] = 49, ["z"] = 2, ["name"] = "default:jungletree"}, {["x"] = 4, ["y"] = 12, ["param1"] = 13, ["z"] = 3, ["name"] = "default:jungleleaves"}, {["x"] = 4, ["y"] = 12, ["param1"] = 49, ["z"] = 4, ["name"] = "default:jungletree"}, {["x"] = 4, ["y"] = 12, ["param1"] = 14, ["z"] = 6, ["name"] = "default:jungleleaves"}, {["x"] = 4, ["y"] = 13, ["param1"] = 14, ["z"] = 2, ["name"] = "default:jungleleaves"}, {["x"] = 4, ["y"] = 13, ["param1"] = 13, ["z"] = 3, ["name"] = "default:jungleleaves"}, {["x"] = 4, ["y"] = 13, ["param1"] = 13, ["z"] = 4, ["name"] = "default:jungleleaves"}, {["x"] = 4, ["y"] = 13, ["param1"] = 14, ["z"] = 5, ["name"] = "default:jungleleaves"}, {["x"] = 4, ["y"] = 14, ["param1"] = 14, ["z"] = 2, ["name"] = "default:jungleleaves"}, {["x"] = 4, ["y"] = 14, ["param1"] = 14, ["z"] = 3, ["name"] = "default:jungleleaves"}, {["x"] = 4, ["y"] = 14, ["param1"] = 14, ["z"] = 4, ["name"] = "default:jungleleaves"}, {["x"] = 5, ["y"] = 5, ["param1"] = 14, ["z"] = 3, ["name"] = "default:jungleleaves"}, {["x"] = 5, ["y"] = 6, ["param1"] = 13, ["z"] = 2, ["name"] = "default:jungleleaves"}, {["x"] = 5, ["y"] = 6, ["param1"] = 14, ["z"] = 3, ["name"] = "default:jungleleaves"}, {["x"] = 5, ["y"] = 7, ["param1"] = 13, ["z"] = 2, ["name"] = "default:jungleleaves"}, {["x"] = 5, ["y"] = 7, ["param1"] = 14, ["z"] = 3, ["name"] = "default:jungleleaves"}, {["x"] = 5, ["y"] = 8, ["param1"] = 14, ["z"] = 1, ["name"] = "default:jungleleaves"}, {["x"] = 5, ["y"] = 8, ["param1"] = 13, ["z"] = 2, ["name"] = "default:jungleleaves"}, {["x"] = 5, ["y"] = 8, ["param1"] = 14, ["z"] = 3, ["name"] = "default:jungleleaves"}, {["x"] = 5, ["y"] = 8, ["param1"] = 14, ["z"] = 5, ["name"] = "default:jungleleaves"}, {["x"] = 5, ["y"] = 9, ["param1"] = 13, ["z"] = 2, ["name"] = "default:jungleleaves"}, {["x"] = 5, ["y"] = 9, ["param1"] = 14, ["z"] = 3, ["name"] = "default:jungleleaves"}, {["x"] = 5, ["y"] = 9, ["param1"] = 13, ["z"] = 4, ["name"] = "default:jungleleaves"}, {["x"] = 5, ["y"] = 9, ["param1"] = 14, ["z"] = 5, ["name"] = "default:jungleleaves"}, {["x"] = 5, ["y"] = 10, ["param1"] = 14, ["z"] = 3, ["name"] = "default:jungleleaves"}, {["x"] = 5, ["y"] = 10, ["param1"] = 13, ["z"] = 4, ["name"] = "default:jungleleaves"}, {["x"] = 5, ["y"] = 11, ["param1"] = 13, ["z"] = 2, ["name"] = "default:jungleleaves"}, {["x"] = 5, ["y"] = 11, ["param1"] = 13, ["z"] = 4, ["name"] = "default:jungleleaves"}, {["x"] = 5, ["y"] = 12, ["param1"] = 14, ["z"] = 1, ["name"] = "default:jungleleaves"}, {["x"] = 5, ["y"] = 12, ["param1"] = 13, ["z"] = 2, ["name"] = "default:jungleleaves"}, {["x"] = 5, ["y"] = 12, ["param1"] = 14, ["z"] = 3, ["name"] = "default:jungleleaves"}, {["x"] = 5, ["y"] = 12, ["param1"] = 13, ["z"] = 4, ["name"] = "default:jungleleaves"}, {["x"] = 5, ["y"] = 12, ["param1"] = 14, ["z"] = 5, ["name"] = "default:jungleleaves"}, {["x"] = 5, ["y"] = 13, ["param1"] = 14, ["z"] = 2, ["name"] = "default:jungleleaves"}, {["x"] = 5, ["y"] = 13, ["param1"] = 14, ["z"] = 3, ["name"] = "default:jungleleaves"}, {["x"] = 5, ["y"] = 13, ["param1"] = 14, ["z"] = 4, ["name"] = "default:jungleleaves"}, {["x"] = 5, ["y"] = 13, ["param1"] = 14, ["z"] = 5, ["name"] = "default:jungleleaves"}, {["x"] = 6, ["y"] = 12, ["param1"] = 14, ["z"] = 2, ["name"] = "default:jungleleaves"}, {["x"] = 6, ["y"] = 12, ["param1"] = 14, ["z"] = 4, ["name"] = "default:jungleleaves"}}