5:return {{["x"] = 0, ["y"] = 0, ["param1"] = 14, ["z"] = 0, ["name"] = "default:pine_bush_needles"}, {["x"] = 0, ["y"] = 0, ["param1"] = 14, ["z"] = 1, ["name"] = "default:pine_bush_needles"}, {["x"] = 0, ["y"] = 0, ["param1"] = 14, ["z"] = 2, ["name"] = "default:pine_bush_needles"}, {["x"] = 0, ["y"] = 0, ["param1"] = 14, ["z"] = 3, ["name"] = "default:pine_bush_needles"}, {["x"] = 0, ["y"] = 1, ["param1"] = 14, ["z"] = 0, ["name"] = "default:snow"}, {["x"] = 0, ["y"] = 1, ["param1"] = 14, ["z"] = 1, ["name"] = "default:pine_bush_needles"}, {["x"] = 0, ["y"] = 1, ["param1"] = 14, ["z"] = 2, ["name"] = "default:pine_bush_needles"}, {["x"] = 0, ["y"] = 1, ["param1"] = 14, ["z"] = 3, ["name"] = "default:pine_bush_needles"}, {["x"] = 0, ["y"] = 2, ["param1"] = 14, ["z"] = 1, ["name"] = "default:snow"}, {["x"] = 0, ["y"] = 2, ["param1"] = 14, ["z"] = 2, ["name"] = "default:snow"}, {["x"] = 0, ["y"] = 2, ["param1"] = 14, ["z"] = 3, ["name"] = "default:snow"}, {["x"] = 1, ["y"] = 0, ["param1"] = 14, ["z"] = 0, ["name"] = "default:pine_bush_needles"}, {["x"] = 1, ["y"] = 0, ["param1"] = 13, ["z"] = 1, ["name"] = "default:pine_bush_stem"}, {["x"] = 1, ["y"] = 0, ["param1"] = 13, ["z"] = 2, ["name"] = "default:pine_bush_stem"}, {["x"] = 1, ["y"] = 0, ["param1"] = 14, ["z"] = 3, ["name"] = "default:pine_bush_needles"}, {["x"] = 1, ["y"] = 1, ["param1"] = 14, ["z"] = 0, ["name"] = "default:pine_bush_needles"}, {["x"] = 1, ["y"] = 1, ["param1"] = 13, ["z"] = 1, ["name"] = "default:pine_bush_needles"}, {["x"] = 1, ["y"] = 1, ["param1"] = 13, ["z"] = 2, ["name"] = "default:pine_bush_needles"}, {["x"] = 1, ["y"] = 1, ["param1"] = 14, ["z"] = 3, ["name"] = "default:snow"}, {["x"] = 1, ["y"] = 2, ["param1"] = 14, ["z"] = 0, ["name"] = "default:snow"}, {["x"] = 1, ["y"] = 2, ["param1"] = 14, ["z"] = 1, ["name"] = "default:snow"}, {["x"] = 1, ["y"] = 2, ["param1"] = 14, ["z"] = 2, ["name"] = "default:snow"}, {["x"] = 2, ["y"] = 0, ["param1"] = 14, ["z"] = 0, ["name"] = "default:pine_bush_needles"}, {["x"] = 2, ["y"] = 0, ["param1"] = 14, ["z"] = 1, ["name"] = "default:pine_bush_needles"}, {["x"] = 2, ["y"] = 0, ["param1"] = 14, ["z"] = 2, ["name"] = "default:pine_bush_needles"}, {["x"] = 2, ["y"] = 0, ["param1"] = 14, ["z"] = 3, ["name"] = "default:pine_bush_needles"}, {["x"] = 2, ["y"] = 1, ["param1"] = 14, ["z"] = 0, ["name"] = "default:pine_bush_needles"}, {["x"] = 2, ["y"] = 1, ["param1"] = 14, ["z"] = 1, ["name"] = "default:pine_bush_needles"}, {["x"] = 2, ["y"] = 1, ["param1"] = 14, ["z"] = 2, ["name"] = "default:pine_bush_needles"}, {["x"] = 2, ["y"] = 1, ["param1"] = 14, ["z"] = 3, ["name"] = "default:pine_bush_needles"}, {["x"] = 2, ["y"] = 2, ["param1"] = 14, ["z"] = 0, ["name"] = "default:snow"}, {["x"] = 2, ["y"] = 2, ["param1"] = 14, ["z"] = 1, ["name"] = "default:snow"}, {["x"] = 2, ["y"] = 2, ["param1"] = 14, ["z"] = 2, ["name"] = "default:snow"}, {["x"] = 2, ["y"] = 2, ["param1"] = 14, ["z"] = 3, ["name"] = "default:snow"}}