5:return {{["x"] = 2, ["y"] = 0, ["param1"] = 14, ["z"] = 3, ["name"] = "default:pine_needles"}, {["x"] = 2, ["y"] = 1, ["param1"] = 14, ["z"] = 2, ["name"] = "default:pine_needles"}, {["x"] = 2, ["y"] = 1, ["param1"] = 14, ["z"] = 3, ["name"] = "default:pine_needles"}, {["x"] = 2, ["y"] = 1, ["param1"] = 14, ["z"] = 4, ["name"] = "default:pine_needles"}, {["x"] = 2, ["y"] = 2, ["param1"] = 14, ["z"] = 2, ["name"] = "default:snow"}, {["x"] = 2, ["y"] = 2, ["param1"] = 14, ["z"] = 3, ["name"] = "default:pine_needles"}, {["x"] = 2, ["y"] = 2, ["param1"] = 14, ["z"] = 4, ["name"] = "default:snow"}, {["x"] = 2, ["y"] = 3, ["param1"] = 14, ["z"] = 3, ["name"] = "default:snow"}, {["x"] = 3, ["y"] = 0, ["param1"] = 14, ["z"] = 2, ["name"] = "default:pine_needles"}, {["x"] = 3, ["y"] = 0, ["z"] = 3, ["name"] = "default:pine_tree"}, {["x"] = 3, ["y"] = 0, ["param1"] = 14, ["z"] = 4, ["name"] = "default:pine_needles"}, {["x"] = 3, ["y"] = 1, ["param1"] = 14, ["z"] = 2, ["name"] = "default:pine_needles"}, {["x"] = 3, ["y"] = 1, ["z"] = 3, ["name"] = "default:pine_tree"}, {["x"] = 3, ["y"] = 1, ["param1"] = 14, ["z"] = 4, ["name"] = "default:pine_needles"}, {["x"] = 3, ["y"] = 2, ["param1"] = 14, ["z"] = 2, ["name"] = "default:pine_needles"}, {["x"] = 3, ["y"] = 2, ["z"] = 3, ["name"] = "default:pine_tree"}, {["x"] = 3, ["y"] = 2, ["param1"] = 14, ["z"] = 4, ["name"] = "default:pine_needles"}, {["x"] = 3, ["y"] = 3, ["param1"] = 14, ["z"] = 2, ["name"] = "default:snow"}, {["x"] = 3, ["y"] = 3, ["param1"] = 13, ["z"] = 3, ["name"] = "default:pine_needles"}, {["x"] = 3, ["y"] = 3, ["param1"] = 14, ["z"] = 4, ["name"] = "default:snow"}, {["x"] = 3, ["y"] = 4, ["param1"] = 14, ["z"] = 3, ["name"] = "default:pine_needles"}, {["x"] = 3, ["y"] = 5, ["param1"] = 14, ["z"] = 3, ["name"] = "default:snow"}, {["x"] = 4, ["y"] = 0, ["param1"] = 14, ["z"] = 3, ["name"] = "default:pine_needles"}, {["x"] = 4, ["y"] = 1, ["param1"] = 14, ["z"] = 2, ["name"] = "default:pine_needles"}, {["x"] = 4, ["y"] = 1, ["param1"] = 14, ["z"] = 3, ["name"] = "default:pine_needles"}, {["x"] = 4, ["y"] = 1, ["param1"] = 14, ["z"] = 4, ["name"] = "default:pine_needles"}, {["x"] = 4, ["y"] = 2, ["param1"] = 14, ["z"] = 2, ["name"] = "default:snow"}, {["x"] = 4, ["y"] = 2, ["param1"] = 14, ["z"] = 3, ["name"] = "default:pine_needles"}, {["x"] = 4, ["y"] = 2, ["param1"] = 14, ["z"] = 4, ["name"] = "default:snow"}, {["x"] = 4, ["y"] = 3, ["param1"] = 14, ["z"] = 3, ["name"] = "default:snow"}}