5:return {{["x"] = 1, ["y"] = 0, ["param1"] = 14, ["z"] = 4, ["name"] = "default:pine_needles"}, {["x"] = 2, ["y"] = 0, ["param1"] = 14, ["z"] = 3, ["name"] = "default:pine_needles"}, {["x"] = 2, ["y"] = 0, ["param1"] = 13, ["z"] = 4, ["name"] = "default:pine_needles"}, {["x"] = 2, ["y"] = 0, ["param1"] = 14, ["z"] = 5, ["name"] = "default:pine_needles"}, {["x"] = 2, ["y"] = 1, ["param1"] = 14, ["z"] = 4, ["name"] = "default:pine_needles"}, {["x"] = 2, ["y"] = 3, ["param1"] = 14, ["z"] = 4, ["name"] = "default:pine_needles"}, {["x"] = 3, ["y"] = 0, ["param1"] = 14, ["z"] = 2, ["name"] = "default:pine_needles"}, {["x"] = 3, ["y"] = 0, ["param1"] = 13, ["z"] = 3, ["name"] = "default:pine_needles"}, {["x"] = 3, ["y"] = 0, ["param1"] = 13, ["z"] = 5, ["name"] = "default:pine_needles"}, {["x"] = 3, ["y"] = 0, ["param1"] = 14, ["z"] = 6, ["name"] = "default:pine_needles"}, {["x"] = 3, ["y"] = 1, ["param1"] = 14, ["z"] = 3, ["name"] = "default:pine_needles"}, {["x"] = 3, ["y"] = 1, ["param1"] = 13, ["z"] = 4, ["name"] = "default:pine_needles"}, {["x"] = 3, ["y"] = 1, ["param1"] = 14, ["z"] = 5, ["name"] = "default:pine_needles"}, {["x"] = 3, ["y"] = 2, ["param1"] = 13, ["z"] = 4, ["name"] = "default:pine_needles"}, {["x"] = 3, ["y"] = 3, ["param1"] = 14, ["z"] = 3, ["name"] = "default:pine_needles"}, {["x"] = 3, ["y"] = 3, ["param1"] = 13, ["z"] = 4, ["name"] = "default:pine_needles"}, {["x"] = 3, ["y"] = 3, ["param1"] = 14, ["z"] = 5, ["name"] = "default:pine_needles"}, {["x"] = 3, ["y"] = 4, ["param1"] = 14, ["z"] = 4, ["name"] = "default:pine_needles"}, {["x"] = 4, ["y"] = 0, ["param1"] = 14, ["z"] = 1, ["name"] = "default:pine_needles"}, {["x"] = 4, ["y"] = 0, ["param1"] = 13, ["z"] = 2, ["name"] = "default:pine_needles"}, {["x"] = 4, ["y"] = 0, ["param1"] = 54, ["z"] = 4, ["name"] = "default:pine_tree"}, {["x"] = 4, ["y"] = 0, ["param1"] = 13, ["z"] = 6, ["name"] = "default:pine_needles"}, {["x"] = 4, ["y"] = 0, ["param1"] = 14, ["z"] = 7, ["name"] = "default:pine_needles"}, {["x"] = 4, ["y"] = 1, ["param1"] = 14, ["z"] = 2, ["name"] = "default:pine_needles"}, {["x"] = 4, ["y"] = 1, ["param1"] = 13, ["z"] = 3, ["name"] = "default:pine_needles"}, {["x"] = 4, ["y"] = 1, ["param1"] = 54, ["z"] = 4, ["name"] = "default:pine_tree"}, {["x"] = 4, ["y"] = 1, ["param1"] = 13, ["z"] = 5, ["name"] = "default:pine_needles"}, {["x"] = 4, ["y"] = 1, ["param1"] = 14, ["z"] = 6, ["name"] = "default:pine_needles"}, {["x"] = 4, ["y"] = 2, ["param1"] = 13, ["z"] = 3, ["name"] = "default:pine_needles"}, {["x"] = 4, ["y"] = 2, ["param1"] = 54, ["z"] = 4, ["name"] = "default:pine_tree"}, {["x"] = 4, ["y"] = 2, ["param1"] = 13, ["z"] = 5, ["name"] = "default:pine_needles"}, {["x"] = 4, ["y"] = 3, ["param1"] = 14, ["z"] = 2, ["name"] = "default:pine_needles"}, {["x"] = 4, ["y"] = 3, ["param1"] = 13, ["z"] = 3, ["name"] = "default:pine_needles"}, {["x"] = 4, ["y"] = 3, ["param1"] = 54, ["z"] = 4, ["name"] = "default:pine_tree"}, {["x"] = 4, ["y"] = 3, ["param1"] = 13, ["z"] = 5, ["name"] = "default:pine_needles"}, {["x"] = 4, ["y"] = 3, ["param1"] = 14, ["z"] = 6, ["name"] = "default:pine_needles"}, {["x"] = 4, ["y"] = 4, ["param1"] = 14, ["z"] = 3, ["name"] = "default:pine_needles"}, {["x"] = 4, ["y"] = 4, ["param1"] = 13, ["z"] = 4, ["name"] = "default:pine_needles"}, {["x"] = 4, ["y"] = 4, ["param1"] = 14, ["z"] = 5, ["name"] = "default:pine_needles"}, {["x"] = 4, ["y"] = 5, ["param1"] = 14, ["z"] = 4, ["name"] = "default:pine_needles"}, {["x"] = 4, ["y"] = 6, ["param1"] = 14, ["z"] = 4, ["name"] = "default:pine_needles"}, {["x"] = 5, ["y"] = 0, ["param1"] = 14, ["z"] = 2, ["name"] = "default:pine_needles"}, {["x"] = 5, ["y"] = 0, ["param1"] = 13, ["z"] = 3, ["name"] = "default:pine_needles"}, {["x"] = 5, ["y"] = 0, ["param1"] = 13, ["z"] = 5, ["name"] = "default:pine_needles"}, {["x"] = 5, ["y"] = 0, ["param1"] = 14, ["z"] = 6, ["name"] = "default:pine_needles"}, {["x"] = 5, ["y"] = 1, ["param1"] = 14, ["z"] = 3, ["name"] = "default:pine_needles"}, {["x"] = 5, ["y"] = 1, ["param1"] = 13, ["z"] = 4, ["name"] = "default:pine_needles"}, {["x"] = 5, ["y"] = 1, ["param1"] = 14, ["z"] = 5, ["name"] = "default:pine_needles"}, {["x"] = 5, ["y"] = 2, ["param1"] = 13, ["z"] = 4, ["name"] = "default:pine_needles"}, {["x"] = 5, ["y"] = 3, ["param1"] = 14, ["z"] = 3, ["name"] = "default:pine_needles"}, {["x"] = 5, ["y"] = 3, ["param1"] = 13, ["z"] = 4, ["name"] = "default:pine_needles"}, {["x"] = 5, ["y"] = 3, ["param1"] = 14, ["z"] = 5, ["name"] = "default:pine_needles"}, {["x"] = 5, ["y"] = 4, ["param1"] = 14, ["z"] = 4, ["name"] = "default:pine_needles"}, {["x"] = 6, ["y"] = 0, ["param1"] = 14, ["z"] = 3, ["name"] = "default:pine_needles"}, {["x"] = 6, ["y"] = 0, ["param1"] = 13, ["z"] = 4, ["name"] = "default:pine_needles"}, {["x"] = 6, ["y"] = 0, ["param1"] = 14, ["z"] = 5, ["name"] = "default:pine_needles"}, {["x"] = 6, ["y"] = 1, ["param1"] = 14, ["z"] = 4, ["name"] = "default:pine_needles"}, {["x"] = 6, ["y"] = 3, ["param1"] = 14, ["z"] = 4, ["name"] = "default:pine_needles"}, {["x"] = 7, ["y"] = 0, ["param1"] = 14, ["z"] = 4, ["name"] = "default:pine_needles"}}